return { { ["y"] = 0, ["x"] = 0, ["name"] = "default:dirt_with_grass", ["z"] = 0, ["meta"] = { ["inventory"] = {  }, ["fields"] = {  } }, ["param2"] = 0, ["param1"] = 0 }, { ["y"] = 0, ["x"] = 0, ["name"] = "default:dirt_with_grass", ["z"] = 1, ["meta"] = { ["inventory"] = {  }, ["fields"] = {  } }, ["param2"] = 0, ["param1"] = 0 }, { ["y"] = 0, ["x"] = 0, ["name"] = "default:dirt_with_grass", ["z"] = 2, ["meta"] = { ["inventory"] = {  }, ["fields"] = {  } }, ["param2"] = 0, ["param1"] = 0 }, { ["y"] = 0, ["x"] = 0, ["name"] = "default:dirt_with_grass", ["z"] = 3, ["meta"] = { ["inventory"] = {  }, ["fields"] = {  } }, ["param2"] = 0, ["param1"] = 0 }, { ["y"] = 0, ["x"] = 0, ["name"] = "default:dirt_with_grass", ["z"] = 4, ["meta"] = { ["inventory"] = {  }, ["fields"] = {  } }, ["param2"] = 0, ["param1"] = 0 }, { ["y"] = 0, ["x"] = 0, ["name"] = "default:dirt_with_grass", ["z"] = 5, ["meta"] = { ["inventory"] = {  }, ["fields"] = {  } }, ["param2"] = 0, ["param1"] = 0 }, { ["y"] = 0, ["x"] = 0, ["name"] = "default:dirt_with_grass", ["z"] = 6, ["meta"] = { ["inventory"] = {  }, ["fields"] = {  } }, ["param2"] = 0, ["param1"] = 0 }, { ["y"] = 0, ["x"] = 0, ["name"] = "default:dirt_with_grass", ["z"] = 7, ["meta"] = { ["inventory"] = {  }, ["fields"] = {  } }, ["param2"] = 0, ["param1"] = 0 }, { ["y"] = 0, ["x"] = 0, ["name"] = "default:dirt_with_grass", ["z"] = 8, ["meta"] = { ["inventory"] = {  }, ["fields"] = {  } }, ["param2"] = 0, ["param1"] = 0 }, { ["y"] = 0, ["x"] = 0, ["name"] = "default:dirt_with_grass", ["z"] = 11, ["meta"] = { ["inventory"] = {  }, ["fields"] = {  } }, ["param2"] = 0, ["param1"] = 0 }, { ["y"] = 0, ["x"] = 0, ["name"] = "default:dirt_with_grass", ["z"] = 12, ["meta"] = { ["inventory"] = {  }, ["fields"] = {  } }, ["param2"] = 0, ["param1"] = 0 }, { ["y"] = 0, ["x"] = 0, ["name"] = "default:dirt_with_grass", ["z"] = 13, ["meta"] = { ["inventory"] = {  }, ["fields"] = {  } }, ["param2"] = 0, ["param1"] = 0 }, { ["y"] = 0, ["x"] = 1, ["name"] = "default:dirt_with_grass", ["z"] = 0, ["meta"] = { ["inventory"] = {  }, ["fields"] = {  } }, ["param2"] = 0, ["param1"] = 0 }, { ["y"] = 0, ["x"] = 1, ["name"] = "building_blocks:fakegrass", ["z"] = 1, ["meta"] = { ["inventory"] = {  }, ["fields"] = {  } }, ["param2"] = 0, ["param1"] = 0 }, { ["y"] = 0, ["x"] = 1, ["name"] = "default:dirt_with_grass", ["z"] = 2, ["meta"] = { ["inventory"] = {  }, ["fields"] = {  } }, ["param2"] = 0, ["param1"] = 0 }, { ["y"] = 0, ["x"] = 1, ["name"] = "default:dirt_with_grass", ["z"] = 3, ["meta"] = { ["inventory"] = {  }, ["fields"] = {  } }, ["param2"] = 0, ["param1"] = 0 }, { ["y"] = 0, ["x"] = 1, ["name"] = "default:dirt_with_grass", ["z"] = 4, ["meta"] = { ["inventory"] = {  }, ["fields"] = {  } }, ["param2"] = 0, ["param1"] = 0 }, { ["y"] = 0, ["x"] = 1, ["name"] = "default:dirt_with_grass", ["z"] = 5, ["meta"] = { ["inventory"] = {  }, ["fields"] = {  } }, ["param2"] = 0, ["param1"] = 0 }, { ["y"] = 0, ["x"] = 1, ["name"] = "default:dirt_with_grass", ["z"] = 6, ["meta"] = { ["inventory"] = {  }, ["fields"] = {  } }, ["param2"] = 0, ["param1"] = 0 }, { ["y"] = 0, ["x"] = 1, ["name"] = "default:grass_1", ["z"] = 9, ["meta"] = { ["inventory"] = {  }, ["fields"] = {  } }, ["param2"] = 0, ["param1"] = 15 }, { ["y"] = 0, ["x"] = 1, ["name"] = "default:dirt_with_grass", ["z"] = 14, ["meta"] = { ["inventory"] = {  }, ["fields"] = {  } }, ["param2"] = 0, ["param1"] = 0 }, { ["y"] = 1, ["x"] = 1, ["name"] = "default:grass_4", ["z"] = 6, ["meta"] = { ["inventory"] = {  }, ["fields"] = {  } }, ["param2"] = 0, ["param1"] = 15 }, { ["y"] = 0, ["x"] = 2, ["name"] = "default:dirt_with_grass", ["z"] = 0, ["meta"] = { ["inventory"] = {  }, ["fields"] = {  } }, ["param2"] = 0, ["param1"] = 0 }, { ["y"] = 0, ["x"] = 2, ["name"] = "default:dirt_with_grass", ["z"] = 1, ["meta"] = { ["inventory"] = {  }, ["fields"] = {  } }, ["param2"] = 0, ["param1"] = 0 }, { ["y"] = 0, ["x"] = 2, ["name"] = "default:dirt_with_grass", ["z"] = 2, ["meta"] = { ["inventory"] = {  }, ["fields"] = {  } }, ["param2"] = 0, ["param1"] = 0 }, { ["y"] = 0, ["x"] = 2, ["name"] = "default:dirt_with_grass", ["z"] = 3, ["meta"] = { ["inventory"] = {  }, ["fields"] = {  } }, ["param2"] = 0, ["param1"] = 0 }, { ["y"] = 0, ["x"] = 2, ["name"] = "default:dirt_with_grass", ["z"] = 4, ["meta"] = { ["inventory"] = {  }, ["fields"] = {  } }, ["param2"] = 0, ["param1"] = 0 }, { ["y"] = 0, ["x"] = 2, ["name"] = "default:cobble", ["z"] = 8, ["meta"] = { ["inventory"] = {  }, ["fields"] = {  } }, ["param2"] = 0, ["param1"] = 0 }, { ["y"] = 0, ["x"] = 2, ["name"] = "default:cobble", ["z"] = 9, ["meta"] = { ["inventory"] = {  }, ["fields"] = {  } }, ["param2"] = 0, ["param1"] = 0 }, { ["y"] = 0, ["x"] = 2, ["name"] = "default:cobble", ["z"] = 10, ["meta"] = { ["inventory"] = {  }, ["fields"] = {  } }, ["param2"] = 0, ["param1"] = 0 }, { ["y"] = 0, ["x"] = 2, ["name"] = "default:cobble", ["z"] = 11, ["meta"] = { ["inventory"] = {  }, ["fields"] = {  } }, ["param2"] = 0, ["param1"] = 0 }, { ["y"] = 0, ["x"] = 2, ["name"] = "default:cobble", ["z"] = 12, ["meta"] = { ["inventory"] = {  }, ["fields"] = {  } }, ["param2"] = 0, ["param1"] = 0 }, { ["y"] = 0, ["x"] = 2, ["name"] = "default:cobble", ["z"] = 13, ["meta"] = { ["inventory"] = {  }, ["fields"] = {  } }, ["param2"] = 0, ["param1"] = 0 }, { ["y"] = 1, ["x"] = 2, ["name"] = "default:grass_4", ["z"] = 0, ["meta"] = { ["inventory"] = {  }, ["fields"] = {  } }, ["param2"] = 0, ["param1"] = 15 }, { ["y"] = 1, ["x"] = 2, ["name"] = "default:grass_4", ["z"] = 3, ["meta"] = { ["inventory"] = {  }, ["fields"] = {  } }, ["param2"] = 0, ["param1"] = 15 }, { ["y"] = 1, ["x"] = 2, ["name"] = "default:grass_4", ["z"] = 4, ["meta"] = { ["inventory"] = {  }, ["fields"] = {  } }, ["param2"] = 0, ["param1"] = 15 }, { ["y"] = 1, ["x"] = 2, ["name"] = "default:cobble", ["z"] = 8, ["meta"] = { ["inventory"] = {  }, ["fields"] = {  } }, ["param2"] = 0, ["param1"] = 0 }, { ["y"] = 1, ["x"] = 2, ["name"] = "default:cobble", ["z"] = 9, ["meta"] = { ["inventory"] = {  }, ["fields"] = {  } }, ["param2"] = 0, ["param1"] = 0 }, { ["y"] = 1, ["x"] = 2, ["name"] = "default:cobble", ["z"] = 10, ["meta"] = { ["inventory"] = {  }, ["fields"] = {  } }, ["param2"] = 0, ["param1"] = 0 }, { ["y"] = 1, ["x"] = 2, ["name"] = "default:cobble", ["z"] = 11, ["meta"] = { ["inventory"] = {  }, ["fields"] = {  } }, ["param2"] = 0, ["param1"] = 0 }, { ["y"] = 1, ["x"] = 2, ["name"] = "default:cobble", ["z"] = 12, ["meta"] = { ["inventory"] = {  }, ["fields"] = {  } }, ["param2"] = 0, ["param1"] = 0 }, { ["y"] = 1, ["x"] = 2, ["name"] = "default:cobble", ["z"] = 13, ["meta"] = { ["inventory"] = {  }, ["fields"] = {  } }, ["param2"] = 0, ["param1"] = 0 }, { ["y"] = 2, ["x"] = 2, ["name"] = "default:cobble", ["z"] = 8, ["meta"] = { ["inventory"] = {  }, ["fields"] = {  } }, ["param2"] = 0, ["param1"] = 0 }, { ["y"] = 2, ["x"] = 2, ["name"] = "default:cobble", ["z"] = 9, ["meta"] = { ["inventory"] = {  }, ["fields"] = {  } }, ["param2"] = 0, ["param1"] = 0 }, { ["y"] = 2, ["x"] = 2, ["name"] = "default:cobble", ["z"] = 10, ["meta"] = { ["inventory"] = {  }, ["fields"] = {  } }, ["param2"] = 0, ["param1"] = 0 }, { ["y"] = 2, ["x"] = 2, ["name"] = "default:cobble", ["z"] = 11, ["meta"] = { ["inventory"] = {  }, ["fields"] = {  } }, ["param2"] = 0, ["param1"] = 0 }, { ["y"] = 2, ["x"] = 2, ["name"] = "default:cobble", ["z"] = 12, ["meta"] = { ["inventory"] = {  }, ["fields"] = {  } }, ["param2"] = 0, ["param1"] = 0 }, { ["y"] = 2, ["x"] = 2, ["name"] = "default:cobble", ["z"] = 13, ["meta"] = { ["inventory"] = {  }, ["fields"] = {  } }, ["param2"] = 0, ["param1"] = 0 }, { ["y"] = 3, ["x"] = 2, ["name"] = "default:cobble", ["z"] = 8, ["meta"] = { ["inventory"] = {  }, ["fields"] = {  } }, ["param2"] = 0, ["param1"] = 0 }, { ["y"] = 3, ["x"] = 2, ["name"] = "default:cobble", ["z"] = 9, ["meta"] = { ["inventory"] = {  }, ["fields"] = {  } }, ["param2"] = 0, ["param1"] = 0 }, { ["y"] = 3, ["x"] = 2, ["name"] = "default:cobble", ["z"] = 10, ["meta"] = { ["inventory"] = {  }, ["fields"] = {  } }, ["param2"] = 0, ["param1"] = 0 }, { ["y"] = 3, ["x"] = 2, ["name"] = "default:cobble", ["z"] = 11, ["meta"] = { ["inventory"] = {  }, ["fields"] = {  } }, ["param2"] = 0, ["param1"] = 0 }, { ["y"] = 3, ["x"] = 2, ["name"] = "default:cobble", ["z"] = 12, ["meta"] = { ["inventory"] = {  }, ["fields"] = {  } }, ["param2"] = 0, ["param1"] = 0 }, { ["y"] = 3, ["x"] = 2, ["name"] = "default:cobble", ["z"] = 13, ["meta"] = { ["inventory"] = {  }, ["fields"] = {  } }, ["param2"] = 0, ["param1"] = 0 }, { ["y"] = 4, ["x"] = 2, ["name"] = "default:cobble", ["z"] = 8, ["meta"] = { ["inventory"] = {  }, ["fields"] = {  } }, ["param2"] = 0, ["param1"] = 0 }, { ["y"] = 4, ["x"] = 2, ["name"] = "default:cobble", ["z"] = 9, ["meta"] = { ["inventory"] = {  }, ["fields"] = {  } }, ["param2"] = 0, ["param1"] = 0 }, { ["y"] = 4, ["x"] = 2, ["name"] = "default:cobble", ["z"] = 10, ["meta"] = { ["inventory"] = {  }, ["fields"] = {  } }, ["param2"] = 0, ["param1"] = 0 }, { ["y"] = 4, ["x"] = 2, ["name"] = "default:cobble", ["z"] = 11, ["meta"] = { ["inventory"] = {  }, ["fields"] = {  } }, ["param2"] = 0, ["param1"] = 0 }, { ["y"] = 4, ["x"] = 2, ["name"] = "default:cobble", ["z"] = 12, ["meta"] = { ["inventory"] = {  }, ["fields"] = {  } }, ["param2"] = 0, ["param1"] = 0 }, { ["y"] = 4, ["x"] = 2, ["name"] = "default:cobble", ["z"] = 13, ["meta"] = { ["inventory"] = {  }, ["fields"] = {  } }, ["param2"] = 0, ["param1"] = 0 }, { ["y"] = 0, ["x"] = 3, ["name"] = "default:dirt_with_grass", ["z"] = 0, ["meta"] = { ["inventory"] = {  }, ["fields"] = {  } }, ["param2"] = 0, ["param1"] = 0 }, { ["y"] = 0, ["x"] = 3, ["name"] = "default:dirt_with_grass", ["z"] = 1, ["meta"] = { ["inventory"] = {  }, ["fields"] = {  } }, ["param2"] = 0, ["param1"] = 0 }, { ["y"] = 0, ["x"] = 3, ["name"] = "default:dirt_with_grass", ["z"] = 2, ["meta"] = { ["inventory"] = {  }, ["fields"] = {  } }, ["param2"] = 0, ["param1"] = 0 }, { ["y"] = 0, ["x"] = 3, ["name"] = "default:cobble", ["z"] = 8, ["meta"] = { ["inventory"] = {  }, ["fields"] = {  } }, ["param2"] = 0, ["param1"] = 0 }, { ["y"] = 0, ["x"] = 3, ["name"] = "default:tree", ["z"] = 9, ["meta"] = { ["inventory"] = {  }, ["fields"] = {  } }, ["param2"] = 0, ["param1"] = 10 }, { ["y"] = 0, ["x"] = 3, ["name"] = "default:tree", ["z"] = 10, ["meta"] = { ["inventory"] = {  }, ["fields"] = {  } }, ["param2"] = 0, ["param1"] = 15 }, { ["y"] = 0, ["x"] = 3, ["name"] = "default:tree", ["z"] = 11, ["meta"] = { ["inventory"] = {  }, ["fields"] = {  } }, ["param2"] = 0, ["param1"] = 10 }, { ["y"] = 0, ["x"] = 3, ["name"] = "default:tree", ["z"] = 12, ["meta"] = { ["inventory"] = {  }, ["fields"] = {  } }, ["param2"] = 0, ["param1"] = 10 }, { ["y"] = 0, ["x"] = 3, ["name"] = "default:cobble", ["z"] = 13, ["meta"] = { ["inventory"] = {  }, ["fields"] = {  } }, ["param2"] = 0, ["param1"] = 0 }, { ["y"] = 1, ["x"] = 3, ["name"] = "default:cobble", ["z"] = 8, ["meta"] = { ["inventory"] = {  }, ["fields"] = {  } }, ["param2"] = 0, ["param1"] = 0 }, { ["y"] = 1, ["x"] = 3, ["name"] = "default:tree", ["z"] = 9, ["meta"] = { ["inventory"] = {  }, ["fields"] = {  } }, ["param2"] = 0, ["param1"] = 10 }, { ["y"] = 1, ["x"] = 3, ["name"] = "default:tree", ["z"] = 10, ["meta"] = { ["inventory"] = {  }, ["fields"] = {  } }, ["param2"] = 0, ["param1"] = 15 }, { ["y"] = 1, ["x"] = 3, ["name"] = "default:tree", ["z"] = 11, ["meta"] = { ["inventory"] = {  }, ["fields"] = {  } }, ["param2"] = 0, ["param1"] = 10 }, { ["y"] = 1, ["x"] = 3, ["name"] = "default:tree", ["z"] = 12, ["meta"] = { ["inventory"] = {  }, ["fields"] = {  } }, ["param2"] = 0, ["param1"] = 11 }, { ["y"] = 1, ["x"] = 3, ["name"] = "default:cobble", ["z"] = 13, ["meta"] = { ["inventory"] = {  }, ["fields"] = {  } }, ["param2"] = 0, ["param1"] = 0 }, { ["y"] = 2, ["x"] = 3, ["name"] = "default:cobble", ["z"] = 8, ["meta"] = { ["inventory"] = {  }, ["fields"] = {  } }, ["param2"] = 0, ["param1"] = 0 }, { ["y"] = 2, ["x"] = 3, ["name"] = "default:leaves", ["z"] = 9, ["meta"] = { ["inventory"] = {  }, ["fields"] = {  } }, ["param2"] = 0, ["param1"] = 10 }, { ["y"] = 2, ["x"] = 3, ["name"] = "default:tree", ["z"] = 10, ["meta"] = { ["inventory"] = {  }, ["fields"] = {  } }, ["param2"] = 0, ["param1"] = 15 }, { ["y"] = 2, ["x"] = 3, ["name"] = "default:leaves", ["z"] = 11, ["meta"] = { ["inventory"] = {  }, ["fields"] = {  } }, ["param2"] = 0, ["param1"] = 10 }, { ["y"] = 2, ["x"] = 3, ["name"] = "default:leaves", ["z"] = 12, ["meta"] = { ["inventory"] = {  }, ["fields"] = {  } }, ["param2"] = 0, ["param1"] = 10 }, { ["y"] = 2, ["x"] = 3, ["name"] = "default:cobble", ["z"] = 13, ["meta"] = { ["inventory"] = {  }, ["fields"] = {  } }, ["param2"] = 0, ["param1"] = 0 }, { ["y"] = 3, ["x"] = 3, ["name"] = "default:cobble", ["z"] = 8, ["meta"] = { ["inventory"] = {  }, ["fields"] = {  } }, ["param2"] = 0, ["param1"] = 0 }, { ["y"] = 3, ["x"] = 3, ["name"] = "default:leaves", ["z"] = 9, ["meta"] = { ["inventory"] = {  }, ["fields"] = {  } }, ["param2"] = 0, ["param1"] = 11 }, { ["y"] = 3, ["x"] = 3, ["name"] = "default:tree", ["z"] = 10, ["meta"] = { ["inventory"] = {  }, ["fields"] = {  } }, ["param2"] = 0, ["param1"] = 15 }, { ["y"] = 3, ["x"] = 3, ["name"] = "default:leaves", ["z"] = 11, ["meta"] = { ["inventory"] = {  }, ["fields"] = {  } }, ["param2"] = 0, ["param1"] = 11 }, { ["y"] = 3, ["x"] = 3, ["name"] = "default:leaves", ["z"] = 12, ["meta"] = { ["inventory"] = {  }, ["fields"] = {  } }, ["param2"] = 0, ["param1"] = 11 }, { ["y"] = 3, ["x"] = 3, ["name"] = "default:cobble", ["z"] = 13, ["meta"] = { ["inventory"] = {  }, ["fields"] = {  } }, ["param2"] = 0, ["param1"] = 0 }, { ["y"] = 4, ["x"] = 3, ["name"] = "default:cobble", ["z"] = 8, ["meta"] = { ["inventory"] = {  }, ["fields"] = {  } }, ["param2"] = 0, ["param1"] = 0 }, { ["y"] = 4, ["x"] = 3, ["name"] = "default:leaves", ["z"] = 9, ["meta"] = { ["inventory"] = {  }, ["fields"] = {  } }, ["param2"] = 0, ["param1"] = 12 }, { ["y"] = 4, ["x"] = 3, ["name"] = "default:tree", ["z"] = 10, ["meta"] = { ["inventory"] = {  }, ["fields"] = {  } }, ["param2"] = 0, ["param1"] = 15 }, { ["y"] = 4, ["x"] = 3, ["name"] = "default:leaves", ["z"] = 11, ["meta"] = { ["inventory"] = {  }, ["fields"] = {  } }, ["param2"] = 0, ["param1"] = 12 }, { ["y"] = 4, ["x"] = 3, ["name"] = "default:leaves", ["z"] = 12, ["meta"] = { ["inventory"] = {  }, ["fields"] = {  } }, ["param2"] = 0, ["param1"] = 12 }, { ["y"] = 4, ["x"] = 3, ["name"] = "default:cobble", ["z"] = 13, ["meta"] = { ["inventory"] = {  }, ["fields"] = {  } }, ["param2"] = 0, ["param1"] = 0 }, { ["y"] = 5, ["x"] = 3, ["name"] = "default:leaves", ["z"] = 9, ["meta"] = { ["inventory"] = {  }, ["fields"] = {  } }, ["param2"] = 0, ["param1"] = 13 }, { ["y"] = 5, ["x"] = 3, ["name"] = "default:leaves", ["z"] = 10, ["meta"] = { ["inventory"] = {  }, ["fields"] = {  } }, ["param2"] = 0, ["param1"] = 13 }, { ["y"] = 5, ["x"] = 3, ["name"] = "default:leaves", ["z"] = 11, ["meta"] = { ["inventory"] = {  }, ["fields"] = {  } }, ["param2"] = 0, ["param1"] = 13 }, { ["y"] = 5, ["x"] = 3, ["name"] = "default:leaves", ["z"] = 12, ["meta"] = { ["inventory"] = {  }, ["fields"] = {  } }, ["param2"] = 0, ["param1"] = 13 }, { ["y"] = 0, ["x"] = 4, ["name"] = "default:grass_4", ["z"] = 2, ["meta"] = { ["inventory"] = {  }, ["fields"] = {  } }, ["param2"] = 0, ["param1"] = 15 }, { ["y"] = 0, ["x"] = 4, ["name"] = "default:cobble", ["z"] = 8, ["meta"] = { ["inventory"] = {  }, ["fields"] = {  } }, ["param2"] = 0, ["param1"] = 0 }, { ["y"] = 0, ["x"] = 4, ["name"] = "default:tree", ["z"] = 9, ["meta"] = { ["inventory"] = {  }, ["fields"] = {  } }, ["param2"] = 0, ["param1"] = 11 }, { ["y"] = 0, ["x"] = 4, ["name"] = "default:tree", ["z"] = 10, ["meta"] = { ["inventory"] = {  }, ["fields"] = {  } }, ["param2"] = 0, ["param1"] = 12 }, { ["y"] = 0, ["x"] = 4, ["name"] = "default:tree", ["z"] = 11, ["meta"] = { ["inventory"] = {  }, ["fields"] = {  } }, ["param2"] = 0, ["param1"] = 10 }, { ["y"] = 0, ["x"] = 4, ["name"] = "default:tree", ["z"] = 12, ["meta"] = { ["inventory"] = {  }, ["fields"] = {  } }, ["param2"] = 0, ["param1"] = 9 }, { ["y"] = 0, ["x"] = 4, ["name"] = "default:cobble", ["z"] = 13, ["meta"] = { ["inventory"] = {  }, ["fields"] = {  } }, ["param2"] = 0, ["param1"] = 0 }, { ["y"] = 1, ["x"] = 4, ["name"] = "default:cobble", ["z"] = 8, ["meta"] = { ["inventory"] = {  }, ["fields"] = {  } }, ["param2"] = 0, ["param1"] = 0 }, { ["y"] = 1, ["x"] = 4, ["name"] = "default:tree", ["z"] = 9, ["meta"] = { ["inventory"] = {  }, ["fields"] = {  } }, ["param2"] = 0, ["param1"] = 11 }, { ["y"] = 1, ["x"] = 4, ["name"] = "default:tree", ["z"] = 10, ["meta"] = { ["inventory"] = {  }, ["fields"] = {  } }, ["param2"] = 0, ["param1"] = 12 }, { ["y"] = 1, ["x"] = 4, ["name"] = "default:tree", ["z"] = 11, ["meta"] = { ["inventory"] = {  }, ["fields"] = {  } }, ["param2"] = 0, ["param1"] = 10 }, { ["y"] = 1, ["x"] = 4, ["name"] = "default:tree", ["z"] = 12, ["meta"] = { ["inventory"] = {  }, ["fields"] = {  } }, ["param2"] = 0, ["param1"] = 9 }, { ["y"] = 1, ["x"] = 4, ["name"] = "default:cobble", ["z"] = 13, ["meta"] = { ["inventory"] = {  }, ["fields"] = {  } }, ["param2"] = 0, ["param1"] = 0 }, { ["y"] = 2, ["x"] = 4, ["name"] = "default:cobble", ["z"] = 8, ["meta"] = { ["inventory"] = {  }, ["fields"] = {  } }, ["param2"] = 0, ["param1"] = 0 }, { ["y"] = 2, ["x"] = 4, ["name"] = "default:leaves", ["z"] = 9, ["meta"] = { ["inventory"] = {  }, ["fields"] = {  } }, ["param2"] = 0, ["param1"] = 10 }, { ["y"] = 2, ["x"] = 4, ["name"] = "default:tree", ["z"] = 10, ["meta"] = { ["inventory"] = {  }, ["fields"] = {  } }, ["param2"] = 0, ["param1"] = 12 }, { ["y"] = 2, ["x"] = 4, ["name"] = "default:leaves", ["z"] = 11, ["meta"] = { ["inventory"] = {  }, ["fields"] = {  } }, ["param2"] = 0, ["param1"] = 9 }, { ["y"] = 2, ["x"] = 4, ["name"] = "default:leaves", ["z"] = 12, ["meta"] = { ["inventory"] = {  }, ["fields"] = {  } }, ["param2"] = 0, ["param1"] = 10 }, { ["y"] = 2, ["x"] = 4, ["name"] = "default:cobble", ["z"] = 13, ["meta"] = { ["inventory"] = {  }, ["fields"] = {  } }, ["param2"] = 0, ["param1"] = 0 }, { ["y"] = 3, ["x"] = 4, ["name"] = "default:cobble", ["z"] = 8, ["meta"] = { ["inventory"] = {  }, ["fields"] = {  } }, ["param2"] = 0, ["param1"] = 0 }, { ["y"] = 3, ["x"] = 4, ["name"] = "default:leaves", ["z"] = 9, ["meta"] = { ["inventory"] = {  }, ["fields"] = {  } }, ["param2"] = 0, ["param1"] = 11 }, { ["y"] = 3, ["x"] = 4, ["name"] = "default:leaves", ["z"] = 10, ["meta"] = { ["inventory"] = {  }, ["fields"] = {  } }, ["param2"] = 0, ["param1"] = 10 }, { ["y"] = 3, ["x"] = 4, ["name"] = "default:leaves", ["z"] = 11, ["meta"] = { ["inventory"] = {  }, ["fields"] = {  } }, ["param2"] = 0, ["param1"] = 10 }, { ["y"] = 3, ["x"] = 4, ["name"] = "default:leaves", ["z"] = 12, ["meta"] = { ["inventory"] = {  }, ["fields"] = {  } }, ["param2"] = 0, ["param1"] = 11 }, { ["y"] = 3, ["x"] = 4, ["name"] = "default:cobble", ["z"] = 13, ["meta"] = { ["inventory"] = {  }, ["fields"] = {  } }, ["param2"] = 0, ["param1"] = 0 }, { ["y"] = 4, ["x"] = 4, ["name"] = "default:cobble", ["z"] = 8, ["meta"] = { ["inventory"] = {  }, ["fields"] = {  } }, ["param2"] = 0, ["param1"] = 0 }, { ["y"] = 4, ["x"] = 4, ["name"] = "default:leaves", ["z"] = 9, ["meta"] = { ["inventory"] = {  }, ["fields"] = {  } }, ["param2"] = 0, ["param1"] = 12 }, { ["y"] = 4, ["x"] = 4, ["name"] = "default:leaves", ["z"] = 10, ["meta"] = { ["inventory"] = {  }, ["fields"] = {  } }, ["param2"] = 0, ["param1"] = 11 }, { ["y"] = 4, ["x"] = 4, ["name"] = "default:leaves", ["z"] = 11, ["meta"] = { ["inventory"] = {  }, ["fields"] = {  } }, ["param2"] = 0, ["param1"] = 11 }, { ["y"] = 4, ["x"] = 4, ["name"] = "default:leaves", ["z"] = 12, ["meta"] = { ["inventory"] = {  }, ["fields"] = {  } }, ["param2"] = 0, ["param1"] = 12 }, { ["y"] = 4, ["x"] = 4, ["name"] = "default:cobble", ["z"] = 13, ["meta"] = { ["inventory"] = {  }, ["fields"] = {  } }, ["param2"] = 0, ["param1"] = 0 }, { ["y"] = 5, ["x"] = 4, ["name"] = "default:leaves", ["z"] = 9, ["meta"] = { ["inventory"] = {  }, ["fields"] = {  } }, ["param2"] = 0, ["param1"] = 13 }, { ["y"] = 5, ["x"] = 4, ["name"] = "default:leaves", ["z"] = 10, ["meta"] = { ["inventory"] = {  }, ["fields"] = {  } }, ["param2"] = 0, ["param1"] = 12 }, { ["y"] = 5, ["x"] = 4, ["name"] = "default:leaves", ["z"] = 11, ["meta"] = { ["inventory"] = {  }, ["fields"] = {  } }, ["param2"] = 0, ["param1"] = 12 }, { ["y"] = 5, ["x"] = 4, ["name"] = "default:leaves", ["z"] = 12, ["meta"] = { ["inventory"] = {  }, ["fields"] = {  } }, ["param2"] = 0, ["param1"] = 13 }, { ["y"] = 0, ["x"] = 5, ["name"] = "default:cobble", ["z"] = 1, ["meta"] = { ["inventory"] = {  }, ["fields"] = {  } }, ["param2"] = 0, ["param1"] = 0 }, { ["y"] = 0, ["x"] = 5, ["name"] = "default:cobble", ["z"] = 2, ["meta"] = { ["inventory"] = {  }, ["fields"] = {  } }, ["param2"] = 0, ["param1"] = 0 }, { ["y"] = 0, ["x"] = 5, ["name"] = "default:cobble", ["z"] = 3, ["meta"] = { ["inventory"] = {  }, ["fields"] = {  } }, ["param2"] = 0, ["param1"] = 0 }, { ["y"] = 0, ["x"] = 5, ["name"] = "default:cobble", ["z"] = 4, ["meta"] = { ["inventory"] = {  }, ["fields"] = {  } }, ["param2"] = 0, ["param1"] = 0 }, { ["y"] = 0, ["x"] = 5, ["name"] = "default:cobble", ["z"] = 5, ["meta"] = { ["inventory"] = {  }, ["fields"] = {  } }, ["param2"] = 0, ["param1"] = 0 }, { ["y"] = 0, ["x"] = 5, ["name"] = "default:cobble", ["z"] = 6, ["meta"] = { ["inventory"] = {  }, ["fields"] = {  } }, ["param2"] = 0, ["param1"] = 0 }, { ["y"] = 0, ["x"] = 5, ["name"] = "default:cobble", ["z"] = 7, ["meta"] = { ["inventory"] = {  }, ["fields"] = {  } }, ["param2"] = 0, ["param1"] = 0 }, { ["y"] = 0, ["x"] = 5, ["name"] = "default:cobble", ["z"] = 8, ["meta"] = { ["inventory"] = {  }, ["fields"] = {  } }, ["param2"] = 0, ["param1"] = 0 }, { ["y"] = 0, ["x"] = 5, ["name"] = "default:tree", ["z"] = 9, ["meta"] = { ["inventory"] = {  }, ["fields"] = {  } }, ["param2"] = 0, ["param1"] = 12 }, { ["y"] = 0, ["x"] = 5, ["name"] = "default:tree", ["z"] = 11, ["meta"] = { ["inventory"] = {  }, ["fields"] = {  } }, ["param2"] = 0, ["param1"] = 11 }, { ["y"] = 0, ["x"] = 5, ["name"] = "default:tree", ["z"] = 12, ["meta"] = { ["inventory"] = {  }, ["fields"] = {  } }, ["param2"] = 0, ["param1"] = 9 }, { ["y"] = 0, ["x"] = 5, ["name"] = "default:cobble", ["z"] = 13, ["meta"] = { ["inventory"] = {  }, ["fields"] = {  } }, ["param2"] = 0, ["param1"] = 0 }, { ["y"] = 1, ["x"] = 5, ["name"] = "default:cobble", ["z"] = 1, ["meta"] = { ["inventory"] = {  }, ["fields"] = {  } }, ["param2"] = 0, ["param1"] = 0 }, { ["y"] = 1, ["x"] = 5, ["name"] = "default:cobble", ["z"] = 2, ["meta"] = { ["inventory"] = {  }, ["fields"] = {  } }, ["param2"] = 0, ["param1"] = 0 }, { ["y"] = 1, ["x"] = 5, ["name"] = "default:cobble", ["z"] = 3, ["meta"] = { ["inventory"] = {  }, ["fields"] = {  } }, ["param2"] = 0, ["param1"] = 0 }, { ["y"] = 1, ["x"] = 5, ["name"] = "default:cobble", ["z"] = 4, ["meta"] = { ["inventory"] = {  }, ["fields"] = {  } }, ["param2"] = 0, ["param1"] = 0 }, { ["y"] = 1, ["x"] = 5, ["name"] = "default:cobble", ["z"] = 5, ["meta"] = { ["inventory"] = {  }, ["fields"] = {  } }, ["param2"] = 0, ["param1"] = 0 }, { ["y"] = 1, ["x"] = 5, ["name"] = "default:cobble", ["z"] = 6, ["meta"] = { ["inventory"] = {  }, ["fields"] = {  } }, ["param2"] = 0, ["param1"] = 0 }, { ["y"] = 1, ["x"] = 5, ["name"] = "default:cobble", ["z"] = 7, ["meta"] = { ["inventory"] = {  }, ["fields"] = {  } }, ["param2"] = 0, ["param1"] = 0 }, { ["y"] = 1, ["x"] = 5, ["name"] = "default:cobble", ["z"] = 8, ["meta"] = { ["inventory"] = {  }, ["fields"] = {  } }, ["param2"] = 0, ["param1"] = 0 }, { ["y"] = 1, ["x"] = 5, ["name"] = "default:tree", ["z"] = 9, ["meta"] = { ["inventory"] = {  }, ["fields"] = {  } }, ["param2"] = 0, ["param1"] = 12 }, { ["y"] = 1, ["x"] = 5, ["name"] = "default:tree", ["z"] = 11, ["meta"] = { ["inventory"] = {  }, ["fields"] = {  } }, ["param2"] = 0, ["param1"] = 11 }, { ["y"] = 1, ["x"] = 5, ["name"] = "default:tree", ["z"] = 12, ["meta"] = { ["inventory"] = {  }, ["fields"] = {  } }, ["param2"] = 0, ["param1"] = 9 }, { ["y"] = 1, ["x"] = 5, ["name"] = "default:cobble", ["z"] = 13, ["meta"] = { ["inventory"] = {  }, ["fields"] = {  } }, ["param2"] = 0, ["param1"] = 0 }, { ["y"] = 2, ["x"] = 5, ["name"] = "default:cobble", ["z"] = 1, ["meta"] = { ["inventory"] = {  }, ["fields"] = {  } }, ["param2"] = 0, ["param1"] = 0 }, { ["y"] = 2, ["x"] = 5, ["name"] = "default:cobble", ["z"] = 2, ["meta"] = { ["inventory"] = {  }, ["fields"] = {  } }, ["param2"] = 0, ["param1"] = 0 }, { ["y"] = 2, ["x"] = 5, ["name"] = "default:cobble", ["z"] = 3, ["meta"] = { ["inventory"] = {  }, ["fields"] = {  } }, ["param2"] = 0, ["param1"] = 0 }, { ["y"] = 2, ["x"] = 5, ["name"] = "default:cobble", ["z"] = 4, ["meta"] = { ["inventory"] = {  }, ["fields"] = {  } }, ["param2"] = 0, ["param1"] = 0 }, { ["y"] = 2, ["x"] = 5, ["name"] = "default:cobble", ["z"] = 5, ["meta"] = { ["inventory"] = {  }, ["fields"] = {  } }, ["param2"] = 0, ["param1"] = 0 }, { ["y"] = 2, ["x"] = 5, ["name"] = "default:cobble", ["z"] = 6, ["meta"] = { ["inventory"] = {  }, ["fields"] = {  } }, ["param2"] = 0, ["param1"] = 0 }, { ["y"] = 2, ["x"] = 5, ["name"] = "default:cobble", ["z"] = 7, ["meta"] = { ["inventory"] = {  }, ["fields"] = {  } }, ["param2"] = 0, ["param1"] = 0 }, { ["y"] = 2, ["x"] = 5, ["name"] = "default:cobble", ["z"] = 8, ["meta"] = { ["inventory"] = {  }, ["fields"] = {  } }, ["param2"] = 0, ["param1"] = 0 }, { ["y"] = 2, ["x"] = 5, ["name"] = "default:leaves", ["z"] = 9, ["meta"] = { ["inventory"] = {  }, ["fields"] = {  } }, ["param2"] = 0, ["param1"] = 10 }, { ["y"] = 2, ["x"] = 5, ["name"] = "default:leaves", ["z"] = 10, ["meta"] = { ["inventory"] = {  }, ["fields"] = {  } }, ["param2"] = 0, ["param1"] = 9 }, { ["y"] = 2, ["x"] = 5, ["name"] = "default:leaves", ["z"] = 11, ["meta"] = { ["inventory"] = {  }, ["fields"] = {  } }, ["param2"] = 0, ["param1"] = 9 }, { ["y"] = 2, ["x"] = 5, ["name"] = "default:leaves", ["z"] = 12, ["meta"] = { ["inventory"] = {  }, ["fields"] = {  } }, ["param2"] = 0, ["param1"] = 10 }, { ["y"] = 2, ["x"] = 5, ["name"] = "default:cobble", ["z"] = 13, ["meta"] = { ["inventory"] = {  }, ["fields"] = {  } }, ["param2"] = 0, ["param1"] = 0 }, { ["y"] = 3, ["x"] = 5, ["name"] = "default:cobble", ["z"] = 1, ["meta"] = { ["inventory"] = {  }, ["fields"] = {  } }, ["param2"] = 0, ["param1"] = 0 }, { ["y"] = 3, ["x"] = 5, ["name"] = "default:cobble", ["z"] = 2, ["meta"] = { ["inventory"] = {  }, ["fields"] = {  } }, ["param2"] = 0, ["param1"] = 0 }, { ["y"] = 3, ["x"] = 5, ["name"] = "default:cobble", ["z"] = 3, ["meta"] = { ["inventory"] = {  }, ["fields"] = {  } }, ["param2"] = 0, ["param1"] = 0 }, { ["y"] = 3, ["x"] = 5, ["name"] = "default:cobble", ["z"] = 4, ["meta"] = { ["inventory"] = {  }, ["fields"] = {  } }, ["param2"] = 0, ["param1"] = 0 }, { ["y"] = 3, ["x"] = 5, ["name"] = "default:cobble", ["z"] = 5, ["meta"] = { ["inventory"] = {  }, ["fields"] = {  } }, ["param2"] = 0, ["param1"] = 0 }, { ["y"] = 3, ["x"] = 5, ["name"] = "default:cobble", ["z"] = 6, ["meta"] = { ["inventory"] = {  }, ["fields"] = {  } }, ["param2"] = 0, ["param1"] = 0 }, { ["y"] = 3, ["x"] = 5, ["name"] = "default:cobble", ["z"] = 7, ["meta"] = { ["inventory"] = {  }, ["fields"] = {  } }, ["param2"] = 0, ["param1"] = 0 }, { ["y"] = 3, ["x"] = 5, ["name"] = "default:cobble", ["z"] = 8, ["meta"] = { ["inventory"] = {  }, ["fields"] = {  } }, ["param2"] = 0, ["param1"] = 0 }, { ["y"] = 3, ["x"] = 5, ["name"] = "default:leaves", ["z"] = 9, ["meta"] = { ["inventory"] = {  }, ["fields"] = {  } }, ["param2"] = 0, ["param1"] = 11 }, { ["y"] = 3, ["x"] = 5, ["name"] = "default:leaves", ["z"] = 10, ["meta"] = { ["inventory"] = {  }, ["fields"] = {  } }, ["param2"] = 0, ["param1"] = 10 }, { ["y"] = 3, ["x"] = 5, ["name"] = "default:leaves", ["z"] = 11, ["meta"] = { ["inventory"] = {  }, ["fields"] = {  } }, ["param2"] = 0, ["param1"] = 10 }, { ["y"] = 3, ["x"] = 5, ["name"] = "default:leaves", ["z"] = 12, ["meta"] = { ["inventory"] = {  }, ["fields"] = {  } }, ["param2"] = 0, ["param1"] = 11 }, { ["y"] = 3, ["x"] = 5, ["name"] = "default:cobble", ["z"] = 13, ["meta"] = { ["inventory"] = {  }, ["fields"] = {  } }, ["param2"] = 0, ["param1"] = 0 }, { ["y"] = 4, ["x"] = 5, ["name"] = "default:cobble", ["z"] = 1, ["meta"] = { ["inventory"] = {  }, ["fields"] = {  } }, ["param2"] = 0, ["param1"] = 0 }, { ["y"] = 4, ["x"] = 5, ["name"] = "default:cobble", ["z"] = 2, ["meta"] = { ["inventory"] = {  }, ["fields"] = {  } }, ["param2"] = 0, ["param1"] = 0 }, { ["y"] = 4, ["x"] = 5, ["name"] = "default:cobble", ["z"] = 3, ["meta"] = { ["inventory"] = {  }, ["fields"] = {  } }, ["param2"] = 0, ["param1"] = 0 }, { ["y"] = 4, ["x"] = 5, ["name"] = "default:cobble", ["z"] = 4, ["meta"] = { ["inventory"] = {  }, ["fields"] = {  } }, ["param2"] = 0, ["param1"] = 0 }, { ["y"] = 4, ["x"] = 5, ["name"] = "default:cobble", ["z"] = 5, ["meta"] = { ["inventory"] = {  }, ["fields"] = {  } }, ["param2"] = 0, ["param1"] = 0 }, { ["y"] = 4, ["x"] = 5, ["name"] = "default:cobble", ["z"] = 6, ["meta"] = { ["inventory"] = {  }, ["fields"] = {  } }, ["param2"] = 0, ["param1"] = 0 }, { ["y"] = 4, ["x"] = 5, ["name"] = "default:cobble", ["z"] = 7, ["meta"] = { ["inventory"] = {  }, ["fields"] = {  } }, ["param2"] = 0, ["param1"] = 0 }, { ["y"] = 4, ["x"] = 5, ["name"] = "default:cobble", ["z"] = 8, ["meta"] = { ["inventory"] = {  }, ["fields"] = {  } }, ["param2"] = 0, ["param1"] = 0 }, { ["y"] = 4, ["x"] = 5, ["name"] = "default:leaves", ["z"] = 9, ["meta"] = { ["inventory"] = {  }, ["fields"] = {  } }, ["param2"] = 0, ["param1"] = 12 }, { ["y"] = 4, ["x"] = 5, ["name"] = "default:leaves", ["z"] = 10, ["meta"] = { ["inventory"] = {  }, ["fields"] = {  } }, ["param2"] = 0, ["param1"] = 11 }, { ["y"] = 4, ["x"] = 5, ["name"] = "vines:side", ["z"] = 11, ["meta"] = { ["inventory"] = {  }, ["fields"] = {  } }, ["param2"] = 3, ["param1"] = 11 }, { ["y"] = 4, ["x"] = 5, ["name"] = "default:leaves", ["z"] = 12, ["meta"] = { ["inventory"] = {  }, ["fields"] = {  } }, ["param2"] = 0, ["param1"] = 12 }, { ["y"] = 4, ["x"] = 5, ["name"] = "default:cobble", ["z"] = 13, ["meta"] = { ["inventory"] = {  }, ["fields"] = {  } }, ["param2"] = 0, ["param1"] = 0 }, { ["y"] = 5, ["x"] = 5, ["name"] = "default:leaves", ["z"] = 9, ["meta"] = { ["inventory"] = {  }, ["fields"] = {  } }, ["param2"] = 0, ["param1"] = 13 }, { ["y"] = 5, ["x"] = 5, ["name"] = "default:leaves", ["z"] = 10, ["meta"] = { ["inventory"] = {  }, ["fields"] = {  } }, ["param2"] = 0, ["param1"] = 12 }, { ["y"] = 5, ["x"] = 5, ["name"] = "default:leaves", ["z"] = 11, ["meta"] = { ["inventory"] = {  }, ["fields"] = {  } }, ["param2"] = 0, ["param1"] = 12 }, { ["y"] = 5, ["x"] = 5, ["name"] = "default:leaves", ["z"] = 12, ["meta"] = { ["inventory"] = {  }, ["fields"] = {  } }, ["param2"] = 0, ["param1"] = 13 }, { ["y"] = 0, ["x"] = 6, ["name"] = "default:cobble", ["z"] = 1, ["meta"] = { ["inventory"] = {  }, ["fields"] = {  } }, ["param2"] = 0, ["param1"] = 0 }, { ["y"] = 0, ["x"] = 6, ["name"] = "default:tree", ["z"] = 2, ["meta"] = { ["inventory"] = {  }, ["fields"] = {  } }, ["param2"] = 0, ["param1"] = 15 }, { ["y"] = 0, ["x"] = 6, ["name"] = "default:papyrus", ["z"] = 3, ["meta"] = { ["inventory"] = {  }, ["fields"] = {  } }, ["param2"] = 0, ["param1"] = 12 }, { ["y"] = 0, ["x"] = 6, ["name"] = "default:papyrus", ["z"] = 4, ["meta"] = { ["inventory"] = {  }, ["fields"] = {  } }, ["param2"] = 0, ["param1"] = 13 }, { ["y"] = 0, ["x"] = 6, ["name"] = "default:papyrus", ["z"] = 6, ["meta"] = { ["inventory"] = {  }, ["fields"] = {  } }, ["param2"] = 0, ["param1"] = 13 }, { ["y"] = 0, ["x"] = 6, ["name"] = "default:papyrus", ["z"] = 7, ["meta"] = { ["inventory"] = {  }, ["fields"] = {  } }, ["param2"] = 0, ["param1"] = 12 }, { ["y"] = 0, ["x"] = 6, ["name"] = "default:tree", ["z"] = 8, ["meta"] = { ["inventory"] = {  }, ["fields"] = {  } }, ["param2"] = 0, ["param1"] = 12 }, { ["y"] = 0, ["x"] = 6, ["name"] = "default:tree", ["z"] = 9, ["meta"] = { ["inventory"] = {  }, ["fields"] = {  } }, ["param2"] = 0, ["param1"] = 11 }, { ["y"] = 0, ["x"] = 6, ["name"] = "default:tree", ["z"] = 11, ["meta"] = { ["inventory"] = {  }, ["fields"] = {  } }, ["param2"] = 0, ["param1"] = 10 }, { ["y"] = 0, ["x"] = 6, ["name"] = "default:tree", ["z"] = 12, ["meta"] = { ["inventory"] = {  }, ["fields"] = {  } }, ["param2"] = 0, ["param1"] = 9 }, { ["y"] = 0, ["x"] = 6, ["name"] = "default:cobble", ["z"] = 13, ["meta"] = { ["inventory"] = {  }, ["fields"] = {  } }, ["param2"] = 0, ["param1"] = 0 }, { ["y"] = 1, ["x"] = 6, ["name"] = "locked_sign:sign_wall_locked", ["z"] = 0, ["meta"] = { ["inventory"] = {  }, ["fields"] = { ["infotext"] = "Locked sign, owned by quentin\
   \
Ferme de\
   \
Bois et Bamboo ", ["text"] = "   \
Ferme de\
   \
Bois et Bamboo", ["formspec"] = "size[6,4]textarea[0,0;6.5,3;text;;${text}]button_exit[2,3;2,1;ok;Write]background[-0.5,-0.5;7,5;bg_signs_lib.jpg]", ["__signslib_new_format"] = "1" } }, ["param2"] = 0, ["param1"] = 15 }, { ["y"] = 1, ["x"] = 6, ["name"] = "default:cobble", ["z"] = 1, ["meta"] = { ["inventory"] = {  }, ["fields"] = {  } }, ["param2"] = 0, ["param1"] = 0 }, { ["y"] = 1, ["x"] = 6, ["name"] = "default:tree", ["z"] = 2, ["meta"] = { ["inventory"] = {  }, ["fields"] = {  } }, ["param2"] = 0, ["param1"] = 15 }, { ["y"] = 1, ["x"] = 6, ["name"] = "default:papyrus", ["z"] = 6, ["meta"] = { ["inventory"] = {  }, ["fields"] = {  } }, ["param2"] = 0, ["param1"] = 13 }, { ["y"] = 1, ["x"] = 6, ["name"] = "default:papyrus", ["z"] = 7, ["meta"] = { ["inventory"] = {  }, ["fields"] = {  } }, ["param2"] = 0, ["param1"] = 12 }, { ["y"] = 1, ["x"] = 6, ["name"] = "default:tree", ["z"] = 8, ["meta"] = { ["inventory"] = {  }, ["fields"] = {  } }, ["param2"] = 0, ["param1"] = 12 }, { ["y"] = 1, ["x"] = 6, ["name"] = "default:tree", ["z"] = 9, ["meta"] = { ["inventory"] = {  }, ["fields"] = {  } }, ["param2"] = 0, ["param1"] = 11 }, { ["y"] = 1, ["x"] = 6, ["name"] = "default:tree", ["z"] = 11, ["meta"] = { ["inventory"] = {  }, ["fields"] = {  } }, ["param2"] = 0, ["param1"] = 10 }, { ["y"] = 1, ["x"] = 6, ["name"] = "default:tree", ["z"] = 12, ["meta"] = { ["inventory"] = {  }, ["fields"] = {  } }, ["param2"] = 0, ["param1"] = 10 }, { ["y"] = 1, ["x"] = 6, ["name"] = "default:cobble", ["z"] = 13, ["meta"] = { ["inventory"] = {  }, ["fields"] = {  } }, ["param2"] = 0, ["param1"] = 0 }, { ["y"] = 2, ["x"] = 6, ["name"] = "default:cobble", ["z"] = 1, ["meta"] = { ["inventory"] = {  }, ["fields"] = {  } }, ["param2"] = 0, ["param1"] = 0 }, { ["y"] = 2, ["x"] = 6, ["name"] = "default:tree", ["z"] = 2, ["meta"] = { ["inventory"] = {  }, ["fields"] = {  } }, ["param2"] = 0, ["param1"] = 15 }, { ["y"] = 2, ["x"] = 6, ["name"] = "default:leaves", ["z"] = 3, ["meta"] = { ["inventory"] = {  }, ["fields"] = {  } }, ["param2"] = 0, ["param1"] = 12 }, { ["y"] = 2, ["x"] = 6, ["name"] = "default:leaves", ["z"] = 4, ["meta"] = { ["inventory"] = {  }, ["fields"] = {  } }, ["param2"] = 0, ["param1"] = 13 }, { ["y"] = 2, ["x"] = 6, ["name"] = "default:papyrus", ["z"] = 6, ["meta"] = { ["inventory"] = {  }, ["fields"] = {  } }, ["param2"] = 0, ["param1"] = 13 }, { ["y"] = 2, ["x"] = 6, ["name"] = "default:papyrus", ["z"] = 7, ["meta"] = { ["inventory"] = {  }, ["fields"] = {  } }, ["param2"] = 0, ["param1"] = 12 }, { ["y"] = 2, ["x"] = 6, ["name"] = "default:tree", ["z"] = 8, ["meta"] = { ["inventory"] = {  }, ["fields"] = {  } }, ["param2"] = 0, ["param1"] = 12 }, { ["y"] = 2, ["x"] = 6, ["name"] = "default:tree", ["z"] = 9, ["meta"] = { ["inventory"] = {  }, ["fields"] = {  } }, ["param2"] = 0, ["param1"] = 11 }, { ["y"] = 2, ["x"] = 6, ["name"] = "default:leaves", ["z"] = 11, ["meta"] = { ["inventory"] = {  }, ["fields"] = {  } }, ["param2"] = 0, ["param1"] = 9 }, { ["y"] = 2, ["x"] = 6, ["name"] = "default:leaves", ["z"] = 12, ["meta"] = { ["inventory"] = {  }, ["fields"] = {  } }, ["param2"] = 0, ["param1"] = 10 }, { ["y"] = 2, ["x"] = 6, ["name"] = "default:cobble", ["z"] = 13, ["meta"] = { ["inventory"] = {  }, ["fields"] = {  } }, ["param2"] = 0, ["param1"] = 0 }, { ["y"] = 3, ["x"] = 6, ["name"] = "default:cobble", ["z"] = 1, ["meta"] = { ["inventory"] = {  }, ["fields"] = {  } }, ["param2"] = 0, ["param1"] = 0 }, { ["y"] = 3, ["x"] = 6, ["name"] = "default:tree", ["z"] = 2, ["meta"] = { ["inventory"] = {  }, ["fields"] = {  } }, ["param2"] = 0, ["param1"] = 15 }, { ["y"] = 3, ["x"] = 6, ["name"] = "default:leaves", ["z"] = 3, ["meta"] = { ["inventory"] = {  }, ["fields"] = {  } }, ["param2"] = 0, ["param1"] = 12 }, { ["y"] = 3, ["x"] = 6, ["name"] = "default:leaves", ["z"] = 4, ["meta"] = { ["inventory"] = {  }, ["fields"] = {  } }, ["param2"] = 0, ["param1"] = 13 }, { ["y"] = 3, ["x"] = 6, ["name"] = "default:papyrus", ["z"] = 6, ["meta"] = { ["inventory"] = {  }, ["fields"] = {  } }, ["param2"] = 0, ["param1"] = 13 }, { ["y"] = 3, ["x"] = 6, ["name"] = "default:leaves", ["z"] = 7, ["meta"] = { ["inventory"] = {  }, ["fields"] = {  } }, ["param2"] = 0, ["param1"] = 12 }, { ["y"] = 3, ["x"] = 6, ["name"] = "default:leaves", ["z"] = 9, ["meta"] = { ["inventory"] = {  }, ["fields"] = {  } }, ["param2"] = 0, ["param1"] = 10 }, { ["y"] = 3, ["x"] = 6, ["name"] = "vines:side", ["z"] = 11, ["meta"] = { ["inventory"] = {  }, ["fields"] = {  } }, ["param2"] = 3, ["param1"] = 10 }, { ["y"] = 3, ["x"] = 6, ["name"] = "default:leaves", ["z"] = 12, ["meta"] = { ["inventory"] = {  }, ["fields"] = {  } }, ["param2"] = 0, ["param1"] = 11 }, { ["y"] = 3, ["x"] = 6, ["name"] = "default:cobble", ["z"] = 13, ["meta"] = { ["inventory"] = {  }, ["fields"] = {  } }, ["param2"] = 0, ["param1"] = 0 }, { ["y"] = 4, ["x"] = 6, ["name"] = "default:cobble", ["z"] = 1, ["meta"] = { ["inventory"] = {  }, ["fields"] = {  } }, ["param2"] = 0, ["param1"] = 0 }, { ["y"] = 4, ["x"] = 6, ["name"] = "default:leaves", ["z"] = 2, ["meta"] = { ["inventory"] = {  }, ["fields"] = {  } }, ["param2"] = 0, ["param1"] = 13 }, { ["y"] = 4, ["x"] = 6, ["name"] = "default:leaves", ["z"] = 3, ["meta"] = { ["inventory"] = {  }, ["fields"] = {  } }, ["param2"] = 0, ["param1"] = 13 }, { ["y"] = 4, ["x"] = 6, ["name"] = "vines:side", ["z"] = 4, ["meta"] = { ["inventory"] = {  }, ["fields"] = {  } }, ["param2"] = 5, ["param1"] = 15 }, { ["y"] = 4, ["x"] = 6, ["name"] = "vines:side", ["z"] = 6, ["meta"] = { ["inventory"] = {  }, ["fields"] = {  } }, ["param2"] = 4, ["param1"] = 13 }, { ["y"] = 4, ["x"] = 6, ["name"] = "default:leaves", ["z"] = 7, ["meta"] = { ["inventory"] = {  }, ["fields"] = {  } }, ["param2"] = 0, ["param1"] = 12 }, { ["y"] = 4, ["x"] = 6, ["name"] = "default:leaves", ["z"] = 9, ["meta"] = { ["inventory"] = {  }, ["fields"] = {  } }, ["param2"] = 0, ["param1"] = 11 }, { ["y"] = 4, ["x"] = 6, ["name"] = "default:leaves", ["z"] = 10, ["meta"] = { ["inventory"] = {  }, ["fields"] = {  } }, ["param2"] = 0, ["param1"] = 11 }, { ["y"] = 4, ["x"] = 6, ["name"] = "default:leaves", ["z"] = 11, ["meta"] = { ["inventory"] = {  }, ["fields"] = {  } }, ["param2"] = 0, ["param1"] = 11 }, { ["y"] = 4, ["x"] = 6, ["name"] = "default:leaves", ["z"] = 12, ["meta"] = { ["inventory"] = {  }, ["fields"] = {  } }, ["param2"] = 0, ["param1"] = 12 }, { ["y"] = 4, ["x"] = 6, ["name"] = "default:cobble", ["z"] = 13, ["meta"] = { ["inventory"] = {  }, ["fields"] = {  } }, ["param2"] = 0, ["param1"] = 0 }, { ["y"] = 5, ["x"] = 6, ["name"] = "default:leaves", ["z"] = 6, ["meta"] = { ["inventory"] = {  }, ["fields"] = {  } }, ["param2"] = 0, ["param1"] = 13 }, { ["y"] = 5, ["x"] = 6, ["name"] = "default:leaves", ["z"] = 7, ["meta"] = { ["inventory"] = {  }, ["fields"] = {  } }, ["param2"] = 0, ["param1"] = 13 }, { ["y"] = 5, ["x"] = 6, ["name"] = "default:leaves", ["z"] = 9, ["meta"] = { ["inventory"] = {  }, ["fields"] = {  } }, ["param2"] = 0, ["param1"] = 12 }, { ["y"] = 5, ["x"] = 6, ["name"] = "default:leaves", ["z"] = 10, ["meta"] = { ["inventory"] = {  }, ["fields"] = {  } }, ["param2"] = 0, ["param1"] = 12 }, { ["y"] = 5, ["x"] = 6, ["name"] = "default:leaves", ["z"] = 11, ["meta"] = { ["inventory"] = {  }, ["fields"] = {  } }, ["param2"] = 0, ["param1"] = 12 }, { ["y"] = 5, ["x"] = 6, ["name"] = "default:leaves", ["z"] = 12, ["meta"] = { ["inventory"] = {  }, ["fields"] = {  } }, ["param2"] = 0, ["param1"] = 13 }, { ["y"] = 0, ["x"] = 7, ["name"] = "vines:side", ["z"] = 0, ["meta"] = { ["inventory"] = {  }, ["fields"] = {  } }, ["param2"] = 4, ["param1"] = 15 }, { ["y"] = 0, ["x"] = 7, ["name"] = "default:papyrus", ["z"] = 2, ["meta"] = { ["inventory"] = {  }, ["fields"] = {  } }, ["param2"] = 0, ["param1"] = 12 }, { ["y"] = 0, ["x"] = 7, ["name"] = "default:papyrus", ["z"] = 3, ["meta"] = { ["inventory"] = {  }, ["fields"] = {  } }, ["param2"] = 0, ["param1"] = 12 }, { ["y"] = 0, ["x"] = 7, ["name"] = "default:papyrus", ["z"] = 4, ["meta"] = { ["inventory"] = {  }, ["fields"] = {  } }, ["param2"] = 0, ["param1"] = 13 }, { ["y"] = 0, ["x"] = 7, ["name"] = "default:papyrus", ["z"] = 6, ["meta"] = { ["inventory"] = {  }, ["fields"] = {  } }, ["param2"] = 0, ["param1"] = 13 }, { ["y"] = 0, ["x"] = 7, ["name"] = "default:papyrus", ["z"] = 7, ["meta"] = { ["inventory"] = {  }, ["fields"] = {  } }, ["param2"] = 0, ["param1"] = 12 }, { ["y"] = 0, ["x"] = 7, ["name"] = "default:tree", ["z"] = 12, ["meta"] = { ["inventory"] = {  }, ["fields"] = {  } }, ["param2"] = 0, ["param1"] = 10 }, { ["y"] = 0, ["x"] = 7, ["name"] = "default:cobble", ["z"] = 13, ["meta"] = { ["inventory"] = {  }, ["fields"] = {  } }, ["param2"] = 0, ["param1"] = 0 }, { ["y"] = 1, ["x"] = 7, ["name"] = "vines:side", ["z"] = 0, ["meta"] = { ["inventory"] = {  }, ["fields"] = {  } }, ["param2"] = 4, ["param1"] = 15 }, { ["y"] = 1, ["x"] = 7, ["name"] = "default:papyrus", ["z"] = 6, ["meta"] = { ["inventory"] = {  }, ["fields"] = {  } }, ["param2"] = 0, ["param1"] = 13 }, { ["y"] = 1, ["x"] = 7, ["name"] = "default:papyrus", ["z"] = 7, ["meta"] = { ["inventory"] = {  }, ["fields"] = {  } }, ["param2"] = 0, ["param1"] = 12 }, { ["y"] = 1, ["x"] = 7, ["name"] = "default:tree", ["z"] = 12, ["meta"] = { ["inventory"] = {  }, ["fields"] = {  } }, ["param2"] = 0, ["param1"] = 10 }, { ["y"] = 1, ["x"] = 7, ["name"] = "default:cobble", ["z"] = 13, ["meta"] = { ["inventory"] = {  }, ["fields"] = {  } }, ["param2"] = 0, ["param1"] = 0 }, { ["y"] = 2, ["x"] = 7, ["name"] = "vines:side", ["z"] = 0, ["meta"] = { ["inventory"] = {  }, ["fields"] = {  } }, ["param2"] = 4, ["param1"] = 15 }, { ["y"] = 2, ["x"] = 7, ["name"] = "default:leaves", ["z"] = 1, ["meta"] = { ["inventory"] = {  }, ["fields"] = {  } }, ["param2"] = 0, ["param1"] = 13 }, { ["y"] = 2, ["x"] = 7, ["name"] = "default:leaves", ["z"] = 2, ["meta"] = { ["inventory"] = {  }, ["fields"] = {  } }, ["param2"] = 0, ["param1"] = 12 }, { ["y"] = 2, ["x"] = 7, ["name"] = "default:leaves", ["z"] = 3, ["meta"] = { ["inventory"] = {  }, ["fields"] = {  } }, ["param2"] = 0, ["param1"] = 12 }, { ["y"] = 2, ["x"] = 7, ["name"] = "default:papyrus", ["z"] = 6, ["meta"] = { ["inventory"] = {  }, ["fields"] = {  } }, ["param2"] = 0, ["param1"] = 13 }, { ["y"] = 2, ["x"] = 7, ["name"] = "default:papyrus", ["z"] = 7, ["meta"] = { ["inventory"] = {  }, ["fields"] = {  } }, ["param2"] = 0, ["param1"] = 12 }, { ["y"] = 2, ["x"] = 7, ["name"] = "default:leaves", ["z"] = 11, ["meta"] = { ["inventory"] = {  }, ["fields"] = {  } }, ["param2"] = 0, ["param1"] = 10 }, { ["y"] = 2, ["x"] = 7, ["name"] = "default:leaves", ["z"] = 12, ["meta"] = { ["inventory"] = {  }, ["fields"] = {  } }, ["param2"] = 0, ["param1"] = 10 }, { ["y"] = 2, ["x"] = 7, ["name"] = "default:cobble", ["z"] = 13, ["meta"] = { ["inventory"] = {  }, ["fields"] = {  } }, ["param2"] = 0, ["param1"] = 0 }, { ["y"] = 3, ["x"] = 7, ["name"] = "vines:side", ["z"] = 0, ["meta"] = { ["inventory"] = {  }, ["fields"] = {  } }, ["param2"] = 4, ["param1"] = 15 }, { ["y"] = 3, ["x"] = 7, ["name"] = "default:leaves", ["z"] = 1, ["meta"] = { ["inventory"] = {  }, ["fields"] = {  } }, ["param2"] = 0, ["param1"] = 13 }, { ["y"] = 3, ["x"] = 7, ["name"] = "default:leaves", ["z"] = 2, ["meta"] = { ["inventory"] = {  }, ["fields"] = {  } }, ["param2"] = 0, ["param1"] = 12 }, { ["y"] = 3, ["x"] = 7, ["name"] = "default:leaves", ["z"] = 3, ["meta"] = { ["inventory"] = {  }, ["fields"] = {  } }, ["param2"] = 0, ["param1"] = 12 }, { ["y"] = 3, ["x"] = 7, ["name"] = "default:leaves", ["z"] = 6, ["meta"] = { ["inventory"] = {  }, ["fields"] = {  } }, ["param2"] = 0, ["param1"] = 13 }, { ["y"] = 3, ["x"] = 7, ["name"] = "default:leaves", ["z"] = 7, ["meta"] = { ["inventory"] = {  }, ["fields"] = {  } }, ["param2"] = 0, ["param1"] = 12 }, { ["y"] = 3, ["x"] = 7, ["name"] = "default:leaves", ["z"] = 8, ["meta"] = { ["inventory"] = {  }, ["fields"] = {  } }, ["param2"] = 0, ["param1"] = 11 }, { ["y"] = 3, ["x"] = 7, ["name"] = "default:leaves", ["z"] = 10, ["meta"] = { ["inventory"] = {  }, ["fields"] = {  } }, ["param2"] = 0, ["param1"] = 10 }, { ["y"] = 3, ["x"] = 7, ["name"] = "default:leaves", ["z"] = 11, ["meta"] = { ["inventory"] = {  }, ["fields"] = {  } }, ["param2"] = 0, ["param1"] = 11 }, { ["y"] = 3, ["x"] = 7, ["name"] = "default:leaves", ["z"] = 12, ["meta"] = { ["inventory"] = {  }, ["fields"] = {  } }, ["param2"] = 0, ["param1"] = 11 }, { ["y"] = 3, ["x"] = 7, ["name"] = "default:cobble", ["z"] = 13, ["meta"] = { ["inventory"] = {  }, ["fields"] = {  } }, ["param2"] = 0, ["param1"] = 0 }, { ["y"] = 4, ["x"] = 7, ["name"] = "vines:side", ["z"] = 0, ["meta"] = { ["inventory"] = {  }, ["fields"] = {  } }, ["param2"] = 4, ["param1"] = 15 }, { ["y"] = 4, ["x"] = 7, ["name"] = "default:leaves", ["z"] = 1, ["meta"] = { ["inventory"] = {  }, ["fields"] = {  } }, ["param2"] = 0, ["param1"] = 13 }, { ["y"] = 4, ["x"] = 7, ["name"] = "default:leaves", ["z"] = 2, ["meta"] = { ["inventory"] = {  }, ["fields"] = {  } }, ["param2"] = 0, ["param1"] = 13 }, { ["y"] = 4, ["x"] = 7, ["name"] = "default:leaves", ["z"] = 3, ["meta"] = { ["inventory"] = {  }, ["fields"] = {  } }, ["param2"] = 0, ["param1"] = 12 }, { ["y"] = 4, ["x"] = 7, ["name"] = "default:leaves", ["z"] = 4, ["meta"] = { ["inventory"] = {  }, ["fields"] = {  } }, ["param2"] = 0, ["param1"] = 13 }, { ["y"] = 4, ["x"] = 7, ["name"] = "default:leaves", ["z"] = 6, ["meta"] = { ["inventory"] = {  }, ["fields"] = {  } }, ["param2"] = 0, ["param1"] = 13 }, { ["y"] = 4, ["x"] = 7, ["name"] = "default:leaves", ["z"] = 7, ["meta"] = { ["inventory"] = {  }, ["fields"] = {  } }, ["param2"] = 0, ["param1"] = 12 }, { ["y"] = 4, ["x"] = 7, ["name"] = "default:leaves", ["z"] = 8, ["meta"] = { ["inventory"] = {  }, ["fields"] = {  } }, ["param2"] = 0, ["param1"] = 12 }, { ["y"] = 4, ["x"] = 7, ["name"] = "default:leaves", ["z"] = 9, ["meta"] = { ["inventory"] = {  }, ["fields"] = {  } }, ["param2"] = 0, ["param1"] = 11 }, { ["y"] = 4, ["x"] = 7, ["name"] = "default:leaves", ["z"] = 11, ["meta"] = { ["inventory"] = {  }, ["fields"] = {  } }, ["param2"] = 0, ["param1"] = 12 }, { ["y"] = 4, ["x"] = 7, ["name"] = "default:leaves", ["z"] = 12, ["meta"] = { ["inventory"] = {  }, ["fields"] = {  } }, ["param2"] = 0, ["param1"] = 12 }, { ["y"] = 4, ["x"] = 7, ["name"] = "default:cobble", ["z"] = 13, ["meta"] = { ["inventory"] = {  }, ["fields"] = {  } }, ["param2"] = 0, ["param1"] = 0 }, { ["y"] = 5, ["x"] = 7, ["name"] = "default:leaves", ["z"] = 3, ["meta"] = { ["inventory"] = {  }, ["fields"] = {  } }, ["param2"] = 0, ["param1"] = 13 }, { ["y"] = 5, ["x"] = 7, ["name"] = "default:leaves", ["z"] = 4, ["meta"] = { ["inventory"] = {  }, ["fields"] = {  } }, ["param2"] = 0, ["param1"] = 13 }, { ["y"] = 5, ["x"] = 7, ["name"] = "default:leaves", ["z"] = 6, ["meta"] = { ["inventory"] = {  }, ["fields"] = {  } }, ["param2"] = 0, ["param1"] = 13 }, { ["y"] = 5, ["x"] = 7, ["name"] = "default:leaves", ["z"] = 7, ["meta"] = { ["inventory"] = {  }, ["fields"] = {  } }, ["param2"] = 0, ["param1"] = 12 }, { ["y"] = 5, ["x"] = 7, ["name"] = "default:leaves", ["z"] = 8, ["meta"] = { ["inventory"] = {  }, ["fields"] = {  } }, ["param2"] = 0, ["param1"] = 13 }, { ["y"] = 5, ["x"] = 7, ["name"] = "default:leaves", ["z"] = 9, ["meta"] = { ["inventory"] = {  }, ["fields"] = {  } }, ["param2"] = 0, ["param1"] = 12 }, { ["y"] = 5, ["x"] = 7, ["name"] = "default:leaves", ["z"] = 10, ["meta"] = { ["inventory"] = {  }, ["fields"] = {  } }, ["param2"] = 0, ["param1"] = 12 }, { ["y"] = 5, ["x"] = 7, ["name"] = "default:leaves", ["z"] = 11, ["meta"] = { ["inventory"] = {  }, ["fields"] = {  } }, ["param2"] = 0, ["param1"] = 13 }, { ["y"] = 5, ["x"] = 7, ["name"] = "default:leaves", ["z"] = 12, ["meta"] = { ["inventory"] = {  }, ["fields"] = {  } }, ["param2"] = 0, ["param1"] = 13 }, { ["y"] = 0, ["x"] = 8, ["name"] = "default:tree", ["z"] = 12, ["meta"] = { ["inventory"] = {  }, ["fields"] = {  } }, ["param2"] = 0, ["param1"] = 15 }, { ["y"] = 0, ["x"] = 8, ["name"] = "default:cobble", ["z"] = 13, ["meta"] = { ["inventory"] = {  }, ["fields"] = {  } }, ["param2"] = 0, ["param1"] = 0 }, { ["y"] = 1, ["x"] = 8, ["name"] = "default:tree", ["z"] = 12, ["meta"] = { ["inventory"] = {  }, ["fields"] = {  } }, ["param2"] = 0, ["param1"] = 15 }, { ["y"] = 1, ["x"] = 8, ["name"] = "default:cobble", ["z"] = 13, ["meta"] = { ["inventory"] = {  }, ["fields"] = {  } }, ["param2"] = 0, ["param1"] = 0 }, { ["y"] = 2, ["x"] = 8, ["name"] = "default:leaves", ["z"] = 1, ["meta"] = { ["inventory"] = {  }, ["fields"] = {  } }, ["param2"] = 0, ["param1"] = 13 }, { ["y"] = 2, ["x"] = 8, ["name"] = "default:leaves", ["z"] = 2, ["meta"] = { ["inventory"] = {  }, ["fields"] = {  } }, ["param2"] = 0, ["param1"] = 12 }, { ["y"] = 2, ["x"] = 8, ["name"] = "default:leaves", ["z"] = 3, ["meta"] = { ["inventory"] = {  }, ["fields"] = {  } }, ["param2"] = 0, ["param1"] = 11 }, { ["y"] = 2, ["x"] = 8, ["name"] = "default:leaves", ["z"] = 4, ["meta"] = { ["inventory"] = {  }, ["fields"] = {  } }, ["param2"] = 0, ["param1"] = 12 }, { ["y"] = 2, ["x"] = 8, ["name"] = "default:leaves", ["z"] = 11, ["meta"] = { ["inventory"] = {  }, ["fields"] = {  } }, ["param2"] = 0, ["param1"] = 12 }, { ["y"] = 2, ["x"] = 8, ["name"] = "default:tree", ["z"] = 12, ["meta"] = { ["inventory"] = {  }, ["fields"] = {  } }, ["param2"] = 0, ["param1"] = 15 }, { ["y"] = 2, ["x"] = 8, ["name"] = "default:cobble", ["z"] = 13, ["meta"] = { ["inventory"] = {  }, ["fields"] = {  } }, ["param2"] = 0, ["param1"] = 0 }, { ["y"] = 3, ["x"] = 8, ["name"] = "default:leaves", ["z"] = 1, ["meta"] = { ["inventory"] = {  }, ["fields"] = {  } }, ["param2"] = 0, ["param1"] = 13 }, { ["y"] = 3, ["x"] = 8, ["name"] = "default:leaves", ["z"] = 2, ["meta"] = { ["inventory"] = {  }, ["fields"] = {  } }, ["param2"] = 0, ["param1"] = 12 }, { ["y"] = 3, ["x"] = 8, ["name"] = "default:leaves", ["z"] = 3, ["meta"] = { ["inventory"] = {  }, ["fields"] = {  } }, ["param2"] = 0, ["param1"] = 12 }, { ["y"] = 3, ["x"] = 8, ["name"] = "default:leaves", ["z"] = 4, ["meta"] = { ["inventory"] = {  }, ["fields"] = {  } }, ["param2"] = 0, ["param1"] = 12 }, { ["y"] = 3, ["x"] = 8, ["name"] = "default:leaves", ["z"] = 8, ["meta"] = { ["inventory"] = {  }, ["fields"] = {  } }, ["param2"] = 0, ["param1"] = 13 }, { ["y"] = 3, ["x"] = 8, ["name"] = "default:leaves", ["z"] = 10, ["meta"] = { ["inventory"] = {  }, ["fields"] = {  } }, ["param2"] = 0, ["param1"] = 12 }, { ["y"] = 3, ["x"] = 8, ["name"] = "default:leaves", ["z"] = 11, ["meta"] = { ["inventory"] = {  }, ["fields"] = {  } }, ["param2"] = 0, ["param1"] = 12 }, { ["y"] = 3, ["x"] = 8, ["name"] = "default:tree", ["z"] = 12, ["meta"] = { ["inventory"] = {  }, ["fields"] = {  } }, ["param2"] = 0, ["param1"] = 15 }, { ["y"] = 3, ["x"] = 8, ["name"] = "default:cobble", ["z"] = 13, ["meta"] = { ["inventory"] = {  }, ["fields"] = {  } }, ["param2"] = 0, ["param1"] = 0 }, { ["y"] = 4, ["x"] = 8, ["name"] = "default:leaves", ["z"] = 1, ["meta"] = { ["inventory"] = {  }, ["fields"] = {  } }, ["param2"] = 0, ["param1"] = 13 }, { ["y"] = 4, ["x"] = 8, ["name"] = "default:leaves", ["z"] = 2, ["meta"] = { ["inventory"] = {  }, ["fields"] = {  } }, ["param2"] = 0, ["param1"] = 12 }, { ["y"] = 4, ["x"] = 8, ["name"] = "default:leaves", ["z"] = 3, ["meta"] = { ["inventory"] = {  }, ["fields"] = {  } }, ["param2"] = 0, ["param1"] = 13 }, { ["y"] = 4, ["x"] = 8, ["name"] = "default:leaves", ["z"] = 4, ["meta"] = { ["inventory"] = {  }, ["fields"] = {  } }, ["param2"] = 0, ["param1"] = 12 }, { ["y"] = 4, ["x"] = 8, ["name"] = "default:apple", ["z"] = 5, ["meta"] = { ["inventory"] = {  }, ["fields"] = {  } }, ["param2"] = 0, ["param1"] = 13 }, { ["y"] = 4, ["x"] = 8, ["name"] = "default:leaves", ["z"] = 9, ["meta"] = { ["inventory"] = {  }, ["fields"] = {  } }, ["param2"] = 0, ["param1"] = 13 }, { ["y"] = 4, ["x"] = 8, ["name"] = "default:leaves", ["z"] = 10, ["meta"] = { ["inventory"] = {  }, ["fields"] = {  } }, ["param2"] = 0, ["param1"] = 12 }, { ["y"] = 4, ["x"] = 8, ["name"] = "default:leaves", ["z"] = 11, ["meta"] = { ["inventory"] = {  }, ["fields"] = {  } }, ["param2"] = 0, ["param1"] = 12 }, { ["y"] = 4, ["x"] = 8, ["name"] = "default:tree", ["z"] = 12, ["meta"] = { ["inventory"] = {  }, ["fields"] = {  } }, ["param2"] = 0, ["param1"] = 15 }, { ["y"] = 4, ["x"] = 8, ["name"] = "default:cobble", ["z"] = 13, ["meta"] = { ["inventory"] = {  }, ["fields"] = {  } }, ["param2"] = 0, ["param1"] = 0 }, { ["y"] = 5, ["x"] = 8, ["name"] = "default:leaves", ["z"] = 2, ["meta"] = { ["inventory"] = {  }, ["fields"] = {  } }, ["param2"] = 0, ["param1"] = 13 }, { ["y"] = 5, ["x"] = 8, ["name"] = "default:leaves", ["z"] = 4, ["meta"] = { ["inventory"] = {  }, ["fields"] = {  } }, ["param2"] = 0, ["param1"] = 13 }, { ["y"] = 5, ["x"] = 8, ["name"] = "default:leaves", ["z"] = 5, ["meta"] = { ["inventory"] = {  }, ["fields"] = {  } }, ["param2"] = 0, ["param1"] = 13 }, { ["y"] = 5, ["x"] = 8, ["name"] = "default:leaves", ["z"] = 7, ["meta"] = { ["inventory"] = {  }, ["fields"] = {  } }, ["param2"] = 0, ["param1"] = 13 }, { ["y"] = 5, ["x"] = 8, ["name"] = "default:leaves", ["z"] = 8, ["meta"] = { ["inventory"] = {  }, ["fields"] = {  } }, ["param2"] = 0, ["param1"] = 13 }, { ["y"] = 5, ["x"] = 8, ["name"] = "default:leaves", ["z"] = 10, ["meta"] = { ["inventory"] = {  }, ["fields"] = {  } }, ["param2"] = 0, ["param1"] = 13 }, { ["y"] = 5, ["x"] = 8, ["name"] = "default:leaves", ["z"] = 11, ["meta"] = { ["inventory"] = {  }, ["fields"] = {  } }, ["param2"] = 0, ["param1"] = 13 }, { ["y"] = 5, ["x"] = 8, ["name"] = "default:leaves", ["z"] = 12, ["meta"] = { ["inventory"] = {  }, ["fields"] = {  } }, ["param2"] = 0, ["param1"] = 13 }, { ["y"] = 0, ["x"] = 9, ["name"] = "default:tree", ["z"] = 2, ["meta"] = { ["inventory"] = {  }, ["fields"] = {  } }, ["param2"] = 0, ["param1"] = 15 }, { ["y"] = 0, ["x"] = 9, ["name"] = "default:tree", ["z"] = 3, ["meta"] = { ["inventory"] = {  }, ["fields"] = {  } }, ["param2"] = 0, ["param1"] = 12 }, { ["y"] = 0, ["x"] = 9, ["name"] = "default:papyrus", ["z"] = 5, ["meta"] = { ["inventory"] = {  }, ["fields"] = {  } }, ["param2"] = 0, ["param1"] = 13 }, { ["y"] = 0, ["x"] = 9, ["name"] = "default:papyrus", ["z"] = 6, ["meta"] = { ["inventory"] = {  }, ["fields"] = {  } }, ["param2"] = 0, ["param1"] = 15 }, { ["y"] = 0, ["x"] = 9, ["name"] = "default:papyrus", ["z"] = 7, ["meta"] = { ["inventory"] = {  }, ["fields"] = {  } }, ["param2"] = 0, ["param1"] = 15 }, { ["y"] = 0, ["x"] = 9, ["name"] = "flowers:waterlily_s3", ["z"] = 9, ["meta"] = { ["inventory"] = {  }, ["fields"] = {  } }, ["param2"] = 0, ["param1"] = 15 }, { ["y"] = 0, ["x"] = 9, ["name"] = "default:ladder", ["z"] = 12, ["meta"] = { ["inventory"] = {  }, ["fields"] = {  } }, ["param2"] = 4, ["param1"] = 15 }, { ["y"] = 0, ["x"] = 9, ["name"] = "default:cobble", ["z"] = 13, ["meta"] = { ["inventory"] = {  }, ["fields"] = {  } }, ["param2"] = 0, ["param1"] = 0 }, { ["y"] = 1, ["x"] = 9, ["name"] = "default:tree", ["z"] = 2, ["meta"] = { ["inventory"] = {  }, ["fields"] = {  } }, ["param2"] = 0, ["param1"] = 15 }, { ["y"] = 1, ["x"] = 9, ["name"] = "default:tree", ["z"] = 3, ["meta"] = { ["inventory"] = {  }, ["fields"] = {  } }, ["param2"] = 0, ["param1"] = 12 }, { ["y"] = 1, ["x"] = 9, ["name"] = "default:papyrus", ["z"] = 6, ["meta"] = { ["inventory"] = {  }, ["fields"] = {  } }, ["param2"] = 0, ["param1"] = 15 }, { ["y"] = 1, ["x"] = 9, ["name"] = "default:papyrus", ["z"] = 7, ["meta"] = { ["inventory"] = {  }, ["fields"] = {  } }, ["param2"] = 0, ["param1"] = 15 }, { ["y"] = 1, ["x"] = 9, ["name"] = "vines:side", ["z"] = 9, ["meta"] = { ["inventory"] = {  }, ["fields"] = {  } }, ["param2"] = 4, ["param1"] = 15 }, { ["y"] = 1, ["x"] = 9, ["name"] = "default:ladder", ["z"] = 12, ["meta"] = { ["inventory"] = {  }, ["fields"] = {  } }, ["param2"] = 4, ["param1"] = 15 }, { ["y"] = 1, ["x"] = 9, ["name"] = "default:cobble", ["z"] = 13, ["meta"] = { ["inventory"] = {  }, ["fields"] = {  } }, ["param2"] = 0, ["param1"] = 0 }, { ["y"] = 2, ["x"] = 9, ["name"] = "default:leaves", ["z"] = 1, ["meta"] = { ["inventory"] = {  }, ["fields"] = {  } }, ["param2"] = 0, ["param1"] = 13 }, { ["y"] = 2, ["x"] = 9, ["name"] = "default:tree", ["z"] = 2, ["meta"] = { ["inventory"] = {  }, ["fields"] = {  } }, ["param2"] = 0, ["param1"] = 15 }, { ["y"] = 2, ["x"] = 9, ["name"] = "default:tree", ["z"] = 3, ["meta"] = { ["inventory"] = {  }, ["fields"] = {  } }, ["param2"] = 0, ["param1"] = 12 }, { ["y"] = 2, ["x"] = 9, ["name"] = "default:papyrus", ["z"] = 6, ["meta"] = { ["inventory"] = {  }, ["fields"] = {  } }, ["param2"] = 0, ["param1"] = 15 }, { ["y"] = 2, ["x"] = 9, ["name"] = "default:papyrus", ["z"] = 7, ["meta"] = { ["inventory"] = {  }, ["fields"] = {  } }, ["param2"] = 0, ["param1"] = 15 }, { ["y"] = 2, ["x"] = 9, ["name"] = "vines:side", ["z"] = 9, ["meta"] = { ["inventory"] = {  }, ["fields"] = {  } }, ["param2"] = 4, ["param1"] = 15 }, { ["y"] = 2, ["x"] = 9, ["name"] = "default:leaves", ["z"] = 11, ["meta"] = { ["inventory"] = {  }, ["fields"] = {  } }, ["param2"] = 0, ["param1"] = 13 }, { ["y"] = 2, ["x"] = 9, ["name"] = "default:ladder", ["z"] = 12, ["meta"] = { ["inventory"] = {  }, ["fields"] = {  } }, ["param2"] = 4, ["param1"] = 15 }, { ["y"] = 2, ["x"] = 9, ["name"] = "default:cobble", ["z"] = 13, ["meta"] = { ["inventory"] = {  }, ["fields"] = {  } }, ["param2"] = 0, ["param1"] = 0 }, { ["y"] = 3, ["x"] = 9, ["name"] = "default:leaves", ["z"] = 1, ["meta"] = { ["inventory"] = {  }, ["fields"] = {  } }, ["param2"] = 0, ["param1"] = 13 }, { ["y"] = 3, ["x"] = 9, ["name"] = "default:tree", ["z"] = 2, ["meta"] = { ["inventory"] = {  }, ["fields"] = {  } }, ["param2"] = 0, ["param1"] = 15 }, { ["y"] = 3, ["x"] = 9, ["name"] = "default:leaves", ["z"] = 3, ["meta"] = { ["inventory"] = {  }, ["fields"] = {  } }, ["param2"] = 0, ["param1"] = 11 }, { ["y"] = 3, ["x"] = 9, ["name"] = "default:leaves", ["z"] = 4, ["meta"] = { ["inventory"] = {  }, ["fields"] = {  } }, ["param2"] = 0, ["param1"] = 12 }, { ["y"] = 3, ["x"] = 9, ["name"] = "default:leaves", ["z"] = 5, ["meta"] = { ["inventory"] = {  }, ["fields"] = {  } }, ["param2"] = 0, ["param1"] = 13 }, { ["y"] = 3, ["x"] = 9, ["name"] = "default:papyrus", ["z"] = 6, ["meta"] = { ["inventory"] = {  }, ["fields"] = {  } }, ["param2"] = 0, ["param1"] = 15 }, { ["y"] = 3, ["x"] = 9, ["name"] = "default:papyrus", ["z"] = 7, ["meta"] = { ["inventory"] = {  }, ["fields"] = {  } }, ["param2"] = 0, ["param1"] = 15 }, { ["y"] = 3, ["x"] = 9, ["name"] = "vines:side", ["z"] = 9, ["meta"] = { ["inventory"] = {  }, ["fields"] = {  } }, ["param2"] = 4, ["param1"] = 15 }, { ["y"] = 3, ["x"] = 9, ["name"] = "default:leaves", ["z"] = 10, ["meta"] = { ["inventory"] = {  }, ["fields"] = {  } }, ["param2"] = 0, ["param1"] = 13 }, { ["y"] = 3, ["x"] = 9, ["name"] = "default:leaves", ["z"] = 11, ["meta"] = { ["inventory"] = {  }, ["fields"] = {  } }, ["param2"] = 0, ["param1"] = 13 }, { ["y"] = 3, ["x"] = 9, ["name"] = "default:ladder", ["z"] = 12, ["meta"] = { ["inventory"] = {  }, ["fields"] = {  } }, ["param2"] = 4, ["param1"] = 15 }, { ["y"] = 3, ["x"] = 9, ["name"] = "default:cobble", ["z"] = 13, ["meta"] = { ["inventory"] = {  }, ["fields"] = {  } }, ["param2"] = 0, ["param1"] = 0 }, { ["y"] = 4, ["x"] = 9, ["name"] = "default:leaves", ["z"] = 1, ["meta"] = { ["inventory"] = {  }, ["fields"] = {  } }, ["param2"] = 0, ["param1"] = 13 }, { ["y"] = 4, ["x"] = 9, ["name"] = "default:tree", ["z"] = 2, ["meta"] = { ["inventory"] = {  }, ["fields"] = {  } }, ["param2"] = 0, ["param1"] = 15 }, { ["y"] = 4, ["x"] = 9, ["name"] = "default:leaves", ["z"] = 3, ["meta"] = { ["inventory"] = {  }, ["fields"] = {  } }, ["param2"] = 0, ["param1"] = 12 }, { ["y"] = 4, ["x"] = 9, ["name"] = "default:leaves", ["z"] = 4, ["meta"] = { ["inventory"] = {  }, ["fields"] = {  } }, ["param2"] = 0, ["param1"] = 12 }, { ["y"] = 4, ["x"] = 9, ["name"] = "default:leaves", ["z"] = 5, ["meta"] = { ["inventory"] = {  }, ["fields"] = {  } }, ["param2"] = 0, ["param1"] = 13 }, { ["y"] = 4, ["x"] = 9, ["name"] = "vines:side", ["z"] = 7, ["meta"] = { ["inventory"] = {  }, ["fields"] = {  } }, ["param2"] = 2, ["param1"] = 15 }, { ["y"] = 4, ["x"] = 9, ["name"] = "vines:side", ["z"] = 10, ["meta"] = { ["inventory"] = {  }, ["fields"] = {  } }, ["param2"] = 2, ["param1"] = 13 }, { ["y"] = 4, ["x"] = 9, ["name"] = "default:leaves", ["z"] = 11, ["meta"] = { ["inventory"] = {  }, ["fields"] = {  } }, ["param2"] = 0, ["param1"] = 13 }, { ["y"] = 4, ["x"] = 9, ["name"] = "default:ladder", ["z"] = 12, ["meta"] = { ["inventory"] = {  }, ["fields"] = {  } }, ["param2"] = 4, ["param1"] = 15 }, { ["y"] = 4, ["x"] = 9, ["name"] = "default:cobble", ["z"] = 13, ["meta"] = { ["inventory"] = {  }, ["fields"] = {  } }, ["param2"] = 0, ["param1"] = 0 }, { ["y"] = 5, ["x"] = 9, ["name"] = "default:leaves", ["z"] = 1, ["meta"] = { ["inventory"] = {  }, ["fields"] = {  } }, ["param2"] = 0, ["param1"] = 13 }, { ["y"] = 5, ["x"] = 9, ["name"] = "default:leaves", ["z"] = 2, ["meta"] = { ["inventory"] = {  }, ["fields"] = {  } }, ["param2"] = 0, ["param1"] = 13 }, { ["y"] = 5, ["x"] = 9, ["name"] = "default:leaves", ["z"] = 3, ["meta"] = { ["inventory"] = {  }, ["fields"] = {  } }, ["param2"] = 0, ["param1"] = 13 }, { ["y"] = 5, ["x"] = 9, ["name"] = "default:leaves", ["z"] = 4, ["meta"] = { ["inventory"] = {  }, ["fields"] = {  } }, ["param2"] = 0, ["param1"] = 13 }, { ["y"] = 5, ["x"] = 9, ["name"] = "default:leaves", ["z"] = 5, ["meta"] = { ["inventory"] = {  }, ["fields"] = {  } }, ["param2"] = 0, ["param1"] = 13 }, { ["y"] = 5, ["x"] = 9, ["name"] = "default:leaves", ["z"] = 10, ["meta"] = { ["inventory"] = {  }, ["fields"] = {  } }, ["param2"] = 0, ["param1"] = 13 }, { ["y"] = 5, ["x"] = 9, ["name"] = "default:leaves", ["z"] = 11, ["meta"] = { ["inventory"] = {  }, ["fields"] = {  } }, ["param2"] = 0, ["param1"] = 13 }, { ["y"] = 0, ["x"] = 10, ["name"] = "default:cobble", ["z"] = 1, ["meta"] = { ["inventory"] = {  }, ["fields"] = {  } }, ["param2"] = 0, ["param1"] = 0 }, { ["y"] = 0, ["x"] = 10, ["name"] = "default:tree", ["z"] = 2, ["meta"] = { ["inventory"] = {  }, ["fields"] = {  } }, ["param2"] = 0, ["param1"] = 9 }, { ["y"] = 0, ["x"] = 10, ["name"] = "default:tree", ["z"] = 3, ["meta"] = { ["inventory"] = {  }, ["fields"] = {  } }, ["param2"] = 0, ["param1"] = 10 }, { ["y"] = 0, ["x"] = 10, ["name"] = "default:papyrus", ["z"] = 5, ["meta"] = { ["inventory"] = {  }, ["fields"] = {  } }, ["param2"] = 0, ["param1"] = 12 }, { ["y"] = 0, ["x"] = 10, ["name"] = "default:papyrus", ["z"] = 6, ["meta"] = { ["inventory"] = {  }, ["fields"] = {  } }, ["param2"] = 0, ["param1"] = 13 }, { ["y"] = 0, ["x"] = 10, ["name"] = "default:papyrus", ["z"] = 7, ["meta"] = { ["inventory"] = {  }, ["fields"] = {  } }, ["param2"] = 0, ["param1"] = 13 }, { ["y"] = 0, ["x"] = 10, ["name"] = "default:tree", ["z"] = 12, ["meta"] = { ["inventory"] = {  }, ["fields"] = {  } }, ["param2"] = 0, ["param1"] = 13 }, { ["y"] = 0, ["x"] = 10, ["name"] = "default:cobble", ["z"] = 13, ["meta"] = { ["inventory"] = {  }, ["fields"] = {  } }, ["param2"] = 0, ["param1"] = 0 }, { ["y"] = 1, ["x"] = 10, ["name"] = "default:cobble", ["z"] = 1, ["meta"] = { ["inventory"] = {  }, ["fields"] = {  } }, ["param2"] = 0, ["param1"] = 0 }, { ["y"] = 1, ["x"] = 10, ["name"] = "default:tree", ["z"] = 2, ["meta"] = { ["inventory"] = {  }, ["fields"] = {  } }, ["param2"] = 0, ["param1"] = 9 }, { ["y"] = 1, ["x"] = 10, ["name"] = "default:tree", ["z"] = 3, ["meta"] = { ["inventory"] = {  }, ["fields"] = {  } }, ["param2"] = 0, ["param1"] = 10 }, { ["y"] = 1, ["x"] = 10, ["name"] = "default:papyrus", ["z"] = 6, ["meta"] = { ["inventory"] = {  }, ["fields"] = {  } }, ["param2"] = 0, ["param1"] = 13 }, { ["y"] = 1, ["x"] = 10, ["name"] = "default:papyrus", ["z"] = 7, ["meta"] = { ["inventory"] = {  }, ["fields"] = {  } }, ["param2"] = 0, ["param1"] = 13 }, { ["y"] = 1, ["x"] = 10, ["name"] = "default:tree", ["z"] = 12, ["meta"] = { ["inventory"] = {  }, ["fields"] = {  } }, ["param2"] = 0, ["param1"] = 13 }, { ["y"] = 1, ["x"] = 10, ["name"] = "default:cobble", ["z"] = 13, ["meta"] = { ["inventory"] = {  }, ["fields"] = {  } }, ["param2"] = 0, ["param1"] = 0 }, { ["y"] = 2, ["x"] = 10, ["name"] = "default:cobble", ["z"] = 1, ["meta"] = { ["inventory"] = {  }, ["fields"] = {  } }, ["param2"] = 0, ["param1"] = 0 }, { ["y"] = 2, ["x"] = 10, ["name"] = "default:leaves", ["z"] = 2, ["meta"] = { ["inventory"] = {  }, ["fields"] = {  } }, ["param2"] = 0, ["param1"] = 10 }, { ["y"] = 2, ["x"] = 10, ["name"] = "default:leaves", ["z"] = 3, ["meta"] = { ["inventory"] = {  }, ["fields"] = {  } }, ["param2"] = 0, ["param1"] = 10 }, { ["y"] = 2, ["x"] = 10, ["name"] = "default:leaves", ["z"] = 4, ["meta"] = { ["inventory"] = {  }, ["fields"] = {  } }, ["param2"] = 0, ["param1"] = 11 }, { ["y"] = 2, ["x"] = 10, ["name"] = "default:leaves", ["z"] = 5, ["meta"] = { ["inventory"] = {  }, ["fields"] = {  } }, ["param2"] = 0, ["param1"] = 12 }, { ["y"] = 2, ["x"] = 10, ["name"] = "default:papyrus", ["z"] = 6, ["meta"] = { ["inventory"] = {  }, ["fields"] = {  } }, ["param2"] = 0, ["param1"] = 13 }, { ["y"] = 2, ["x"] = 10, ["name"] = "default:leaves", ["z"] = 7, ["meta"] = { ["inventory"] = {  }, ["fields"] = {  } }, ["param2"] = 0, ["param1"] = 13 }, { ["y"] = 2, ["x"] = 10, ["name"] = "default:leaves", ["z"] = 8, ["meta"] = { ["inventory"] = {  }, ["fields"] = {  } }, ["param2"] = 0, ["param1"] = 13 }, { ["y"] = 2, ["x"] = 10, ["name"] = "default:leaves", ["z"] = 9, ["meta"] = { ["inventory"] = {  }, ["fields"] = {  } }, ["param2"] = 0, ["param1"] = 13 }, { ["y"] = 2, ["x"] = 10, ["name"] = "default:leaves", ["z"] = 11, ["meta"] = { ["inventory"] = {  }, ["fields"] = {  } }, ["param2"] = 0, ["param1"] = 12 }, { ["y"] = 2, ["x"] = 10, ["name"] = "default:tree", ["z"] = 12, ["meta"] = { ["inventory"] = {  }, ["fields"] = {  } }, ["param2"] = 0, ["param1"] = 13 }, { ["y"] = 2, ["x"] = 10, ["name"] = "default:cobble", ["z"] = 13, ["meta"] = { ["inventory"] = {  }, ["fields"] = {  } }, ["param2"] = 0, ["param1"] = 0 }, { ["y"] = 3, ["x"] = 10, ["name"] = "default:cobble", ["z"] = 1, ["meta"] = { ["inventory"] = {  }, ["fields"] = {  } }, ["param2"] = 0, ["param1"] = 0 }, { ["y"] = 3, ["x"] = 10, ["name"] = "default:leaves", ["z"] = 2, ["meta"] = { ["inventory"] = {  }, ["fields"] = {  } }, ["param2"] = 0, ["param1"] = 11 }, { ["y"] = 3, ["x"] = 10, ["name"] = "default:leaves", ["z"] = 3, ["meta"] = { ["inventory"] = {  }, ["fields"] = {  } }, ["param2"] = 0, ["param1"] = 11 }, { ["y"] = 3, ["x"] = 10, ["name"] = "default:leaves", ["z"] = 4, ["meta"] = { ["inventory"] = {  }, ["fields"] = {  } }, ["param2"] = 0, ["param1"] = 11 }, { ["y"] = 3, ["x"] = 10, ["name"] = "default:leaves", ["z"] = 5, ["meta"] = { ["inventory"] = {  }, ["fields"] = {  } }, ["param2"] = 0, ["param1"] = 12 }, { ["y"] = 3, ["x"] = 10, ["name"] = "default:papyrus", ["z"] = 6, ["meta"] = { ["inventory"] = {  }, ["fields"] = {  } }, ["param2"] = 0, ["param1"] = 13 }, { ["y"] = 3, ["x"] = 10, ["name"] = "default:leaves", ["z"] = 7, ["meta"] = { ["inventory"] = {  }, ["fields"] = {  } }, ["param2"] = 0, ["param1"] = 13 }, { ["y"] = 3, ["x"] = 10, ["name"] = "default:leaves", ["z"] = 8, ["meta"] = { ["inventory"] = {  }, ["fields"] = {  } }, ["param2"] = 0, ["param1"] = 13 }, { ["y"] = 3, ["x"] = 10, ["name"] = "default:leaves", ["z"] = 9, ["meta"] = { ["inventory"] = {  }, ["fields"] = {  } }, ["param2"] = 0, ["param1"] = 13 }, { ["y"] = 3, ["x"] = 10, ["name"] = "default:leaves", ["z"] = 10, ["meta"] = { ["inventory"] = {  }, ["fields"] = {  } }, ["param2"] = 0, ["param1"] = 12 }, { ["y"] = 3, ["x"] = 10, ["name"] = "default:leaves", ["z"] = 11, ["meta"] = { ["inventory"] = {  }, ["fields"] = {  } }, ["param2"] = 0, ["param1"] = 12 }, { ["y"] = 3, ["x"] = 10, ["name"] = "default:leaves", ["z"] = 12, ["meta"] = { ["inventory"] = {  }, ["fields"] = {  } }, ["param2"] = 0, ["param1"] = 13 }, { ["y"] = 3, ["x"] = 10, ["name"] = "default:cobble", ["z"] = 13, ["meta"] = { ["inventory"] = {  }, ["fields"] = {  } }, ["param2"] = 0, ["param1"] = 0 }, { ["y"] = 4, ["x"] = 10, ["name"] = "default:cobble", ["z"] = 1, ["meta"] = { ["inventory"] = {  }, ["fields"] = {  } }, ["param2"] = 0, ["param1"] = 0 }, { ["y"] = 4, ["x"] = 10, ["name"] = "vines:side", ["z"] = 2, ["meta"] = { ["inventory"] = {  }, ["fields"] = {  } }, ["param2"] = 4, ["param1"] = 12 }, { ["y"] = 4, ["x"] = 10, ["name"] = "default:leaves", ["z"] = 3, ["meta"] = { ["inventory"] = {  }, ["fields"] = {  } }, ["param2"] = 0, ["param1"] = 12 }, { ["y"] = 4, ["x"] = 10, ["name"] = "default:leaves", ["z"] = 4, ["meta"] = { ["inventory"] = {  }, ["fields"] = {  } }, ["param2"] = 0, ["param1"] = 12 }, { ["y"] = 4, ["x"] = 10, ["name"] = "default:leaves", ["z"] = 5, ["meta"] = { ["inventory"] = {  }, ["fields"] = {  } }, ["param2"] = 0, ["param1"] = 13 }, { ["y"] = 4, ["x"] = 10, ["name"] = "default:leaves", ["z"] = 6, ["meta"] = { ["inventory"] = {  }, ["fields"] = {  } }, ["param2"] = 0, ["param1"] = 13 }, { ["y"] = 4, ["x"] = 10, ["name"] = "default:leaves", ["z"] = 7, ["meta"] = { ["inventory"] = {  }, ["fields"] = {  } }, ["param2"] = 0, ["param1"] = 13 }, { ["y"] = 4, ["x"] = 10, ["name"] = "default:leaves", ["z"] = 8, ["meta"] = { ["inventory"] = {  }, ["fields"] = {  } }, ["param2"] = 0, ["param1"] = 13 }, { ["y"] = 4, ["x"] = 10, ["name"] = "default:leaves", ["z"] = 10, ["meta"] = { ["inventory"] = {  }, ["fields"] = {  } }, ["param2"] = 0, ["param1"] = 12 }, { ["y"] = 4, ["x"] = 10, ["name"] = "default:leaves", ["z"] = 11, ["meta"] = { ["inventory"] = {  }, ["fields"] = {  } }, ["param2"] = 0, ["param1"] = 12 }, { ["y"] = 4, ["x"] = 10, ["name"] = "default:leaves", ["z"] = 12, ["meta"] = { ["inventory"] = {  }, ["fields"] = {  } }, ["param2"] = 0, ["param1"] = 13 }, { ["y"] = 4, ["x"] = 10, ["name"] = "default:cobble", ["z"] = 13, ["meta"] = { ["inventory"] = {  }, ["fields"] = {  } }, ["param2"] = 0, ["param1"] = 0 }, { ["y"] = 5, ["x"] = 10, ["name"] = "default:leaves", ["z"] = 2, ["meta"] = { ["inventory"] = {  }, ["fields"] = {  } }, ["param2"] = 0, ["param1"] = 13 }, { ["y"] = 5, ["x"] = 10, ["name"] = "default:leaves", ["z"] = 3, ["meta"] = { ["inventory"] = {  }, ["fields"] = {  } }, ["param2"] = 0, ["param1"] = 13 }, { ["y"] = 5, ["x"] = 10, ["name"] = "default:leaves", ["z"] = 4, ["meta"] = { ["inventory"] = {  }, ["fields"] = {  } }, ["param2"] = 0, ["param1"] = 13 }, { ["y"] = 5, ["x"] = 10, ["name"] = "default:leaves", ["z"] = 6, ["meta"] = { ["inventory"] = {  }, ["fields"] = {  } }, ["param2"] = 0, ["param1"] = 13 }, { ["y"] = 5, ["x"] = 10, ["name"] = "default:leaves", ["z"] = 7, ["meta"] = { ["inventory"] = {  }, ["fields"] = {  } }, ["param2"] = 0, ["param1"] = 13 }, { ["y"] = 5, ["x"] = 10, ["name"] = "default:leaves", ["z"] = 8, ["meta"] = { ["inventory"] = {  }, ["fields"] = {  } }, ["param2"] = 0, ["param1"] = 13 }, { ["y"] = 5, ["x"] = 10, ["name"] = "default:leaves", ["z"] = 9, ["meta"] = { ["inventory"] = {  }, ["fields"] = {  } }, ["param2"] = 0, ["param1"] = 13 }, { ["y"] = 5, ["x"] = 10, ["name"] = "default:leaves", ["z"] = 10, ["meta"] = { ["inventory"] = {  }, ["fields"] = {  } }, ["param2"] = 0, ["param1"] = 13 }, { ["y"] = 5, ["x"] = 10, ["name"] = "default:leaves", ["z"] = 11, ["meta"] = { ["inventory"] = {  }, ["fields"] = {  } }, ["param2"] = 0, ["param1"] = 12 }, { ["y"] = 5, ["x"] = 10, ["name"] = "default:leaves", ["z"] = 12, ["meta"] = { ["inventory"] = {  }, ["fields"] = {  } }, ["param2"] = 0, ["param1"] = 13 }, { ["y"] = 0, ["x"] = 11, ["name"] = "default:ladder", ["z"] = 0, ["meta"] = { ["inventory"] = {  }, ["fields"] = {  } }, ["param2"] = 4, ["param1"] = 15 }, { ["y"] = 0, ["x"] = 11, ["name"] = "default:cobble", ["z"] = 1, ["meta"] = { ["inventory"] = {  }, ["fields"] = {  } }, ["param2"] = 0, ["param1"] = 0 }, { ["y"] = 0, ["x"] = 11, ["name"] = "default:papyrus", ["z"] = 2, ["meta"] = { ["inventory"] = {  }, ["fields"] = {  } }, ["param2"] = 0, ["param1"] = 8 }, { ["y"] = 0, ["x"] = 11, ["name"] = "default:papyrus", ["z"] = 3, ["meta"] = { ["inventory"] = {  }, ["fields"] = {  } }, ["param2"] = 0, ["param1"] = 9 }, { ["y"] = 0, ["x"] = 11, ["name"] = "default:papyrus", ["z"] = 5, ["meta"] = { ["inventory"] = {  }, ["fields"] = {  } }, ["param2"] = 0, ["param1"] = 11 }, { ["y"] = 0, ["x"] = 11, ["name"] = "default:papyrus", ["z"] = 6, ["meta"] = { ["inventory"] = {  }, ["fields"] = {  } }, ["param2"] = 0, ["param1"] = 12 }, { ["y"] = 0, ["x"] = 11, ["name"] = "default:papyrus", ["z"] = 7, ["meta"] = { ["inventory"] = {  }, ["fields"] = {  } }, ["param2"] = 0, ["param1"] = 12 }, { ["y"] = 0, ["x"] = 11, ["name"] = "default:papyrus", ["z"] = 8, ["meta"] = { ["inventory"] = {  }, ["fields"] = {  } }, ["param2"] = 0, ["param1"] = 12 }, { ["y"] = 0, ["x"] = 11, ["name"] = "default:papyrus", ["z"] = 9, ["meta"] = { ["inventory"] = {  }, ["fields"] = {  } }, ["param2"] = 0, ["param1"] = 12 }, { ["y"] = 0, ["x"] = 11, ["name"] = "default:papyrus", ["z"] = 10, ["meta"] = { ["inventory"] = {  }, ["fields"] = {  } }, ["param2"] = 0, ["param1"] = 11 }, { ["y"] = 0, ["x"] = 11, ["name"] = "default:papyrus", ["z"] = 11, ["meta"] = { ["inventory"] = {  }, ["fields"] = {  } }, ["param2"] = 0, ["param1"] = 11 }, { ["y"] = 0, ["x"] = 11, ["name"] = "default:tree", ["z"] = 12, ["meta"] = { ["inventory"] = {  }, ["fields"] = {  } }, ["param2"] = 0, ["param1"] = 11 }, { ["y"] = 0, ["x"] = 11, ["name"] = "default:cobble", ["z"] = 13, ["meta"] = { ["inventory"] = {  }, ["fields"] = {  } }, ["param2"] = 0, ["param1"] = 0 }, { ["y"] = 1, ["x"] = 11, ["name"] = "default:ladder", ["z"] = 0, ["meta"] = { ["inventory"] = {  }, ["fields"] = {  } }, ["param2"] = 4, ["param1"] = 15 }, { ["y"] = 1, ["x"] = 11, ["name"] = "default:cobble", ["z"] = 1, ["meta"] = { ["inventory"] = {  }, ["fields"] = {  } }, ["param2"] = 0, ["param1"] = 0 }, { ["y"] = 1, ["x"] = 11, ["name"] = "default:papyrus", ["z"] = 2, ["meta"] = { ["inventory"] = {  }, ["fields"] = {  } }, ["param2"] = 0, ["param1"] = 9 }, { ["y"] = 1, ["x"] = 11, ["name"] = "default:papyrus", ["z"] = 3, ["meta"] = { ["inventory"] = {  }, ["fields"] = {  } }, ["param2"] = 0, ["param1"] = 9 }, { ["y"] = 1, ["x"] = 11, ["name"] = "default:papyrus", ["z"] = 5, ["meta"] = { ["inventory"] = {  }, ["fields"] = {  } }, ["param2"] = 0, ["param1"] = 11 }, { ["y"] = 1, ["x"] = 11, ["name"] = "default:papyrus", ["z"] = 6, ["meta"] = { ["inventory"] = {  }, ["fields"] = {  } }, ["param2"] = 0, ["param1"] = 12 }, { ["y"] = 1, ["x"] = 11, ["name"] = "default:papyrus", ["z"] = 7, ["meta"] = { ["inventory"] = {  }, ["fields"] = {  } }, ["param2"] = 0, ["param1"] = 12 }, { ["y"] = 1, ["x"] = 11, ["name"] = "default:papyrus", ["z"] = 8, ["meta"] = { ["inventory"] = {  }, ["fields"] = {  } }, ["param2"] = 0, ["param1"] = 12 }, { ["y"] = 1, ["x"] = 11, ["name"] = "default:papyrus", ["z"] = 9, ["meta"] = { ["inventory"] = {  }, ["fields"] = {  } }, ["param2"] = 0, ["param1"] = 12 }, { ["y"] = 1, ["x"] = 11, ["name"] = "default:papyrus", ["z"] = 10, ["meta"] = { ["inventory"] = {  }, ["fields"] = {  } }, ["param2"] = 0, ["param1"] = 11 }, { ["y"] = 1, ["x"] = 11, ["name"] = "default:papyrus", ["z"] = 11, ["meta"] = { ["inventory"] = {  }, ["fields"] = {  } }, ["param2"] = 0, ["param1"] = 11 }, { ["y"] = 1, ["x"] = 11, ["name"] = "default:tree", ["z"] = 12, ["meta"] = { ["inventory"] = {  }, ["fields"] = {  } }, ["param2"] = 0, ["param1"] = 11 }, { ["y"] = 1, ["x"] = 11, ["name"] = "default:cobble", ["z"] = 13, ["meta"] = { ["inventory"] = {  }, ["fields"] = {  } }, ["param2"] = 0, ["param1"] = 0 }, { ["y"] = 2, ["x"] = 11, ["name"] = "default:ladder", ["z"] = 0, ["meta"] = { ["inventory"] = {  }, ["fields"] = {  } }, ["param2"] = 4, ["param1"] = 15 }, { ["y"] = 2, ["x"] = 11, ["name"] = "default:cobble", ["z"] = 1, ["meta"] = { ["inventory"] = {  }, ["fields"] = {  } }, ["param2"] = 0, ["param1"] = 0 }, { ["y"] = 2, ["x"] = 11, ["name"] = "default:papyrus", ["z"] = 2, ["meta"] = { ["inventory"] = {  }, ["fields"] = {  } }, ["param2"] = 0, ["param1"] = 10 }, { ["y"] = 2, ["x"] = 11, ["name"] = "default:papyrus", ["z"] = 3, ["meta"] = { ["inventory"] = {  }, ["fields"] = {  } }, ["param2"] = 0, ["param1"] = 10 }, { ["y"] = 2, ["x"] = 11, ["name"] = "default:leaves", ["z"] = 4, ["meta"] = { ["inventory"] = {  }, ["fields"] = {  } }, ["param2"] = 0, ["param1"] = 10 }, { ["y"] = 2, ["x"] = 11, ["name"] = "default:leaves", ["z"] = 5, ["meta"] = { ["inventory"] = {  }, ["fields"] = {  } }, ["param2"] = 0, ["param1"] = 11 }, { ["y"] = 2, ["x"] = 11, ["name"] = "default:leaves", ["z"] = 6, ["meta"] = { ["inventory"] = {  }, ["fields"] = {  } }, ["param2"] = 0, ["param1"] = 12 }, { ["y"] = 2, ["x"] = 11, ["name"] = "default:leaves", ["z"] = 7, ["meta"] = { ["inventory"] = {  }, ["fields"] = {  } }, ["param2"] = 0, ["param1"] = 12 }, { ["y"] = 2, ["x"] = 11, ["name"] = "default:leaves", ["z"] = 8, ["meta"] = { ["inventory"] = {  }, ["fields"] = {  } }, ["param2"] = 0, ["param1"] = 12 }, { ["y"] = 2, ["x"] = 11, ["name"] = "default:leaves", ["z"] = 9, ["meta"] = { ["inventory"] = {  }, ["fields"] = {  } }, ["param2"] = 0, ["param1"] = 12 }, { ["y"] = 2, ["x"] = 11, ["name"] = "default:leaves", ["z"] = 10, ["meta"] = { ["inventory"] = {  }, ["fields"] = {  } }, ["param2"] = 0, ["param1"] = 11 }, { ["y"] = 2, ["x"] = 11, ["name"] = "default:leaves", ["z"] = 11, ["meta"] = { ["inventory"] = {  }, ["fields"] = {  } }, ["param2"] = 0, ["param1"] = 11 }, { ["y"] = 2, ["x"] = 11, ["name"] = "default:leaves", ["z"] = 12, ["meta"] = { ["inventory"] = {  }, ["fields"] = {  } }, ["param2"] = 0, ["param1"] = 11 }, { ["y"] = 2, ["x"] = 11, ["name"] = "default:cobble", ["z"] = 13, ["meta"] = { ["inventory"] = {  }, ["fields"] = {  } }, ["param2"] = 0, ["param1"] = 0 }, { ["y"] = 3, ["x"] = 11, ["name"] = "default:ladder", ["z"] = 0, ["meta"] = { ["inventory"] = {  }, ["fields"] = {  } }, ["param2"] = 4, ["param1"] = 15 }, { ["y"] = 3, ["x"] = 11, ["name"] = "default:cobble", ["z"] = 1, ["meta"] = { ["inventory"] = {  }, ["fields"] = {  } }, ["param2"] = 0, ["param1"] = 0 }, { ["y"] = 3, ["x"] = 11, ["name"] = "default:papyrus", ["z"] = 2, ["meta"] = { ["inventory"] = {  }, ["fields"] = {  } }, ["param2"] = 0, ["param1"] = 11 }, { ["y"] = 3, ["x"] = 11, ["name"] = "default:papyrus", ["z"] = 3, ["meta"] = { ["inventory"] = {  }, ["fields"] = {  } }, ["param2"] = 0, ["param1"] = 11 }, { ["y"] = 3, ["x"] = 11, ["name"] = "default:leaves", ["z"] = 4, ["meta"] = { ["inventory"] = {  }, ["fields"] = {  } }, ["param2"] = 0, ["param1"] = 11 }, { ["y"] = 3, ["x"] = 11, ["name"] = "default:leaves", ["z"] = 5, ["meta"] = { ["inventory"] = {  }, ["fields"] = {  } }, ["param2"] = 0, ["param1"] = 12 }, { ["y"] = 3, ["x"] = 11, ["name"] = "default:leaves", ["z"] = 6, ["meta"] = { ["inventory"] = {  }, ["fields"] = {  } }, ["param2"] = 0, ["param1"] = 12 }, { ["y"] = 3, ["x"] = 11, ["name"] = "default:leaves", ["z"] = 7, ["meta"] = { ["inventory"] = {  }, ["fields"] = {  } }, ["param2"] = 0, ["param1"] = 12 }, { ["y"] = 3, ["x"] = 11, ["name"] = "default:leaves", ["z"] = 8, ["meta"] = { ["inventory"] = {  }, ["fields"] = {  } }, ["param2"] = 0, ["param1"] = 12 }, { ["y"] = 3, ["x"] = 11, ["name"] = "default:leaves", ["z"] = 9, ["meta"] = { ["inventory"] = {  }, ["fields"] = {  } }, ["param2"] = 0, ["param1"] = 12 }, { ["y"] = 3, ["x"] = 11, ["name"] = "default:leaves", ["z"] = 10, ["meta"] = { ["inventory"] = {  }, ["fields"] = {  } }, ["param2"] = 0, ["param1"] = 11 }, { ["y"] = 3, ["x"] = 11, ["name"] = "default:leaves", ["z"] = 11, ["meta"] = { ["inventory"] = {  }, ["fields"] = {  } }, ["param2"] = 0, ["param1"] = 11 }, { ["y"] = 3, ["x"] = 11, ["name"] = "default:leaves", ["z"] = 12, ["meta"] = { ["inventory"] = {  }, ["fields"] = {  } }, ["param2"] = 0, ["param1"] = 12 }, { ["y"] = 3, ["x"] = 11, ["name"] = "default:cobble", ["z"] = 13, ["meta"] = { ["inventory"] = {  }, ["fields"] = {  } }, ["param2"] = 0, ["param1"] = 0 }, { ["y"] = 4, ["x"] = 11, ["name"] = "default:ladder", ["z"] = 0, ["meta"] = { ["inventory"] = {  }, ["fields"] = {  } }, ["param2"] = 4, ["param1"] = 15 }, { ["y"] = 4, ["x"] = 11, ["name"] = "default:cobble", ["z"] = 1, ["meta"] = { ["inventory"] = {  }, ["fields"] = {  } }, ["param2"] = 0, ["param1"] = 0 }, { ["y"] = 4, ["x"] = 11, ["name"] = "default:leaves", ["z"] = 2, ["meta"] = { ["inventory"] = {  }, ["fields"] = {  } }, ["param2"] = 0, ["param1"] = 12 }, { ["y"] = 4, ["x"] = 11, ["name"] = "default:leaves", ["z"] = 3, ["meta"] = { ["inventory"] = {  }, ["fields"] = {  } }, ["param2"] = 0, ["param1"] = 12 }, { ["y"] = 4, ["x"] = 11, ["name"] = "default:leaves", ["z"] = 4, ["meta"] = { ["inventory"] = {  }, ["fields"] = {  } }, ["param2"] = 0, ["param1"] = 12 }, { ["y"] = 4, ["x"] = 11, ["name"] = "default:leaves", ["z"] = 5, ["meta"] = { ["inventory"] = {  }, ["fields"] = {  } }, ["param2"] = 0, ["param1"] = 13 }, { ["y"] = 4, ["x"] = 11, ["name"] = "default:leaves", ["z"] = 6, ["meta"] = { ["inventory"] = {  }, ["fields"] = {  } }, ["param2"] = 0, ["param1"] = 12 }, { ["y"] = 4, ["x"] = 11, ["name"] = "default:leaves", ["z"] = 7, ["meta"] = { ["inventory"] = {  }, ["fields"] = {  } }, ["param2"] = 0, ["param1"] = 12 }, { ["y"] = 4, ["x"] = 11, ["name"] = "default:leaves", ["z"] = 8, ["meta"] = { ["inventory"] = {  }, ["fields"] = {  } }, ["param2"] = 0, ["param1"] = 12 }, { ["y"] = 4, ["x"] = 11, ["name"] = "default:leaves", ["z"] = 9, ["meta"] = { ["inventory"] = {  }, ["fields"] = {  } }, ["param2"] = 0, ["param1"] = 12 }, { ["y"] = 4, ["x"] = 11, ["name"] = "default:leaves", ["z"] = 10, ["meta"] = { ["inventory"] = {  }, ["fields"] = {  } }, ["param2"] = 0, ["param1"] = 12 }, { ["y"] = 4, ["x"] = 11, ["name"] = "default:leaves", ["z"] = 11, ["meta"] = { ["inventory"] = {  }, ["fields"] = {  } }, ["param2"] = 0, ["param1"] = 12 }, { ["y"] = 4, ["x"] = 11, ["name"] = "default:leaves", ["z"] = 12, ["meta"] = { ["inventory"] = {  }, ["fields"] = {  } }, ["param2"] = 0, ["param1"] = 12 }, { ["y"] = 4, ["x"] = 11, ["name"] = "default:cobble", ["z"] = 13, ["meta"] = { ["inventory"] = {  }, ["fields"] = {  } }, ["param2"] = 0, ["param1"] = 0 }, { ["y"] = 5, ["x"] = 11, ["name"] = "default:leaves", ["z"] = 2, ["meta"] = { ["inventory"] = {  }, ["fields"] = {  } }, ["param2"] = 0, ["param1"] = 13 }, { ["y"] = 5, ["x"] = 11, ["name"] = "default:leaves", ["z"] = 3, ["meta"] = { ["inventory"] = {  }, ["fields"] = {  } }, ["param2"] = 0, ["param1"] = 13 }, { ["y"] = 5, ["x"] = 11, ["name"] = "default:leaves", ["z"] = 4, ["meta"] = { ["inventory"] = {  }, ["fields"] = {  } }, ["param2"] = 0, ["param1"] = 13 }, { ["y"] = 5, ["x"] = 11, ["name"] = "default:leaves", ["z"] = 6, ["meta"] = { ["inventory"] = {  }, ["fields"] = {  } }, ["param2"] = 0, ["param1"] = 13 }, { ["y"] = 5, ["x"] = 11, ["name"] = "default:leaves", ["z"] = 7, ["meta"] = { ["inventory"] = {  }, ["fields"] = {  } }, ["param2"] = 0, ["param1"] = 13 }, { ["y"] = 5, ["x"] = 11, ["name"] = "default:leaves", ["z"] = 8, ["meta"] = { ["inventory"] = {  }, ["fields"] = {  } }, ["param2"] = 0, ["param1"] = 13 }, { ["y"] = 5, ["x"] = 11, ["name"] = "default:leaves", ["z"] = 9, ["meta"] = { ["inventory"] = {  }, ["fields"] = {  } }, ["param2"] = 0, ["param1"] = 13 }, { ["y"] = 5, ["x"] = 11, ["name"] = "default:leaves", ["z"] = 10, ["meta"] = { ["inventory"] = {  }, ["fields"] = {  } }, ["param2"] = 0, ["param1"] = 13 }, { ["y"] = 5, ["x"] = 11, ["name"] = "default:leaves", ["z"] = 11, ["meta"] = { ["inventory"] = {  }, ["fields"] = {  } }, ["param2"] = 0, ["param1"] = 13 }, { ["y"] = 5, ["x"] = 11, ["name"] = "default:leaves", ["z"] = 12, ["meta"] = { ["inventory"] = {  }, ["fields"] = {  } }, ["param2"] = 0, ["param1"] = 13 }, { ["y"] = 0, ["x"] = 12, ["name"] = "default:cobble", ["z"] = 1, ["meta"] = { ["inventory"] = {  }, ["fields"] = {  } }, ["param2"] = 0, ["param1"] = 0 }, { ["y"] = 0, ["x"] = 12, ["name"] = "default:papyrus", ["z"] = 2, ["meta"] = { ["inventory"] = {  }, ["fields"] = {  } }, ["param2"] = 0, ["param1"] = 8 }, { ["y"] = 0, ["x"] = 12, ["name"] = "default:papyrus", ["z"] = 3, ["meta"] = { ["inventory"] = {  }, ["fields"] = {  } }, ["param2"] = 0, ["param1"] = 8 }, { ["y"] = 0, ["x"] = 12, ["name"] = "default:tree", ["z"] = 5, ["meta"] = { ["inventory"] = {  }, ["fields"] = {  } }, ["param2"] = 0, ["param1"] = 12 }, { ["y"] = 0, ["x"] = 12, ["name"] = "default:tree", ["z"] = 6, ["meta"] = { ["inventory"] = {  }, ["fields"] = {  } }, ["param2"] = 0, ["param1"] = 15 }, { ["y"] = 0, ["x"] = 12, ["name"] = "default:tree", ["z"] = 7, ["meta"] = { ["inventory"] = {  }, ["fields"] = {  } }, ["param2"] = 0, ["param1"] = 13 }, { ["y"] = 0, ["x"] = 12, ["name"] = "default:tree", ["z"] = 8, ["meta"] = { ["inventory"] = {  }, ["fields"] = {  } }, ["param2"] = 0, ["param1"] = 13 }, { ["y"] = 0, ["x"] = 12, ["name"] = "default:tree", ["z"] = 9, ["meta"] = { ["inventory"] = {  }, ["fields"] = {  } }, ["param2"] = 0, ["param1"] = 11 }, { ["y"] = 0, ["x"] = 12, ["name"] = "default:tree", ["z"] = 10, ["meta"] = { ["inventory"] = {  }, ["fields"] = {  } }, ["param2"] = 0, ["param1"] = 10 }, { ["y"] = 0, ["x"] = 12, ["name"] = "default:tree", ["z"] = 11, ["meta"] = { ["inventory"] = {  }, ["fields"] = {  } }, ["param2"] = 0, ["param1"] = 9 }, { ["y"] = 0, ["x"] = 12, ["name"] = "default:tree", ["z"] = 12, ["meta"] = { ["inventory"] = {  }, ["fields"] = {  } }, ["param2"] = 0, ["param1"] = 8 }, { ["y"] = 0, ["x"] = 12, ["name"] = "default:cobble", ["z"] = 13, ["meta"] = { ["inventory"] = {  }, ["fields"] = {  } }, ["param2"] = 0, ["param1"] = 0 }, { ["y"] = 0, ["x"] = 12, ["name"] = "default:ladder", ["z"] = 14, ["meta"] = { ["inventory"] = {  }, ["fields"] = {  } }, ["param2"] = 5, ["param1"] = 15 }, { ["y"] = 1, ["x"] = 12, ["name"] = "default:cobble", ["z"] = 1, ["meta"] = { ["inventory"] = {  }, ["fields"] = {  } }, ["param2"] = 0, ["param1"] = 0 }, { ["y"] = 1, ["x"] = 12, ["name"] = "default:papyrus", ["z"] = 2, ["meta"] = { ["inventory"] = {  }, ["fields"] = {  } }, ["param2"] = 0, ["param1"] = 9 }, { ["y"] = 1, ["x"] = 12, ["name"] = "default:papyrus", ["z"] = 3, ["meta"] = { ["inventory"] = {  }, ["fields"] = {  } }, ["param2"] = 0, ["param1"] = 9 }, { ["y"] = 1, ["x"] = 12, ["name"] = "default:tree", ["z"] = 5, ["meta"] = { ["inventory"] = {  }, ["fields"] = {  } }, ["param2"] = 0, ["param1"] = 12 }, { ["y"] = 1, ["x"] = 12, ["name"] = "default:tree", ["z"] = 6, ["meta"] = { ["inventory"] = {  }, ["fields"] = {  } }, ["param2"] = 0, ["param1"] = 15 }, { ["y"] = 1, ["x"] = 12, ["name"] = "default:tree", ["z"] = 7, ["meta"] = { ["inventory"] = {  }, ["fields"] = {  } }, ["param2"] = 0, ["param1"] = 13 }, { ["y"] = 1, ["x"] = 12, ["name"] = "default:tree", ["z"] = 8, ["meta"] = { ["inventory"] = {  }, ["fields"] = {  } }, ["param2"] = 0, ["param1"] = 13 }, { ["y"] = 1, ["x"] = 12, ["name"] = "default:tree", ["z"] = 9, ["meta"] = { ["inventory"] = {  }, ["fields"] = {  } }, ["param2"] = 0, ["param1"] = 11 }, { ["y"] = 1, ["x"] = 12, ["name"] = "default:tree", ["z"] = 10, ["meta"] = { ["inventory"] = {  }, ["fields"] = {  } }, ["param2"] = 0, ["param1"] = 10 }, { ["y"] = 1, ["x"] = 12, ["name"] = "default:tree", ["z"] = 11, ["meta"] = { ["inventory"] = {  }, ["fields"] = {  } }, ["param2"] = 0, ["param1"] = 9 }, { ["y"] = 1, ["x"] = 12, ["name"] = "default:tree", ["z"] = 12, ["meta"] = { ["inventory"] = {  }, ["fields"] = {  } }, ["param2"] = 0, ["param1"] = 9 }, { ["y"] = 1, ["x"] = 12, ["name"] = "default:cobble", ["z"] = 13, ["meta"] = { ["inventory"] = {  }, ["fields"] = {  } }, ["param2"] = 0, ["param1"] = 0 }, { ["y"] = 1, ["x"] = 12, ["name"] = "default:ladder", ["z"] = 14, ["meta"] = { ["inventory"] = {  }, ["fields"] = {  } }, ["param2"] = 5, ["param1"] = 15 }, { ["y"] = 2, ["x"] = 12, ["name"] = "default:cobble", ["z"] = 1, ["meta"] = { ["inventory"] = {  }, ["fields"] = {  } }, ["param2"] = 0, ["param1"] = 0 }, { ["y"] = 2, ["x"] = 12, ["name"] = "default:leaves", ["z"] = 2, ["meta"] = { ["inventory"] = {  }, ["fields"] = {  } }, ["param2"] = 0, ["param1"] = 10 }, { ["y"] = 2, ["x"] = 12, ["name"] = "default:leaves", ["z"] = 3, ["meta"] = { ["inventory"] = {  }, ["fields"] = {  } }, ["param2"] = 0, ["param1"] = 10 }, { ["y"] = 2, ["x"] = 12, ["name"] = "default:leaves", ["z"] = 4, ["meta"] = { ["inventory"] = {  }, ["fields"] = {  } }, ["param2"] = 0, ["param1"] = 9 }, { ["y"] = 2, ["x"] = 12, ["name"] = "default:leaves", ["z"] = 5, ["meta"] = { ["inventory"] = {  }, ["fields"] = {  } }, ["param2"] = 0, ["param1"] = 10 }, { ["y"] = 2, ["x"] = 12, ["name"] = "default:tree", ["z"] = 6, ["meta"] = { ["inventory"] = {  }, ["fields"] = {  } }, ["param2"] = 0, ["param1"] = 15 }, { ["y"] = 2, ["x"] = 12, ["name"] = "default:leaves", ["z"] = 7, ["meta"] = { ["inventory"] = {  }, ["fields"] = {  } }, ["param2"] = 0, ["param1"] = 11 }, { ["y"] = 2, ["x"] = 12, ["name"] = "default:leaves", ["z"] = 8, ["meta"] = { ["inventory"] = {  }, ["fields"] = {  } }, ["param2"] = 0, ["param1"] = 11 }, { ["y"] = 2, ["x"] = 12, ["name"] = "default:tree", ["z"] = 9, ["meta"] = { ["inventory"] = {  }, ["fields"] = {  } }, ["param2"] = 0, ["param1"] = 11 }, { ["y"] = 2, ["x"] = 12, ["name"] = "default:leaves", ["z"] = 10, ["meta"] = { ["inventory"] = {  }, ["fields"] = {  } }, ["param2"] = 0, ["param1"] = 10 }, { ["y"] = 2, ["x"] = 12, ["name"] = "default:leaves", ["z"] = 11, ["meta"] = { ["inventory"] = {  }, ["fields"] = {  } }, ["param2"] = 0, ["param1"] = 10 }, { ["y"] = 2, ["x"] = 12, ["name"] = "default:leaves", ["z"] = 12, ["meta"] = { ["inventory"] = {  }, ["fields"] = {  } }, ["param2"] = 0, ["param1"] = 10 }, { ["y"] = 2, ["x"] = 12, ["name"] = "default:cobble", ["z"] = 13, ["meta"] = { ["inventory"] = {  }, ["fields"] = {  } }, ["param2"] = 0, ["param1"] = 0 }, { ["y"] = 2, ["x"] = 12, ["name"] = "default:ladder", ["z"] = 14, ["meta"] = { ["inventory"] = {  }, ["fields"] = {  } }, ["param2"] = 5, ["param1"] = 15 }, { ["y"] = 3, ["x"] = 12, ["name"] = "default:cobble", ["z"] = 1, ["meta"] = { ["inventory"] = {  }, ["fields"] = {  } }, ["param2"] = 0, ["param1"] = 0 }, { ["y"] = 3, ["x"] = 12, ["name"] = "default:leaves", ["z"] = 2, ["meta"] = { ["inventory"] = {  }, ["fields"] = {  } }, ["param2"] = 0, ["param1"] = 11 }, { ["y"] = 3, ["x"] = 12, ["name"] = "default:leaves", ["z"] = 3, ["meta"] = { ["inventory"] = {  }, ["fields"] = {  } }, ["param2"] = 0, ["param1"] = 11 }, { ["y"] = 3, ["x"] = 12, ["name"] = "default:leaves", ["z"] = 4, ["meta"] = { ["inventory"] = {  }, ["fields"] = {  } }, ["param2"] = 0, ["param1"] = 10 }, { ["y"] = 3, ["x"] = 12, ["name"] = "default:leaves", ["z"] = 5, ["meta"] = { ["inventory"] = {  }, ["fields"] = {  } }, ["param2"] = 0, ["param1"] = 11 }, { ["y"] = 3, ["x"] = 12, ["name"] = "default:tree", ["z"] = 6, ["meta"] = { ["inventory"] = {  }, ["fields"] = {  } }, ["param2"] = 0, ["param1"] = 15 }, { ["y"] = 3, ["x"] = 12, ["name"] = "default:leaves", ["z"] = 7, ["meta"] = { ["inventory"] = {  }, ["fields"] = {  } }, ["param2"] = 0, ["param1"] = 12 }, { ["y"] = 3, ["x"] = 12, ["name"] = "default:leaves", ["z"] = 8, ["meta"] = { ["inventory"] = {  }, ["fields"] = {  } }, ["param2"] = 0, ["param1"] = 11 }, { ["y"] = 3, ["x"] = 12, ["name"] = "default:leaves", ["z"] = 9, ["meta"] = { ["inventory"] = {  }, ["fields"] = {  } }, ["param2"] = 0, ["param1"] = 11 }, { ["y"] = 3, ["x"] = 12, ["name"] = "default:leaves", ["z"] = 10, ["meta"] = { ["inventory"] = {  }, ["fields"] = {  } }, ["param2"] = 0, ["param1"] = 11 }, { ["y"] = 3, ["x"] = 12, ["name"] = "default:leaves", ["z"] = 11, ["meta"] = { ["inventory"] = {  }, ["fields"] = {  } }, ["param2"] = 0, ["param1"] = 11 }, { ["y"] = 3, ["x"] = 12, ["name"] = "default:leaves", ["z"] = 12, ["meta"] = { ["inventory"] = {  }, ["fields"] = {  } }, ["param2"] = 0, ["param1"] = 11 }, { ["y"] = 3, ["x"] = 12, ["name"] = "default:cobble", ["z"] = 13, ["meta"] = { ["inventory"] = {  }, ["fields"] = {  } }, ["param2"] = 0, ["param1"] = 0 }, { ["y"] = 3, ["x"] = 12, ["name"] = "default:ladder", ["z"] = 14, ["meta"] = { ["inventory"] = {  }, ["fields"] = {  } }, ["param2"] = 5, ["param1"] = 15 }, { ["y"] = 4, ["x"] = 12, ["name"] = "default:cobble", ["z"] = 1, ["meta"] = { ["inventory"] = {  }, ["fields"] = {  } }, ["param2"] = 0, ["param1"] = 0 }, { ["y"] = 4, ["x"] = 12, ["name"] = "default:leaves", ["z"] = 2, ["meta"] = { ["inventory"] = {  }, ["fields"] = {  } }, ["param2"] = 0, ["param1"] = 12 }, { ["y"] = 4, ["x"] = 12, ["name"] = "default:leaves", ["z"] = 3, ["meta"] = { ["inventory"] = {  }, ["fields"] = {  } }, ["param2"] = 0, ["param1"] = 12 }, { ["y"] = 4, ["x"] = 12, ["name"] = "default:leaves", ["z"] = 4, ["meta"] = { ["inventory"] = {  }, ["fields"] = {  } }, ["param2"] = 0, ["param1"] = 11 }, { ["y"] = 4, ["x"] = 12, ["name"] = "default:leaves", ["z"] = 5, ["meta"] = { ["inventory"] = {  }, ["fields"] = {  } }, ["param2"] = 0, ["param1"] = 12 }, { ["y"] = 4, ["x"] = 12, ["name"] = "default:tree", ["z"] = 6, ["meta"] = { ["inventory"] = {  }, ["fields"] = {  } }, ["param2"] = 0, ["param1"] = 15 }, { ["y"] = 4, ["x"] = 12, ["name"] = "default:leaves", ["z"] = 7, ["meta"] = { ["inventory"] = {  }, ["fields"] = {  } }, ["param2"] = 0, ["param1"] = 13 }, { ["y"] = 4, ["x"] = 12, ["name"] = "default:leaves", ["z"] = 8, ["meta"] = { ["inventory"] = {  }, ["fields"] = {  } }, ["param2"] = 0, ["param1"] = 12 }, { ["y"] = 4, ["x"] = 12, ["name"] = "default:leaves", ["z"] = 9, ["meta"] = { ["inventory"] = {  }, ["fields"] = {  } }, ["param2"] = 0, ["param1"] = 12 }, { ["y"] = 4, ["x"] = 12, ["name"] = "default:leaves", ["z"] = 10, ["meta"] = { ["inventory"] = {  }, ["fields"] = {  } }, ["param2"] = 0, ["param1"] = 12 }, { ["y"] = 4, ["x"] = 12, ["name"] = "default:leaves", ["z"] = 11, ["meta"] = { ["inventory"] = {  }, ["fields"] = {  } }, ["param2"] = 0, ["param1"] = 12 }, { ["y"] = 4, ["x"] = 12, ["name"] = "vines:side", ["z"] = 12, ["meta"] = { ["inventory"] = {  }, ["fields"] = {  } }, ["param2"] = 5, ["param1"] = 12 }, { ["y"] = 4, ["x"] = 12, ["name"] = "default:cobble", ["z"] = 13, ["meta"] = { ["inventory"] = {  }, ["fields"] = {  } }, ["param2"] = 0, ["param1"] = 0 }, { ["y"] = 4, ["x"] = 12, ["name"] = "default:ladder", ["z"] = 14, ["meta"] = { ["inventory"] = {  }, ["fields"] = {  } }, ["param2"] = 5, ["param1"] = 15 }, { ["y"] = 5, ["x"] = 12, ["name"] = "default:leaves", ["z"] = 2, ["meta"] = { ["inventory"] = {  }, ["fields"] = {  } }, ["param2"] = 0, ["param1"] = 13 }, { ["y"] = 5, ["x"] = 12, ["name"] = "default:leaves", ["z"] = 3, ["meta"] = { ["inventory"] = {  }, ["fields"] = {  } }, ["param2"] = 0, ["param1"] = 13 }, { ["y"] = 5, ["x"] = 12, ["name"] = "default:leaves", ["z"] = 4, ["meta"] = { ["inventory"] = {  }, ["fields"] = {  } }, ["param2"] = 0, ["param1"] = 12 }, { ["y"] = 5, ["x"] = 12, ["name"] = "default:leaves", ["z"] = 5, ["meta"] = { ["inventory"] = {  }, ["fields"] = {  } }, ["param2"] = 0, ["param1"] = 13 }, { ["y"] = 5, ["x"] = 12, ["name"] = "default:leaves", ["z"] = 6, ["meta"] = { ["inventory"] = {  }, ["fields"] = {  } }, ["param2"] = 0, ["param1"] = 13 }, { ["y"] = 5, ["x"] = 12, ["name"] = "default:leaves", ["z"] = 8, ["meta"] = { ["inventory"] = {  }, ["fields"] = {  } }, ["param2"] = 0, ["param1"] = 13 }, { ["y"] = 5, ["x"] = 12, ["name"] = "default:leaves", ["z"] = 9, ["meta"] = { ["inventory"] = {  }, ["fields"] = {  } }, ["param2"] = 0, ["param1"] = 13 }, { ["y"] = 5, ["x"] = 12, ["name"] = "default:leaves", ["z"] = 10, ["meta"] = { ["inventory"] = {  }, ["fields"] = {  } }, ["param2"] = 0, ["param1"] = 13 }, { ["y"] = 5, ["x"] = 12, ["name"] = "default:leaves", ["z"] = 11, ["meta"] = { ["inventory"] = {  }, ["fields"] = {  } }, ["param2"] = 0, ["param1"] = 13 }, { ["y"] = 5, ["x"] = 12, ["name"] = "default:leaves", ["z"] = 12, ["meta"] = { ["inventory"] = {  }, ["fields"] = {  } }, ["param2"] = 0, ["param1"] = 13 }, { ["y"] = 0, ["x"] = 13, ["name"] = "default:cobble", ["z"] = 1, ["meta"] = { ["inventory"] = {  }, ["fields"] = {  } }, ["param2"] = 0, ["param1"] = 0 }, { ["y"] = 0, ["x"] = 13, ["name"] = "default:tree", ["z"] = 2, ["meta"] = { ["inventory"] = {  }, ["fields"] = {  } }, ["param2"] = 0, ["param1"] = 15 }, { ["y"] = 0, ["x"] = 13, ["name"] = "default:tree", ["z"] = 3, ["meta"] = { ["inventory"] = {  }, ["fields"] = {  } }, ["param2"] = 0, ["param1"] = 11 }, { ["y"] = 0, ["x"] = 13, ["name"] = "default:tree", ["z"] = 5, ["meta"] = { ["inventory"] = {  }, ["fields"] = {  } }, ["param2"] = 0, ["param1"] = 12 }, { ["y"] = 0, ["x"] = 13, ["name"] = "default:tree", ["z"] = 6, ["meta"] = { ["inventory"] = {  }, ["fields"] = {  } }, ["param2"] = 0, ["param1"] = 12 }, { ["y"] = 0, ["x"] = 13, ["name"] = "default:cobble", ["z"] = 7, ["meta"] = { ["inventory"] = {  }, ["fields"] = {  } }, ["param2"] = 0, ["param1"] = 0 }, { ["y"] = 0, ["x"] = 13, ["name"] = "default:cobble", ["z"] = 8, ["meta"] = { ["inventory"] = {  }, ["fields"] = {  } }, ["param2"] = 0, ["param1"] = 0 }, { ["y"] = 0, ["x"] = 13, ["name"] = "default:cobble", ["z"] = 9, ["meta"] = { ["inventory"] = {  }, ["fields"] = {  } }, ["param2"] = 0, ["param1"] = 0 }, { ["y"] = 0, ["x"] = 13, ["name"] = "default:cobble", ["z"] = 10, ["meta"] = { ["inventory"] = {  }, ["fields"] = {  } }, ["param2"] = 0, ["param1"] = 0 }, { ["y"] = 0, ["x"] = 13, ["name"] = "default:cobble", ["z"] = 11, ["meta"] = { ["inventory"] = {  }, ["fields"] = {  } }, ["param2"] = 0, ["param1"] = 0 }, { ["y"] = 0, ["x"] = 13, ["name"] = "default:cobble", ["z"] = 12, ["meta"] = { ["inventory"] = {  }, ["fields"] = {  } }, ["param2"] = 0, ["param1"] = 0 }, { ["y"] = 0, ["x"] = 13, ["name"] = "default:cobble", ["z"] = 13, ["meta"] = { ["inventory"] = {  }, ["fields"] = {  } }, ["param2"] = 0, ["param1"] = 0 }, { ["y"] = 0, ["x"] = 13, ["name"] = "default:dirt_with_grass", ["z"] = 14, ["meta"] = { ["inventory"] = {  }, ["fields"] = {  } }, ["param2"] = 0, ["param1"] = 0 }, { ["y"] = 1, ["x"] = 13, ["name"] = "default:cobble", ["z"] = 1, ["meta"] = { ["inventory"] = {  }, ["fields"] = {  } }, ["param2"] = 0, ["param1"] = 0 }, { ["y"] = 1, ["x"] = 13, ["name"] = "default:tree", ["z"] = 2, ["meta"] = { ["inventory"] = {  }, ["fields"] = {  } }, ["param2"] = 0, ["param1"] = 15 }, { ["y"] = 1, ["x"] = 13, ["name"] = "default:tree", ["z"] = 3, ["meta"] = { ["inventory"] = {  }, ["fields"] = {  } }, ["param2"] = 0, ["param1"] = 11 }, { ["y"] = 1, ["x"] = 13, ["name"] = "default:tree", ["z"] = 5, ["meta"] = { ["inventory"] = {  }, ["fields"] = {  } }, ["param2"] = 0, ["param1"] = 12 }, { ["y"] = 1, ["x"] = 13, ["name"] = "default:tree", ["z"] = 6, ["meta"] = { ["inventory"] = {  }, ["fields"] = {  } }, ["param2"] = 0, ["param1"] = 12 }, { ["y"] = 1, ["x"] = 13, ["name"] = "default:cobble", ["z"] = 7, ["meta"] = { ["inventory"] = {  }, ["fields"] = {  } }, ["param2"] = 0, ["param1"] = 0 }, { ["y"] = 1, ["x"] = 13, ["name"] = "default:cobble", ["z"] = 8, ["meta"] = { ["inventory"] = {  }, ["fields"] = {  } },