5:return {{["y"] = 0, ["x"] = 0, ["name"] = "default:stone", ["z"] = 0, ["meta"] = {["inventory"] = {}, ["fields"] = {}}}, {["y"] = 0, ["x"] = 0, ["name"] = "default:stone", ["z"] = 1, ["meta"] = {["inventory"] = {}, ["fields"] = {}}}, {["y"] = 0, ["x"] = 0, ["name"] = "default:stone", ["z"] = 2, ["meta"] = {["inventory"] = {}, ["fields"] = {}}}, {["y"] = 0, ["x"] = 0, ["name"] = "default:stone", ["z"] = 3, ["meta"] = {["inventory"] = {}, ["fields"] = {}}}, {["y"] = 0, ["x"] = 0, ["name"] = "default:stone", ["z"] = 4, ["meta"] = {["inventory"] = {}, ["fields"] = {}}}, {["y"] = 0, ["x"] = 0, ["name"] = "default:stone", ["z"] = 5, ["meta"] = {["inventory"] = {}, ["fields"] = {}}}, {["y"] = 0, ["x"] = 0, ["name"] = "default:stone", ["z"] = 6, ["meta"] = {["inventory"] = {}, ["fields"] = {}}}, {["y"] = 0, ["x"] = 0, ["name"] = "default:stone", ["z"] = 7, ["meta"] = {["inventory"] = {}, ["fields"] = {}}}, {["y"] = 0, ["x"] = 0, ["name"] = "default:stone", ["z"] = 8, ["meta"] = {["inventory"] = {}, ["fields"] = {}}}, {["y"] = 0, ["x"] = 0, ["name"] = "default:stone", ["z"] = 9, ["meta"] = {["inventory"] = {}, ["fields"] = {}}}, {["y"] = 0, ["x"] = 0, ["name"] = "default:stone", ["z"] = 10, ["meta"] = {["inventory"] = {}, ["fields"] = {}}}, {["y"] = 0, ["x"] = 0, ["name"] = "default:stone", ["z"] = 11, ["meta"] = {["inventory"] = {}, ["fields"] = {}}}, {["y"] = 0, ["x"] = 0, ["name"] = "default:stone", ["z"] = 12, ["meta"] = {["inventory"] = {}, ["fields"] = {}}}, {["y"] = 0, ["x"] = 0, ["name"] = "default:stone", ["z"] = 13, ["meta"] = {["inventory"] = {}, ["fields"] = {}}}, {["y"] = 0, ["x"] = 0, ["name"] = "default:stone", ["z"] = 14, ["meta"] = {["inventory"] = {}, ["fields"] = {}}}, {["y"] = 0, ["x"] = 0, ["name"] = "default:dirt", ["z"] = 15, ["meta"] = {["inventory"] = {}, ["fields"] = {}}}, {["y"] = 0, ["x"] = 0, ["name"] = "default:dirt", ["z"] = 16, ["meta"] = {["inventory"] = {}, ["fields"] = {}}}, {["y"] = 0, ["x"] = 0, ["name"] = "default:water_flowing", ["z"] = 17, ["meta"] = {["inventory"] = {}, ["fields"] = {}}, ["param2"] = 15, ["param1"] = 13}, {["y"] = 1, ["x"] = 0, ["name"] = "default:stone", ["z"] = 0, ["meta"] = {["inventory"] = {}, ["fields"] = {}}}, {["y"] = 1, ["x"] = 0, ["name"] = "default:stone", ["z"] = 1, ["meta"] = {["inventory"] = {}, ["fields"] = {}}}, {["y"] = 1, ["x"] = 0, ["name"] = "default:stone", ["z"] = 2, ["meta"] = {["inventory"] = {}, ["fields"] = {}}}, {["y"] = 1, ["x"] = 0, ["name"] = "default:stone", ["z"] = 3, ["meta"] = {["inventory"] = {}, ["fields"] = {}}}, {["y"] = 1, ["x"] = 0, ["name"] = "default:stone", ["z"] = 4, ["meta"] = {["inventory"] = {}, ["fields"] = {}}}, {["y"] = 1, ["x"] = 0, ["name"] = "default:stone", ["z"] = 5, ["meta"] = {["inventory"] = {}, ["fields"] = {}}}, {["y"] = 1, ["x"] = 0, ["name"] = "default:stone", ["z"] = 6, ["meta"] = {["inventory"] = {}, ["fields"] = {}}}, {["y"] = 1, ["x"] = 0, ["name"] = "default:stone", ["z"] = 7, ["meta"] = {["inventory"] = {}, ["fields"] = {}}}, {["y"] = 1, ["x"] = 0, ["name"] = "default:stone", ["z"] = 8, ["meta"] = {["inventory"] = {}, ["fields"] = {}}}, {["y"] = 1, ["x"] = 0, ["name"] = "default:stone", ["z"] = 9, ["meta"] = {["inventory"] = {}, ["fields"] = {}}}, {["y"] = 1, ["x"] = 0, ["name"] = "default:stone", ["z"] = 10, ["meta"] = {["inventory"] = {}, ["fields"] = {}}}, {["y"] = 1, ["x"] = 0, ["name"] = "default:stone", ["z"] = 11, ["meta"] = {["inventory"] = {}, ["fields"] = {}}}, {["y"] = 1, ["x"] = 0, ["name"] = "default:stone", ["z"] = 12, ["meta"] = {["inventory"] = {}, ["fields"] = {}}}, {["y"] = 1, ["x"] = 0, ["name"] = "default:stone", ["z"] = 13, ["meta"] = {["inventory"] = {}, ["fields"] = {}}}, {["y"] = 1, ["x"] = 0, ["name"] = "default:stone", ["z"] = 14, ["meta"] = {["inventory"] = {}, ["fields"] = {}}}, {["y"] = 1, ["x"] = 0, ["name"] = "default:dirt", ["z"] = 15, ["meta"] = {["inventory"] = {}, ["fields"] = {}}}, {["y"] = 1, ["x"] = 0, ["name"] = "default:water_flowing", ["z"] = 16, ["meta"] = {["inventory"] = {}, ["fields"] = {}}, ["param2"] = 7, ["param1"] = 12}, {["y"] = 1, ["x"] = 0, ["name"] = "default:water_flowing", ["z"] = 17, ["meta"] = {["inventory"] = {}, ["fields"] = {}}, ["param2"] = 14, ["param1"] = 13}, {["y"] = 1, ["x"] = 0, ["name"] = "default:cobble", ["z"] = 21, ["meta"] = {["inventory"] = {}, ["fields"] = {}}}, {["y"] = 1, ["x"] = 0, ["name"] = "default:cobble", ["z"] = 22, ["meta"] = {["inventory"] = {}, ["fields"] = {}}}, {["y"] = 2, ["x"] = 0, ["name"] = "default:stone", ["z"] = 0, ["meta"] = {["inventory"] = {}, ["fields"] = {}}}, {["y"] = 2, ["x"] = 0, ["name"] = "default:stone", ["z"] = 1, ["meta"] = {["inventory"] = {}, ["fields"] = {}}}, {["y"] = 2, ["x"] = 0, ["name"] = "default:stone", ["z"] = 2, ["meta"] = {["inventory"] = {}, ["fields"] = {}}}, {["y"] = 2, ["x"] = 0, ["name"] = "default:stone", ["z"] = 3, ["meta"] = {["inventory"] = {}, ["fields"] = {}}}, {["y"] = 2, ["x"] = 0, ["name"] = "default:stone", ["z"] = 4, ["meta"] = {["inventory"] = {}, ["fields"] = {}}}, {["y"] = 2, ["x"] = 0, ["name"] = "default:stone", ["z"] = 5, ["meta"] = {["inventory"] = {}, ["fields"] = {}}}, {["y"] = 2, ["x"] = 0, ["name"] = "default:stone", ["z"] = 6, ["meta"] = {["inventory"] = {}, ["fields"] = {}}}, {["y"] = 2, ["x"] = 0, ["name"] = "default:stone", ["z"] = 7, ["meta"] = {["inventory"] = {}, ["fields"] = {}}}, {["y"] = 2, ["x"] = 0, ["name"] = "default:stone", ["z"] = 8, ["meta"] = {["inventory"] = {}, ["fields"] = {}}}, {["y"] = 2, ["x"] = 0, ["name"] = "default:stone", ["z"] = 9, ["meta"] = {["inventory"] = {}, ["fields"] = {}}}, {["y"] = 2, ["x"] = 0, ["name"] = "default:stone", ["z"] = 10, ["meta"] = {["inventory"] = {}, ["fields"] = {}}}, {["y"] = 2, ["x"] = 0, ["name"] = "default:stone", ["z"] = 11, ["meta"] = {["inventory"] = {}, ["fields"] = {}}}, {["y"] = 2, ["x"] = 0, ["name"] = "default:stone", ["z"] = 12, ["meta"] = {["inventory"] = {}, ["fields"] = {}}}, {["y"] = 2, ["x"] = 0, ["name"] = "default:stone", ["z"] = 13, ["meta"] = {["inventory"] = {}, ["fields"] = {}}}, {["y"] = 2, ["x"] = 0, ["name"] = "default:dirt", ["z"] = 14, ["meta"] = {["inventory"] = {}, ["fields"] = {}}}, {["y"] = 2, ["x"] = 0, ["name"] = "default:dirt", ["z"] = 15, ["meta"] = {["inventory"] = {}, ["fields"] = {}}}, {["y"] = 2, ["x"] = 0, ["name"] = "default:water_flowing", ["z"] = 16, ["meta"] = {["inventory"] = {}, ["fields"] = {}}, ["param2"] = 15, ["param1"] = 13}, {["y"] = 3, ["x"] = 0, ["name"] = "default:stone", ["z"] = 0, ["meta"] = {["inventory"] = {}, ["fields"] = {}}}, {["y"] = 3, ["x"] = 0, ["name"] = "default:stone", ["z"] = 1, ["meta"] = {["inventory"] = {}, ["fields"] = {}}}, {["y"] = 3, ["x"] = 0, ["name"] = "default:stone", ["z"] = 2, ["meta"] = {["inventory"] = {}, ["fields"] = {}}}, {["y"] = 3, ["x"] = 0, ["name"] = "default:stone", ["z"] = 3, ["meta"] = {["inventory"] = {}, ["fields"] = {}}}, {["y"] = 3, ["x"] = 0, ["name"] = "default:stone", ["z"] = 4, ["meta"] = {["inventory"] = {}, ["fields"] = {}}}, {["y"] = 3, ["x"] = 0, ["name"] = "default:stone", ["z"] = 5, ["meta"] = {["inventory"] = {}, ["fields"] = {}}}, {["y"] = 3, ["x"] = 0, ["name"] = "default:stone", ["z"] = 6, ["meta"] = {["inventory"] = {}, ["fields"] = {}}}, {["y"] = 3, ["x"] = 0, ["name"] = "default:stone", ["z"] = 7, ["meta"] = {["inventory"] = {}, ["fields"] = {}}}, {["y"] = 3, ["x"] = 0, ["name"] = "default:stone", ["z"] = 8, ["meta"] = {["inventory"] = {}, ["fields"] = {}}}, {["y"] = 3, ["x"] = 0, ["name"] = "default:stone", ["z"] = 9, ["meta"] = {["inventory"] = {}, ["fields"] = {}}}, {["y"] = 3, ["x"] = 0, ["name"] = "default:stone", ["z"] = 10, ["meta"] = {["inventory"] = {}, ["fields"] = {}}}, {["y"] = 3, ["x"] = 0, ["name"] = "default:stone", ["z"] = 11, ["meta"] = {["inventory"] = {}, ["fields"] = {}}}, {["y"] = 3, ["x"] = 0, ["name"] = "default:stone", ["z"] = 12, ["meta"] = {["inventory"] = {}, ["fields"] = {}}}, {["y"] = 3, ["x"] = 0, ["name"] = "default:stone", ["z"] = 13, ["meta"] = {["inventory"] = {}, ["fields"] = {}}}, {["y"] = 3, ["x"] = 0, ["name"] = "default:dirt", ["z"] = 14, ["meta"] = {["inventory"] = {}, ["fields"] = {}}}, {["y"] = 3, ["x"] = 0, ["name"] = "default:water_flowing", ["z"] = 15, ["meta"] = {["inventory"] = {}, ["fields"] = {}}, ["param2"] = 7, ["param1"] = 12}, {["y"] = 3, ["x"] = 0, ["name"] = "default:water_flowing", ["z"] = 16, ["meta"] = {["inventory"] = {}, ["fields"] = {}}, ["param2"] = 14, ["param1"] = 13}, {["y"] = 4, ["x"] = 0, ["name"] = "default:ice", ["z"] = 0, ["meta"] = {["inventory"] = {}, ["fields"] = {}}}, {["y"] = 4, ["x"] = 0, ["name"] = "default:ice", ["z"] = 1, ["meta"] = {["inventory"] = {}, ["fields"] = {}}}, {["y"] = 4, ["x"] = 0, ["name"] = "default:ice", ["z"] = 2, ["meta"] = {["inventory"] = {}, ["fields"] = {}}}, {["y"] = 4, ["x"] = 0, ["name"] = "default:ice", ["z"] = 3, ["meta"] = {["inventory"] = {}, ["fields"] = {}}}, {["y"] = 4, ["x"] = 0, ["name"] = "default:stone", ["z"] = 4, ["meta"] = {["inventory"] = {}, ["fields"] = {}}}, {["y"] = 4, ["x"] = 0, ["name"] = "default:stone", ["z"] = 5, ["meta"] = {["inventory"] = {}, ["fields"] = {}}}, {["y"] = 4, ["x"] = 0, ["name"] = "default:stone", ["z"] = 6, ["meta"] = {["inventory"] = {}, ["fields"] = {}}}, {["y"] = 4, ["x"] = 0, ["name"] = "default:stone", ["z"] = 7, ["meta"] = {["inventory"] = {}, ["fields"] = {}}}, {["y"] = 4, ["x"] = 0, ["name"] = "default:stone", ["z"] = 8, ["meta"] = {["inventory"] = {}, ["fields"] = {}}}, {["y"] = 4, ["x"] = 0, ["name"] = "default:stone", ["z"] = 9, ["meta"] = {["inventory"] = {}, ["fields"] = {}}}, {["y"] = 4, ["x"] = 0, ["name"] = "default:stone", ["z"] = 10, ["meta"] = {["inventory"] = {}, ["fields"] = {}}}, {["y"] = 4, ["x"] = 0, ["name"] = "default:stone", ["z"] = 11, ["meta"] = {["inventory"] = {}, ["fields"] = {}}}, {["y"] = 4, ["x"] = 0, ["name"] = "default:stone", ["z"] = 12, ["meta"] = {["inventory"] = {}, ["fields"] = {}}}, {["y"] = 4, ["x"] = 0, ["name"] = "default:dirt", ["z"] = 13, ["meta"] = {["inventory"] = {}, ["fields"] = {}}}, {["y"] = 4, ["x"] = 0, ["name"] = "default:water_flowing", ["z"] = 14, ["meta"] = {["inventory"] = {}, ["fields"] = {}}, ["param2"] = 6, ["param1"] = 12}, {["y"] = 4, ["x"] = 0, ["name"] = "default:water_flowing", ["z"] = 15, ["meta"] = {["inventory"] = {}, ["fields"] = {}}, ["param2"] = 13, ["param1"] = 13}, {["y"] = 5, ["x"] = 0, ["name"] = "default:ice", ["z"] = 0, ["meta"] = {["inventory"] = {}, ["fields"] = {}}}, {["y"] = 5, ["x"] = 0, ["name"] = "default:ice", ["z"] = 1, ["meta"] = {["inventory"] = {}, ["fields"] = {}}}, {["y"] = 5, ["x"] = 0, ["name"] = "default:ice", ["z"] = 2, ["meta"] = {["inventory"] = {}, ["fields"] = {}}}, {["y"] = 5, ["x"] = 0, ["name"] = "default:ice", ["z"] = 3, ["meta"] = {["inventory"] = {}, ["fields"] = {}}}, {["y"] = 5, ["x"] = 0, ["name"] = "default:stone", ["z"] = 4, ["meta"] = {["inventory"] = {}, ["fields"] = {}}}, {["y"] = 5, ["x"] = 0, ["name"] = "default:stone", ["z"] = 5, ["meta"] = {["inventory"] = {}, ["fields"] = {}}}, {["y"] = 5, ["x"] = 0, ["name"] = "default:stone", ["z"] = 6, ["meta"] = {["inventory"] = {}, ["fields"] = {}}}, {["y"] = 5, ["x"] = 0, ["name"] = "default:stone", ["z"] = 7, ["meta"] = {["inventory"] = {}, ["fields"] = {}}}, {["y"] = 5, ["x"] = 0, ["name"] = "default:stone", ["z"] = 8, ["meta"] = {["inventory"] = {}, ["fields"] = {}}}, {["y"] = 5, ["x"] = 0, ["name"] = "default:stone", ["z"] = 9, ["meta"] = {["inventory"] = {}, ["fields"] = {}}}, {["y"] = 5, ["x"] = 0, ["name"] = "default:stone", ["z"] = 10, ["meta"] = {["inventory"] = {}, ["fields"] = {}}}, {["y"] = 5, ["x"] = 0, ["name"] = "default:dirt_with_grass", ["z"] = 11, ["meta"] = {["inventory"] = {}, ["fields"] = {}}}, {["y"] = 5, ["x"] = 0, ["name"] = "default:dirt_with_grass", ["z"] = 12, ["meta"] = {["inventory"] = {}, ["fields"] = {}}}, {["y"] = 5, ["x"] = 0, ["name"] = "default:cobble", ["z"] = 13, ["meta"] = {["inventory"] = {}, ["fields"] = {}}}, {["y"] = 5, ["x"] = 0, ["name"] = "default:cobble", ["z"] = 14, ["meta"] = {["inventory"] = {}, ["fields"] = {}}}, {["y"] = 6, ["x"] = 0, ["name"] = "default:ice", ["z"] = 0, ["meta"] = {["inventory"] = {}, ["fields"] = {}}}, {["y"] = 6, ["x"] = 0, ["name"] = "default:ice", ["z"] = 1, ["meta"] = {["inventory"] = {}, ["fields"] = {}}}, {["y"] = 6, ["x"] = 0, ["name"] = "default:dirt", ["z"] = 2, ["meta"] = {["inventory"] = {}, ["fields"] = {}}}, {["y"] = 6, ["x"] = 0, ["name"] = "default:dirt", ["z"] = 3, ["meta"] = {["inventory"] = {}, ["fields"] = {}}}, {["y"] = 6, ["x"] = 0, ["name"] = "default:dirt", ["z"] = 4, ["meta"] = {["inventory"] = {}, ["fields"] = {}}}, {["y"] = 6, ["x"] = 0, ["name"] = "default:dirt", ["z"] = 5, ["meta"] = {["inventory"] = {}, ["fields"] = {}}}, {["y"] = 6, ["x"] = 0, ["name"] = "default:dirt", ["z"] = 6, ["meta"] = {["inventory"] = {}, ["fields"] = {}}}, {["y"] = 6, ["x"] = 0, ["name"] = "default:dirt", ["z"] = 7, ["meta"] = {["inventory"] = {}, ["fields"] = {}}}, {["y"] = 6, ["x"] = 0, ["name"] = "default:dirt", ["z"] = 8, ["meta"] = {["inventory"] = {}, ["fields"] = {}}}, {["y"] = 6, ["x"] = 0, ["name"] = "default:dirt", ["z"] = 9, ["meta"] = {["inventory"] = {}, ["fields"] = {}}}, {["y"] = 6, ["x"] = 0, ["name"] = "default:dirt", ["z"] = 10, ["meta"] = {["inventory"] = {}, ["fields"] = {}}}, {["y"] = 6, ["x"] = 0, ["name"] = "stairs:slab_cobble", ["z"] = 11, ["meta"] = {["inventory"] = {}, ["fields"] = {}}, ["param1"] = 13}, {["y"] = 6, ["x"] = 0, ["name"] = "stairs:slab_cobble", ["z"] = 12, ["meta"] = {["inventory"] = {}, ["fields"] = {}}, ["param1"] = 13}, {["y"] = 7, ["x"] = 0, ["name"] = "default:dirt_with_grass", ["z"] = 0, ["meta"] = {["inventory"] = {}, ["fields"] = {}}}, {["y"] = 7, ["x"] = 0, ["name"] = "default:dirt_with_grass", ["z"] = 1, ["meta"] = {["inventory"] = {}, ["fields"] = {}}}, {["y"] = 7, ["x"] = 0, ["name"] = "default:dirt_with_grass", ["z"] = 2, ["meta"] = {["inventory"] = {}, ["fields"] = {}}}, {["y"] = 7, ["x"] = 0, ["name"] = "default:dirt_with_grass", ["z"] = 3, ["meta"] = {["inventory"] = {}, ["fields"] = {}}}, {["y"] = 7, ["x"] = 0, ["name"] = "default:dirt_with_grass", ["z"] = 4, ["meta"] = {["inventory"] = {}, ["fields"] = {}}}, {["y"] = 7, ["x"] = 0, ["name"] = "default:dirt_with_grass", ["z"] = 5, ["meta"] = {["inventory"] = {}, ["fields"] = {}}}, {["y"] = 7, ["x"] = 0, ["name"] = "default:dirt_with_grass", ["z"] = 6, ["meta"] = {["inventory"] = {}, ["fields"] = {}}}, {["y"] = 7, ["x"] = 0, ["name"] = "default:dirt_with_grass", ["z"] = 7, ["meta"] = {["inventory"] = {}, ["fields"] = {}}}, {["y"] = 7, ["x"] = 0, ["name"] = "default:dirt_with_grass", ["z"] = 8, ["meta"] = {["inventory"] = {}, ["fields"] = {}}}, {["y"] = 7, ["x"] = 0, ["name"] = "default:dirt_with_grass", ["z"] = 9, ["meta"] = {["inventory"] = {}, ["fields"] = {}}}, {["y"] = 7, ["x"] = 0, ["name"] = "default:dirt_with_grass", ["z"] = 10, ["meta"] = {["inventory"] = {}, ["fields"] = {}}}, {["y"] = 10, ["x"] = 0, ["name"] = "default:leaves", ["z"] = 1, ["meta"] = {["inventory"] = {}, ["fields"] = {}}, ["param1"] = 13}, {["y"] = 10, ["x"] = 0, ["name"] = "default:leaves", ["z"] = 2, ["meta"] = {["inventory"] = {}, ["fields"] = {}}, ["param1"] = 12}, {["y"] = 10, ["x"] = 0, ["name"] = "default:leaves", ["z"] = 3, ["meta"] = {["inventory"] = {}, ["fields"] = {}}, ["param1"] = 13}, {["y"] = 10, ["x"] = 0, ["name"] = "default:leaves", ["z"] = 4, ["meta"] = {["inventory"] = {}, ["fields"] = {}}, ["param1"] = 12}, {["y"] = 10, ["x"] = 0, ["name"] = "default:leaves", ["z"] = 5, ["meta"] = {["inventory"] = {}, ["fields"] = {}}, ["param1"] = 29}, {["y"] = 11, ["x"] = 0, ["name"] = "default:leaves", ["z"] = 1, ["meta"] = {["inventory"] = {}, ["fields"] = {}}, ["param1"] = 13}, {["y"] = 11, ["x"] = 0, ["name"] = "default:leaves", ["z"] = 2, ["meta"] = {["inventory"] = {}, ["fields"] = {}}, ["param1"] = 12}, {["y"] = 11, ["x"] = 0, ["name"] = "default:leaves", ["z"] = 3, ["meta"] = {["inventory"] = {}, ["fields"] = {}}, ["param1"] = 13}, {["y"] = 11, ["x"] = 0, ["name"] = "default:leaves", ["z"] = 4, ["meta"] = {["inventory"] = {}, ["fields"] = {}}, ["param1"] = 28}, {["y"] = 11, ["x"] = 0, ["name"] = "default:leaves", ["z"] = 5, ["meta"] = {["inventory"] = {}, ["fields"] = {}}, ["param1"] = 45}, {["y"] = 12, ["x"] = 0, ["name"] = "default:leaves", ["z"] = 1, ["meta"] = {["inventory"] = {}, ["fields"] = {}}, ["param1"] = 13}, {["y"] = 12, ["x"] = 0, ["name"] = "default:leaves", ["z"] = 2, ["meta"] = {["inventory"] = {}, ["fields"] = {}}, ["param1"] = 12}, {["y"] = 12, ["x"] = 0, ["name"] = "default:leaves", ["z"] = 3, ["meta"] = {["inventory"] = {}, ["fields"] = {}}, ["param1"] = 29}, {["y"] = 12, ["x"] = 0, ["name"] = "default:leaves", ["z"] = 4, ["meta"] = {["inventory"] = {}, ["fields"] = {}}, ["param1"] = 44}, {["y"] = 12, ["x"] = 0, ["name"] = "default:leaves", ["z"] = 5, ["meta"] = {["inventory"] = {}, ["fields"] = {}}, ["param1"] = 61}, {["y"] = 13, ["x"] = 0, ["name"] = "default:leaves", ["z"] = 2, ["meta"] = {["inventory"] = {}, ["fields"] = {}}, ["param1"] = 29}, {["y"] = 13, ["x"] = 0, ["name"] = "default:leaves", ["z"] = 3, ["meta"] = {["inventory"] = {}, ["fields"] = {}}, ["param1"] = 45}, {["y"] = 13, ["x"] = 0, ["name"] = "default:leaves", ["z"] = 4, ["meta"] = {["inventory"] = {}, ["fields"] = {}}, ["param1"] = 61}, {["y"] = 14, ["x"] = 0, ["name"] = "default:leaves", ["z"] = 2, ["meta"] = {["inventory"] = {}, ["fields"] = {}}, ["param1"] = 45}, {["y"] = 14, ["x"] = 0, ["name"] = "default:leaves", ["z"] = 3, ["meta"] = {["inventory"] = {}, ["fields"] = {}}, ["param1"] = 61}, {["y"] = 14, ["x"] = 0, ["name"] = "default:leaves", ["z"] = 4, ["meta"] = {["inventory"] = {}, ["fields"] = {}}, ["param1"] = 77}, {["y"] = 0, ["x"] = 1, ["name"] = "default:stone", ["z"] = 0, ["meta"] = {["inventory"] = {}, ["fields"] = {}}}, {["y"] = 0, ["x"] = 1, ["name"] = "default:stone", ["z"] = 1, ["meta"] = {["inventory"] = {}, ["fields"] = {}}}, {["y"] = 0, ["x"] = 1, ["name"] = "default:stone", ["z"] = 2, ["meta"] = {["inventory"] = {}, ["fields"] = {}}}, {["y"] = 0, ["x"] = 1, ["name"] = "default:stone", ["z"] = 3, ["meta"] = {["inventory"] = {}, ["fields"] = {}}}, {["y"] = 0, ["x"] = 1, ["name"] = "default:stone", ["z"] = 4, ["meta"] = {["inventory"] = {}, ["fields"] = {}}}, {["y"] = 0, ["x"] = 1, ["name"] = "default:stone", ["z"] = 5, ["meta"] = {["inventory"] = {}, ["fields"] = {}}}, {["y"] = 0, ["x"] = 1, ["name"] = "default:stone", ["z"] = 6, ["meta"] = {["inventory"] = {}, ["fields"] = {}}}, {["y"] = 0, ["x"] = 1, ["name"] = "default:stone", ["z"] = 7, ["meta"] = {["inventory"] = {}, ["fields"] = {}}}, {["y"] = 0, ["x"] = 1, ["name"] = "default:stone", ["z"] = 8, ["meta"] = {["inventory"] = {}, ["fields"] = {}}}, {["y"] = 0, ["x"] = 1, ["name"] = "default:stone", ["z"] = 9, ["meta"] = {["inventory"] = {}, ["fields"] = {}}}, {["y"] = 0, ["x"] = 1, ["name"] = "default:stone", ["z"] = 10, ["meta"] = {["inventory"] = {}, ["fields"] = {}}}, {["y"] = 0, ["x"] = 1, ["name"] = "default:stone", ["z"] = 11, ["meta"] = {["inventory"] = {}, ["fields"] = {}}}, {["y"] = 0, ["x"] = 1, ["name"] = "default:stone", ["z"] = 12, ["meta"] = {["inventory"] = {}, ["fields"] = {}}}, {["y"] = 0, ["x"] = 1, ["name"] = "default:stone", ["z"] = 13, ["meta"] = {["inventory"] = {}, ["fields"] = {}}}, {["y"] = 0, ["x"] = 1, ["name"] = "default:stone", ["z"] = 14, ["meta"] = {["inventory"] = {}, ["fields"] = {}}}, {["y"] = 0, ["x"] = 1, ["name"] = "default:dirt", ["z"] = 15, ["meta"] = {["inventory"] = {}, ["fields"] = {}}}, {["y"] = 0, ["x"] = 1, ["name"] = "vines:root_end", ["z"] = 16, ["meta"] = {["inventory"] = {}, ["fields"] = {}}, ["param1"] = 11}, {["y"] = 0, ["x"] = 1, ["name"] = "default:water_flowing", ["z"] = 17, ["meta"] = {["inventory"] = {}, ["fields"] = {}}, ["param2"] = 15, ["param1"] = 12}, {["y"] = 1, ["x"] = 1, ["name"] = "default:stone", ["z"] = 0, ["meta"] = {["inventory"] = {}, ["fields"] = {}}}, {["y"] = 1, ["x"] = 1, ["name"] = "default:stone", ["z"] = 1, ["meta"] = {["inventory"] = {}, ["fields"] = {}}}, {["y"] = 1, ["x"] = 1, ["name"] = "default:stone", ["z"] = 2, ["meta"] = {["inventory"] = {}, ["fields"] = {}}}, {["y"] = 1, ["x"] = 1, ["name"] = "default:stone", ["z"] = 3, ["meta"] = {["inventory"] = {}, ["fields"] = {}}}, {["y"] = 1, ["x"] = 1, ["name"] = "default:stone", ["z"] = 4, ["meta"] = {["inventory"] = {}, ["fields"] = {}}}, {["y"] = 1, ["x"] = 1, ["name"] = "default:stone", ["z"] = 5, ["meta"] = {["inventory"] = {}, ["fields"] = {}}}, {["y"] = 1, ["x"] = 1, ["name"] = "default:stone", ["z"] = 6, ["meta"] = {["inventory"] = {}, ["fields"] = {}}}, {["y"] = 1, ["x"] = 1, ["name"] = "default:stone", ["z"] = 7, ["meta"] = {["inventory"] = {}, ["fields"] = {}}}, {["y"] = 1, ["x"] = 1, ["name"] = "default:stone", ["z"] = 8, ["meta"] = {["inventory"] = {}, ["fields"] = {}}}, {["y"] = 1, ["x"] = 1, ["name"] = "default:stone", ["z"] = 9, ["meta"] = {["inventory"] = {}, ["fields"] = {}}}, {["y"] = 1, ["x"] = 1, ["name"] = "default:stone", ["z"] = 10, ["meta"] = {["inventory"] = {}, ["fields"] = {}}}, {["y"] = 1, ["x"] = 1, ["name"] = "default:stone", ["z"] = 11, ["meta"] = {["inventory"] = {}, ["fields"] = {}}}, {["y"] = 1, ["x"] = 1, ["name"] = "default:stone", ["z"] = 12, ["meta"] = {["inventory"] = {}, ["fields"] = {}}}, {["y"] = 1, ["x"] = 1, ["name"] = "default:stone", ["z"] = 13, ["meta"] = {["inventory"] = {}, ["fields"] = {}}}, {["y"] = 1, ["x"] = 1, ["name"] = "default:stone", ["z"] = 14, ["meta"] = {["inventory"] = {}, ["fields"] = {}}}, {["y"] = 1, ["x"] = 1, ["name"] = "default:dirt", ["z"] = 15, ["meta"] = {["inventory"] = {}, ["fields"] = {}}}, {["y"] = 1, ["x"] = 1, ["name"] = "default:dirt", ["z"] = 16, ["meta"] = {["inventory"] = {}, ["fields"] = {}}}, {["y"] = 1, ["x"] = 1, ["name"] = "default:water_flowing", ["z"] = 17, ["meta"] = {["inventory"] = {}, ["fields"] = {}}, ["param2"] = 15, ["param1"] = 12}, {["y"] = 1, ["x"] = 1, ["name"] = "default:cobble", ["z"] = 21, ["meta"] = {["inventory"] = {}, ["fields"] = {}}}, {["y"] = 1, ["x"] = 1, ["name"] = "default:cobble", ["z"] = 22, ["meta"] = {["inventory"] = {}, ["fields"] = {}}}, {["y"] = 2, ["x"] = 1, ["name"] = "default:stone", ["z"] = 0, ["meta"] = {["inventory"] = {}, ["fields"] = {}}}, {["y"] = 2, ["x"] = 1, ["name"] = "default:stone", ["z"] = 1, ["meta"] = {["inventory"] = {}, ["fields"] = {}}}, {["y"] = 2, ["x"] = 1, ["name"] = "default:stone", ["z"] = 2, ["meta"] = {["inventory"] = {}, ["fields"] = {}}}, {["y"] = 2, ["x"] = 1, ["name"] = "default:stone", ["z"] = 3, ["meta"] = {["inventory"] = {}, ["fields"] = {}}}, {["y"] = 2, ["x"] = 1, ["name"] = "default:stone", ["z"] = 4, ["meta"] = {["inventory"] = {}, ["fields"] = {}}}, {["y"] = 2, ["x"] = 1, ["name"] = "default:stone", ["z"] = 5, ["meta"] = {["inventory"] = {}, ["fields"] = {}}}, {["y"] = 2, ["x"] = 1, ["name"] = "default:stone", ["z"] = 6, ["meta"] = {["inventory"] = {}, ["fields"] = {}}}, {["y"] = 2, ["x"] = 1, ["name"] = "default:stone", ["z"] = 7, ["meta"] = {["inventory"] = {}, ["fields"] = {}}}, {["y"] = 2, ["x"] = 1, ["name"] = "default:stone", ["z"] = 8, ["meta"] = {["inventory"] = {}, ["fields"] = {}}}, {["y"] = 2, ["x"] = 1, ["name"] = "default:stone", ["z"] = 9, ["meta"] = {["inventory"] = {}, ["fields"] = {}}}, {["y"] = 2, ["x"] = 1, ["name"] = "default:stone", ["z"] = 10, ["meta"] = {["inventory"] = {}, ["fields"] = {}}}, {["y"] = 2, ["x"] = 1, ["name"] = "default:stone", ["z"] = 11, ["meta"] = {["inventory"] = {}, ["fields"] = {}}}, {["y"] = 2, ["x"] = 1, ["name"] = "default:stone", ["z"] = 12, ["meta"] = {["inventory"] = {}, ["fields"] = {}}}, {["y"] = 2, ["x"] = 1, ["name"] = "default:stone", ["z"] = 13, ["meta"] = {["inventory"] = {}, ["fields"] = {}}}, {["y"] = 2, ["x"] = 1, ["name"] = "default:dirt", ["z"] = 14, ["meta"] = {["inventory"] = {}, ["fields"] = {}}}, {["y"] = 2, ["x"] = 1, ["name"] = "default:dirt", ["z"] = 15, ["meta"] = {["inventory"] = {}, ["fields"] = {}}}, {["y"] = 2, ["x"] = 1, ["name"] = "default:water_flowing", ["z"] = 16, ["meta"] = {["inventory"] = {}, ["fields"] = {}}, ["param2"] = 7, ["param1"] = 12}, {["y"] = 2, ["x"] = 1, ["name"] = "default:water_flowing", ["z"] = 17, ["meta"] = {["inventory"] = {}, ["fields"] = {}}, ["param2"] = 14, ["param1"] = 13}, {["y"] = 3, ["x"] = 1, ["name"] = "default:stone", ["z"] = 0, ["meta"] = {["inventory"] = {}, ["fields"] = {}}}, {["y"] = 3, ["x"] = 1, ["name"] = "default:stone", ["z"] = 1, ["meta"] = {["inventory"] = {}, ["fields"] = {}}}, {["y"] = 3, ["x"] = 1, ["name"] = "default:stone", ["z"] = 2, ["meta"] = {["inventory"] = {}, ["fields"] = {}}}, {["y"] = 3, ["x"] = 1, ["name"] = "default:stone", ["z"] = 3, ["meta"] = {["inventory"] = {}, ["fields"] = {}}}, {["y"] = 3, ["x"] = 1, ["name"] = "default:stone", ["z"] = 4, ["meta"] = {["inventory"] = {}, ["fields"] = {}}}, {["y"] = 3, ["x"] = 1, ["name"] = "default:stone", ["z"] = 5, ["meta"] = {["inventory"] = {}, ["fields"] = {}}}, {["y"] = 3, ["x"] = 1, ["name"] = "default:stone", ["z"] = 6, ["meta"] = {["inventory"] = {}, ["fields"] = {}}}, {["y"] = 3, ["x"] = 1, ["name"] = "default:stone", ["z"] = 7, ["meta"] = {["inventory"] = {}, ["fields"] = {}}}, {["y"] = 3, ["x"] = 1, ["name"] = "default:stone", ["z"] = 8, ["meta"] = {["inventory"] = {}, ["fields"] = {}}}, {["y"] = 3, ["x"] = 1, ["name"] = "default:stone", ["z"] = 9, ["meta"] = {["inventory"] = {}, ["fields"] = {}}}, {["y"] = 3, ["x"] = 1, ["name"] = "default:stone", ["z"] = 10, ["meta"] = {["inventory"] = {}, ["fields"] = {}}}, {["y"] = 3, ["x"] = 1, ["name"] = "default:stone", ["z"] = 11, ["meta"] = {["inventory"] = {}, ["fields"] = {}}}, {["y"] = 3, ["x"] = 1, ["name"] = "default:stone", ["z"] = 12, ["meta"] = {["inventory"] = {}, ["fields"] = {}}}, {["y"] = 3, ["x"] = 1, ["name"] = "default:stone", ["z"] = 13, ["meta"] = {["inventory"] = {}, ["fields"] = {}}}, {["y"] = 3, ["x"] = 1, ["name"] = "default:dirt", ["z"] = 14, ["meta"] = {["inventory"] = {}, ["fields"] = {}}}, {["y"] = 3, ["x"] = 1, ["name"] = "default:water_flowing", ["z"] = 15, ["meta"] = {["inventory"] = {}, ["fields"] = {}}, ["param2"] = 7, ["param1"] = 11}, {["y"] = 3, ["x"] = 1, ["name"] = "default:water_flowing", ["z"] = 16, ["meta"] = {["inventory"] = {}, ["fields"] = {}}, ["param2"] = 14, ["param1"] = 12}, {["y"] = 4, ["x"] = 1, ["name"] = "default:ice", ["z"] = 0, ["meta"] = {["inventory"] = {}, ["fields"] = {}}}, {["y"] = 4, ["x"] = 1, ["name"] = "default:ice", ["z"] = 1, ["meta"] = {["inventory"] = {}, ["fields"] = {}}}, {["y"] = 4, ["x"] = 1, ["name"] = "default:ice", ["z"] = 2, ["meta"] = {["inventory"] = {}, ["fields"] = {}}}, {["y"] = 4, ["x"] = 1, ["name"] = "default:ice", ["z"] = 3, ["meta"] = {["inventory"] = {}, ["fields"] = {}}}, {["y"] = 4, ["x"] = 1, ["name"] = "default:stone", ["z"] = 4, ["meta"] = {["inventory"] = {}, ["fields"] = {}}}, {["y"] = 4, ["x"] = 1, ["name"] = "default:stone", ["z"] = 5, ["meta"] = {["inventory"] = {}, ["fields"] = {}}}, {["y"] = 4, ["x"] = 1, ["name"] = "default:stone", ["z"] = 6, ["meta"] = {["inventory"] = {}, ["fields"] = {}}}, {["y"] = 4, ["x"] = 1, ["name"] = "default:stone", ["z"] = 7, ["meta"] = {["inventory"] = {}, ["fields"] = {}}}, {["y"] = 4, ["x"] = 1, ["name"] = "default:stone", ["z"] = 8, ["meta"] = {["inventory"] = {}, ["fields"] = {}}}, {["y"] = 4, ["x"] = 1, ["name"] = "default:stone", ["z"] = 9, ["meta"] = {["inventory"] = {}, ["fields"] = {}}}, {["y"] = 4, ["x"] = 1, ["name"] = "default:stone", ["z"] = 10, ["meta"] = {["inventory"] = {}, ["fields"] = {}}}, {["y"] = 4, ["x"] = 1, ["name"] = "default:stone", ["z"] = 11, ["meta"] = {["inventory"] = {}, ["fields"] = {}}}, {["y"] = 4, ["x"] = 1, ["name"] = "default:stone", ["z"] = 12, ["meta"] = {["inventory"] = {}, ["fields"] = {}}}, {["y"] = 4, ["x"] = 1, ["name"] = "default:dirt", ["z"] = 13, ["meta"] = {["inventory"] = {}, ["fields"] = {}}}, {["y"] = 4, ["x"] = 1, ["name"] = "default:water_flowing", ["z"] = 14, ["meta"] = {["inventory"] = {}, ["fields"] = {}}, ["param2"] = 5, ["param1"] = 11}, {["y"] = 4, ["x"] = 1, ["name"] = "default:water_flowing", ["z"] = 15, ["meta"] = {["inventory"] = {}, ["fields"] = {}}, ["param2"] = 12, ["param1"] = 12}, {["y"] = 5, ["x"] = 1, ["name"] = "default:ice", ["z"] = 0, ["meta"] = {["inventory"] = {}, ["fields"] = {}}}, {["y"] = 5, ["x"] = 1, ["name"] = "default:ice", ["z"] = 1, ["meta"] = {["inventory"] = {}, ["fields"] = {}}}, {["y"] = 5, ["x"] = 1, ["name"] = "default:ice", ["z"] = 2, ["meta"] = {["inventory"] = {}, ["fields"] = {}}}, {["y"] = 5, ["x"] = 1, ["name"] = "default:ice", ["z"] = 3, ["meta"] = {["inventory"] = {}, ["fields"] = {}}}, {["y"] = 5, ["x"] = 1, ["name"] = "default:stone", ["z"] = 4, ["meta"] = {["inventory"] = {}, ["fields"] = {}}}, {["y"] = 5, ["x"] = 1, ["name"] = "default:stone", ["z"] = 5, ["meta"] = {["inventory"] = {}, ["fields"] = {}}}, {["y"] = 5, ["x"] = 1, ["name"] = "default:stone", ["z"] = 6, ["meta"] = {["inventory"] = {}, ["fields"] = {}}}, {["y"] = 5, ["x"] = 1, ["name"] = "default:stone", ["z"] = 7, ["meta"] = {["inventory"] = {}, ["fields"] = {}}}, {["y"] = 5, ["x"] = 1, ["name"] = "default:stone", ["z"] = 8, ["meta"] = {["inventory"] = {}, ["fields"] = {}}}, {["y"] = 5, ["x"] = 1, ["name"] = "default:stone", ["z"] = 9, ["meta"] = {["inventory"] = {}, ["fields"] = {}}}, {["y"] = 5, ["x"] = 1, ["name"] = "default:stone", ["z"] = 10, ["meta"] = {["inventory"] = {}, ["fields"] = {}}}, {["y"] = 5, ["x"] = 1, ["name"] = "default:dirt_with_grass", ["z"] = 11, ["meta"] = {["inventory"] = {}, ["fields"] = {}}}, {["y"] = 5, ["x"] = 1, ["name"] = "default:dirt_with_grass", ["z"] = 12, ["meta"] = {["inventory"] = {}, ["fields"] = {}}}, {["y"] = 5, ["x"] = 1, ["name"] = "default:cobble", ["z"] = 13, ["meta"] = {["inventory"] = {}, ["fields"] = {}}}, {["y"] = 5, ["x"] = 1, ["name"] = "default:cobble", ["z"] = 14, ["meta"] = {["inventory"] = {}, ["fields"] = {}}}, {["y"] = 6, ["x"] = 1, ["name"] = "default:ice", ["z"] = 0, ["meta"] = {["inventory"] = {}, ["fields"] = {}}}, {["y"] = 6, ["x"] = 1, ["name"] = "default:ice", ["z"] = 1, ["meta"] = {["inventory"] = {}, ["fields"] = {}}}, {["y"] = 6, ["x"] = 1, ["name"] = "default:dirt", ["z"] = 2, ["meta"] = {["inventory"] = {}, ["fields"] = {}}}, {["y"] = 6, ["x"] = 1, ["name"] = "default:dirt", ["z"] = 3, ["meta"] = {["inventory"] = {}, ["fields"] = {}}}, {["y"] = 6, ["x"] = 1, ["name"] = "default:dirt", ["z"] = 4, ["meta"] = {["inventory"] = {}, ["fields"] = {}}}, {["y"] = 6, ["x"] = 1, ["name"] = "default:dirt", ["z"] = 5, ["meta"] = {["inventory"] = {}, ["fields"] = {}}}, {["y"] = 6, ["x"] = 1, ["name"] = "default:dirt", ["z"] = 6, ["meta"] = {["inventory"] = {}, ["fields"] = {}}}, {["y"] = 6, ["x"] = 1, ["name"] = "default:dirt", ["z"] = 7, ["meta"] = {["inventory"] = {}, ["fields"] = {}}}, {["y"] = 6, ["x"] = 1, ["name"] = "default:dirt", ["z"] = 8, ["meta"] = {["inventory"] = {}, ["fields"] = {}}}, {["y"] = 6, ["x"] = 1, ["name"] = "default:dirt", ["z"] = 9, ["meta"] = {["inventory"] = {}, ["fields"] = {}}}, {["y"] = 6, ["x"] = 1, ["name"] = "default:dirt", ["z"] = 10, ["meta"] = {["inventory"] = {}, ["fields"] = {}}}, {["y"] = 6, ["x"] = 1, ["name"] = "stairs:slab_cobble", ["z"] = 11, ["meta"] = {["inventory"] = {}, ["fields"] = {}}, ["param1"] = 12}, {["y"] = 6, ["x"] = 1, ["name"] = "stairs:slab_cobble", ["z"] = 12, ["meta"] = {["inventory"] = {}, ["fields"] = {}}, ["param1"] = 12}, {["y"] = 7, ["x"] = 1, ["name"] = "default:dirt_with_grass", ["z"] = 0, ["meta"] = {["inventory"] = {}, ["fields"] = {}}}, {["y"] = 7, ["x"] = 1, ["name"] = "default:dirt_with_grass", ["z"] = 1, ["meta"] = {["inventory"] = {}, ["fields"] = {}}}, {["y"] = 7, ["x"] = 1, ["name"] = "default:dirt_with_grass", ["z"] = 2, ["meta"] = {["inventory"] = {}, ["fields"] = {}}}, {["y"] = 7, ["x"] = 1, ["name"] = "default:dirt", ["z"] = 3, ["meta"] = {["inventory"] = {}, ["fields"] = {}}}, {["y"] = 7, ["x"] = 1, ["name"] = "default:dirt_with_grass", ["z"] = 4, ["meta"] = {["inventory"] = {}, ["fields"] = {}}}, {["y"] = 7, ["x"] = 1, ["name"] = "default:dirt_with_grass", ["z"] = 5, ["meta"] = {["inventory"] = {}, ["fields"] = {}}}, {["y"] = 7, ["x"] = 1, ["name"] = "default:dirt_with_grass", ["z"] = 6, ["meta"] = {["inventory"] = {}, ["fields"] = {}}}, {["y"] = 7, ["x"] = 1, ["name"] = "default:dirt_with_grass", ["z"] = 7, ["meta"] = {["inventory"] = {}, ["fields"] = {}}}, {["y"] = 7, ["x"] = 1, ["name"] = "default:dirt_with_grass", ["z"] = 8, ["meta"] = {["inventory"] = {}, ["fields"] = {}}}, {["y"] = 7, ["x"] = 1, ["name"] = "default:dirt_with_grass", ["z"] = 9, ["meta"] = {["inventory"] = {}, ["fields"] = {}}}, {["y"] = 7, ["x"] = 1, ["name"] = "default:dirt_with_grass", ["z"] = 10, ["meta"] = {["inventory"] = {}, ["fields"] = {}}}, {["y"] = 8, ["x"] = 1, ["name"] = "default:tree", ["z"] = 3, ["meta"] = {["inventory"] = {}, ["fields"] = {}}, ["param1"] = 15}, {["y"] = 9, ["x"] = 1, ["name"] = "default:tree", ["z"] = 3, ["meta"] = {["inventory"] = {}, ["fields"] = {}}, ["param1"] = 31}, {["y"] = 10, ["x"] = 1, ["name"] = "default:leaves", ["z"] = 1, ["meta"] = {["inventory"] = {}, ["fields"] = {}}, ["param1"] = 13}, {["y"] = 10, ["x"] = 1, ["name"] = "default:leaves", ["z"] = 2, ["meta"] = {["inventory"] = {}, ["fields"] = {}}, ["param1"] = 12}, {["y"] = 10, ["x"] = 1, ["name"] = "default:tree", ["z"] = 3, ["meta"] = {["inventory"] = {}, ["fields"] = {}}, ["param1"] = 15}, {["y"] = 10, ["x"] = 1, ["name"] = "default:leaves", ["z"] = 4, ["meta"] = {["inventory"] = {}, ["fields"] = {}}, ["param1"] = 27}, {["y"] = 11, ["x"] = 1, ["name"] = "default:leaves", ["z"] = 1, ["meta"] = {["inventory"] = {}, ["fields"] = {}}, ["param1"] = 13}, {["y"] = 11, ["x"] = 1, ["name"] = "default:leaves", ["z"] = 2, ["meta"] = {["inventory"] = {}, ["fields"] = {}}, ["param1"] = 12}, {["y"] = 11, ["x"] = 1, ["name"] = "default:tree", ["z"] = 3, ["meta"] = {["inventory"] = {}, ["fields"] = {}}, ["param1"] = 31}, {["y"] = 11, ["x"] = 1, ["name"] = "default:leaves", ["z"] = 4, ["meta"] = {["inventory"] = {}, ["fields"] = {}}, ["param1"] = 43}, {["y"] = 11, ["x"] = 1, ["name"] = "default:leaves", ["z"] = 5, ["meta"] = {["inventory"] = {}, ["fields"] = {}}, ["param1"] = 60}, {["y"] = 12, ["x"] = 1, ["name"] = "default:leaves", ["z"] = 1, ["meta"] = {["inventory"] = {}, ["fields"] = {}}, ["param1"] = 13}, {["y"] = 12, ["x"] = 1, ["name"] = "default:leaves", ["z"] = 2, ["meta"] = {["inventory"] = {}, ["fields"] = {}}, ["param1"] = 28}, {["y"] = 12, ["x"] = 1, ["name"] = "default:tree", ["z"] = 3, ["meta"] = {["inventory"] = {}, ["fields"] = {}}, ["param1"] = 47}, {["y"] = 12, ["x"] = 1, ["name"] = "default:leaves", ["z"] = 4, ["meta"] = {["inventory"] = {}, ["fields"] = {}}, ["param1"] = 59}, {["y"] = 12, ["x"] = 1, ["name"] = "default:leaves", ["z"] = 5, ["meta"] = {["inventory"] = {}, ["fields"] = {}}, ["param1"] = 76}, {["y"] = 13, ["x"] = 1, ["name"] = "default:leaves", ["z"] = 2, ["meta"] = {["inventory"] = {}, ["fields"] = {}}, ["param1"] = 45}, {["y"] = 13, ["x"] = 1, ["name"] = "default:leaves", ["z"] = 3, ["meta"] = {["inventory"] = {}, ["fields"] = {}}, ["param1"] = 60}, {["y"] = 13, ["x"] = 1, ["name"] = "default:leaves", ["z"] = 4, ["meta"] = {["inventory"] = {}, ["fields"] = {}}, ["param1"] = 76}, {["y"] = 13, ["x"] = 1, ["name"] = "default:leaves", ["z"] = 5, ["meta"] = {["inventory"] = {}, ["fields"] = {}}, ["param1"] = 93}, {["y"] = 14, ["x"] = 1, ["name"] = "default:leaves", ["z"] = 2, ["meta"] = {["inventory"] = {}, ["fields"] = {}}, ["param1"] = 61}, {["y"] = 14, ["x"] = 1, ["name"] = "default:leaves", ["z"] = 3, ["meta"] = {["inventory"] = {}, ["fields"] = {}}, ["param1"] = 77}, {["y"] = 14, ["x"] = 1, ["name"] = "default:leaves", ["z"] = 4, ["meta"] = {["inventory"] = {}, ["fields"] = {}}, ["param1"] = 93}, {["y"] = 14, ["x"] = 1, ["name"] = "default:leaves", ["z"] = 5, ["meta"] = {["inventory"] = {}, ["fields"] = {}}, ["param1"] = 109}, {["y"] = 27, ["x"] = 1, ["name"] = "default:tree", ["z"] = 6, ["meta"] = {["inventory"] = {}, ["fields"] = {}}, ["param2"] = 2}, {["y"] = 27, ["x"] = 1, ["name"] = "default:tree", ["z"] = 7, ["meta"] = {["inventory"] = {}, ["fields"] = {}}, ["param2"] = 2}, {["y"] = 27, ["x"] = 1, ["name"] = "default:tree", ["z"] = 8, ["meta"] = {["inventory"] = {}, ["fields"] = {}}, ["param2"] = 2}, {["y"] = 27, ["x"] = 1, ["name"] = "default:tree", ["z"] = 9, ["meta"] = {["inventory"] = {}, ["fields"] = {}}, ["param2"] = 7}, {["y"] = 27, ["x"] = 1, ["name"] = "default:tree", ["z"] = 10, ["meta"] = {["inventory"] = {}, ["fields"] = {}}, ["param2"] = 7}, {["y"] = 27, ["x"] = 1, ["name"] = "default:tree", ["z"] = 11, ["meta"] = {["inventory"] = {}, ["fields"] = {}}, ["param2"] = 9}, {["y"] = 27, ["x"] = 1, ["name"] = "default:tree", ["z"] = 12, ["meta"] = {["inventory"] = {}, ["fields"] = {}}, ["param2"] = 9}, {["y"] = 27, ["x"] = 1, ["name"] = "default:tree", ["z"] = 13, ["meta"] = {["inventory"] = {}, ["fields"] = {}}, ["param2"] = 9}, {["y"] = 27, ["x"] = 1, ["name"] = "default:tree", ["z"] = 14, ["meta"] = {["inventory"] = {}, ["fields"] = {}}, ["param2"] = 9}, {["y"] = 27, ["x"] = 1, ["name"] = "default:tree", ["z"] = 15, ["meta"] = {["inventory"] = {}, ["fields"] = {}}, ["param2"] = 9}, {["y"] = 27, ["x"] = 1, ["name"] = "default:tree", ["z"] = 16, ["meta"] = {["inventory"] = {}, ["fields"] = {}}, ["param2"] = 9}, {["y"] = 27, ["x"] = 1, ["name"] = "default:tree", ["z"] = 17, ["meta"] = {["inventory"] = {}, ["fields"] = {}}, ["param2"] = 9}, {["y"] = 27, ["x"] = 1, ["name"] = "default:tree", ["z"] = 18, ["meta"] = {["inventory"] = {}, ["fields"] = {}}, ["param2"] = 9}, {["y"] = 27, ["x"] = 1, ["name"] = "default:tree", ["z"] = 19, ["meta"] = {["inventory"] = {}, ["fields"] = {}}, ["param2"] = 9}, {["y"] = 27, ["x"] = 1, ["name"] = "default:tree", ["z"] = 20, ["meta"] = {["inventory"] = {}, ["fields"] = {}}, ["param2"] = 1}, {["y"] = 27, ["x"] = 1, ["name"] = "default:tree", ["z"] = 21, ["meta"] = {["inventory"] = {}, ["fields"] = {}}, ["param2"] = 2}, {["y"] = 27, ["x"] = 1, ["name"] = "default:tree", ["z"] = 22, ["meta"] = {["inventory"] = {}, ["fields"] = {}}, ["param2"] = 2}, {["y"] = 28, ["x"] = 1, ["name"] = "fences:fence_wood_2", ["z"] = 6, ["meta"] = {["inventory"] = {}, ["fields"] = {}}, ["param1"] = 189}, {["y"] = 28, ["x"] = 1, ["name"] = "fences:fence_wood_1", ["z"] = 7, ["meta"] = {["inventory"] = {}, ["fields"] = {}}, ["param1"] = 175}, {["y"] = 28, ["x"] = 1, ["name"] = "default:tree", ["z"] = 8, ["meta"] = {["inventory"] = {}, ["fields"] = {}}, ["param2"] = 2}, {["y"] = 28, ["x"] = 1, ["name"] = "fences:fence_wood_2", ["z"] = 9, ["meta"] = {["inventory"] = {}, ["fields"] = {}}, ["param1"] = 189}, {["y"] = 28, ["x"] = 1, ["name"] = "fences:fence_wood_3", ["z"] = 10, ["meta"] = {["inventory"] = {}, ["fields"] = {}}, ["param1"] = 205}, {["y"] = 28, ["x"] = 1, ["name"] = "fences:fence_wood_3", ["z"] = 11, ["meta"] = {["inventory"] = {}, ["fields"] = {}}, ["param1"] = 189}, {["y"] = 28, ["x"] = 1, ["name"] = "fences:fence_wood_3", ["z"] = 12, ["meta"] = {["inventory"] = {}, ["fields"] = {}}, ["param1"] = 173}, {["y"] = 28, ["x"] = 1, ["name"] = "fences:fence_wood_3", ["z"] = 13, ["meta"] = {["inventory"] = {}, ["fields"] = {}}, ["param1"] = 157}, {["y"] = 28, ["x"] = 1, ["name"] = "fences:fence_wood_3", ["z"] = 14, ["meta"] = {["inventory"] = {}, ["fields"] = {}}, ["param1"] = 141}, {["y"] = 28, ["x"] = 1, ["name"] = "fences:fence_wood_3", ["z"] = 15, ["meta"] = {["inventory"] = {}, ["fields"] = {}}, ["param1"] = 157}, {["y"] = 28, ["x"] = 1, ["name"] = "fences:fence_wood_3", ["z"] = 16, ["meta"] = {["inventory"] = {}, ["fields"] = {}}, ["param1"] = 173}, {["y"] = 28, ["x"] = 1, ["name"] = "fences:fence_wood_3", ["z"] = 17, ["meta"] = {["inventory"] = {}, ["fields"] = {}}, ["param1"] = 189}, {["y"] = 28, ["x"] = 1, ["name"] = "fences:fence_wood_3", ["z"] = 18, ["meta"] = {["inventory"] = {}, ["fields"] = {}}, ["param1"] = 205}, {["y"] = 28, ["x"] = 1, ["name"] = "fences:fence_wood_1", ["z"] = 19, ["meta"] = {["inventory"] = {}, ["fields"] = {}}, ["param1"] = 191}, {["y"] = 28, ["x"] = 1, ["name"] = "default:tree", ["z"] = 20, ["meta"] = {["inventory"] = {}, ["fields"] = {}}, ["param2"] = 2}, {["y"] = 28, ["x"] = 1, ["name"] = "fences:fence_wood_2", ["z"] = 21, ["meta"] = {["inventory"] = {}, ["fields"] = {}}, ["param1"] = 175}, {["y"] = 28, ["x"] = 1, ["name"] = "fences:fence_wood_1", ["z"] = 22, ["meta"] = {["inventory"] = {}, ["fields"] = {}}, ["param1"] = 189}, {["y"] = 29, ["x"] = 1, ["name"] = "fences:fence_wood_2", ["z"] = 6, ["meta"] = {["inventory"] = {}, ["fields"] = {}}, ["param1"] = 205}, {["y"] = 29, ["x"] = 1, ["name"] = "fences:fence_wood_1", ["z"] = 7, ["meta"] = {["inventory"] = {}, ["fields"] = {}}, ["param1"] = 189}, {["y"] = 29, ["x"] = 1, ["name"] = "default:tree", ["z"] = 8, ["meta"] = {["inventory"] = {}, ["fields"] = {}}, ["param2"] = 2}, {["y"] = 29, ["x"] = 1, ["name"] = "fences:fence_wood", ["z"] = 9, ["meta"] = {["inventory"] = {}, ["fields"] = {}}, ["param1"] = 205}, {["y"] = 29, ["x"] = 1, ["name"] = "fences:fence_wood", ["z"] = 11, ["meta"] = {["inventory"] = {}, ["fields"] = {}}, ["param1"] = 205}, {["y"] = 29, ["x"] = 1, ["name"] = "fences:fence_wood", ["z"] = 17, ["meta"] = {["inventory"] = {}, ["fields"] = {}}, ["param1"] = 205}, {["y"] = 29, ["x"] = 1, ["name"] = "fences:fence_wood", ["z"] = 19, ["meta"] = {["inventory"] = {}, ["fields"] = {}}, ["param1"] = 205}, {["y"] = 29, ["x"] = 1, ["name"] = "default:tree", ["z"] = 20, ["meta"] = {["inventory"] = {}, ["fields"] = {}}, ["param2"] = 2}, {["y"] = 29, ["x"] = 1, ["name"] = "fences:fence_wood_2", ["z"] = 21, ["meta"] = {["inventory"] = {}, ["fields"] = {}}, ["param1"] = 189}, {["y"] = 29, ["x"] = 1, ["name"] = "fences:fence_wood_1", ["z"] = 22, ["meta"] = {["inventory"] = {}, ["fields"] = {}}, ["param1"] = 205}, {["y"] = 30, ["x"] = 1, ["name"] = "fences:fence_wood_2", ["z"] = 6, ["meta"] = {["inventory"] = {}, ["fields"] = {}}, ["param1"] = 189}, {["y"] = 30, ["x"] = 1, ["name"] = "fences:fence_wood_1", ["z"] = 7, ["meta"] = {["inventory"] = {}, ["fields"] = {}}, ["param1"] = 173}, {["y"] = 30, ["x"] = 1, ["name"] = "default:tree", ["z"] = 8, ["meta"] = {["inventory"] = {}, ["fields"] = {}}, ["param2"] = 2}, {["y"] = 30, ["x"] = 1, ["name"] = "fences:fence_wood", ["z"] = 9, ["meta"] = {["inventory"] = {}, ["fields"] = {}}, ["param1"] = 221}, {["y"] = 30, ["x"] = 1, ["name"] = "moreblocks:super_glow_glass", ["z"] = 10, ["meta"] = {["inventory"] = {}, ["fields"] = {}}}, {["y"] = 30, ["x"] = 1, ["name"] = "fences:fence_wood_2", ["z"] = 11, ["meta"] = {["inventory"] = {}, ["fields"] = {}}, ["param1"] = 221}, {["y"] = 30, ["x"] = 1, ["name"] = "fences:fence_wood_3", ["z"] = 12, ["meta"] = {["inventory"] = {}, ["fields"] = {}}, ["param1"] = 205}, {["y"] = 30, ["x"] = 1, ["name"] = "fences:fence_wood_3", ["z"] = 13, ["meta"] = {["inventory"] = {}, ["fields"] = {}}, ["param1"] = 189}, {["y"] = 30, ["x"] = 1, ["name"] = "fences:fence_wood_3", ["z"] = 14, ["meta"] = {["inventory"] = {}, ["fields"] = {}}, ["param1"] = 173}, {["y"] = 30, ["x"] = 1, ["name"] = "fences:fence_wood_3", ["z"] = 15, ["meta"] = {["inventory"] = {}, ["fields"] = {}}, ["param1"] = 189}, {["y"] = 30, ["x"] = 1, ["name"] = "fences:fence_wood_3", ["z"] = 16, ["meta"] = {["inventory"] = {}, ["fields"] = {}}, ["param1"] = 205}, {["y"] = 30, ["x"] = 1, ["name"] = "fences:fence_wood_1", ["z"] = 17, ["meta"] = {["inventory"] = {}, ["fields"] = {}}, ["param1"] = 221}, {["y"] = 30, ["x"] = 1, ["name"] = "moreblocks:super_glow_glass", ["z"] = 18, ["meta"] = {["inventory"] = {}, ["fields"] = {}}}, {["y"] = 30, ["x"] = 1, ["name"] = "fences:fence_wood", ["z"] = 19, ["meta"] = {["inventory"] = {}, ["fields"] = {}}, ["param1"] = 221}, {["y"] = 30, ["x"] = 1, ["name"] = "default:tree", ["z"] = 20, ["meta"] = {["inventory"] = {}, ["fields"] = {}}, ["param2"] = 2}, {["y"] = 30, ["x"] = 1, ["name"] = "fences:fence_wood_2", ["z"] = 21, ["meta"] = {["inventory"] = {}, ["fields"] = {}}, ["param1"] = 173}, {["y"] = 30, ["x"] = 1, ["name"] = "fences:fence_wood_1", ["z"] = 22, ["meta"] = {["inventory"] = {}, ["fields"] = {}}, ["param1"] = 189}, {["y"] = 31, ["x"] = 1, ["name"] = "fences:fence_wood_2", ["z"] = 6, ["meta"] = {["inventory"] = {}, ["fields"] = {}}, ["param1"] = 173}, {["y"] = 31, ["x"] = 1, ["name"] = "fences:fence_wood_1", ["z"] = 7, ["meta"] = {["inventory"] = {}, ["fields"] = {}}, ["param1"] = 157}, {["y"] = 31, ["x"] = 1, ["name"] = "default:tree", ["z"] = 8, ["meta"] = {["inventory"] = {}, ["fields"] = {}}, ["param2"] = 2}, {["y"] = 31, ["x"] = 1, ["name"] = "fences:fence_wood_2", ["z"] = 9, ["meta"] = {["inventory"] = {}, ["fields"] = {}}, ["param1"] = 205}, {["y"] = 31, ["x"] = 1, ["name"] = "fences:fence_wood_3", ["z"] = 10, ["meta"] = {["inventory"] = {}, ["fields"] = {}}, ["param1"] = 221}, {["y"] = 31, ["x"] = 1, ["name"] = "fences:fence_wood_1", ["z"] = 11, ["meta"] = {["inventory"] = {}, ["fields"] = {}}, ["param1"] = 205}, {["y"] = 31, ["x"] = 1, ["name"] = "fences:fence_wood_2", ["z"] = 17, ["meta"] = {["inventory"] = {}, ["fields"] = {}}, ["param1"] = 205}, {["y"] = 31, ["x"] = 1, ["name"] = "fences:fence_wood_3", ["z"] = 18, ["meta"] = {["inventory"] = {}, ["fields"] = {}}, ["param1"] = 221}, {["y"] = 31, ["x"] = 1, ["name"] = "fences:fence_wood_1", ["z"] = 19, ["meta"] = {["inventory"] = {}, ["fields"] = {}}, ["param1"] = 205}, {["y"] = 31, ["x"] = 1, ["name"] = "default:tree", ["z"] = 20, ["meta"] = {["inventory"] = {}, ["fields"] = {}}, ["param2"] = 2}, {["y"] = 31, ["x"] = 1, ["name"] = "fences:fence_wood_2", ["z"] = 21, ["meta"] = {["inventory"] = {}, ["fields"] = {}}, ["param1"] = 157}, {["y"] = 31, ["x"] = 1, ["name"] = "fences:fence_wood_1", ["z"] = 22, ["meta"] = {["inventory"] = {}, ["fields"] = {}}, ["param1"] = 173}, {["y"] = 32, ["x"] = 1, ["name"] = "default:tree", ["z"] = 6, ["meta"] = {["inventory"] = {}, ["fields"] = {}}}, {["y"] = 32, ["x"] = 1, ["name"] = "default:tree", ["z"] = 7, ["meta"] = {["inventory"] = {}, ["fields"] = {}}}, {["y"] = 32, ["x"] = 1, ["name"] = "default:tree", ["z"] = 8, ["meta"] = {["inventory"] = {}, ["fields"] = {}}, ["param2"] = 2}, {["y"] = 32, ["x"] = 1, ["name"] = "default:tree", ["z"] = 9, ["meta"] = {["inventory"] = {}, ["fields"] = {}}, ["param2"] = 7}, {["y"] = 32, ["x"] = 1, ["name"] = "default:tree", ["z"] = 10, ["meta"] = {["inventory"] = {}, ["fields"] = {}}, ["param2"] = 7}, {["y"] = 32, ["x"] = 1, ["name"] = "default:tree", ["z"] = 11, ["meta"] = {["inventory"] = {}, ["fields"] = {}}, ["param2"] = 7}, {["y"] = 32, ["x"] = 1, ["name"] = "default:tree", ["z"] = 12, ["meta"] = {["inventory"] = {}, ["fields"] = {}}, ["param2"] = 7}, {["y"] = 32, ["x"] = 1, ["name"] = "default:tree", ["z"] = 13, ["meta"] = {["inventory"] = {}, ["fields"] = {}}, ["param2"] = 7}, {["y"] = 32, ["x"] = 1, ["name"] = "default:tree", ["z"] = 14, ["meta"] = {["inventory"] = {}, ["fields"] = {}}, ["param2"] = 7}, {["y"] = 32, ["x"] = 1, ["name"] = "default:tree", ["z"] = 15, ["meta"] = {["inventory"] = {}, ["fields"] = {}}, ["param2"] = 7}, {["y"] = 32, ["x"] = 1, ["name"] = "default:tree", ["z"] = 16, ["meta"] = {["inventory"] = {}, ["fields"] = {}}, ["param2"] = 7}, {["y"] = 32, ["x"] = 1, ["name"] = "default:tree", ["z"] = 17, ["meta"] = {["inventory"] = {}, ["fields"] = {}}, ["param2"] = 7}, {["y"] = 32, ["x"] = 1, ["name"] = "default:tree", ["z"] = 18, ["meta"] = {["inventory"] = {}, ["fields"] = {}}, ["param2"] = 7}, {["y"] = 32, ["x"] = 1, ["name"] = "default:tree", ["z"] = 19, ["meta"] = {["inventory"] = {}, ["fields"] = {}}, ["param2"] = 7}, {["y"] = 32, ["x"] = 1, ["name"] = "default:tree", ["z"] = 20, ["meta"] = {["inventory"] = {}, ["fields"] = {}}, ["param2"] = 2}, {["y"] = 32, ["x"] = 1, ["name"] = "default:tree", ["z"] = 21, ["meta"] = {["inventory"] = {}, ["fields"] = {}}, ["param2"] = 3}, {["y"] = 32, ["x"] = 1, ["name"] = "default:tree", ["z"] = 22, ["meta"] = {["inventory"] = {}, ["fields"] = {}}, ["param2"] = 3}, {["y"] = 33, ["x"] = 1, ["name"] = "default:tree", ["z"] = 6, ["meta"] = {["inventory"] = {}, ["fields"] = {}}}, {["y"] = 33, ["x"] = 1, ["name"] = "default:tree", ["z"] = 7, ["meta"] = {["inventory"] = {}, ["fields"] = {}}}, {["y"] = 33, ["x"] = 1, ["name"] = "default:tree", ["z"] = 8, ["meta"] = {["inventory"] = {}, ["fields"] = {}}}, {["y"] = 33, ["x"] = 1, ["name"] = "default:tree", ["z"] = 9, ["meta"] = {["inventory"] = {}, ["fields"] = {}}}, {["y"] = 33, ["x"] = 1, ["name"] = "default:tree", ["z"] = 10, ["meta"] = {["inventory"] = {}, ["fields"] = {}}, ["param2"] = 2}, {["y"] = 33, ["x"] = 1, ["name"] = "default:tree", ["z"] = 11, ["meta"] = {["inventory"] = {}, ["fields"] = {}}, ["param2"] = 2}, {["y"] = 33, ["x"] = 1, ["name"] = "default:tree", ["z"] = 12, ["meta"] = {["inventory"] = {}, ["fields"] = {}}, ["param2"] = 2}, {["y"] = 33, ["x"] = 1, ["name"] = "default:tree", ["z"] = 13, ["meta"] = {["inventory"] = {}, ["fields"] = {}}, ["param2"] = 2}, {["y"] = 33, ["x"] = 1, ["name"] = "default:tree", ["z"] = 14, ["meta"] = {["inventory"] = {}, ["fields"] = {}}, ["param2"] = 2}, {["y"] = 33, ["x"] = 1, ["name"] = "default:tree", ["z"] = 15, ["meta"] = {["inventory"] = {}, ["fields"] = {}}, ["param2"] = 2}, {["y"] = 33, ["x"] = 1, ["name"] = "default:tree", ["z"] = 16, ["meta"] = {["inventory"] = {}, ["fields"] = {}}, ["param2"] = 2}, {["y"] = 33, ["x"] = 1, ["name"] = "default:tree", ["z"] = 17, ["meta"] = {["inventory"] = {}, ["fields"] = {}}, ["param2"] = 2}, {["y"] = 33, ["x"] = 1, ["name"] = "default:tree", ["z"] = 18, ["meta"] = {["inventory"] = {}, ["fields"] = {}}, ["param2"] = 2}, {["y"] = 33, ["x"] = 1, ["name"] = "default:tree", ["z"] = 19, ["meta"] = {["inventory"] = {}, ["fields"] = {}}, ["param2"] = 2}, {["y"] = 33, ["x"] = 1, ["name"] = "default:tree", ["z"] = 20, ["meta"] = {["inventory"] = {}, ["fields"] = {}}, ["param2"] = 2}, {["y"] = 33, ["x"] = 1, ["name"] = "default:tree", ["z"] = 21, ["meta"] = {["inventory"] = {}, ["fields"] = {}}, ["param2"] = 2}, {["y"] = 33, ["x"] = 1, ["name"] = "default:tree", ["z"] = 22, ["meta"] = {["inventory"] = {}, ["fields"] = {}}, ["param2"] = 3}, {["y"] = 34, ["x"] = 1, ["name"] = "default:tree", ["z"] = 7, ["meta"] = {["inventory"] = {}, ["fields"] = {}}}, {["y"] = 34, ["x"] = 1, ["name"] = "default:tree", ["z"] = 8, ["meta"] = {["inventory"] = {}, ["fields"] = {}}}, {["y"] = 34, ["x"] = 1, ["name"] = "default:tree", ["z"] = 9, ["meta"] = {["inventory"] = {}, ["fields"] = {}}}, {["y"] = 34, ["x"] = 1, ["name"] = "default:tree", ["z"] = 10, ["meta"] = {["inventory"] = {}, ["fields"] = {}}, ["param2"] = 2}, {["y"] = 34, ["x"] = 1, ["name"] = "default:tree", ["z"] = 11, ["meta"] = {["inventory"] = {}, ["fields"] = {}}, ["param2"] = 2}, {["y"] = 34, ["x"] = 1, ["name"] = "default:tree", ["z"] = 12, ["meta"] = {["inventory"] = {}, ["fields"] = {}}, ["param2"] = 2}, {["y"] = 34, ["x"] = 1, ["name"] = "default:tree", ["z"] = 13, ["meta"] = {["inventory"] = {}, ["fields"] = {}}, ["param2"] = 2}, {["y"] = 34, ["x"] = 1, ["name"] = "default:tree", ["z"] = 14, ["meta"] = {["inventory"] = {}, ["fields"] = {}}, ["param2"] = 2}, {["y"] = 34, ["x"] = 1, ["name"] = "default:tree", ["z"] = 15, ["meta"] = {["inventory"] = {}, ["fields"] = {}}, ["param2"] = 2}, {["y"] = 34, ["x"] = 1, ["name"] = "default:tree", ["z"] = 16, ["meta"] = {["inventory"] = {}, ["fields"] = {}}, ["param2"] = 2}, {["y"] = 34, ["x"] = 1, ["name"] = "default:tree", ["z"] = 17, ["meta"] = {["inventory"] = {}, ["fields"] = {}}, ["param2"] = 2}, {["y"] = 34, ["x"] = 1, ["name"] = "default:tree", ["z"] = 18, ["meta"] = {["inventory"] = {}, ["fields"] = {}}, ["param2"] = 2}, {["y"] = 34, ["x"] = 1, ["name"] = "default:tree", ["z"] = 19, ["meta"] = {["inventory"] = {}, ["fields"] = {}}, ["param2"] = 2}, {["y"] = 34, ["x"] = 1, ["name"] = "default:tree", ["z"] = 20, ["meta"] = {["inventory"] = {}, ["fields"] = {}}, ["param2"] = 2}, {["y"] = 34, ["x"] = 1, ["name"] = "default:tree", ["z"] = 21, ["meta"] = {["inventory"] = {}, ["fields"] = {}}, ["param2"] = 2}, {["y"] = 0, ["x"] = 2, ["name"] = "default:stone", ["z"] = 0, ["meta"] = {["inventory"] = {}, ["fields"] = {}}}, {["y"] = 0, ["x"] = 2, ["name"] = "default:stone", ["z"] = 1, ["meta"] = {["inventory"] = {}, ["fields"] = {}}}, {["y"] = 0, ["x"] = 2, ["name"] = "default:stone", ["z"] = 2, ["meta"] = {["inventory"] = {}, ["fields"] = {}}}, {["y"] = 0, ["x"] = 2, ["name"] = "default:stone", ["z"] = 3, ["meta"] = {["inventory"] = {}, ["fields"] = {}}}, {["y"] = 0, ["x"] = 2, ["name"] = "default:stone", ["z"] = 4, ["meta"] = {["inventory"] = {}, ["fields"] = {}}}, {["y"] = 0, ["x"] = 2, ["name"] = "default:stone", ["z"] = 5, ["meta"] = {["inventory"] = {}, ["fields"] = {}}}, {["y"] = 0, ["x"] = 2, ["name"] = "default:stone", ["z"] = 6, ["meta"] = {["inventory"] = {}, ["fields"] = {}}}, {["y"] = 0, ["x"] = 2, ["name"] = "default:stone", ["z"] = 7, ["meta"] = {["inventory"] = {}, ["fields"] = {}}}, {["y"] = 0, ["x"] = 2, ["name"] = "default:stone", ["z"] = 8, ["meta"] = {["inventory"] = {}, ["fields"] = {}}}, {["y"] = 0, ["x"] = 2, ["name"] = "default:stone", ["z"] = 9, ["meta"] = {["inventory"] = {}, ["fields"] = {}}}, {["y"] = 0, ["x"] = 2, ["name"] = "default:stone", ["z"] = 10, ["meta"] = {["inventory"] = {}, ["fields"] = {}}}, {["y"] = 0, ["x"] = 2, ["name"] = "default:stone", ["z"] = 11, ["meta"] = {["inventory"] = {}, ["fields"] = {}}}, {["y"] = 0, ["x"] = 2, ["name"] = "default:stone", ["z"] = 12, ["meta"] = {["inventory"] = {}, ["fields"] = {}}}, {["y"] = 0, ["x"] = 2, ["name"] = "default:stone", ["z"] = 13, ["meta"] = {["inventory"] = {}, ["fields"] = {}}}, {["y"] = 0, ["x"] = 2, ["name"] = "default:stone", ["z"] = 14, ["meta"] = {["inventory"] = {}, ["fields"] = {}}}, {["y"] = 0, ["x"] = 2, ["name"] = "default:stone", ["z"] = 15, ["meta"] = {["inventory"] = {}, ["fields"] = {}}}, {["y"] = 0, ["x"] = 2, ["name"] = "default:water_flowing", ["z"] = 16, ["meta"] = {["inventory"] = {}, ["fields"] = {}}, ["param2"] = 14, ["param1"] = 10}, {["y"] = 0, ["x"] = 2, ["name"] = "default:water_flowing", ["z"] = 17, ["meta"] = {["inventory"] = {}, ["fields"] = {}}, ["param2"] = 7, ["param1"] = 11}, {["y"] = 0, ["x"] = 2, ["name"] = "default:water_flowing", ["z"] = 18, ["meta"] = {["inventory"] = {}, ["fields"] = {}}, ["param2"] = 14, ["param1"] = 12}, {["y"] = 1, ["x"] = 2, ["name"] = "default:stone", ["z"] = 0, ["meta"] = {["inventory"] = {}, ["fields"] = {}}}, {["y"] = 1, ["x"] = 2, ["name"] = "default:stone", ["z"] = 1, ["meta"] = {["inventory"] = {}, ["fields"] = {}}}, {["y"] = 1, ["x"] = 2, ["name"] = "default:stone", ["z"] = 2, ["meta"] = {["inventory"] = {}, ["fields"] = {}}}, {["y"] = 1, ["x"] = 2, ["name"] = "default:stone", ["z"] = 3, ["meta"] = {["inventory"] = {}, ["fields"] = {}}}, {["y"] = 1, ["x"] = 2, ["name"] = "default:stone", ["z"] = 4, ["meta"] = {["inventory"] = {}, ["fields"] = {}}}, {["y"] = 1, ["x"] = 2, ["name"] = "default:stone", ["z"] = 5, ["meta"] = {["inventory"] = {}, ["fields"] = {}}}, {["y"] = 1, ["x"] = 2, ["name"] = "default:stone", ["z"] = 6, ["meta"] = {["inventory"] = {}, ["fields"] = {}}}, {["y"] = 1, ["x"] = 2, ["name"] = "default:stone", ["z"] = 7, ["meta"] = {["inventory"] = {}, ["fields"] = {}}}, {["y"] = 1, ["x"] = 2, ["name"] = "default:stone", ["z"] = 8, ["meta"] = {["inventory"] = {}, ["fields"] = {}}}, {["y"] = 1, ["x"] = 2, ["name"] = "default:stone", ["z"] = 9, ["meta"] = {["inventory"] = {}, ["fields"] = {}}}, {["y"] = 1, ["x"] = 2, ["name"] = "default:stone", ["z"] = 10, ["meta"] = {["inventory"] = {}, ["fields"] = {}}}, {["y"] = 1, ["x"] = 2, ["name"] = "default:stone", ["z"] = 11, ["meta"] = {["inventory"] = {}, ["fields"] = {}}}, {["y"] = 1, ["x"] = 2, ["name"] = "default:stone", ["z"] = 12, ["meta"] = {["inventory"] = {}, ["fields"] = {}}}, {["y"] = 1, ["x"] = 2, ["name"] = "default:stone", ["z"] = 13, ["meta"] = {["inventory"] = {}, ["fields"] = {}}}, {["y"] = 1, ["x"] = 2, ["name"] = "default:stone", ["z"] = 14, ["meta"] = {["inventory"] = {}, ["fields"] = {}}}, {["y"] = 1, ["x"] = 2, ["name"] = "default:dirt", ["z"] = 15, ["meta"] = {["inventory"] = {}, ["fields"] = {}}}, {["y"] = 1, ["x"] = 2, ["name"] = "default:dirt", ["z"] = 16, ["meta"] = {["inventory"] = {}, ["fields"] = {}}}, {["y"] = 1, ["x"] = 2, ["name"] = "default:water_flowing", ["z"] = 17, ["meta"] = {["inventory"] = {}, ["fields"] = {}}, ["param2"] = 15, ["param1"] = 11}, {["y"] = 1, ["x"] = 2, ["name"] = "default:cobble", ["z"] = 21, ["meta"] = {["inventory"] = {}, ["fields"] = {}}}, {["y"] = 1, ["x"] = 2, ["name"] = "default:cobble", ["z"] = 22, ["meta"] = {["inventory"] = {}, ["fields"] = {}}}, {["y"] = 2, ["x"] = 2, ["name"] = "default:stone", ["z"] = 0, ["meta"] = {["inventory"] = {}, ["fields"] = {}}}, {["y"] = 2, ["x"] = 2, ["name"] = "default:stone", ["z"] = 1, ["meta"] = {["inventory"] = {}, ["fields"] = {}}}, {["y"] = 2, ["x"] = 2, ["name"] = "default:stone", ["z"] = 2, ["meta"] = {["inventory"] = {}, ["fields"] = {}}}, {["y"] = 2, ["x"] = 2, ["name"] = "default:stone", ["z"] = 3, ["meta"] = {["inventory"] = {}, ["fields"] = {}}}, {["y"] = 2, ["x"] = 2, ["name"] = "default:stone", ["z"] = 4, ["meta"] = {["inventory"] = {}, ["fields"] = {}}}, {["y"] = 2, ["x"] = 2, ["name"] = "default:stone", ["z"] = 5, ["meta"] = {["inventory"] = {}, ["fields"] = {}}}, {["y"] = 2, ["x"] = 2, ["name"] = "default:stone", ["z"] = 6, ["meta"] = {["inventory"] = {}, ["fields"] = {}}}, {["y"] = 2, ["x"] = 2, ["name"] = "default:stone", ["z"] = 7, ["meta"] = {["inventory"] = {}, ["fields"] = {}}}, {["y"] = 2, ["x"] = 2, ["name"] = "default:dirt", ["z"] = 8, ["meta"] = {["inventory"] = {}, ["fields"] = {}}}, {["y"] = 2, ["x"] = 2, ["name"] = "default:dirt", ["z"] = 9, ["meta"] = {["inventory"] = {}, ["fields"] = {}}}, {["y"] = 2, ["x"] = 2, ["name"] = "default:dirt", ["z"] = 10, ["meta"] = {["inventory"] = {}, ["fields"] = {}}}, {["y"] = 2, ["x"] = 2, ["name"] = "default:dirt", ["z"] = 11, ["meta"] = {["inventory"] = {}, ["fields"] = {}}}, {["y"] = 2, ["x"] = 2, ["name"] = "default:dirt", ["z"] = 12, ["meta"] = {["inventory"] = {}, ["fields"] = {}}}, {["y"] = 2, ["x"] = 2, ["name"] = "default:stone", ["z"] = 13, ["meta"] = {["inventory"] = {}, ["fields"] = {}}}, {["y"] = 2, ["x"] = 2, ["name"] = "default:stone", ["z"] = 14, ["meta"] = {["inventory"] = {}, ["fields"] = {}}}, {["y"] = 2, ["x"] = 2, ["name"] = "default:dirt", ["z"] = 15, ["meta"] = {["inventory"] = {}, ["fields"] = {}}}, {["y"] = 2, ["x"] = 2, ["name"] = "default:water_flowing", ["z"] = 16, ["meta"] = {["inventory"] = {}, ["fields"] = {}}, ["param2"] = 6, ["param1"] = 11}, {["y"] = 2, ["x"] = 2, ["name"] = "default:water_flowing", ["z"] = 17, ["meta"] = {["inventory"] = {}, ["fields"] = {}}, ["param2"] = 13, ["param1"] = 12}, {["y"] = 2, ["x"] = 2, ["name"] = "stairs:slab_cobble", ["z"] = 21, ["meta"] = {["inventory"] = {}, ["fields"] = {}}, ["param1"] = 13}, {["y"] = 2, ["x"] = 2, ["name"] = "stairs:slab_cobble", ["z"] = 22, ["meta"] = {["inventory"] = {}, ["fields"] = {}}, ["param1"] = 13}, {["y"] = 3, ["x"] = 2, ["name"] = "default:stone", ["z"] = 0, ["meta"] = {["inventory"] = {}, ["fields"] = {}}}, {["y"] = 3, ["x"] = 2, ["name"] = "default:stone", ["z"] = 1, ["meta"] = {["inventory"] = {}, ["fields"] = {}}}, {["y"] = 3, ["x"] = 2, ["name"] = "default:stone", ["z"] = 2, ["meta"] = {["inventory"] = {}, ["fields"] = {}}}, {["y"] = 3, ["x"] = 2, ["name"] = "default:stone", ["z"] = 3, ["meta"] = {["inventory"] = {}, ["fields"] = {}}}, {["y"] = 3, ["x"] = 2, ["name"] = "default:stone", ["z"] = 4, ["meta"] = {["inventory"] = {}, ["fields"] = {}}}, {["y"] = 3, ["x"] = 2, ["name"] = "default:stone", ["z"] = 5, ["meta"] = {["inventory"] = {}, ["fields"] = {}}}, {["y"] = 3, ["x"] = 2, ["name"] = "default:stone", ["z"] = 6, ["meta"] = {["inventory"] = {}, ["fields"] = {}}}, {["y"] = 3, ["x"] = 2, ["name"] = "default:stone", ["z"] = 7, ["meta"] = {["inventory"] = {}, ["fields"] = {}}}, {["y"] = 3, ["x"] = 2, ["name"] = "default:dirt", ["z"] = 8, ["meta"] = {["inventory"] = {}, ["fields"] = {}}}, {["y"] = 3, ["x"] = 2, ["name"] = "default:dirt", ["z"] = 9, ["meta"] = {["inventory"] = {}, ["fields"] = {}}}, {["y"] = 3, ["x"] = 2, ["name"] = "default:dirt", ["z"] = 10, ["meta"] = {["inventory"] = {}, ["fields"] = {}}}, {["y"] = 3, ["x"] = 2, ["name"] = "default:dirt", ["z"] = 11, ["meta"] = {["inventory"] = {}, ["fields"] = {}}}, {["y"] = 3, ["x"] = 2, ["name"] = "default:dirt", ["z"] = 12, ["meta"] = {["inventory"] = {}, ["fields"] = {}}}, {["y"] = 3, ["x"] = 2, ["name"] = "default:stone", ["z"] = 13, ["meta"] = {["inventory"] = {}, ["fields"] = {}}}, {["y"] = 3, ["x"] = 2, ["name"] = "default:dirt", ["z"] = 14, ["meta"] = {["inventory"] = {}, ["fields"] = {}}}, {["y"] = 3, ["x"] = 2, ["name"] = "default:dirt", ["z"] = 15, ["meta"] = {["inventory"] = {}, ["fields"] = {}}}, {["y"] = 3, ["x"] = 2, ["name"] = "vines:root_end", ["z"] = 17, ["meta"] = {["inventory"] = {}, ["fields"] = {}}, ["param1"] = 12}, {["y"] = 4, ["x"] = 2, ["name"] = "default:stone", ["z"] = 0, ["meta"] = {["inventory"] = {}, ["fields"] = {}}}, {["y"] = 4, ["x"] = 2, ["name"] = "default:stone", ["z"] = 1, ["meta"] = {["inventory"] = {}, ["fields"] = {}}}, {["y"] = 4, ["x"] = 2, ["name"] = "default:stone", ["z"] = 2, ["meta"] = {["inventory"] = {}, ["fields"] = {}}}, {["y"] = 4, ["x"] = 2, ["name"] = "default:stone", ["z"] = 3, ["meta"] = {["inventory"] = {}, ["fields"] = {}}}, {["y"] = 4, ["x"] = 2, ["name"] = "default:stone", ["z"] = 4, ["meta"] = {["inventory"] = {}, ["fields"] = {}}}, {["y"] = 4, ["x"] = 2, ["name"] = "default:stone", ["z"] = 5, ["meta"] = {["inventory"] = {}, ["fields"] = {}}}, {["y"] = 4, ["x"] = 2, ["name"] = "default:stone", ["z"] = 6, ["meta"] = {["inventory"] = {}, ["fields"] = {}}}, {["y"] = 4, ["x"] = 2, ["name"] = "default:stone", ["z"] = 7, ["meta"] = {["inventory"] = {}, ["fields"] = {}}}, {["y"] = 4, ["x"] = 2, ["name"] = "default:dirt", ["z"] = 8, ["meta"] = {["inventory"] = {}, ["fields"] = {}}}, {["y"] = 4, ["x"] = 2, ["name"] = "default:dirt", ["z"] = 9, ["meta"] = {["inventory"] = {}, ["fields"] = {}}}, {["y"] = 4, ["x"] = 2, ["name"] = "default:dirt", ["z"] = 10, ["meta"] = {["inventory"] = {}, ["fields"] = {}}}, {["y"] = 4, ["x"] = 2, ["name"] = "default:dirt", ["z"] = 11, ["meta"] = {["inventory"] = {}, ["fields"] = {}}}, {["y"] = 4, ["x"] = 2, ["name"] = "default:dirt", ["z"] = 12, ["meta"] = {["inventory"] = {}, ["fields"] = {}}}, {["y"] = 4, ["x"] = 2, ["name"] = "default:dirt_with_grass", ["z"] = 13, ["meta"] = {["inventory"] = {}, ["fields"] = {}}}, {["y"] = 4, ["x"] = 2, ["name"] = "default:dirt_with_grass", ["z"] = 14, ["meta"] = {["inventory"] = {}, ["fields"] = {}}}, {["y"] = 4, ["x"] = 2, ["name"] = "default:cobble", ["z"] = 15, ["meta"] = {["inventory"] = {}, ["fields"] = {}}}, {["y"] = 4, ["x"] = 2, ["name"] = "default:cobble", ["z"] = 16, ["meta"] = {["inventory"] = {}, ["fields"] = {}}}, {["y"] = 4, ["x"] = 2, ["name"] = "vines:root_middle", ["z"] = 17, ["meta"] = {["inventory"] = {}, ["fields"] = {}}, ["param1"] = 12}, {["y"] = 5, ["x"] = 2, ["name"] = "default:stone", ["z"] = 0, ["meta"] = {["inventory"] = {}, ["fields"] = {}}}, {["y"] = 5, ["x"] = 2, ["name"] = "default:stone", ["z"] = 1, ["meta"] = {["inventory"] = {}, ["fields"] = {}}}, {["y"] = 5, ["x"] = 2, ["name"] = "default:stone", ["z"] = 2, ["meta"] = {["inventory"] = {}, ["fields"] = {}}}, {["y"] = 5, ["x"] = 2, ["name"] = "default:stone", ["z"] = 3, ["meta"] = {["inventory"] = {}, ["fields"] = {}}}, {["y"] = 5, ["x"] = 2, ["name"] = "default:stone", ["z"] = 4, ["meta"] = {["inventory"] = {}, ["fields"] = {}}}, {["y"] = 5, ["x"] = 2, ["name"] = "default:stone", ["z"] = 5, ["meta"] = {["inventory"] = {}, ["fields"] = {}}}, {["y"] = 5, ["x"] = 2, ["name"] = "default:stone", ["z"] = 6, ["meta"] = {["inventory"] = {}, ["fields"] = {}}}, {["y"] = 5, ["x"] = 2, ["name"] = "default:stone", ["z"] = 7, ["meta"] = {["inventory"] = {}, ["fields"] = {}}}, {["y"] = 5, ["x"] = 2, ["name"] = "default:dirt", ["z"] = 8, ["meta"] = {["inventory"] = {}, ["fields"] = {}}}, {["y"] = 5, ["x"] = 2, ["name"] = "default:dirt", ["z"] = 9, ["meta"] = {["inventory"] = {}, ["fields"] = {}}}, {["y"] = 5, ["x"] = 2, ["name"] = "default:dirt", ["z"] = 10, ["meta"] = {["inventory"] = {}, ["fields"] = {}}}, {["y"] = 5, ["x"] = 2, ["name"] = "default:dirt", ["z"] = 11, ["meta"] = {["inventory"] = {}, ["fields"] = {}}}, {["y"] = 5, ["x"] = 2, ["name"] = "default:dirt", ["z"] = 12, ["meta"] = {["inventory"] = {}, ["fields"] = {}}}, {["y"] = 5, ["x"] = 2, ["name"] = "stairs:slab_cobble", ["z"] = 13, ["meta"] = {["inventory"] = {}, ["fields"] = {}}, ["param1"] = 11}, {["y"] = 5, ["x"] = 2, ["name"] = "stairs:slab_cobble", ["z"] = 14, ["meta"] = {["inventory"] = {}, ["fields"] = {}}, ["param1"] = 11}, {["y"] = 5, ["x"] = 2, ["name"] = "vines:root_middle", ["z"] = 17, ["meta"] = {["inventory"] = {}, ["fields"] = {}}, ["param1"] = 12}, {["y"] = 6, ["x"] = 2, ["name"] = "default:stone", ["z"] = 0, ["meta"] = {["inventory"] = {}, ["fields"] = {}}}, {["y"] = 6, ["x"] = 2, ["name"] = "default:stone", ["z"] = 1, ["meta"] = {["inventory"] = {}, ["fields"] = {}}}, {["y"] = 6, ["x"] = 2, ["name"] = "default:dirt", ["z"] = 2, ["meta"] = {["inventory"] = {}, ["fields"] = {}}}, {["y"] = 6, ["x"] = 2, ["name"] = "default:dirt", ["z"] = 3, ["meta"] = {["inventory"] = {}, ["fields"] = {}}}, {["y"] = 6, ["x"] = 2, ["name"] = "default:dirt", ["z"] = 4, ["meta"] = {["inventory"] = {}, ["fields"] = {}}}, {["y"] = 6, ["x"] = 2, ["name"] = "default:dirt", ["z"] = 5, ["meta"] = {["inventory"] = {}, ["fields"] = {}}}, {["y"] = 6, ["x"] = 2, ["name"] = "default:dirt", ["z"] = 6, ["meta"] = {["inventory"] = {}, ["fields"] = {}}}, {["y"] = 6, ["x"] = 2, ["name"] = "default:dirt", ["z"] = 7, ["meta"] = {["inventory"] = {}, ["fields"] = {}}}, {["y"] = 6, ["x"] = 2, ["name"] = "default:dirt", ["z"] = 8, ["meta"] = {["inventory"] = {}, ["fields"] = {}}}, {["y"] = 6, ["x"] = 2, ["name"] = "default:dirt", ["z"] = 9, ["meta"] = {["inventory"] = {}, ["fields"] = {}}}, {["y"] = 6, ["x"] = 2, ["name"] = "default:dirt", ["z"] = 10, ["meta"] = {["inventory"] = {}, ["fields"] = {}}}, {["y"] = 6, ["x"] = 2, ["name"] = "default:dirt", ["z"] = 11, ["meta"] = {["inventory"] = {}, ["fields"] = {}}}, {["y"] = 6, ["x"] = 2, ["name"] = "default:dirt", ["z"] = 12, ["meta"] = {["inventory"] = {}, ["fields"] = {}}}, {["y"] = 6, ["x"] = 2, ["name"] = "vines:root_end", ["z"] = 13, ["meta"] = {["inventory"] = {}, ["fields"] = {}}, ["param1"] = 12}, {["y"] = 6, ["x"] = 2, ["name"] = "vines:root_middle", ["z"] = 17, ["meta"] = {["inventory"] = {}, ["fields"] = {}}, ["param1"] = 12}, {["y"] = 7, ["x"] = 2, ["name"] = "default:dirt_with_grass", ["z"] = 0, ["meta"] = {["inventory"] = {}, ["fields"] = {}}}, {["y"] = 7, ["x"] = 2, ["name"] = "default:dirt_with_grass", ["z"] = 1, ["meta"] = {["inventory"] = {}, ["fields"] = {}}}, {["y"] = 7, ["x"] = 2, ["name"] = "default:dirt_with_grass", ["z"] = 2, ["meta"] = {["inventory"] = {}, ["fields"] = {}}}, {["y"] = 7, ["x"] = 2, ["name"] = "default:dirt_with_grass", ["z"] = 3, ["meta"] = {["inventory"] = {}, ["fields"] = {}}}, {["y"] = 7, ["x"] = 2, ["name"] = "default:dirt_with_grass", ["z"] = 4, ["meta"] = {["inventory"] = {}, ["fields"] = {}}}, {["y"] = 7, ["x"] = 2, ["name"] = "default:dirt_with_grass", ["z"] = 5, ["meta"] = {["inventory"] = {}, ["fields"] = {}}}, {["y"] = 7, ["x"] = 2, ["name"] = "default:dirt_with_grass", ["z"] = 6, ["meta"] = {["inventory"] = {}, ["fields"] = {}}}, {["y"] = 7, ["x"] = 2, ["name"] = "default:dirt_with_grass", ["z"] = 7, ["meta"] = {["inventory"] = {}, ["fields"] = {}}}, {["y"] = 7, ["x"] = 2, ["name"] = "default:dirt_with_grass", ["z"] = 8, ["meta"] = {["inventory"] = {}, ["fields"] = {}}}, {["y"] = 7, ["x"] = 2, ["name"] = "default:dirt_with_grass", ["z"] = 9, ["meta"] = {["inventory"] = {}, ["fields"] = {}}}, {["y"] = 7, ["x"] = 2, ["name"] = "default:dirt_with_grass", ["z"] = 10, ["meta"] = {["inventory"] = {}, ["fields"] = {}}}, {["y"] = 7, ["x"] = 2, ["name"] = "default:dirt", ["z"] = 11, ["meta"] = {["inventory"] = {}, ["fields"] = {}}}, {["y"] = 7, ["x"] = 2, ["name"] = "default:dirt", ["z"] = 12, ["meta"] = {["inventory"] = {}, ["fields"] = {}}}, {["y"] = 7, ["x"] = 2, ["name"] = "default:dirt", ["z"] = 13, ["meta"] = {["inventory"] = {}, ["fields"] = {}}}, {["y"] = 7, ["x"] = 2, ["name"] = "default:dirt", ["z"] = 14, ["meta"] = {["inventory"] = {}, ["fields"] = {}}}, {["y"] = 7, ["x"] = 2, ["name"] = "default:dirt", ["z"] = 15, ["meta"] = {["inventory"] = {}, ["fields"] = {}}}, {["y"] = 7, ["x"] = 2, ["name"] = "default:dirt", ["z"] = 16, ["meta"] = {["inventory"] = {}, ["fields"] = {}}}, {["y"] = 7, ["x"] = 2, ["name"] = "default:dirt", ["z"] = 17, ["meta"] = {["inventory"] = {}, ["fields"] = {}}}, {["y"] = 7, ["x"] = 2, ["name"] = "default:dirt_with_grass", ["z"] = 18, ["meta"] = {["inventory"] = {}, ["fields"] = {}}}, {["y"] = 7, ["x"] = 2, ["name"] = "default:dirt_with_grass", ["z"] = 19, ["meta"] = {["inventory"] = {}, ["fields"] = {}}}, {["y"] = 7, ["x"] = 2, ["name"] = "default:dirt_with_grass", ["z"] = 20, ["meta"] = {["inventory"] = {}, ["fields"] = {}}}, {["y"] = 7, ["x"] = 2, ["name"] = "default:dirt_with_grass", ["z"] = 21, ["meta"] = {["inventory"] = {}, ["fields"] = {}}}, {["y"] = 8, ["x"] = 2, ["name"] = "default:tree", ["z"] = 11, ["meta"] = {["inventory"] = {}, ["fields"] = {}}, ["param2"] = 7}, {["y"] = 8, ["x"] = 2, ["name"] = "default:tree", ["z"] = 12, ["meta"] = {["inventory"] = {}, ["fields"] = {}}, ["param2"] = 7}, {["y"] = 8, ["x"] = 2, ["name"] = "default:tree", ["z"] = 13, ["meta"] = {["inventory"] = {}, ["fields"] = {}}, ["param2"] = 7}, {["y"] = 8, ["x"] = 2, ["name"] = "default:tree", ["z"] = 14, ["meta"] = {["inventory"] = {}, ["fields"] = {}}, ["param2"] = 7}, {["y"] = 8, ["x"] = 2, ["name"] = "default:tree", ["z"] = 15, ["meta"] = {["inventory"] = {}, ["fields"] = {}}, ["param2"] = 7}, {["y"] = 8, ["x"] = 2, ["name"] = "default:tree", ["z"] = 16, ["meta"] = {["inventory"] = {}, ["fields"] = {}}, ["param2"] = 7}, {["y"] = 8, ["x"] = 2, ["name"] = "default:tree", ["z"] = 17, ["meta"] = {["inventory"] = {}, ["fields"] = {}}, ["param2"] = 7}, {["y"] = 10, ["x"] = 2, ["name"] = "default:leaves", ["z"] = 1, ["meta"] = {["inventory"] = {}, ["fields"] = {}}, ["param1"] = 13}, {["y"] = 10, ["x"] = 2, ["name"] = "default:leaves", ["z"] = 2, ["meta"] = {["inventory"] = {}, ["fields"] = {}}, ["param1"] = 12}, {["y"] = 10, ["x"] = 2, ["name"] = "default:leaves", ["z"] = 3, ["meta"] = {["inventory"] = {}, ["fields"] = {}}, ["param1"] = 28}, {["y"] = 10, ["x"] = 2, ["name"] = "default:leaves", ["z"] = 4, ["meta"] = {["inventory"] = {}, ["fields"] = {}}, ["param1"] = 44}, {["y"] = 10, ["x"] = 2, ["name"] = "default:leaves", ["z"] = 5, ["meta"] = {["inventory"] = {}, ["fields"] = {}}, ["param1"] = 59}, {["y"] = 11, ["x"] = 2, ["name"] = "default:leaves", ["z"] = 1, ["meta"] = {["inventory"] = {}, ["fields"] = {}}, ["param1"] = 13}, {["y"] = 11, ["x"] = 2, ["name"] = "default:leaves", ["z"] = 2, ["meta"] = {["inventory"] = {}, ["fields"] = {}}, ["param1"] = 28}, {["y"] = 11, ["x"] = 2, ["name"] = "default:leaves", ["z"] = 3, ["meta"] = {["inventory"] = {}, ["fields"] = {}}, ["param1"] = 44}, {["y"] = 11, ["x"] = 2, ["name"] = "default:leaves", ["z"] = 4, ["meta"] = {["inventory"] = {}, ["fields"] = {}}, ["param1"] = 60}, {["y"] = 11, ["x"] = 2, ["name"] = "default:leaves", ["z"] = 5, ["meta"] = {["inventory"] = {}, ["fields"] = {}}, ["param1"] = 75}, {["y"] = 12, ["x"] = 2, ["name"] = "default:leaves", ["z"] = 1, ["meta"] = {["inventory"] = {}, ["fields"] = {}}, ["param1"] = 29}, {["y"] = 12, ["x"] = 2, ["name"] = "default:leaves", ["z"] = 2, ["meta"] = {["inventory"] = {}, ["fields"] = {}}, ["param1"] = 44}, {["y"] = 12, ["x"] = 2, ["name"] = "default:leaves", ["z"] = 3, ["meta"] = {["inventory"] = {}, ["fields"] = {}}, ["param1"] = 60}, {["y"] = 12, ["x"] = 2, ["name"] = "default:leaves", ["z"] = 4, ["meta"] = {["inventory"] = {}, ["fields"] = {}}, ["param1"] = 76}, {["y"] = 12, ["x"] = 2, ["name"] = "default:leaves", ["z"] = 5, ["meta"] = {["inventory"] = {}, ["fields"] = {}}, ["param1"] = 91}, {["y"] = 13, ["x"] = 2, ["name"] = "default:leaves", ["z"] = 2, ["meta"] = {["inventory"] = {}, ["fields"] = {}}, ["param1"] = 61}, {["y"] = 13, ["x"] = 2, ["name"] = "default:leaves", ["z"] = 3, ["meta"] = {["inventory"] = {}, ["fields"] = {}}, ["param1"] = 76}, {["y"] = 13, ["x"] = 2, ["name"] = "default:leaves", ["z"] = 4, ["meta"] = {["inventory"] = {}, ["fields"] = {}}, ["param1"] = 92}, {["y"] = 13, ["x"] = 2, ["name"] = "default:leaves", ["z"] = 5, ["meta"] = {["inventory"] = {}, ["fields"] = {}}, ["param1"] = 108}, {["y"] = 14, ["x"] = 2, ["name"] = "default:leaves", ["z"] = 2, ["meta"] = {["inventory"] = {}, ["fields"] = {}}, ["param1"] = 77}, {["y"] = 14, ["x"] = 2, ["name"] = "default:leaves", ["z"] = 3, ["meta"] = {["inventory"] = {}, ["fields"] = {}}, ["param1"] = 93}, {["y"] = 14, ["x"] = 2, ["name"] = "default:leaves", ["z"] = 4, ["meta"] = {["inventory"] = {}, ["fields"] = {}}, ["param1"] = 109}, {["y"] = 14, ["x"] = 2, ["name"] = "default:leaves", ["z"] = 5, ["meta"] = {["inventory"] = {}, ["fields"] = {}}, ["param1"] = 124}, {["y"] = 26, ["x"] = 2, ["name"] = "stairs:stair_cobble", ["z"] = 10, ["meta"] = {["inventory"] = {}, ["fields"] = {}}, ["param2"] = 23, ["param1"] = 156}, {["y"] = 26, ["x"] = 2, ["name"] = "stairs:stair_cobble", ["z"] = 18, ["meta"] = {["inventory"] = {}, ["fields"] = {}}, ["param2"] = 23, ["param1"] = 156}, {["y"] = 27, ["x"] = 2, ["name"] = "default:tree", ["z"] = 5, ["meta"] = {["inventory"] = {}, ["fields"] = {}}, ["param2"] = 2}, {["y"] = 27, ["x"] = 2, ["name"] = "default:stone", ["z"] = 6, ["meta"] = {["inventory"] = {}, ["fields"] = {}}}, {["y"] = 27, ["x"] = 2, ["name"] = "default:stone", ["z"] = 7, ["meta"] = {["inventory"] = {}, ["fields"] = {}}}, {["y"] = 27, ["x"] = 2, ["name"] = "default:tree", ["z"] = 8, ["meta"] = {["inventory"] = {}, ["fields"] = {}}, ["param2"] = 18}, {["y"] = 27, ["x"] = 2, ["name"] = "stairs:slab_wood", ["z"] = 9, ["meta"] = {["inventory"] = {}, ["fields"] = {}}, ["param1"] = 155}, {["y"] = 27, ["x"] = 2, ["name"] = "stairs:slab_wood", ["z"] = 10, ["meta"] = {["inventory"] = {}, ["fields"] = {}}, ["param1"] = 171}, {["y"] = 27, ["x"] = 2, ["name"] = "stairs:slab_wood", ["z"] = 11, ["meta"] = {["inventory"] = {}, ["fields"] = {}}, ["param1"] = 155}, {["y"] = 27, ["x"] = 2, ["name"] = "stairs:slab_wood", ["z"] = 12, ["meta"] = {["inventory"] = {}, ["fields"] = {}}, ["param1"] = 139}, {["y"] = 27, ["x"] = 2, ["name"] = "stairs:slab_wood", ["z"] = 13, ["meta"] = {["inventory"] = {}, ["fields"] = {}}, ["param1"] = 123}, {["y"] = 27, ["x"] = 2, ["name"] = "stairs:slab_wood", ["z"] = 14, ["meta"] = {["inventory"] = {}, ["fields"] = {}}, ["param1"] = 107}, {["y"] = 27, ["x"] = 2, ["name"] = "stairs:slab_wood", ["z"] = 15, ["meta"] = {["inventory"] = {}, ["fields"] = {}}, ["param1"] = 123}, {["y"] = 27, ["x"] = 2, ["name"] = "stairs:slab_wood", ["z"] = 16, ["meta"] = {["inventory"] = {}, ["fields"] = {}}, ["param1"] = 139}, {["y"] = 27, ["x"] = 2, ["name"] = "stairs:slab_wood", ["z"] = 17, ["meta"] = {["inventory"] = {}, ["fields"] = {}}, ["param1"] = 155}, {["y"] = 27, ["x"] = 2, ["name"] = "stairs:slab_wood", ["z"] = 18, ["meta"] = {["inventory"] = {}, ["fields"] = {}}, ["param1"] = 171}, {["y"] = 27, ["x"] = 2, ["name"] = "stairs:slab_wood", ["z"] = 19, ["meta"] = {["inventory"] = {}, ["fields"] = {}}, ["param1"] = 156}, {["y"] = 27, ["x"] = 2, ["name"] = "default:tree", ["z"] = 20, ["meta"] = {["inventory"] = {}, ["fields"] = {}}, ["param2"] = 18}, {["y"] = 27, ["x"] = 2, ["name"] = "default:stone", ["z"] = 21, ["meta"] = {["inventory"] = {}, ["fields"] = {}}}, {["y"] = 27, ["x"] = 2, ["name"] = "default:stone", ["z"] = 22, ["meta"] = {["inventory"] = {}, ["fields"] = {}}}, {["y"] = 27, ["x"] = 2, ["name"] = "default:tree", ["z"] = 23, ["meta"] = {["inventory"] = {}, ["fields"] = {}}, ["param2"] = 3}, {["y"] = 28, ["x"] = 2, ["name"] = "fences:fence_wood", ["z"] = 5, ["meta"] = {["inventory"] = {}, ["fields"] = {}}, ["param1"] = 221}, {["y"] = 28, ["x"] = 2, ["name"] = "fences:fence_wood", ["z"] = 23, ["meta"] = {["inventory"] = {}, ["fields"] = {}}, ["param1"] = 221}, {["y"] = 29, ["x"] = 2, ["name"] = "moreblocks:super_glow_glass", ["z"] = 5, ["meta"] = {["inventory"] = {}, ["fields"] = {}}}, {["y"] = 29, ["x"] = 2, ["name"] = "moreblocks:super_glow_glass", ["z"] = 23, ["meta"] = {["inventory"] = {}, ["fields"] = {}}}, {["y"] = 30, ["x"] = 2, ["name"] = "fences:fence_wood", ["z"] = 5, ["meta"] = {["inventory"] = {}, ["fields"] = {}}, ["param1"] = 221}, {["y"] = 30, ["x"] = 2, ["name"] = "fences:fence_wood", ["z"] = 23, ["meta"] = {["inventory"] = {}, ["fields"] = {}}, ["param1"] = 221}, {["y"] = 31, ["x"] = 2, ["name"] = "fences:fence_wood", ["z"] = 5, ["meta"] = {["inventory"] = {}, ["fields"] = {}}, ["param1"] = 205}, {["y"] = 31, ["x"] = 2, ["name"] = "fences:fence_wood", ["z"] = 23, ["meta"] = {["inventory"] = {}, ["fields"] = {}}, ["param1"] = 205}, {["y"] = 32, ["x"] = 2, ["name"] = "default:tree", ["z"] = 5, ["meta"] = {["inventory"] = {}, ["fields"] = {}}, ["param2"] = 2}, {["y"] = 32, ["x"] = 2, ["name"] = "moreblocks:slab_glass", ["z"] = 6, ["meta"] = {["inventory"] = {}, ["fields"] = {}}, ["param2"] = 22, ["param1"] = 171}, {["y"] = 32, ["x"] = 2, ["name"] = "moreblocks:slab_glass", ["z"] = 7, ["meta"] = {["inventory"] = {}, ["fields"] = {}}, ["param2"] = 22, ["param1"] = 155}, {["y"] = 32, ["x"] = 2, ["name"] = "default:tree", ["z"] = 8, ["meta"] = {["inventory"] = {}, ["fields"] = {}}, ["param2"] = 12}, {["y"] = 32, ["x"] = 2, ["name"] = "stairs:slab_wood", ["z"] = 9, ["meta"] = {["inventory"] = {}, ["fields"] = {}}, ["param2"] = 20, ["param1"] = 171}, {["y"] = 32, ["x"] = 2, ["name"] = "stairs:slab_wood", ["z"] = 10, ["meta"] = {["inventory"] = {}, ["fields"] = {}}, ["param2"] = 20, ["param1"] = 187}, {["y"] = 32, ["x"] = 2, ["name"] = "stairs:slab_wood", ["z"] = 11, ["meta"] = {["inventory"] = {}, ["fields"] = {}}, ["param2"] = 20, ["param1"] = 204}, {["y"] = 32, ["x"] = 2, ["name"] = "stairs:slab_wood", ["z"] = 12, ["meta"] = {["inventory"] = {}, ["fields"] = {}}, ["param2"] = 20, ["param1"] = 187}, {["y"] = 32, ["x"] = 2, ["name"] = "stairs:slab_wood", ["z"] = 13, ["meta"] = {["inventory"] = {}, ["fields"] = {}}, ["param2"] = 20, ["param1"] = 171}, {["y"] = 32, ["x"] = 2, ["name"] = "stairs:slab_wood", ["z"] = 14, ["meta"] = {["inventory"] = {}, ["fields"] = {}}, ["param2"] = 20, ["param1"] = 155}, {["y"] = 32, ["x"] = 2, ["name"] = "stairs:slab_wood", ["z"] = 15, ["meta"] = {["inventory"] = {}, ["fields"] = {}}, ["param2"] = 20, ["param1"] = 171}, {["y"] = 32, ["x"] = 2, ["name"] = "stairs:slab_wood", ["z"] = 16, ["meta"] = {["inventory"] = {}, ["fields"] = {}}, ["param2"] = 20, ["param1"] = 187}, {["y"] = 32, ["x"] = 2, ["name"] = "stairs:slab_wood", ["z"] = 17, ["meta"] = {["inventory"] = {}, ["fields"] = {}}, ["param2"] = 20, ["param1"] = 204}, {["y"] = 32, ["x"] = 2, ["name"] = "stairs:slab_wood", ["z"] = 18, ["meta"] = {["inventory"] = {}, ["fields"] = {}}, ["param2"] = 20, ["param1"] = 187}, {["y"] = 32, ["x"] = 2, ["name"] = "stairs:slab_wood", ["z"] = 19, ["meta"] = {["inventory"] = {}, ["fields"] = {}}, ["param2"] = 20, ["param1"] = 171}, {["y"] = 32, ["x"] = 2, ["name"] = "default:tree", ["z"] = 20, ["meta"] = {["inventory"] = {}, ["fields"] = {}}, ["param2"] = 12}, {["y"] = 32, ["x"] = 2, ["name"] = "moreblocks:slab_glass", ["z"] = 21, ["meta"] = {["inventory"] = {}, ["fields"] = {}}, ["param2"] = 21, ["param1"] = 155}, {["y"] = 32, ["x"] = 2, ["name"] = "moreblocks:slab_glass", ["z"] = 22, ["meta"] = {["inventory"] = {}, ["fields"] = {}}, ["param2"] = 21, ["param1"] = 171}, {["y"] = 32, ["x"] = 2, ["name"] = "default:tree", ["z"] = 23, ["meta"] = {["inventory"] = {}, ["fields"] = {}}}, {["y"] = 33, ["x"] = 2, ["name"] = "default:tree", ["z"] = 5, ["meta"] = {["inventory"] = {}, ["fields"] = {}}}, {["y"] = 33, ["x"] = 2, ["name"] = "default:tree", ["z"] = 23, ["meta"] = {["inventory"] = {}, ["fields"] = {}}}, {["y"] = 34, ["x"] = 2, ["name"] = "default:tree", ["z"] = 6, ["meta"] = {["inventory"] = {}, ["fields"] = {}}, ["param2"] = 2}, {["y"] = 34, ["x"] = 2, ["name"] = "default:tree", ["z"] = 22, ["meta"] = {["inventory"] = {}, ["fields"] = {}}, ["param2"] = 3}, {["y"] = 35, ["x"] = 2, ["name"] = "default:tree", ["z"] = 7, ["meta"] = {["inventory"] = {}, ["fields"] = {}}}, {["y"] = 35, ["x"] = 2, ["name"] = "default:tree", ["z"] = 8, ["meta"] = {["inventory"] = {}, ["fields"] = {}}}, {["y"] = 35, ["x"] = 2, ["name"] = "default:tree", ["z"] = 9, ["meta"] = {["inventory"] = {}, ["fields"] = {}}, ["param2"] = 2}, {["y"] = 35, ["x"] = 2, ["name"] = "default:tree", ["z"] = 10, ["meta"] = {["inventory"] = {}, ["fields"] = {}}}, {["y"] = 35, ["x"] = 2, ["name"] = "default:tree", ["z"] = 11, ["meta"] = {["inventory"] = {}, ["fields"] = {}}}, {["y"] = 35, ["x"] = 2, ["name"] = "default:tree", ["z"] = 12, ["meta"] = {["inventory"] = {}, ["fields"] = {}}}, {["y"] = 35, ["x"] = 2, ["name"] = "default:tree", ["z"] = 13, ["meta"] = {["inventory"] = {}, ["fields"] = {}}}, {["y"] = 35, ["x"] = 2, ["name"] = "default:tree", ["z"] = 14, ["meta"] = {["inventory"] = {}, ["fields"] = {}}}, {["y"] = 35, ["x"] = 2, ["name"] = "default:tree", ["z"] = 15, ["meta"] = {["inventory"] = {}, ["fields"] = {}}}, {["y"] = 35, ["x"] = 2, ["name"] = "default:tree", ["z"] = 16, ["meta"] = {["inventory"] = {}, ["fields"] = {}}}, {["y"] = 35, ["x"] = 2, ["name"] = "default:tree", ["z"] = 17, ["meta"] = {["inventory"] = {}, ["fields"] = {}}}, {["y"] = 35, ["x"] = 2, ["name"] = "default:tree", ["z"] = 18, ["meta"] = {["inventory"] = {}, ["fields"] = {}}}, {["y"] = 35, ["x"] = 2, ["name"] = "default:tree", ["z"] = 19, ["meta"] = {["inventory"] = {}, ["fields"] = {}}}, {["y"] = 35, ["x"] = 2, ["name"] = "default:tree", ["z"] = 20, ["meta"] = {["inventory"] = {}, ["fields"] = {}}, ["param2"] = 3}, {["y"] = 35, ["x"] = 2, ["name"] = "default:tree", ["z"] = 21, ["meta"] = {["inventory"] = {}, ["fields"] = {}}, ["param2"] = 3}, {["y"] = 0, ["x"] = 3, ["name"] = "default:stone", ["z"] = 0, ["meta"] = {["inventory"] = {}, ["fields"] = {}}}, {["y"] = 0, ["x"] = 3, ["name"] = "default:stone", ["z"] = 1, ["meta"] = {["inventory"] = {}, ["fields"] = {}}}, {["y"] = 0, ["x"] = 3, ["name"] = "default:stone", ["z"] = 2, ["meta"] = {["inventory"] = {}, ["fields"] = {}}}, {["y"] = 0, ["x"] = 3, ["name"] = "default:stone", ["z"] = 3, ["meta"] = {["inventory"] = {}, ["fields"] = {}}}, {["y"] = 0, ["x"] = 3, ["name"] = "default:stone", ["z"] = 4, ["meta"] = {["inventory"] = {}, ["fields"] = {}}}, {["y"] = 0, ["x"] = 3, ["name"] = "default:stone", ["z"] = 5, ["meta"] = {["inventory"] = {}, ["fields"] = {}}}, {["y"] = 0, ["x"] = 3, ["name"] = "default:stone", ["z"] = 6, ["meta"] = {["inventory"] = {}, ["fields"] = {}}}, {["y"] = 0, ["x"] = 3, ["name"] = "default:stone", ["z"] = 7, ["meta"] = {["inventory"] = {}, ["fields"] = {}}}, {["y"] = 0, ["x"] = 3, ["name"] = "default:stone", ["z"] = 8, ["meta"] = {["inventory"] = {}, ["fields"] = {}}}, {["y"] = 0, ["x"] = 3, ["name"] = "default:stone", ["z"] = 9, ["meta"] = {["inventory"] = {}, ["fields"] = {}}}, {["y"] = 0, ["x"] = 3, ["name"] = "default:stone", ["z"] = 10, ["meta"] = {["inventory"] = {}, ["fields"] = {}}}, {["y"] = 0, ["x"] = 3, ["name"] = "default:stone", ["z"] = 11, ["meta"] = {["inventory"] = {}, ["fields"] = {}}}, {["y"] = 0, ["x"] = 3, ["name"] = "default:stone", ["z"] = 12, ["meta"] = {["inventory"] = {}, ["fields"] = {}}}, {["y"] = 0, ["x"] = 3, ["name"] = "default:stone", ["z"] = 13, ["meta"] = {["inventory"] = {}, ["fields"] = {}}}, {["y"] = 0, ["x"] = 3, ["name"] = "default:stone", ["z"] = 14, ["meta"] = {["inventory"] = {}, ["fields"] = {}}}, {["y"] = 0, ["x"] = 3, ["name"] = "default:stone", ["z"] = 15, ["meta"] = {["inventory"] = {}, ["fields"] = {}}}, {["y"] = 0, ["x"] = 3, ["name"] = "default:dirt", ["z"] = 16, ["meta"] = {["inventory"] = {}, ["fields"] = {}}}, {["y"] = 0, ["x"] = 3, ["name"] = "default:water_flowing", ["z"] = 17, ["meta"] = {["inventory"] = {}, ["fields"] = {}}, ["param2"] = 7, ["param1"] = 10}, {["y"] = 0, ["x"] = 3, ["name"] = "default:water_flowing", ["z"] = 18, ["meta"] = {["inventory"] = {}, ["fields"] = {}}, ["param2"] = 14, ["param1"] = 11}, {["y"] = 0, ["x"] = 3, ["name"] = "vines:root_middle", ["z"] = 19, ["meta"] = {["inventory"] = {}, ["fields"] = {}}, ["param1"] = 11}, {["y"] = 1, ["x"] = 3, ["name"] = "default:stone", ["z"] = 0, ["meta"] = {["inventory"] = {}, ["fields"] = {}}}, {["y"] = 1, ["x"] = 3, ["name"] = "default:stone", ["z"] = 1, ["meta"] = {["inventory"] = {}, ["fields"] = {}}}, {["y"] = 1, ["x"] = 3, ["name"] = "default:stone", ["z"] = 2, ["meta"] = {["inventory"] = {}, ["fields"] = {}}}, {["y"] = 1, ["x"] = 3, ["name"] = "default:stone", ["z"] = 3, ["meta"] = {["inventory"] = {}, ["fields"] = {}}}, {["y"] = 1, ["x"] = 3, ["name"] = "default:stone", ["z"] = 4, ["meta"] = {["inventory"] = {}, ["fields"] = {}}}, {["y"] = 1, ["x"] = 3, ["name"] = "default:stone", ["z"] = 5, ["meta"] = {["inventory"] = {}, ["fields"] = {}}}, {["y"] = 1, ["x"] = 3, ["name"] = "default:stone", ["z"] = 6, ["meta"] = {["inventory"] = {}, ["fields"] = {}}}, {["y"] = 1, ["x"] = 3, ["name"] = "default:stone", ["z"] = 7, ["meta"] = {["inventory"] = {}, ["fields"] = {}}}, {["y"] = 1, ["x"] = 3, ["name"] = "default:stone", ["z"] = 8, ["meta"] = {["inventory"] = {}, ["fields"] = {}}}, {["y"] = 1, ["x"] = 3, ["name"] = "default:stone", ["z"] = 9, ["meta"] = {["inventory"] = {}, ["fields"] = {}}}, {["y"] = 1, ["x"] = 3, ["name"] = "default:stone", ["z"] = 10, ["meta"] = {["inventory"] = {}, ["fields"] = {}}}, {["y"] = 1, ["x"] = 3, ["name"] = "default:stone", ["z"] = 11, ["meta"] = {["inventory"] = {}, ["fields"] = {}}}, {["y"] = 1, ["x"] = 3, ["name"] = "default:stone", ["z"] = 12, ["meta"] = {["inventory"] = {}, ["fields"] = {}}}, {["y"] = 1, ["x"] = 3, ["name"] = "default:stone", ["z"] = 13, ["meta"] = {["inventory"] = {}, ["fields"] = {}}}, {["y"] = 1, ["x"] = 3, ["name"] = "default:stone", ["z"] = 14, ["meta"] = {["inventory"] = {}, ["fields"] = {}}}, {["y"] = 1, ["x"] = 3, ["name"] = "default:dirt", ["z"] = 15, ["meta"] = {["inventory"] = {}, ["fields"] = {}}}, {["y"] = 1, ["x"] = 3, ["name"] = "default:dirt", ["z"] = 16, ["meta"] = {["inventory"] = {}, ["fields"] = {}}}, {["y"] = 1, ["x"] = 3, ["name"] = "default:water_flowing", ["z"] = 17, ["meta"] = {["inventory"] = {}, ["fields"] = {}}, ["param2"] = 15, ["param1"] = 10}, {["y"] = 1, ["x"] = 3, ["name"] = "vines:root_middle", ["z"] = 19, ["meta"] = {["inventory"] = {}, ["fields"] = {}}, ["param1"] = 11}, {["y"] = 1, ["x"] = 3, ["name"] = "default:cobble", ["z"] = 21, ["meta"] = {["inventory"] = {}, ["fields"] = {}}}, {["y"] = 1, ["x"] = 3, ["name"] = "default:cobble", ["z"] = 22, ["meta"] = {["inventory"] = {}, ["fields"] = {}}}, {["y"] = 2, ["x"] = 3, ["name"] = "default:stone", ["z"] = 0, ["meta"] = {["inventory"] = {}, ["fields"] = {}}}, {["y"] = 2, ["x"] = 3, ["name"] = "default:stone", ["z"] = 1, ["meta"] = {["inventory"] = {}, ["fields"] = {}}}, {["y"] = 2, ["x"] = 3, ["name"] = "default:stone", ["z"] = 2, ["meta"] = {["inventory"] = {}, ["fields"] = {}}}, {["y"] = 2, ["x"] = 3, ["name"] = "default:stone", ["z"] = 3, ["meta"] = {["inventory"] = {}, ["fields"] = {}}}, {["y"] = 2, ["x"] = 3, ["name"] = "default:stone", ["z"] = 4, ["meta"] = {["inventory"] = {}, ["fields"] = {}}}, {["y"] = 2, ["x"] = 3, ["name"] = "default:stone", ["z"] = 5, ["meta"] = {["inventory"] = {}, ["fields"] = {}}}, {["y"] = 2, ["x"] = 3, ["name"] = "default:stone", ["z"] = 6, ["meta"] = {["inventory"] = {}, ["fields"] = {}}}, {["y"] = 2, ["x"] = 3, ["name"] = "default:stone", ["z"] = 7, ["meta"] = {["inventory"] = {}, ["fields"] = {}}}, {["y"] = 2, ["x"] = 3, ["name"] = "default:stone", ["z"] = 8, ["meta"] = {["inventory"] = {}, ["fields"] = {}}}, {["y"] = 2, ["x"] = 3, ["name"] = "default:stone", ["z"] = 9, ["meta"] = {["inventory"] = {}, ["fields"] = {}}}, {["y"] = 2, ["x"] = 3, ["name"] = "default:stone", ["z"] = 10, ["meta"] = {["inventory"] = {}, ["fields"] = {}}}, {["y"] = 2, ["x"] = 3, ["name"] = "default:stone", ["z"] = 11, ["meta"] = {["inventory"] = {}, ["fields"] = {}}}, {["y"] = 2, ["x"] = 3, ["name"] = "default:stone", ["z"] = 12, ["meta"] = {["inventory"] = {}, ["fields"] = {}}}, {["y"] = 2, ["x"] = 3, ["name"] = "default:stone", ["z"] = 13, ["meta"] = {["inventory"] = {}, ["fields"] = {}}}, {["y"] = 2, ["x"] = 3, ["name"] = "default:stone", ["z"] = 14, ["meta"] = {["inventory"] = {}, ["fields"] = {}}}, {["y"] = 2, ["x"] = 3, ["name"] = "default:dirt", ["z"] = 15, ["meta"] = {["inventory"] = {}, ["fields"] = {}}}, {["y"] = 2, ["x"] = 3, ["name"] = "default:water_flowing", ["z"] = 16, ["meta"] = {["inventory"] = {}, ["fields"] = {}}, ["param2"] = 5, ["param1"] = 10}, {["y"] = 2, ["x"] = 3, ["name"] = "default:water_flowing", ["z"] = 17, ["meta"] = {["inventory"] = {}, ["fields"] = {}}, ["param2"] = 12, ["param1"] = 11}, {["y"] = 2, ["x"] = 3, ["name"] = "vines:root_middle", ["z"] = 19, ["meta"] = {["inventory"] = {}, ["fields"] = {}}, ["param1"] = 11}, {["y"] = 2, ["x"] = 3, ["name"] = "stairs:slab_cobble", ["z"] = 21, ["meta"] = {["inventory"] = {}, ["fields"] = {}}, ["param1"] = 12}, {["y"] = 2, ["x"] = 3, ["name"] = "stairs:slab_cobble", ["z"] = 22, ["meta"] = {["inventory"] = {}, ["fields"] = {}}, ["param1"] = 12}, {["y"] = 3, ["x"] = 3, ["name"] = "default:stone", ["z"] = 0, ["meta"] = {["inventory"] = {}, ["fields"] = {}}}, {["y"] = 3, ["x"] = 3, ["name"] = "default:stone", ["z"] = 1, ["meta"] = {["inventory"] = {}, ["fields"] = {}}}, {["y"] = 3, ["x"] = 3, ["name"] = "default:stone", ["z"] = 2, ["meta"] = {["inventory"] = {}, ["fields"] = {}}}, {["y"] = 3, ["x"] = 3, ["name"] = "default:stone", ["z"] = 3, ["meta"] = {["inventory"] = {}, ["fields"] = {}}}, {["y"] = 3, ["x"] = 3, ["name"] = "default:stone", ["z"] = 4, ["meta"] = {["inventory"] = {}, ["fields"] = {}}}, {["y"] = 3, ["x"] = 3, ["name"] = "default:stone", ["z"] = 5, ["meta"] = {["inventory"] = {}, ["fields"] = {}}}, {["y"] = 3, ["x"] = 3, ["name"] = "default:stone", ["z"] = 6, ["meta"] = {["inventory"] = {}, ["fields"] = {}}}, {["y"] = 3, ["x"] = 3, ["name"] = "default:stone", ["z"] = 7, ["meta"] = {["inventory"] = {}, ["fields"] = {}}}, {["y"] = 3, ["x"] = 3, ["name"] = "default:stone", ["z"] = 8, ["meta"] = {["inventory"] = {}, ["fields"] = {}}}, {["y"] = 3, ["x"] = 3, ["name"] = "default:stone", ["z"] = 9, ["meta"] = {["inventory"] = {}, ["fields"] = {}}}, {["y"] = 3, ["x"] = 3, ["name"] = "default:stone", ["z"] = 10, ["meta"] = {["inventory"] = {}, ["fields"] = {}}}, {["y"] = 3, ["x"] = 3, ["name"] = "default:stone", ["z"] = 11, ["meta"] = {["inventory"] = {}, ["fields"] = {}}}, {["y"] = 3, ["x"] = 3, ["name"] = "default:stone", ["z"] = 12, ["meta"] = {["inventory"] = {}, ["fields"] = {}}}, {["y"] = 3, ["x"] = 3, ["name"] = "default:stone", ["z"] = 13, ["meta"] = {["inventory"] = {}, ["fields"] = {}}}, {["y"] = 3, ["x"] = 3, ["name"] = "default:dirt", ["z"] = 14, ["meta"] = {["inventory"] = {}, ["fields"] = {}}}, {["y"] = 3, ["x"] = 3, ["name"] = "default:dirt", ["z"] = 15, ["meta"] = {["inventory"] = {}, ["fields"] = {}}}, {["y"] = 3, ["x"] = 3, ["name"] = "vines:root_middle", ["z"] = 19, ["meta"] = {["inventory"] = {}, ["fields"] = {}}, ["param1"] = 11}, {["y"] = 3, ["x"] = 3, ["name"] = "vines:root_end", ["z"] = 24, ["meta"] = {["inventory"] = {}, ["fields"] = {}}, ["param1"] = 13}, {["y"] = 4, ["x"] = 3, ["name"] = "default:stone", ["z"] = 0, ["meta"] = {["inventory"] = {}, ["fields"] = {}}}, {["y"] = 4, ["x"] = 3, ["name"] = "default:stone", ["z"] = 1, ["meta"] = {["inventory"] = {}, ["fields"] = {}}}, {["y"] = 4, ["x"] = 3, ["name"] = "default:stone", ["z"] = 2, ["meta"] = {["inventory"] = {}, ["fields"] = {}}}, {["y"] = 4, ["x"] = 3, ["name"] = "default:stone", ["z"] = 3, ["meta"] = {["inventory"] = {}, ["fields"] = {}}}, {["y"] = 4, ["x"] = 3, ["name"] = "default:stone", ["z"] = 4, ["meta"] = {["inventory"] = {}, ["fields"] = {}}}, {["y"] = 4, ["x"] = 3, ["name"] = "default:stone", ["z"] = 5, ["meta"] = {["inventory"] = {}, ["fields"] = {}}}, {["y"] = 4, ["x"] = 3, ["name"] = "default:stone", ["z"] = 6, ["meta"] = {["inventory"] = {}, ["fields"] = {}}}, {["y"] = 4, ["x"] = 3, ["name"] = "default:stone", ["z"] = 7, ["meta"] = {["inventory"] = {}, ["fields"] = {}}}, {["y"] = 4, ["x"] = 3, ["name"] = "default:stone", ["z"] = 8, ["meta"] = {["inventory"] = {}, ["fields"] = {}}}, {["y"] = 4, ["x"] = 3, ["name"] = "default:stone", ["z"] = 9, ["meta"] = {["inventory"] = {}, ["fields"] = {}}}, {["y"] = 4, ["x"] = 3, ["name"] = "default:stone", ["z"] = 10, ["meta"] = {["inventory"] = {}, ["fields"] = {}}}, {["y"] = 4, ["x"] = 3, ["name"] = "default:stone", ["z"] = 11, ["meta"] = {["inventory"] = {}, ["fields"] = {}}}, {["y"] = 4, ["x"] = 3, ["name"] = "default:stone", ["z"] = 12, ["meta"] = {["inventory"] = {}, ["fields"] = {}}}, {["y"] = 4, ["x"] = 3, ["name"] = "default:stone", ["z"] = 13, ["meta"] = {["inventory"] = {}, ["fields"] = {}}}, {["y"] = 4, ["x"] = 3, ["name"] = "default:dirt_with_grass", ["z"] = 14, ["meta"] = {["inventory"] = {}, ["fields"] = {}}}, {["y"] = 4, ["x"] = 3, ["name"] = "default:cobble", ["z"] = 15, ["meta"] = {["inventory"] = {}, ["fields"] = {}}}, {["y"] = 4, ["x"] = 3, ["name"] = "default:cobble", ["z"] = 16, ["meta"] = {["inventory"] = {}, ["fields"] = {}}}, {["y"] = 4, ["x"] = 3, ["name"] = "vines:root_middle", ["z"] = 19, ["meta"] = {["inventory"] = {}, ["fields"] = {}}, ["param1"] = 11}, {["y"] = 4, ["x"] = 3, ["name"] = "vines:root_middle", ["z"] = 24, ["meta"] = {["inventory"] = {}, ["fields"] = {}}, ["param1"] = 13}, {["y"] = 5, ["x"] = 3, ["name"] = "default:stone", ["z"] = 0, ["meta"] = {["inventory"] = {}, ["fields"] = {}}}, {["y"] = 5, ["x"] = 3, ["name"] = "default:stone", ["z"] = 1, ["meta"] = {["inventory"] = {}, ["fields"] = {}}}, {["y"] = 5, ["x"] = 3, ["name"] = "default:stone", ["z"] = 2, ["meta"] = {["inventory"] = {}, ["fields"] = {}}}, {["y"] = 5, ["x"] = 3, ["name"] = "default:stone", ["z"] = 3, ["meta"] = {["inventory"] = {}, ["fields"] = {}}}, {["y"] = 5, ["x"] = 3, ["name"] = "default:stone", ["z"] = 4, ["meta"] = {["inventory"] = {}, ["fields"] = {}}}, {["y"] = 5, ["x"] = 3, ["name"] = "default:stone", ["z"] = 5, ["meta"] = {["inventory"] = {}, ["fields"] = {}}}, {["y"] = 5, ["x"] = 3, ["name"] = "default:stone", ["z"] = 6, ["meta"] = {["inventory"] = {}, ["fields"] = {}}}, {["y"] = 5, ["x"] = 3, ["name"] = "default:stone", ["z"] = 7, ["meta"] = {["inventory"] = {}, ["fields"] = {}}}, {["y"] = 5, ["x"] = 3, ["name"] = "default:stone", ["z"] = 8, ["meta"] = {["inventory"] = {}, ["fields"] = {}}}, {["y"] = 5, ["x"] = 3, ["name"] = "default:stone", ["z"] = 9, ["meta"] = {["inventory"] = {}, ["fields"] = {}}}, {["y"] = 5, ["x"] = 3, ["name"] = "default:stone", ["z"] = 10, ["meta"] = {["inventory"] = {}, ["fields"] = {}}}, {["y"] = 5, ["x"] = 3, ["name"] = "default:dirt", ["z"] = 11, ["meta"] = {["inventory"] = {}, ["fields"] = {}}}, {["y"] = 5, ["x"] = 3, ["name"] = "default:dirt", ["z"] = 12, ["meta"] = {["inventory"] = {}, ["fields"] = {}}}, {["y"] = 5, ["x"] = 3, ["name"] = "stairs:slab_cobble", ["z"] = 13, ["meta"] = {["inventory"] = {}, ["fields"] = {}}, ["param1"] = 10}, {["y"] = 5, ["x"] = 3, ["name"] = "stairs:slab_cobble", ["z"] = 14, ["meta"] = {["inventory"] = {}, ["fields"] = {}}, ["param1"] = 10}, {["y"] = 5, ["x"] = 3, ["name"] = "vines:root_middle", ["z"] = 19, ["meta"] = {["inventory"] = {}, ["fields"] = {}}, ["param1"] = 11}, {["y"] = 5, ["x"] = 3, ["name"] = "vines:root_middle", ["z"] = 24, ["meta"] = {["inventory"] = {}, ["fields"] = {}}, ["param1"] = 13}, {["y"] = 6, ["x"] = 3, ["name"] = "default:stone", ["z"] = 0, ["meta"] = {["inventory"] = {}, ["fields"] = {}}}, {["y"] = 6, ["x"] = 3, ["name"] = "default:stone", ["z"] = 1, ["meta"] = {["inventory"] = {}, ["fields"] = {}}}, {["y"] = 6, ["x"] = 3, ["name"] = "default:dirt", ["z"] = 2, ["meta"] = {["inventory"] = {}, ["fields"] = {}}}, {["y"] = 6, ["x"] = 3, ["name"] = "default:dirt", ["z"] = 3, ["meta"] = {["inventory"] = {}, ["fields"] = {}}}, {["y"] = 6, ["x"] = 3, ["name"] = "default:dirt", ["z"] = 4, ["meta"] = {["inventory"] = {}, ["fields"] = {}}}, {["y"] = 6, ["x"] = 3, ["name"] = "default:dirt", ["z"] = 5, ["meta"] = {["inventory"] = {}, ["fields"] = {}}}, {["y"] = 6, ["x"] = 3, ["name"] = "default:dirt", ["z"] = 6, ["meta"] = {["inventory"] = {}, ["fields"] = {}}}, {["y"] = 6, ["x"] = 3, ["name"] = "default:dirt", ["z"] = 7, ["meta"] = {["inventory"] = {}, ["fields"] = {}}}, {["y"] = 6, ["x"] = 3, ["name"] = "default:dirt", ["z"] = 8, ["meta"] = {["inventory"] = {}, ["fields"] = {}}}, {["y"] = 6, ["x"] = 3, ["name"] = "default:dirt", ["z"] = 9, ["meta"] = {["inventory"] = {}, ["fields"] = {}}}, {["y"] = 6, ["x"] = 3, ["name"] = "default:dirt", ["z"] = 10, ["meta"] = {["inventory"] = {}, ["fields"] = {}}}, {["y"] = 6, ["x"] = 3, ["name"] = "default:dirt", ["z"] = 11, ["meta"] = {["inventory"] = {}, ["fields"] = {}}}, {["y"] = 6, ["x"] = 3, ["name"] = "default:dirt", ["z"] = 12, ["meta"] = {["inventory"] = {}, ["fields"] = {}}}, {["y"] = 6, ["x"] = 3, ["name"] = "vines:root_middle", ["z"] = 19, ["meta"] = {["inventory"] = {}, ["fields"] = {}}, ["param1"] = 11}, {["y"] = 6, ["x"] = 3, ["name"] = "vines:root_middle", ["z"] = 24, ["meta"] = {["inventory"] = {}, ["fields"] = {}}, ["param1"] = 13}, {["y"] = 7, ["x"] = 3, ["name"] = "default:dirt_with_grass", ["z"] = 0, ["meta"] = {["inventory"] = {}, ["fields"] = {}}}, {["y"] = 7, ["x"] = 3, ["name"] = "default:dirt_with_grass", ["z"] = 1, ["meta"] = {["inventory"] = {}, ["fields"] = {}}}, {["y"] = 7, ["x"] = 3, ["name"] = "default:dirt_with_grass", ["z"] = 2, ["meta"] = {["inventory"] = {}, ["fields"] = {}}}, {["y"] = 7, ["x"] = 3, ["name"] = "default:dirt_with_grass", ["z"] = 3, ["meta"] = {["inventory"] = {}, ["fields"] = {}}}, {["y"] = 7, ["x"] = 3, ["name"] = "default:dirt_with_grass", ["z"] = 4, ["meta"] = {["inventory"] = {}, ["fields"] = {}}}, {["y"] = 7, ["x"] = 3, ["name"] = "default:dirt_with_grass", ["z"] = 5, ["meta"] = {["inventory"] = {}, ["fields"] = {}}}, {["y"] = 7, ["x"] = 3, ["name"] = "default:dirt_with_grass", ["z"] = 6, ["meta"] = {["inventory"] = {}, ["fields"] = {}}}, {["y"] = 7, ["x"] = 3, ["name"] = "default:dirt_with_grass", ["z"] = 7, ["meta"] = {["inventory"] = {}, ["fields"] = {}}}, {["y"] = 7, ["x"] = 3, ["name"] = "default:dirt", ["z"] = 8, ["meta"] = {["inventory"] = {}, ["fields"] = {}}}, {["y"] = 7, ["x"] = 3, ["name"] = "default:dirt", ["z"] = 9, ["meta"] = {["inventory"] = {}, ["fields"] = {}}}, {["y"] = 7, ["x"] = 3, ["name"] = "default:dirt", ["z"] = 10, ["meta"] = {["inventory"] = {}, ["fields"] = {}}}, {["y"] = 7, ["x"] = 3, ["name"] = "default:dirt", ["z"] = 11, ["meta"] = {["inventory"] = {}, ["fields"] = {}}}, {["y"] = 7, ["x"] = 3, ["name"] = "default:dirt", ["z"] = 12, ["meta"] = {["inventory"] = {}, ["fields"] = {}}}, {["y"] = 7, ["x"] = 3, ["name"] = "default:dirt", ["z"] = 13, ["meta"] = {["inventory"] = {}, ["fields"] = {}}}, {["y"] = 7, ["x"] = 3, ["name"] = "default:dirt", ["z"] = 14, ["meta"] = {["inventory"] = {}, ["fields"] = {}}}, {["y"] = 7, ["x"] = 3, ["name"] = "default:dirt", ["z"] = 15, ["meta"] = {["inventory"] = {}, ["fields"] = {}}}, {["y"] = 7, ["x"] = 3, ["name"] = "default:dirt", ["z"] = 16, ["meta"] = {["inventory"] = {}, ["fields"] = {}}}, {["y"] = 7, ["x"] = 3, ["name"] = "default:dirt", ["z"] = 17, ["meta"] = {["inventory"] = {}, ["fields"] = {}}}, {["y"] = 7, ["x"] = 3, ["name"] = "default:dirt", ["z"] = 18, ["meta"] = {["inventory"] = {}, ["fields"] = {}}}, {["y"] = 7, ["x"] = 3, ["name"] = "default:dirt", ["z"] = 19, ["meta"] = {["inventory"] = {}, ["fields"] = {}}}, {["y"] = 7, ["x"] = 3, ["name"] = "default:dirt", ["z"] = 20, ["meta"] = {["inventory"] = {}, ["fields"] = {}}}, {["y"] = 7, ["x"] = 3, ["name"] = "default:dirt_with_grass", ["z"] = 21, ["meta"] = {["inventory"] = {}, ["fields"] = {}}},