return { { ["x"] = 0, ["meta"] = { ["fields"] = {  }, ["inventory"] = {  } }, ["param2"] = 0, ["y"] = 0, ["param1"] = 0, ["z"] = 0, ["name"] = "lavatemple:brick" }, { ["x"] = 0, ["meta"] = { ["fields"] = {  }, ["inventory"] = {  } }, ["param2"] = 0, ["y"] = 0, ["param1"] = 0, ["z"] = 1, ["name"] = "lavatemple:brick" }, { ["x"] = 0, ["meta"] = { ["fields"] = {  }, ["inventory"] = {  } }, ["param2"] = 0, ["y"] = 0, ["param1"] = 0, ["z"] = 2, ["name"] = "lavatemple:brick" }, { ["x"] = 0, ["meta"] = { ["fields"] = {  }, ["inventory"] = {  } }, ["param2"] = 0, ["y"] = 0, ["param1"] = 0, ["z"] = 3, ["name"] = "lavatemple:brick" }, { ["x"] = 0, ["meta"] = { ["fields"] = {  }, ["inventory"] = {  } }, ["param2"] = 0, ["y"] = 0, ["param1"] = 0, ["z"] = 4, ["name"] = "lavatemple:brick" }, { ["x"] = 0, ["meta"] = { ["fields"] = {  }, ["inventory"] = {  } }, ["param2"] = 0, ["y"] = 0, ["param1"] = 0, ["z"] = 5, ["name"] = "lavatemple:brick" }, { ["x"] = 0, ["meta"] = { ["fields"] = {  }, ["inventory"] = {  } }, ["param2"] = 0, ["y"] = 0, ["param1"] = 0, ["z"] = 6, ["name"] = "lavatemple:brick" }, { ["x"] = 0, ["meta"] = { ["fields"] = {  }, ["inventory"] = {  } }, ["param2"] = 0, ["y"] = 0, ["param1"] = 0, ["z"] = 7, ["name"] = "lavatemple:brick" }, { ["x"] = 0, ["meta"] = { ["fields"] = {  }, ["inventory"] = {  } }, ["param2"] = 0, ["y"] = 0, ["param1"] = 0, ["z"] = 8, ["name"] = "lavatemple:brick" }, { ["x"] = 0, ["meta"] = { ["fields"] = {  }, ["inventory"] = {  } }, ["param2"] = 0, ["y"] = 0, ["param1"] = 0, ["z"] = 9, ["name"] = "lavatemple:brick" }, { ["x"] = 0, ["meta"] = { ["fields"] = {  }, ["inventory"] = {  } }, ["param2"] = 0, ["y"] = 0, ["param1"] = 0, ["z"] = 10, ["name"] = "lavatemple:brick" }, { ["x"] = 0, ["meta"] = { ["fields"] = {  }, ["inventory"] = {  } }, ["param2"] = 0, ["y"] = 1, ["param1"] = 0, ["z"] = 0, ["name"] = "lavatemple:brick" }, { ["x"] = 0, ["meta"] = { ["fields"] = {  }, ["inventory"] = {  } }, ["param2"] = 0, ["y"] = 1, ["param1"] = 0, ["z"] = 1, ["name"] = "lavatemple:brick" }, { ["x"] = 0, ["meta"] = { ["fields"] = {  }, ["inventory"] = {  } }, ["param2"] = 0, ["y"] = 1, ["param1"] = 0, ["z"] = 2, ["name"] = "lavatemple:brick" }, { ["x"] = 0, ["meta"] = { ["fields"] = {  }, ["inventory"] = {  } }, ["param2"] = 0, ["y"] = 1, ["param1"] = 0, ["z"] = 3, ["name"] = "lavatemple:brick" }, { ["x"] = 0, ["meta"] = { ["fields"] = {  }, ["inventory"] = {  } }, ["param2"] = 0, ["y"] = 1, ["param1"] = 0, ["z"] = 4, ["name"] = "lavatemple:brick" }, { ["x"] = 0, ["meta"] = { ["fields"] = {  }, ["inventory"] = {  } }, ["param2"] = 0, ["y"] = 1, ["param1"] = 0, ["z"] = 5, ["name"] = "lavatemple:brick" }, { ["x"] = 0, ["meta"] = { ["fields"] = {  }, ["inventory"] = {  } }, ["param2"] = 0, ["y"] = 1, ["param1"] = 0, ["z"] = 6, ["name"] = "lavatemple:brick" }, { ["x"] = 0, ["meta"] = { ["fields"] = {  }, ["inventory"] = {  } }, ["param2"] = 0, ["y"] = 1, ["param1"] = 0, ["z"] = 7, ["name"] = "lavatemple:brick" }, { ["x"] = 0, ["meta"] = { ["fields"] = {  }, ["inventory"] = {  } }, ["param2"] = 0, ["y"] = 1, ["param1"] = 0, ["z"] = 8, ["name"] = "lavatemple:brick" }, { ["x"] = 0, ["meta"] = { ["fields"] = {  }, ["inventory"] = {  } }, ["param2"] = 0, ["y"] = 1, ["param1"] = 0, ["z"] = 9, ["name"] = "lavatemple:brick" }, { ["x"] = 0, ["meta"] = { ["fields"] = {  }, ["inventory"] = {  } }, ["param2"] = 0, ["y"] = 1, ["param1"] = 0, ["z"] = 10, ["name"] = "lavatemple:brick" }, { ["x"] = 0, ["meta"] = { ["fields"] = {  }, ["inventory"] = {  } }, ["param2"] = 0, ["y"] = 2, ["param1"] = 0, ["z"] = 0, ["name"] = "lavatemple:brick" }, { ["x"] = 0, ["meta"] = { ["fields"] = {  }, ["inventory"] = {  } }, ["param2"] = 0, ["y"] = 2, ["param1"] = 0, ["z"] = 1, ["name"] = "lavatemple:brick" }, { ["x"] = 0, ["meta"] = { ["fields"] = {  }, ["inventory"] = {  } }, ["param2"] = 0, ["y"] = 2, ["param1"] = 0, ["z"] = 2, ["name"] = "lavatemple:brick" }, { ["x"] = 0, ["meta"] = { ["fields"] = {  }, ["inventory"] = {  } }, ["param2"] = 0, ["y"] = 2, ["param1"] = 0, ["z"] = 3, ["name"] = "lavatemple:brick" }, { ["x"] = 0, ["meta"] = { ["fields"] = {  }, ["inventory"] = {  } }, ["param2"] = 0, ["y"] = 2, ["param1"] = 0, ["z"] = 4, ["name"] = "lavatemple:brick" }, { ["x"] = 0, ["meta"] = { ["fields"] = {  }, ["inventory"] = {  } }, ["param2"] = 0, ["y"] = 2, ["param1"] = 0, ["z"] = 5, ["name"] = "lavatemple:brick" }, { ["x"] = 0, ["meta"] = { ["fields"] = {  }, ["inventory"] = {  } }, ["param2"] = 0, ["y"] = 2, ["param1"] = 0, ["z"] = 6, ["name"] = "lavatemple:brick" }, { ["x"] = 0, ["meta"] = { ["fields"] = {  }, ["inventory"] = {  } }, ["param2"] = 0, ["y"] = 2, ["param1"] = 0, ["z"] = 7, ["name"] = "lavatemple:brick" }, { ["x"] = 0, ["meta"] = { ["fields"] = {  }, ["inventory"] = {  } }, ["param2"] = 0, ["y"] = 2, ["param1"] = 0, ["z"] = 8, ["name"] = "lavatemple:brick" }, { ["x"] = 0, ["meta"] = { ["fields"] = {  }, ["inventory"] = {  } }, ["param2"] = 0, ["y"] = 2, ["param1"] = 0, ["z"] = 9, ["name"] = "lavatemple:brick" }, { ["x"] = 0, ["meta"] = { ["fields"] = {  }, ["inventory"] = {  } }, ["param2"] = 0, ["y"] = 2, ["param1"] = 0, ["z"] = 10, ["name"] = "lavatemple:brick" }, { ["x"] = 0, ["meta"] = { ["fields"] = {  }, ["inventory"] = {  } }, ["param2"] = 0, ["y"] = 3, ["param1"] = 0, ["z"] = 0, ["name"] = "lavatemple:brick" }, { ["x"] = 0, ["meta"] = { ["fields"] = {  }, ["inventory"] = {  } }, ["param2"] = 0, ["y"] = 3, ["param1"] = 0, ["z"] = 1, ["name"] = "lavatemple:brick" }, { ["x"] = 0, ["meta"] = { ["fields"] = {  }, ["inventory"] = {  } }, ["param2"] = 0, ["y"] = 3, ["param1"] = 0, ["z"] = 2, ["name"] = "lavatemple:brick" }, { ["x"] = 0, ["meta"] = { ["fields"] = {  }, ["inventory"] = {  } }, ["param2"] = 0, ["y"] = 3, ["param1"] = 0, ["z"] = 3, ["name"] = "lavatemple:brick" }, { ["x"] = 0, ["meta"] = { ["fields"] = {  }, ["inventory"] = {  } }, ["param2"] = 0, ["y"] = 3, ["param1"] = 0, ["z"] = 4, ["name"] = "lavatemple:brick" }, { ["x"] = 0, ["meta"] = { ["fields"] = {  }, ["inventory"] = {  } }, ["param2"] = 0, ["y"] = 3, ["param1"] = 0, ["z"] = 5, ["name"] = "lavatemple:brick" }, { ["x"] = 0, ["meta"] = { ["fields"] = {  }, ["inventory"] = {  } }, ["param2"] = 0, ["y"] = 3, ["param1"] = 0, ["z"] = 6, ["name"] = "lavatemple:brick" }, { ["x"] = 0, ["meta"] = { ["fields"] = {  }, ["inventory"] = {  } }, ["param2"] = 0, ["y"] = 3, ["param1"] = 0, ["z"] = 7, ["name"] = "lavatemple:brick" }, { ["x"] = 0, ["meta"] = { ["fields"] = {  }, ["inventory"] = {  } }, ["param2"] = 0, ["y"] = 3, ["param1"] = 0, ["z"] = 8, ["name"] = "lavatemple:brick" }, { ["x"] = 0, ["meta"] = { ["fields"] = {  }, ["inventory"] = {  } }, ["param2"] = 0, ["y"] = 3, ["param1"] = 0, ["z"] = 9, ["name"] = "lavatemple:brick" }, { ["x"] = 0, ["meta"] = { ["fields"] = {  }, ["inventory"] = {  } }, ["param2"] = 0, ["y"] = 3, ["param1"] = 0, ["z"] = 10, ["name"] = "lavatemple:brick" }, { ["x"] = 0, ["meta"] = { ["fields"] = {  }, ["inventory"] = {  } }, ["param2"] = 0, ["y"] = 4, ["param1"] = 0, ["z"] = 0, ["name"] = "lavatemple:brick" }, { ["x"] = 0, ["meta"] = { ["fields"] = {  }, ["inventory"] = {  } }, ["param2"] = 0, ["y"] = 4, ["param1"] = 0, ["z"] = 1, ["name"] = "lavatemple:brick" }, { ["x"] = 0, ["meta"] = { ["fields"] = {  }, ["inventory"] = {  } }, ["param2"] = 0, ["y"] = 4, ["param1"] = 0, ["z"] = 2, ["name"] = "lavatemple:brick" }, { ["x"] = 0, ["meta"] = { ["fields"] = {  }, ["inventory"] = {  } }, ["param2"] = 0, ["y"] = 4, ["param1"] = 0, ["z"] = 3, ["name"] = "lavatemple:brick" }, { ["x"] = 0, ["meta"] = { ["fields"] = {  }, ["inventory"] = {  } }, ["param2"] = 0, ["y"] = 4, ["param1"] = 0, ["z"] = 4, ["name"] = "lavatemple:brick" }, { ["x"] = 0, ["meta"] = { ["fields"] = {  }, ["inventory"] = {  } }, ["param2"] = 0, ["y"] = 4, ["param1"] = 0, ["z"] = 5, ["name"] = "lavatemple:brick" }, { ["x"] = 0, ["meta"] = { ["fields"] = {  }, ["inventory"] = {  } }, ["param2"] = 0, ["y"] = 4, ["param1"] = 0, ["z"] = 6, ["name"] = "lavatemple:brick" }, { ["x"] = 0, ["meta"] = { ["fields"] = {  }, ["inventory"] = {  } }, ["param2"] = 0, ["y"] = 4, ["param1"] = 0, ["z"] = 7, ["name"] = "lavatemple:brick" }, { ["x"] = 0, ["meta"] = { ["fields"] = {  }, ["inventory"] = {  } }, ["param2"] = 0, ["y"] = 4, ["param1"] = 0, ["z"] = 8, ["name"] = "lavatemple:brick" }, { ["x"] = 0, ["meta"] = { ["fields"] = {  }, ["inventory"] = {  } }, ["param2"] = 0, ["y"] = 4, ["param1"] = 0, ["z"] = 9, ["name"] = "lavatemple:brick" }, { ["x"] = 0, ["meta"] = { ["fields"] = {  }, ["inventory"] = {  } }, ["param2"] = 0, ["y"] = 4, ["param1"] = 0, ["z"] = 10, ["name"] = "lavatemple:brick" }, { ["x"] = 0, ["meta"] = { ["fields"] = {  }, ["inventory"] = {  } }, ["param2"] = 0, ["y"] = 5, ["param1"] = 0, ["z"] = 0, ["name"] = "lavatemple:brick" }, { ["x"] = 0, ["meta"] = { ["fields"] = {  }, ["inventory"] = {  } }, ["param2"] = 0, ["y"] = 5, ["param1"] = 0, ["z"] = 1, ["name"] = "lavatemple:brick" }, { ["x"] = 0, ["meta"] = { ["fields"] = {  }, ["inventory"] = {  } }, ["param2"] = 0, ["y"] = 5, ["param1"] = 0, ["z"] = 2, ["name"] = "lavatemple:brick" }, { ["x"] = 0, ["meta"] = { ["fields"] = {  }, ["inventory"] = {  } }, ["param2"] = 0, ["y"] = 5, ["param1"] = 0, ["z"] = 3, ["name"] = "lavatemple:brick" }, { ["x"] = 0, ["meta"] = { ["fields"] = {  }, ["inventory"] = {  } }, ["param2"] = 0, ["y"] = 5, ["param1"] = 0, ["z"] = 4, ["name"] = "lavatemple:brick" }, { ["x"] = 0, ["meta"] = { ["fields"] = {  }, ["inventory"] = {  } }, ["param2"] = 0, ["y"] = 5, ["param1"] = 0, ["z"] = 5, ["name"] = "lavatemple:brick" }, { ["x"] = 0, ["meta"] = { ["fields"] = {  }, ["inventory"] = {  } }, ["param2"] = 0, ["y"] = 5, ["param1"] = 0, ["z"] = 6, ["name"] = "lavatemple:brick" }, { ["x"] = 0, ["meta"] = { ["fields"] = {  }, ["inventory"] = {  } }, ["param2"] = 0, ["y"] = 5, ["param1"] = 0, ["z"] = 7, ["name"] = "lavatemple:brick" }, { ["x"] = 0, ["meta"] = { ["fields"] = {  }, ["inventory"] = {  } }, ["param2"] = 0, ["y"] = 5, ["param1"] = 0, ["z"] = 8, ["name"] = "lavatemple:brick" }, { ["x"] = 0, ["meta"] = { ["fields"] = {  }, ["inventory"] = {  } }, ["param2"] = 0, ["y"] = 5, ["param1"] = 0, ["z"] = 9, ["name"] = "lavatemple:brick" }, { ["x"] = 0, ["meta"] = { ["fields"] = {  }, ["inventory"] = {  } }, ["param2"] = 0, ["y"] = 5, ["param1"] = 0, ["z"] = 10, ["name"] = "lavatemple:brick" }, { ["x"] = 0, ["meta"] = { ["fields"] = {  }, ["inventory"] = {  } }, ["param2"] = 0, ["y"] = 6, ["param1"] = 0, ["z"] = 0, ["name"] = "lavatemple:brick" }, { ["x"] = 0, ["meta"] = { ["fields"] = {  }, ["inventory"] = {  } }, ["param2"] = 0, ["y"] = 6, ["param1"] = 0, ["z"] = 1, ["name"] = "lavatemple:brick" }, { ["x"] = 0, ["meta"] = { ["fields"] = {  }, ["inventory"] = {  } }, ["param2"] = 0, ["y"] = 6, ["param1"] = 0, ["z"] = 2, ["name"] = "lavatemple:brick" }, { ["x"] = 0, ["meta"] = { ["fields"] = {  }, ["inventory"] = {  } }, ["param2"] = 0, ["y"] = 6, ["param1"] = 0, ["z"] = 3, ["name"] = "lavatemple:brick" }, { ["x"] = 0, ["meta"] = { ["fields"] = {  }, ["inventory"] = {  } }, ["param2"] = 0, ["y"] = 6, ["param1"] = 0, ["z"] = 4, ["name"] = "lavatemple:brick" }, { ["x"] = 0, ["meta"] = { ["fields"] = {  }, ["inventory"] = {  } }, ["param2"] = 0, ["y"] = 6, ["param1"] = 0, ["z"] = 5, ["name"] = "lavatemple:brick" }, { ["x"] = 0, ["meta"] = { ["fields"] = {  }, ["inventory"] = {  } }, ["param2"] = 0, ["y"] = 6, ["param1"] = 0, ["z"] = 6, ["name"] = "lavatemple:brick" }, { ["x"] = 0, ["meta"] = { ["fields"] = {  }, ["inventory"] = {  } }, ["param2"] = 0, ["y"] = 6, ["param1"] = 0, ["z"] = 7, ["name"] = "lavatemple:brick" }, { ["x"] = 0, ["meta"] = { ["fields"] = {  }, ["inventory"] = {  } }, ["param2"] = 0, ["y"] = 6, ["param1"] = 0, ["z"] = 8, ["name"] = "lavatemple:brick" }, { ["x"] = 0, ["meta"] = { ["fields"] = {  }, ["inventory"] = {  } }, ["param2"] = 0, ["y"] = 6, ["param1"] = 0, ["z"] = 9, ["name"] = "lavatemple:brick" }, { ["x"] = 0, ["meta"] = { ["fields"] = {  }, ["inventory"] = {  } }, ["param2"] = 0, ["y"] = 6, ["param1"] = 0, ["z"] = 10, ["name"] = "lavatemple:brick" }, { ["x"] = 0, ["meta"] = { ["fields"] = {  }, ["inventory"] = {  } }, ["param2"] = 0, ["y"] = 7, ["param1"] = 0, ["z"] = 0, ["name"] = "lavatemple:brick" }, { ["x"] = 0, ["meta"] = { ["fields"] = {  }, ["inventory"] = {  } }, ["param2"] = 0, ["y"] = 7, ["param1"] = 0, ["z"] = 1, ["name"] = "lavatemple:brick" }, { ["x"] = 0, ["meta"] = { ["fields"] = {  }, ["inventory"] = {  } }, ["param2"] = 0, ["y"] = 7, ["param1"] = 0, ["z"] = 2, ["name"] = "lavatemple:brick" }, { ["x"] = 0, ["meta"] = { ["fields"] = {  }, ["inventory"] = {  } }, ["param2"] = 0, ["y"] = 7, ["param1"] = 0, ["z"] = 3, ["name"] = "lavatemple:brick" }, { ["x"] = 0, ["meta"] = { ["fields"] = {  }, ["inventory"] = {  } }, ["param2"] = 0, ["y"] = 7, ["param1"] = 0, ["z"] = 4, ["name"] = "lavatemple:brick" }, { ["x"] = 0, ["meta"] = { ["fields"] = {  }, ["inventory"] = {  } }, ["param2"] = 0, ["y"] = 7, ["param1"] = 0, ["z"] = 5, ["name"] = "lavatemple:brick" }, { ["x"] = 0, ["meta"] = { ["fields"] = {  }, ["inventory"] = {  } }, ["param2"] = 0, ["y"] = 7, ["param1"] = 0, ["z"] = 6, ["name"] = "lavatemple:brick" }, { ["x"] = 0, ["meta"] = { ["fields"] = {  }, ["inventory"] = {  } }, ["param2"] = 0, ["y"] = 7, ["param1"] = 0, ["z"] = 7, ["name"] = "lavatemple:brick" }, { ["x"] = 0, ["meta"] = { ["fields"] = {  }, ["inventory"] = {  } }, ["param2"] = 0, ["y"] = 7, ["param1"] = 0, ["z"] = 8, ["name"] = "lavatemple:brick" }, { ["x"] = 0, ["meta"] = { ["fields"] = {  }, ["inventory"] = {  } }, ["param2"] = 0, ["y"] = 7, ["param1"] = 0, ["z"] = 9, ["name"] = "lavatemple:brick" }, { ["x"] = 0, ["meta"] = { ["fields"] = {  }, ["inventory"] = {  } }, ["param2"] = 0, ["y"] = 7, ["param1"] = 0, ["z"] = 10, ["name"] = "lavatemple:brick" }, { ["x"] = 0, ["meta"] = { ["fields"] = {  }, ["inventory"] = {  } }, ["param2"] = 0, ["y"] = 8, ["param1"] = 0, ["z"] = 0, ["name"] = "lavatemple:brick" }, { ["x"] = 0, ["meta"] = { ["fields"] = {  }, ["inventory"] = {  } }, ["param2"] = 0, ["y"] = 8, ["param1"] = 0, ["z"] = 1, ["name"] = "lavatemple:brick" }, { ["x"] = 0, ["meta"] = { ["fields"] = {  }, ["inventory"] = {  } }, ["param2"] = 0, ["y"] = 8, ["param1"] = 0, ["z"] = 2, ["name"] = "lavatemple:brick" }, { ["x"] = 0, ["meta"] = { ["fields"] = {  }, ["inventory"] = {  } }, ["param2"] = 0, ["y"] = 8, ["param1"] = 0, ["z"] = 3, ["name"] = "lavatemple:brick" }, { ["x"] = 0, ["meta"] = { ["fields"] = {  }, ["inventory"] = {  } }, ["param2"] = 0, ["y"] = 8, ["param1"] = 0, ["z"] = 4, ["name"] = "lavatemple:brick" }, { ["x"] = 0, ["meta"] = { ["fields"] = {  }, ["inventory"] = {  } }, ["param2"] = 0, ["y"] = 8, ["param1"] = 0, ["z"] = 5, ["name"] = "lavatemple:brick" }, { ["x"] = 0, ["meta"] = { ["fields"] = {  }, ["inventory"] = {  } }, ["param2"] = 0, ["y"] = 8, ["param1"] = 0, ["z"] = 6, ["name"] = "lavatemple:brick" }, { ["x"] = 0, ["meta"] = { ["fields"] = {  }, ["inventory"] = {  } }, ["param2"] = 0, ["y"] = 8, ["param1"] = 0, ["z"] = 7, ["name"] = "lavatemple:brick" }, { ["x"] = 0, ["meta"] = { ["fields"] = {  }, ["inventory"] = {  } }, ["param2"] = 0, ["y"] = 8, ["param1"] = 0, ["z"] = 8, ["name"] = "lavatemple:brick" }, { ["x"] = 0, ["meta"] = { ["fields"] = {  }, ["inventory"] = {  } }, ["param2"] = 0, ["y"] = 8, ["param1"] = 0, ["z"] = 9, ["name"] = "lavatemple:brick" }, { ["x"] = 0, ["meta"] = { ["fields"] = {  }, ["inventory"] = {  } }, ["param2"] = 0, ["y"] = 8, ["param1"] = 0, ["z"] = 10, ["name"] = "lavatemple:brick" }, { ["x"] = 1, ["meta"] = { ["fields"] = {  }, ["inventory"] = {  } }, ["param2"] = 0, ["y"] = 0, ["param1"] = 0, ["z"] = 0, ["name"] = "lavatemple:brick" }, { ["x"] = 1, ["meta"] = { ["fields"] = {  }, ["inventory"] = {  } }, ["param2"] = 0, ["y"] = 0, ["param1"] = 0, ["z"] = 1, ["name"] = "lavatemple:brick" }, { ["x"] = 1, ["meta"] = { ["fields"] = {  }, ["inventory"] = {  } }, ["param2"] = 0, ["y"] = 0, ["param1"] = 0, ["z"] = 2, ["name"] = "lavatemple:brick" }, { ["x"] = 1, ["meta"] = { ["fields"] = {  }, ["inventory"] = {  } }, ["param2"] = 0, ["y"] = 0, ["param1"] = 0, ["z"] = 3, ["name"] = "lavatemple:brick" }, { ["x"] = 1, ["meta"] = { ["fields"] = {  }, ["inventory"] = {  } }, ["param2"] = 0, ["y"] = 0, ["param1"] = 0, ["z"] = 4, ["name"] = "lavatemple:brick" }, { ["x"] = 1, ["meta"] = { ["fields"] = {  }, ["inventory"] = {  } }, ["param2"] = 0, ["y"] = 0, ["param1"] = 0, ["z"] = 5, ["name"] = "lavatemple:brick" }, { ["x"] = 1, ["meta"] = { ["fields"] = {  }, ["inventory"] = {  } }, ["param2"] = 0, ["y"] = 0, ["param1"] = 0, ["z"] = 6, ["name"] = "lavatemple:brick" }, { ["x"] = 1, ["meta"] = { ["fields"] = {  }, ["inventory"] = {  } }, ["param2"] = 0, ["y"] = 0, ["param1"] = 0, ["z"] = 7, ["name"] = "lavatemple:brick" }, { ["x"] = 1, ["meta"] = { ["fields"] = {  }, ["inventory"] = {  } }, ["param2"] = 0, ["y"] = 0, ["param1"] = 0, ["z"] = 8, ["name"] = "lavatemple:brick" }, { ["x"] = 1, ["meta"] = { ["fields"] = {  }, ["inventory"] = {  } }, ["param2"] = 0, ["y"] = 0, ["param1"] = 0, ["z"] = 9, ["name"] = "lavatemple:brick" }, { ["x"] = 1, ["meta"] = { ["fields"] = {  }, ["inventory"] = {  } }, ["param2"] = 0, ["y"] = 0, ["param1"] = 0, ["z"] = 10, ["name"] = "lavatemple:brick" }, { ["x"] = 1, ["meta"] = { ["fields"] = {  }, ["inventory"] = {  } }, ["param2"] = 0, ["y"] = 1, ["param1"] = 0, ["z"] = 0, ["name"] = "lavatemple:brick" }, { ["x"] = 1, ["meta"] = { ["fields"] = {  }, ["inventory"] = {  } }, ["param2"] = 0, ["y"] = 1, ["param1"] = 0, ["z"] = 1, ["name"] = "lavatemple:brick" }, { ["x"] = 1, ["meta"] = { ["fields"] = {  }, ["inventory"] = {  } }, ["param2"] = 0, ["y"] = 1, ["param1"] = 0, ["z"] = 2, ["name"] = "lavatemple:brick" }, { ["x"] = 1, ["meta"] = { ["fields"] = {  }, ["inventory"] = {  } }, ["param2"] = 0, ["y"] = 1, ["param1"] = 0, ["z"] = 3, ["name"] = "lavatemple:brick" }, { ["x"] = 1, ["meta"] = { ["fields"] = {  }, ["inventory"] = {  } }, ["param2"] = 0, ["y"] = 1, ["param1"] = 0, ["z"] = 4, ["name"] = "lavatemple:brick" }, { ["x"] = 1, ["meta"] = { ["fields"] = {  }, ["inventory"] = {  } }, ["param2"] = 0, ["y"] = 1, ["param1"] = 0, ["z"] = 5, ["name"] = "lavatemple:brick" }, { ["x"] = 1, ["meta"] = { ["fields"] = {  }, ["inventory"] = {  } }, ["param2"] = 0, ["y"] = 1, ["param1"] = 0, ["z"] = 6, ["name"] = "lavatemple:brick" }, { ["x"] = 1, ["meta"] = { ["fields"] = {  }, ["inventory"] = {  } }, ["param2"] = 0, ["y"] = 1, ["param1"] = 0, ["z"] = 7, ["name"] = "lavatemple:brick" }, { ["x"] = 1, ["meta"] = { ["fields"] = {  }, ["inventory"] = {  } }, ["param2"] = 0, ["y"] = 1, ["param1"] = 0, ["z"] = 8, ["name"] = "lavatemple:brick" }, { ["x"] = 1, ["meta"] = { ["fields"] = {  }, ["inventory"] = {  } }, ["param2"] = 0, ["y"] = 1, ["param1"] = 0, ["z"] = 9, ["name"] = "lavatemple:brick" }, { ["x"] = 1, ["meta"] = { ["fields"] = {  }, ["inventory"] = {  } }, ["param2"] = 0, ["y"] = 1, ["param1"] = 0, ["z"] = 10, ["name"] = "lavatemple:brick" }, { ["x"] = 1, ["meta"] = { ["fields"] = {  }, ["inventory"] = {  } }, ["param2"] = 0, ["y"] = 2, ["param1"] = 0, ["z"] = 0, ["name"] = "lavatemple:brick" }, { ["x"] = 1, ["meta"] = { ["fields"] = {  }, ["inventory"] = {  } }, ["param2"] = 0, ["y"] = 2, ["param1"] = 0, ["z"] = 1, ["name"] = "lavatemple:brick" }, { ["x"] = 1, ["meta"] = { ["fields"] = {  }, ["inventory"] = {  } }, ["param2"] = 0, ["y"] = 2, ["param1"] = 0, ["z"] = 2, ["name"] = "lavatemple:brick" }, { ["x"] = 1, ["meta"] = { ["fields"] = {  }, ["inventory"] = {  } }, ["param2"] = 0, ["y"] = 2, ["param1"] = 0, ["z"] = 3, ["name"] = "lavatemple:brick" }, { ["x"] = 1, ["meta"] = { ["fields"] = {  }, ["inventory"] = {  } }, ["param2"] = 0, ["y"] = 2, ["param1"] = 0, ["z"] = 4, ["name"] = "lavatemple:brick" }, { ["x"] = 1, ["meta"] = { ["fields"] = {  }, ["inventory"] = {  } }, ["param2"] = 0, ["y"] = 2, ["param1"] = 0, ["z"] = 5, ["name"] = "lavatemple:brick" }, { ["x"] = 1, ["meta"] = { ["fields"] = {  }, ["inventory"] = {  } }, ["param2"] = 0, ["y"] = 2, ["param1"] = 0, ["z"] = 6, ["name"] = "lavatemple:brick" }, { ["x"] = 1, ["meta"] = { ["fields"] = {  }, ["inventory"] = {  } }, ["param2"] = 0, ["y"] = 2, ["param1"] = 0, ["z"] = 7, ["name"] = "lavatemple:brick" }, { ["x"] = 1, ["meta"] = { ["fields"] = {  }, ["inventory"] = {  } }, ["param2"] = 0, ["y"] = 2, ["param1"] = 0, ["z"] = 8, ["name"] = "lavatemple:brick" }, { ["x"] = 1, ["meta"] = { ["fields"] = {  }, ["inventory"] = {  } }, ["param2"] = 0, ["y"] = 2, ["param1"] = 0, ["z"] = 9, ["name"] = "lavatemple:brick" }, { ["x"] = 1, ["meta"] = { ["fields"] = {  }, ["inventory"] = {  } }, ["param2"] = 0, ["y"] = 2, ["param1"] = 0, ["z"] = 10, ["name"] = "lavatemple:brick" }, { ["x"] = 1, ["meta"] = { ["fields"] = {  }, ["inventory"] = {  } }, ["param2"] = 0, ["y"] = 3, ["param1"] = 0, ["z"] = 0, ["name"] = "lavatemple:brick" }, { ["x"] = 1, ["meta"] = { ["fields"] = {  }, ["inventory"] = {  } }, ["param2"] = 0, ["y"] = 3, ["param1"] = 0, ["z"] = 1, ["name"] = "lavatemple:brick" }, { ["x"] = 1, ["meta"] = { ["fields"] = {  }, ["inventory"] = {  } }, ["param2"] = 0, ["y"] = 3, ["param1"] = 0, ["z"] = 2, ["name"] = "lavatemple:brick" }, { ["x"] = 1, ["meta"] = { ["fields"] = {  }, ["inventory"] = {  } }, ["param2"] = 0, ["y"] = 3, ["param1"] = 0, ["z"] = 3, ["name"] = "lavatemple:brick" }, { ["x"] = 1, ["meta"] = { ["fields"] = {  }, ["inventory"] = {  } }, ["param2"] = 0, ["y"] = 3, ["param1"] = 0, ["z"] = 4, ["name"] = "lavatemple:brick" }, { ["x"] = 1, ["meta"] = { ["fields"] = {  }, ["inventory"] = {  } }, ["param2"] = 0, ["y"] = 3, ["param1"] = 0, ["z"] = 5, ["name"] = "lavatemple:brick" }, { ["x"] = 1, ["meta"] = { ["fields"] = {  }, ["inventory"] = {  } }, ["param2"] = 0, ["y"] = 3, ["param1"] = 0, ["z"] = 6, ["name"] = "lavatemple:brick" }, { ["x"] = 1, ["meta"] = { ["fields"] = {  }, ["inventory"] = {  } }, ["param2"] = 0, ["y"] = 3, ["param1"] = 0, ["z"] = 7, ["name"] = "lavatemple:brick" }, { ["x"] = 1, ["meta"] = { ["fields"] = {  }, ["inventory"] = {  } }, ["param2"] = 0, ["y"] = 3, ["param1"] = 0, ["z"] = 8, ["name"] = "lavatemple:brick" }, { ["x"] = 1, ["meta"] = { ["fields"] = {  }, ["inventory"] = {  } }, ["param2"] = 0, ["y"] = 3, ["param1"] = 0, ["z"] = 9, ["name"] = "lavatemple:brick" }, { ["x"] = 1, ["meta"] = { ["fields"] = {  }, ["inventory"] = {  } }, ["param2"] = 0, ["y"] = 3, ["param1"] = 0, ["z"] = 10, ["name"] = "lavatemple:brick" }, { ["x"] = 1, ["meta"] = { ["fields"] = {  }, ["inventory"] = {  } }, ["param2"] = 0, ["y"] = 4, ["param1"] = 0, ["z"] = 0, ["name"] = "lavatemple:brick" }, { ["x"] = 1, ["meta"] = { ["fields"] = {  }, ["inventory"] = {  } }, ["param2"] = 0, ["y"] = 4, ["param1"] = 0, ["z"] = 1, ["name"] = "lavatemple:brick" }, { ["x"] = 1, ["meta"] = { ["fields"] = {  }, ["inventory"] = {  } }, ["param2"] = 0, ["y"] = 4, ["param1"] = 0, ["z"] = 9, ["name"] = "lavatemple:brick" }, { ["x"] = 1, ["meta"] = { ["fields"] = {  }, ["inventory"] = {  } }, ["param2"] = 0, ["y"] = 4, ["param1"] = 0, ["z"] = 10, ["name"] = "lavatemple:brick" }, { ["x"] = 1, ["meta"] = { ["fields"] = {  }, ["inventory"] = {  } }, ["param2"] = 0, ["y"] = 5, ["param1"] = 0, ["z"] = 0, ["name"] = "lavatemple:brick" }, { ["x"] = 1, ["meta"] = { ["fields"] = {  }, ["inventory"] = {  } }, ["param2"] = 0, ["y"] = 5, ["param1"] = 0, ["z"] = 1, ["name"] = "lavatemple:brick" }, { ["x"] = 1, ["meta"] = { ["fields"] = {  }, ["inventory"] = {  } }, ["param2"] = 0, ["y"] = 5, ["param1"] = 0, ["z"] = 9, ["name"] = "lavatemple:brick" }, { ["x"] = 1, ["meta"] = { ["fields"] = {  }, ["inventory"] = {  } }, ["param2"] = 0, ["y"] = 5, ["param1"] = 0, ["z"] = 10, ["name"] = "lavatemple:brick" }, { ["x"] = 1, ["meta"] = { ["fields"] = {  }, ["inventory"] = {  } }, ["param2"] = 0, ["y"] = 6, ["param1"] = 0, ["z"] = 0, ["name"] = "lavatemple:brick" }, { ["x"] = 1, ["meta"] = { ["fields"] = {  }, ["inventory"] = {  } }, ["param2"] = 0, ["y"] = 6, ["param1"] = 0, ["z"] = 1, ["name"] = "lavatemple:brick" }, { ["x"] = 1, ["meta"] = { ["fields"] = {  }, ["inventory"] = {  } }, ["param2"] = 0, ["y"] = 6, ["param1"] = 0, ["z"] = 9, ["name"] = "lavatemple:brick" }, { ["x"] = 1, ["meta"] = { ["fields"] = {  }, ["inventory"] = {  } }, ["param2"] = 0, ["y"] = 6, ["param1"] = 0, ["z"] = 10, ["name"] = "lavatemple:brick" }, { ["x"] = 1, ["meta"] = { ["fields"] = {  }, ["inventory"] = {  } }, ["param2"] = 0, ["y"] = 7, ["param1"] = 0, ["z"] = 0, ["name"] = "lavatemple:brick" }, { ["x"] = 1, ["meta"] = { ["fields"] = {  }, ["inventory"] = {  } }, ["param2"] = 0, ["y"] = 7, ["param1"] = 0, ["z"] = 1, ["name"] = "lavatemple:brick" }, { ["x"] = 1, ["meta"] = { ["fields"] = {  }, ["inventory"] = {  } }, ["param2"] = 0, ["y"] = 7, ["param1"] = 0, ["z"] = 2, ["name"] = "lavatemple:brick" }, { ["x"] = 1, ["meta"] = { ["fields"] = {  }, ["inventory"] = {  } }, ["param2"] = 0, ["y"] = 7, ["param1"] = 0, ["z"] = 3, ["name"] = "lavatemple:brick" }, { ["x"] = 1, ["meta"] = { ["fields"] = {  }, ["inventory"] = {  } }, ["param2"] = 0, ["y"] = 7, ["param1"] = 0, ["z"] = 7, ["name"] = "lavatemple:brick" }, { ["x"] = 1, ["meta"] = { ["fields"] = {  }, ["inventory"] = {  } }, ["param2"] = 0, ["y"] = 7, ["param1"] = 0, ["z"] = 8, ["name"] = "lavatemple:brick" }, { ["x"] = 1, ["meta"] = { ["fields"] = {  }, ["inventory"] = {  } }, ["param2"] = 0, ["y"] = 7, ["param1"] = 0, ["z"] = 9, ["name"] = "lavatemple:brick" }, { ["x"] = 1, ["meta"] = { ["fields"] = {  }, ["inventory"] = {  } }, ["param2"] = 0, ["y"] = 7, ["param1"] = 0, ["z"] = 10, ["name"] = "lavatemple:brick" }, { ["x"] = 1, ["meta"] = { ["fields"] = {  }, ["inventory"] = {  } }, ["param2"] = 0, ["y"] = 8, ["param1"] = 0, ["z"] = 0, ["name"] = "lavatemple:brick" }, { ["x"] = 1, ["meta"] = { ["fields"] = {  }, ["inventory"] = {  } }, ["param2"] = 0, ["y"] = 8, ["param1"] = 0, ["z"] = 1, ["name"] = "lavatemple:brick" }, { ["x"] = 1, ["meta"] = { ["fields"] = {  }, ["inventory"] = {  } }, ["param2"] = 0, ["y"] = 8, ["param1"] = 0, ["z"] = 2, ["name"] = "lavatemple:brick" }, { ["x"] = 1, ["meta"] = { ["fields"] = {  }, ["inventory"] = {  } }, ["param2"] = 0, ["y"] = 8, ["param1"] = 0, ["z"] = 3, ["name"] = "lavatemple:brick" }, { ["x"] = 1, ["meta"] = { ["fields"] = {  }, ["inventory"] = {  } }, ["param2"] = 0, ["y"] = 8, ["param1"] = 0, ["z"] = 4, ["name"] = "lavatemple:brick" }, { ["x"] = 1, ["meta"] = { ["fields"] = {  }, ["inventory"] = {  } }, ["param2"] = 0, ["y"] = 8, ["param1"] = 0, ["z"] = 5, ["name"] = "lavatemple:brick" }, { ["x"] = 1, ["meta"] = { ["fields"] = {  }, ["inventory"] = {  } }, ["param2"] = 0, ["y"] = 8, ["param1"] = 0, ["z"] = 6, ["name"] = "lavatemple:brick" }, { ["x"] = 1, ["meta"] = { ["fields"] = {  }, ["inventory"] = {  } }, ["param2"] = 0, ["y"] = 8, ["param1"] = 0, ["z"] = 7, ["name"] = "lavatemple:brick" }, { ["x"] = 1, ["meta"] = { ["fields"] = {  }, ["inventory"] = {  } }, ["param2"] = 0, ["y"] = 8, ["param1"] = 0, ["z"] = 8, ["name"] = "lavatemple:brick" }, { ["x"] = 1, ["meta"] = { ["fields"] = {  }, ["inventory"] = {  } }, ["param2"] = 0, ["y"] = 8, ["param1"] = 0, ["z"] = 9, ["name"] = "lavatemple:brick" }, { ["x"] = 1, ["meta"] = { ["fields"] = {  }, ["inventory"] = {  } }, ["param2"] = 0, ["y"] = 8, ["param1"] = 0, ["z"] = 10, ["name"] = "lavatemple:brick" }, { ["x"] = 2, ["meta"] = { ["fields"] = {  }, ["inventory"] = {  } }, ["param2"] = 0, ["y"] = 0, ["param1"] = 0, ["z"] = 0, ["name"] = "lavatemple:brick" }, { ["x"] = 2, ["meta"] = { ["fields"] = {  }, ["inventory"] = {  } }, ["param2"] = 0, ["y"] = 0, ["param1"] = 0, ["z"] = 1, ["name"] = "lavatemple:brick" }, { ["x"] = 2, ["meta"] = { ["fields"] = {  }, ["inventory"] = {  } }, ["param2"] = 0, ["y"] = 0, ["param1"] = 0, ["z"] = 2, ["name"] = "lavatemple:brick" }, { ["x"] = 2, ["meta"] = { ["fields"] = {  }, ["inventory"] = {  } }, ["param2"] = 0, ["y"] = 0, ["param1"] = 0, ["z"] = 3, ["name"] = "lavatemple:brick" }, { ["x"] = 2, ["meta"] = { ["fields"] = {  }, ["inventory"] = {  } }, ["param2"] = 0, ["y"] = 0, ["param1"] = 0, ["z"] = 4, ["name"] = "lavatemple:brick" }, { ["x"] = 2, ["meta"] = { ["fields"] = {  }, ["inventory"] = {  } }, ["param2"] = 0, ["y"] = 0, ["param1"] = 0, ["z"] = 5, ["name"] = "lavatemple:brick" }, { ["x"] = 2, ["meta"] = { ["fields"] = {  }, ["inventory"] = {  } }, ["param2"] = 0, ["y"] = 0, ["param1"] = 0, ["z"] = 6, ["name"] = "lavatemple:brick" }, { ["x"] = 2, ["meta"] = { ["fields"] = {  }, ["inventory"] = {  } }, ["param2"] = 0, ["y"] = 0, ["param1"] = 0, ["z"] = 7, ["name"] = "lavatemple:brick" }, { ["x"] = 2, ["meta"] = { ["fields"] = {  }, ["inventory"] = {  } }, ["param2"] = 0, ["y"] = 0, ["param1"] = 0, ["z"] = 8, ["name"] = "lavatemple:brick" }, { ["x"] = 2, ["meta"] = { ["fields"] = {  }, ["inventory"] = {  } }, ["param2"] = 0, ["y"] = 0, ["param1"] = 0, ["z"] = 9, ["name"] = "lavatemple:brick" }, { ["x"] = 2, ["meta"] = { ["fields"] = {  }, ["inventory"] = {  } }, ["param2"] = 0, ["y"] = 0, ["param1"] = 0, ["z"] = 10, ["name"] = "lavatemple:brick" }, { ["x"] = 2, ["meta"] = { ["fields"] = {  }, ["inventory"] = {  } }, ["param2"] = 0, ["y"] = 1, ["param1"] = 0, ["z"] = 0, ["name"] = "lavatemple:brick" }, { ["x"] = 2, ["meta"] = { ["fields"] = {  }, ["inventory"] = {  } }, ["param2"] = 0, ["y"] = 1, ["param1"] = 0, ["z"] = 1, ["name"] = "lavatemple:brick" }, { ["x"] = 2, ["meta"] = { ["fields"] = {  }, ["inventory"] = {  } }, ["param2"] = 0, ["y"] = 1, ["param1"] = 0, ["z"] = 2, ["name"] = "lavatemple:brick" }, { ["x"] = 2, ["meta"] = { ["fields"] = {  }, ["inventory"] = {  } }, ["param2"] = 0, ["y"] = 1, ["param1"] = 0, ["z"] = 3, ["name"] = "lavatemple:brick" }, { ["x"] = 2, ["meta"] = { ["fields"] = {  }, ["inventory"] = {  } }, ["param2"] = 0, ["y"] = 1, ["param1"] = 0, ["z"] = 4, ["name"] = "lavatemple:brick" }, { ["x"] = 2, ["meta"] = { ["fields"] = {  }, ["inventory"] = {  } }, ["param2"] = 0, ["y"] = 1, ["param1"] = 0, ["z"] = 5, ["name"] = "lavatemple:brick" }, { ["x"] = 2, ["meta"] = { ["fields"] = {  }, ["inventory"] = {  } }, ["param2"] = 0, ["y"] = 1, ["param1"] = 0, ["z"] = 6, ["name"] = "lavatemple:brick" }, { ["x"] = 2, ["meta"] = { ["fields"] = {  }, ["inventory"] = {  } }, ["param2"] = 0, ["y"] = 1, ["param1"] = 0, ["z"] = 7, ["name"] = "lavatemple:brick" }, { ["x"] = 2, ["meta"] = { ["fields"] = {  }, ["inventory"] = {  } }, ["param2"] = 0, ["y"] = 1, ["param1"] = 0, ["z"] = 8, ["name"] = "lavatemple:brick" }, { ["x"] = 2, ["meta"] = { ["fields"] = {  }, ["inventory"] = {  } }, ["param2"] = 0, ["y"] = 1, ["param1"] = 0, ["z"] = 9, ["name"] = "lavatemple:brick" }, { ["x"] = 2, ["meta"] = { ["fields"] = {  }, ["inventory"] = {  } }, ["param2"] = 0, ["y"] = 1, ["param1"] = 0, ["z"] = 10, ["name"] = "lavatemple:brick" }, { ["x"] = 2, ["meta"] = { ["fields"] = {  }, ["inventory"] = {  } }, ["param2"] = 0, ["y"] = 2, ["param1"] = 0, ["z"] = 0, ["name"] = "lavatemple:brick" }, { ["x"] = 2, ["meta"] = { ["fields"] = {  }, ["inventory"] = {  } }, ["param2"] = 0, ["y"] = 2, ["param1"] = 0, ["z"] = 1, ["name"] = "lavatemple:brick" }, { ["x"] = 2, ["meta"] = { ["fields"] = {  }, ["inventory"] = {  } }, ["param2"] = 0, ["y"] = 2, ["param1"] = 0, ["z"] = 2, ["name"] = "lavatemple:brick" }, { ["x"] = 2, ["meta"] = { ["fields"] = {  }, ["inventory"] = {  } }, ["param2"] = 0, ["y"] = 2, ["param1"] = 0, ["z"] = 3, ["name"] = "lavatemple:brick" }, { ["x"] = 2, ["meta"] = { ["fields"] = {  }, ["inventory"] = {  } }, ["param2"] = 0, ["y"] = 2, ["param1"] = 0, ["z"] = 4, ["name"] = "lavatemple:brick" }, { ["x"] = 2, ["meta"] = { ["fields"] = {  }, ["inventory"] = {  } }, ["param2"] = 0, ["y"] = 2, ["param1"] = 0, ["z"] = 5, ["name"] = "lavatemple:brick" }, { ["x"] = 2, ["meta"] = { ["fields"] = {  }, ["inventory"] = {  } }, ["param2"] = 0, ["y"] = 2, ["param1"] = 0, ["z"] = 6, ["name"] = "lavatemple:brick" }, { ["x"] = 2, ["meta"] = { ["fields"] = {  }, ["inventory"] = {  } }, ["param2"] = 0, ["y"] = 2, ["param1"] = 0, ["z"] = 7, ["name"] = "lavatemple:brick" }, { ["x"] = 2, ["meta"] = { ["fields"] = {  }, ["inventory"] = {  } }, ["param2"] = 0, ["y"] = 2, ["param1"] = 0, ["z"] = 8, ["name"] = "lavatemple:brick" }, { ["x"] = 2, ["meta"] = { ["fields"] = {  }, ["inventory"] = {  } }, ["param2"] = 0, ["y"] = 2, ["param1"] = 0, ["z"] = 9, ["name"] = "lavatemple:brick" }, { ["x"] = 2, ["meta"] = { ["fields"] = {  }, ["inventory"] = {  } }, ["param2"] = 0, ["y"] = 2, ["param1"] = 0, ["z"] = 10, ["name"] = "lavatemple:brick" }, { ["x"] = 2, ["meta"] = { ["fields"] = {  }, ["inventory"] = {  } }, ["param2"] = 0, ["y"] = 3, ["param1"] = 0, ["z"] = 0, ["name"] = "lavatemple:brick" }, { ["x"] = 2, ["meta"] = { ["fields"] = {  }, ["inventory"] = {  } }, ["param2"] = 0, ["y"] = 3, ["param1"] = 0, ["z"] = 1, ["name"] = "lavatemple:brick" }, { ["x"] = 2, ["meta"] = { ["fields"] = {  }, ["inventory"] = {  } }, ["param2"] = 0, ["y"] = 3, ["param1"] = 0, ["z"] = 2, ["name"] = "default:lava_source" }, { ["x"] = 2, ["meta"] = { ["fields"] = {  }, ["inventory"] = {  } }, ["param2"] = 0, ["y"] = 3, ["param1"] = 0, ["z"] = 3, ["name"] = "default:lava_source" }, { ["x"] = 2, ["meta"] = { ["fields"] = {  }, ["inventory"] = {  } }, ["param2"] = 0, ["y"] = 3, ["param1"] = 0, ["z"] = 4, ["name"] = "default:lava_source" }, { ["x"] = 2, ["meta"] = { ["fields"] = {  }, ["inventory"] = {  } }, ["param2"] = 0, ["y"] = 3, ["param1"] = 0, ["z"] = 5, ["name"] = "default:lava_source" }, { ["x"] = 2, ["meta"] = { ["fields"] = {  }, ["inventory"] = {  } }, ["param2"] = 0, ["y"] = 3, ["param1"] = 0, ["z"] = 6, ["name"] = "default:lava_source" }, { ["x"] = 2, ["meta"] = { ["fields"] = {  }, ["inventory"] = {  } }, ["param2"] = 0, ["y"] = 3, ["param1"] = 0, ["z"] = 7, ["name"] = "default:lava_source" }, { ["x"] = 2, ["meta"] = { ["fields"] = {  }, ["inventory"] = {  } }, ["param2"] = 0, ["y"] = 3, ["param1"] = 0, ["z"] = 8, ["name"] = "default:lava_source" }, { ["x"] = 2, ["meta"] = { ["fields"] = {  }, ["inventory"] = {  } }, ["param2"] = 0, ["y"] = 3, ["param1"] = 0, ["z"] = 9, ["name"] = "lavatemple:brick" }, { ["x"] = 2, ["meta"] = { ["fields"] = {  }, ["inventory"] = {  } }, ["param2"] = 0, ["y"] = 3, ["param1"] = 0, ["z"] = 10, ["name"] = "lavatemple:brick" }, { ["x"] = 2, ["meta"] = { ["fields"] = {  }, ["inventory"] = {  } }, ["param2"] = 0, ["y"] = 4, ["param1"] = 0, ["z"] = 0, ["name"] = "lavatemple:brick" }, { ["x"] = 2, ["meta"] = { ["fields"] = {  }, ["inventory"] = {  } }, ["param2"] = 0, ["y"] = 4, ["param1"] = 0, ["z"] = 1, ["name"] = "lavatemple:brick" }, { ["x"] = 2, ["meta"] = { ["fields"] = {  }, ["inventory"] = {  } }, ["param2"] = 0, ["y"] = 4, ["param1"] = 0, ["z"] = 9, ["name"] = "lavatemple:brick" }, { ["x"] = 2, ["meta"] = { ["fields"] = {  }, ["inventory"] = {  } }, ["param2"] = 0, ["y"] = 4, ["param1"] = 0, ["z"] = 10, ["name"] = "lavatemple:brick" }, { ["x"] = 2, ["meta"] = { ["fields"] = {  }, ["inventory"] = {  } }, ["param2"] = 0, ["y"] = 5, ["param1"] = 0, ["z"] = 0, ["name"] = "lavatemple:brick" }, { ["x"] = 2, ["meta"] = { ["fields"] = {  }, ["inventory"] = {  } }, ["param2"] = 0, ["y"] = 5, ["param1"] = 0, ["z"] = 1, ["name"] = "lavatemple:brick" }, { ["x"] = 2, ["meta"] = { ["fields"] = {  }, ["inventory"] = {  } }, ["param2"] = 0, ["y"] = 5, ["param1"] = 0, ["z"] = 9, ["name"] = "lavatemple:brick" }, { ["x"] = 2, ["meta"] = { ["fields"] = {  }, ["inventory"] = {  } }, ["param2"] = 0, ["y"] = 5, ["param1"] = 0, ["z"] = 10, ["name"] = "lavatemple:brick" }, { ["x"] = 2, ["meta"] = { ["fields"] = {  }, ["inventory"] = {  } }, ["param2"] = 0, ["y"] = 6, ["param1"] = 0, ["z"] = 0, ["name"] = "lavatemple:brick" }, { ["x"] = 2, ["meta"] = { ["fields"] = {  }, ["inventory"] = {  } }, ["param2"] = 0, ["y"] = 6, ["param1"] = 0, ["z"] = 1, ["name"] = "lavatemple:brick" }, { ["x"] = 2, ["meta"] = { ["fields"] = {  }, ["inventory"] = {  } }, ["param2"] = 0, ["y"] = 6, ["param1"] = 0, ["z"] = 9, ["name"] = "lavatemple:brick" }, { ["x"] = 2, ["meta"] = { ["fields"] = {  }, ["inventory"] = {  } }, ["param2"] = 0, ["y"] = 6, ["param1"] = 0, ["z"] = 10, ["name"] = "lavatemple:brick" }, { ["x"] = 2, ["meta"] = { ["fields"] = {  }, ["inventory"] = {  } }, ["param2"] = 0, ["y"] = 7, ["param1"] = 0, ["z"] = 0, ["name"] = "lavatemple:brick" }, { ["x"] = 2, ["meta"] = { ["fields"] = {  }, ["inventory"] = {  } }, ["param2"] = 0, ["y"] = 7, ["param1"] = 0, ["z"] = 1, ["name"] = "lavatemple:brick" }, { ["x"] = 2, ["meta"] = { ["fields"] = {  }, ["inventory"] = {  } }, ["param2"] = 0, ["y"] = 7, ["param1"] = 0, ["z"] = 2, ["name"] = "lavatemple:brick" }, { ["x"] = 2, ["meta"] = { ["fields"] = {  }, ["inventory"] = {  } }, ["param2"] = 0, ["y"] = 7, ["param1"] = 0, ["z"] = 3, ["name"] = "lavatemple:brick" }, { ["x"] = 2, ["meta"] = { ["fields"] = {  }, ["inventory"] = {  } }, ["param2"] = 0, ["y"] = 7, ["param1"] = 0, ["z"] = 7, ["name"] = "lavatemple:brick" }, { ["x"] = 2, ["meta"] = { ["fields"] = {  }, ["inventory"] = {  } }, ["param2"] = 0, ["y"] = 7, ["param1"] = 0, ["z"] = 8, ["name"] = "lavatemple:brick" }, { ["x"] = 2, ["meta"] = { ["fields"] = {  }, ["inventory"] = {  } }, ["param2"] = 0, ["y"] = 7, ["param1"] = 0, ["z"] = 9, ["name"] = "lavatemple:brick" }, { ["x"] = 2, ["meta"] = { ["fields"] = {  }, ["inventory"] = {  } }, ["param2"] = 0, ["y"] = 7, ["param1"] = 0, ["z"] = 10, ["name"] = "lavatemple:brick" }, { ["x"] = 2, ["meta"] = { ["fields"] = {  }, ["inventory"] = {  } }, ["param2"] = 0, ["y"] = 8, ["param1"] = 0, ["z"] = 0, ["name"] = "lavatemple:brick" }, { ["x"] = 2, ["meta"] = { ["fields"] = {  }, ["inventory"] = {  } }, ["param2"] = 0, ["y"] = 8, ["param1"] = 0, ["z"] = 1, ["name"] = "lavatemple:brick" }, { ["x"] = 2, ["meta"] = { ["fields"] = {  }, ["inventory"] = {  } }, ["param2"] = 0, ["y"] = 8, ["param1"] = 0, ["z"] = 2, ["name"] = "lavatemple:brick" }, { ["x"] = 2, ["meta"] = { ["fields"] = {  }, ["inventory"] = {  } }, ["param2"] = 0, ["y"] = 8, ["param1"] = 0, ["z"] = 3, ["name"] = "lavatemple:brick" }, { ["x"] = 2, ["meta"] = { ["fields"] = {  }, ["inventory"] = {  } }, ["param2"] = 0, ["y"] = 8, ["param1"] = 0, ["z"] = 4, ["name"] = "lavatemple:brick" }, { ["x"] = 2, ["meta"] = { ["fields"] = {  }, ["inventory"] = {  } }, ["param2"] = 0, ["y"] = 8, ["param1"] = 0, ["z"] = 5, ["name"] = "lavatemple:brick" }, { ["x"] = 2, ["meta"] = { ["fields"] = {  }, ["inventory"] = {  } }, ["param2"] = 0, ["y"] = 8, ["param1"] = 0, ["z"] = 6, ["name"] = "lavatemple:brick" }, { ["x"] = 2, ["meta"] = { ["fields"] = {  }, ["inventory"] = {  } }, ["param2"] = 0, ["y"] = 8, ["param1"] = 0, ["z"] = 7, ["name"] = "lavatemple:brick" }, { ["x"] = 2, ["meta"] = { ["fields"] = {  }, ["inventory"] = {  } }, ["param2"] = 0, ["y"] = 8, ["param1"] = 0, ["z"] = 8, ["name"] = "lavatemple:brick" }, { ["x"] = 2, ["meta"] = { ["fields"] = {  }, ["inventory"] = {  } }, ["param2"] = 0, ["y"] = 8, ["param1"] = 0, ["z"] = 9, ["name"] = "lavatemple:brick" }, { ["x"] = 2, ["meta"] = { ["fields"] = {  }, ["inventory"] = {  } }, ["param2"] = 0, ["y"] = 8, ["param1"] = 0, ["z"] = 10, ["name"] = "lavatemple:brick" }, { ["x"] = 3, ["meta"] = { ["fields"] = {  }, ["inventory"] = {  } }, ["param2"] = 0, ["y"] = 0, ["param1"] = 0, ["z"] = 0, ["name"] = "lavatemple:brick" }, { ["x"] = 3, ["meta"] = { ["fields"] = {  }, ["inventory"] = {  } }, ["param2"] = 0, ["y"] = 0, ["param1"] = 0, ["z"] = 1, ["name"] = "lavatemple:brick" }, { ["x"] = 3, ["meta"] = { ["fields"] = {  }, ["inventory"] = {  } }, ["param2"] = 0, ["y"] = 0, ["param1"] = 0, ["z"] = 2, ["name"] = "lavatemple:brick" }, { ["x"] = 3, ["meta"] = { ["fields"] = {  }, ["inventory"] = {  } }, ["param2"] = 0, ["y"] = 0, ["param1"] = 0, ["z"] = 3, ["name"] = "lavatemple:brick" }, { ["x"] = 3, ["meta"] = { ["fields"] = {  }, ["inventory"] = {  } }, ["param2"] = 0, ["y"] = 0, ["param1"] = 0, ["z"] = 4, ["name"] = "lavatemple:brick" }, { ["x"] = 3, ["meta"] = { ["fields"] = {  }, ["inventory"] = {  } }, ["param2"] = 0, ["y"] = 0, ["param1"] = 0, ["z"] = 5, ["name"] = "lavatemple:brick" }, { ["x"] = 3, ["meta"] = { ["fields"] = {  }, ["inventory"] = {  } }, ["param2"] = 0, ["y"] = 0, ["param1"] = 0, ["z"] = 6, ["name"] = "lavatemple:brick" }, { ["x"] = 3, ["meta"] = { ["fields"] = {  }, ["inventory"] = {  } }, ["param2"] = 0, ["y"] = 0, ["param1"] = 0, ["z"] = 7, ["name"] = "lavatemple:brick" }, { ["x"] = 3, ["meta"] = { ["fields"] = {  }, ["inventory"] = {  } }, ["param2"] = 0, ["y"] = 0, ["param1"] = 0, ["z"] = 8, ["name"] = "lavatemple:brick" }, { ["x"] = 3, ["meta"] = { ["fields"] = {  }, ["inventory"] = {  } }, ["param2"] = 0, ["y"] = 0, ["param1"] = 0, ["z"] = 9, ["name"] = "lavatemple:brick" }, { ["x"] = 3, ["meta"] = { ["fields"] = {  }, ["inventory"] = {  } }, ["param2"] = 0, ["y"] = 0, ["param1"] = 0, ["z"] = 10, ["name"] = "lavatemple:brick" }, { ["x"] = 3, ["meta"] = { ["fields"] = {  }, ["inventory"] = {  } }, ["param2"] = 0, ["y"] = 1, ["param1"] = 0, ["z"] = 0, ["name"] = "lavatemple:brick" }, { ["x"] = 3, ["meta"] = { ["fields"] = {  }, ["inventory"] = {  } }, ["param2"] = 0, ["y"] = 1, ["param1"] = 0, ["z"] = 1, ["name"] = "lavatemple:brick" }, { ["x"] = 3, ["meta"] = { ["fields"] = {  }, ["inventory"] = {  } }, ["param2"] = 0, ["y"] = 1, ["param1"] = 0, ["z"] = 2, ["name"] = "lavatemple:brick" }, { ["x"] = 3, ["meta"] = { ["fields"] = {  }, ["inventory"] = {  } }, ["param2"] = 0, ["y"] = 1, ["param1"] = 0, ["z"] = 3, ["name"] = "lavatemple:brick" }, { ["x"] = 3, ["meta"] = { ["fields"] = {  }, ["inventory"] = {  } }, ["param2"] = 0, ["y"] = 1, ["param1"] = 0, ["z"] = 4, ["name"] = "lavatemple:brick" }, { ["x"] = 3, ["meta"] = { ["fields"] = { ["infotext"] = "Chest", ["formspec"] = "size[8,9]list[current_name;main;0,0;8,4;]list[current_player;main;0,5;8,4;]" }, ["inventory"] = { ["main"] = { "lavatemple:teleport_orb", "", "", "", "", "", "", "lavatemple:teleport_orb", "", "", "default:mese", "default:mese 3", "default:diamondblock 3", "default:diamondblock 7", "", "", "", "", "", "", "", "", "", "", "lavatemple:teleport_orb", "", "", "", "", "", "", "lavatemple:teleport_orb" } } }, ["param2"] = 3, ["y"] = 1, ["param1"] = 0, ["z"] = 5, ["name"] = "default:chest" }, { ["x"] = 3, ["meta"] = { ["fields"] = {  }, ["inventory"] = {  } }, ["param2"] = 0, ["y"] = 1, ["param1"] = 0, ["z"] = 6, ["name"] = "lavatemple:brick" }, { ["x"] = 3, ["meta"] = { ["fields"] = {  }, ["inventory"] = {  } }, ["param2"] = 0, ["y"] = 1, ["param1"] = 0, ["z"] = 7, ["name"] = "lavatemple:brick" }, { ["x"] = 3, ["meta"] = { ["fields"] = {  }, ["inventory"] = {  } }, ["param2"] = 0, ["y"] = 1, ["param1"] = 0, ["z"] = 8, ["name"] = "lavatemple:brick" }, { ["x"] = 3, ["meta"] = { ["fields"] = {  }, ["inventory"] = {  } }, ["param2"] = 0, ["y"] = 1, ["param1"] = 0, ["z"] = 9, ["name"] = "lavatemple:brick" }, { ["x"] = 3, ["meta"] = { ["fields"] = {  }, ["inventory"] = {  } }, ["param2"] = 0, ["y"] = 1, ["param1"] = 0, ["z"] = 10, ["name"] = "lavatemple:brick" }, { ["x"] = 3, ["meta"] = { ["fields"] = {  }, ["inventory"] = {  } }, ["param2"] = 0, ["y"] = 2, ["param1"] = 0, ["z"] = 0, ["name"] = "lavatemple:brick" }, { ["x"] = 3, ["meta"] = { ["fields"] = {  }, ["inventory"] = {  } }, ["param2"] = 0, ["y"] = 2, ["param1"] = 0, ["z"] = 1, ["name"] = "lavatemple:brick" }, { ["x"] = 3, ["meta"] = { ["fields"] = {  }, ["inventory"] = {  } }, ["param2"] = 0, ["y"] = 2, ["param1"] = 0, ["z"] = 2, ["name"] = "lavatemple:brick" }, { ["x"] = 3, ["meta"] = { ["fields"] = {  }, ["inventory"] = {  } }, ["param2"] = 0, ["y"] = 2, ["param1"] = 0, ["z"] = 3, ["name"] = "lavatemple:brick" }, { ["x"] = 3, ["meta"] = { ["fields"] = {  }, ["inventory"] = {  } }, ["param2"] = 0, ["y"] = 2, ["param1"] = 0, ["z"] = 4, ["name"] = "lavatemple:brick" }, { ["x"] = 3, ["meta"] = { ["fields"] = {  }, ["inventory"] = {  } }, ["param2"] = 0, ["y"] = 2, ["param1"] = 0, ["z"] = 5, ["name"] = "lavatemple:brick" }, { ["x"] = 3, ["meta"] = { ["fields"] = {  }, ["inventory"] = {  } }, ["param2"] = 0, ["y"] = 2, ["param1"] = 0, ["z"] = 6, ["name"] = "lavatemple:brick" }, { ["x"] = 3, ["meta"] = { ["fields"] = {  }, ["inventory"] = {  } }, ["param2"] = 0, ["y"] = 2, ["param1"] = 0, ["z"] = 7, ["name"] = "lavatemple:brick" }, { ["x"] = 3, ["meta"] = { ["fields"] = {  }, ["inventory"] = {  } }, ["param2"] = 0, ["y"] = 2, ["param1"] = 0, ["z"] = 8, ["name"] = "lavatemple:brick" }, { ["x"] = 3, ["meta"] = { ["fields"] = {  }, ["inventory"] = {  } }, ["param2"] = 0, ["y"] = 2, ["param1"] = 0, ["z"] = 9, ["name"] = "lavatemple:brick" }, { ["x"] = 3, ["meta"] = { ["fields"] = {  }, ["inventory"] = {  } }, ["param2"] = 0, ["y"] = 2, ["param1"] = 0, ["z"] = 10, ["name"] = "lavatemple:brick" }, { ["x"] = 3, ["meta"] = { ["fields"] = {  }, ["inventory"] = {  } }, ["param2"] = 0, ["y"] = 3, ["param1"] = 0, ["z"] = 0, ["name"] = "lavatemple:brick" }, { ["x"] = 3, ["meta"] = { ["fields"] = {  }, ["inventory"] = {  } }, ["param2"] = 0, ["y"] = 3, ["param1"] = 0, ["z"] = 1, ["name"] = "lavatemple:brick" }, { ["x"] = 3, ["meta"] = { ["fields"] = {  }, ["inventory"] = {  } }, ["param2"] = 0, ["y"] = 3, ["param1"] = 0, ["z"] = 2, ["name"] = "default:lava_source" }, { ["x"] = 3, ["meta"] = { ["fields"] = {  }, ["inventory"] = {  } }, ["param2"] = 0, ["y"] = 3, ["param1"] = 0, ["z"] = 3, ["name"] = "default:lava_source" }, { ["x"] = 3, ["meta"] = { ["fields"] = {  }, ["inventory"] = {  } }, ["param2"] = 0, ["y"] = 3, ["param1"] = 0, ["z"] = 4, ["name"] = "default:lava_source" }, { ["x"] = 3, ["meta"] = { ["fields"] = {  }, ["inventory"] = {  } }, ["param2"] = 0, ["y"] = 3, ["param1"] = 0, ["z"] = 5, ["name"] = "default:lava_source" }, { ["x"] = 3, ["meta"] = { ["fields"] = {  }, ["inventory"] = {  } }, ["param2"] = 0, ["y"] = 3, ["param1"] = 0, ["z"] = 6, ["name"] = "default:lava_source" }, { ["x"] = 3, ["meta"] = { ["fields"] = {  }, ["inventory"] = {  } }, ["param2"] = 0, ["y"] = 3, ["param1"] = 0, ["z"] = 7, ["name"] = "default:lava_source" }, { ["x"] = 3, ["meta"] = { ["fields"] = {  }, ["inventory"] = {  } }, ["param2"] = 0, ["y"] = 3, ["param1"] = 0, ["z"] = 8, ["name"] = "default:lava_source" }, { ["x"] = 3, ["meta"] = { ["fields"] = {  }, ["inventory"] = {  } }, ["param2"] = 0, ["y"] = 3, ["param1"] = 0, ["z"] = 9, ["name"] = "lavatemple:brick" }, { ["x"] = 3, ["meta"] = { ["fields"] = {  }, ["inventory"] = {  } }, ["param2"] = 0, ["y"] = 3, ["param1"] = 0, ["z"] = 10, ["name"] = "lavatemple:brick" }, { ["x"] = 3, ["meta"] = { ["fields"] = {  }, ["inventory"] = {  } }, ["param2"] = 0, ["y"] = 4, ["param1"] = 0, ["z"] = 0, ["name"] = "lavatemple:brick" }, { ["x"] = 3, ["meta"] = { ["fields"] = {  }, ["inventory"] = {  } }, ["param2"] = 0, ["y"] = 4, ["param1"] = 0, ["z"] = 1, ["name"] = "lavatemple:brick" }, { ["x"] = 3, ["meta"] = { ["fields"] = {  }, ["inventory"] = {  } }, ["param2"] = 2, ["y"] = 4, ["param1"] = 204, ["z"] = 5, ["name"] = "lavatemple:ladder" }, { ["x"] = 3, ["meta"] = { ["fields"] = {  }, ["inventory"] = {  } }, ["param2"] = 0, ["y"] = 4, ["param1"] = 0, ["z"] = 9, ["name"] = "lavatemple:brick" }, { ["x"] = 3, ["meta"] = { ["fields"] = {  }, ["inventory"] = {  } }, ["param2"] = 0, ["y"] = 4, ["param1"] = 0, ["z"] = 10, ["name"] = "lavatemple:brick" }, { ["x"] = 3, ["meta"] = { ["fields"] = {  }, ["inventory"] = {  } }, ["param2"] = 0, ["y"] = 5, ["param1"] = 0, ["z"] = 0, ["name"] = "lavatemple:brick" }, { ["x"] = 3, ["meta"] = { ["fields"] = {  }, ["inventory"] = {  } }, ["param2"] = 0, ["y"] = 5, ["param1"] = 0, ["z"] = 1, ["name"] = "lavatemple:brick" }, { ["x"] = 3, ["meta"] = { ["fields"] = {  }, ["inventory"] = {  } }, ["param2"] = 2, ["y"] = 5, ["param1"] = 187, ["z"] = 5, ["name"] = "lavatemple:ladder" }, { ["x"] = 3, ["meta"] = { ["fields"] = {  }, ["inventory"] = {  } }, ["param2"] = 0, ["y"] = 5, ["param1"] = 0, ["z"] = 9, ["name"] = "lavatemple:brick" }, { ["x"] = 3, ["meta"] = { ["fields"] = {  }, ["inventory"] = {  } }, ["param2"] = 0, ["y"] = 5, ["param1"] = 0, ["z"] = 10, ["name"] = "lavatemple:brick" }, { ["x"] = 3, ["meta"] = { ["fields"] = {  }, ["inventory"] = {  } }, ["param2"] = 0, ["y"] = 6, ["param1"] = 0, ["z"] = 0, ["name"] = "lavatemple:brick" }, { ["x"] = 3, ["meta"] = { ["fields"] = {  }, ["inventory"] = {  } }, ["param2"] = 0, ["y"] = 6, ["param1"] = 0, ["z"] = 1, ["name"] = "lavatemple:brick" }, { ["x"] = 3, ["meta"] = { ["fields"] = {  }, ["inventory"] = {  } }, ["param2"] = 0, ["y"] = 6, ["param1"] = 0, ["z"] = 9, ["name"] = "lavatemple:brick" }, { ["x"] = 3, ["meta"] = { ["fields"] = {  }, ["inventory"] = {  } }, ["param2"] = 0, ["y"] = 6, ["param1"] = 0, ["z"] = 10, ["name"] = "lavatemple:brick" }, { ["x"] = 3, ["meta"] = { ["fields"] = {  }, ["inventory"] = {  } }, ["param2"] = 0, ["y"] = 7, ["param1"] = 0, ["z"] = 0, ["name"] = "lavatemple:brick" }, { ["x"] = 3, ["meta"] = { ["fields"] = {  }, ["inventory"] = {  } }, ["param2"] = 0, ["y"] = 7, ["param1"] = 0, ["z"] = 1, ["name"] = "lavatemple:brick" }, { ["x"] = 3, ["meta"] = { ["fields"] = {  }, ["inventory"] = {  } }, ["param2"] = 0, ["y"] = 7, ["param1"] = 0, ["z"] = 2, ["name"] = "lavatemple:brick" }, { ["x"] = 3, ["meta"] = { ["fields"] = {  }, ["inventory"] = {  } }, ["param2"] = 0, ["y"] = 7, ["param1"] = 0, ["z"] = 3, ["name"] = "lavatemple:brick" }, { ["x"] = 3, ["meta"] = { ["fields"] = {  }, ["inventory"] = {  } }, ["param2"] = 0, ["y"] = 7, ["param1"] = 0, ["z"] = 7, ["name"] = "lavatemple:brick" }, { ["x"] = 3, ["meta"] = { ["fields"] = {  }, ["inventory"] = {  } }, ["param2"] = 0, ["y"] = 7, ["param1"] = 0, ["z"] = 8, ["name"] = "lavatemple:brick" }, { ["x"] = 3, ["meta"] = { ["fields"] = {  }, ["inventory"] = {  } }, ["param2"] = 0, ["y"] = 7, ["param1"] = 0, ["z"] = 9, ["name"] = "lavatemple:brick" }, { ["x"] = 3, ["meta"] = { ["fields"] = {  }, ["inventory"] = {  } }, ["param2"] = 0, ["y"] = 7, ["param1"] = 0, ["z"] = 10, ["name"] = "lavatemple:brick" }, { ["x"] = 3, ["meta"] = { ["fields"] = {  }, ["inventory"] = {  } }, ["param2"] = 0, ["y"] = 8, ["param1"] = 0, ["z"] = 0, ["name"] = "lavatemple:brick" }, { ["x"] = 3, ["meta"] = { ["fields"] = {  }, ["inventory"] = {  } }, ["param2"] = 0, ["y"] = 8, ["param1"] = 0, ["z"] = 1, ["name"] = "lavatemple:brick" }, { ["x"] = 3, ["meta"] = { ["fields"] = {  }, ["inventory"] = {  } }, ["param2"] = 0, ["y"] = 8, ["param1"] = 0, ["z"] = 2, ["name"] = "lavatemple:brick" }, { ["x"] = 3, ["meta"] = { ["fields"] = {  }, ["inventory"] = {  } }, ["param2"] = 0, ["y"] = 8, ["param1"] = 0, ["z"] = 3, ["name"] = "lavatemple:brick" }, { ["x"] = 3, ["meta"] = { ["fields"] = {  }, ["inventory"] = {  } }, ["param2"] = 0, ["y"] = 8, ["param1"] = 0, ["z"] = 4, ["name"] = "lavatemple:brick" }, { ["x"] = 3, ["meta"] = { ["fields"] = {  }, ["inventory"] = {  } }, ["param2"] = 0, ["y"] = 8, ["param1"] = 0, ["z"] = 5, ["name"] = "lavatemple:brick" }, { ["x"] = 3, ["meta"] = { ["fields"] = {  }, ["inventory"] = {  } }, ["param2"] = 0, ["y"] = 8, ["param1"] = 0, ["z"] = 6, ["name"] = "lavatemple:brick" }, { ["x"] = 3, ["meta"] = { ["fields"] = {  }, ["inventory"] = {  } }, ["param2"] = 0, ["y"] = 8, ["param1"] = 0, ["z"] = 7, ["name"] = "lavatemple:brick" }, { ["x"] = 3, ["meta"] = { ["fields"] = {  }, ["inventory"] = {  } }, ["param2"] = 0, ["y"] = 8, ["param1"] = 0, ["z"] = 8, ["name"] = "lavatemple:brick" }, { ["x"] = 3, ["meta"] = { ["fields"] = {  }, ["inventory"] = {  } }, ["param2"] = 0, ["y"] = 8, ["param1"] = 0, ["z"] = 9, ["name"] = "lavatemple:brick" }, { ["x"] = 3, ["meta"] = { ["fields"] = {  }, ["inventory"] = {  } }, ["param2"] = 0, ["y"] = 8, ["param1"] = 0, ["z"] = 10, ["name"] = "lavatemple:brick" }, { ["x"] = 4, ["meta"] = { ["fields"] = {  }, ["inventory"] = {  } }, ["param2"] = 0, ["y"] = 0, ["param1"] = 0, ["z"] = 0, ["name"] = "lavatemple:brick" }, { ["x"] = 4, ["meta"] = { ["fields"] = {  }, ["inventory"] = {  } }, ["param2"] = 0, ["y"] = 0, ["param1"] = 0, ["z"] = 1, ["name"] = "lavatemple:brick" }, { ["x"] = 4, ["meta"] = { ["fields"] = {  }, ["inventory"] = {  } }, ["param2"] = 0, ["y"] = 0, ["param1"] = 0, ["z"] = 2, ["name"] = "lavatemple:brick" }, { ["x"] = 4, ["meta"] = { ["fields"] = {  }, ["inventory"] = {  } }, ["param2"] = 0, ["y"] = 0, ["param1"] = 0, ["z"] = 3, ["name"] = "lavatemple:brick" }, { ["x"] = 4, ["meta"] = { ["fields"] = {  }, ["inventory"] = {  } }, ["param2"] = 0, ["y"] = 0, ["param1"] = 0, ["z"] = 4, ["name"] = "lavatemple:brick" }, { ["x"] = 4, ["meta"] = { ["fields"] = {  }, ["inventory"] = {  } }, ["param2"] = 0, ["y"] = 0, ["param1"] = 0, ["z"] = 5, ["name"] = "lavatemple:brick" }, { ["x"] = 4, ["meta"] = { ["fields"] = {  }, ["inventory"] = {  } }, ["param2"] = 0, ["y"] = 0, ["param1"] = 0, ["z"] = 6, ["name"] = "lavatemple:brick" }, { ["x"] = 4, ["meta"] = { ["fields"] = {  }, ["inventory"] = {  } }, ["param2"] = 0, ["y"] = 0, ["param1"] = 0, ["z"] = 7, ["name"] = "lavatemple:brick" }, { ["x"] = 4, ["meta"] = { ["fields"] = {  }, ["inventory"] = {  } }, ["param2"] = 0, ["y"] = 0, ["param1"] = 0, ["z"] = 8, ["name"] = "lavatemple:brick" }, { ["x"] = 4, ["meta"] = { ["fields"] = {  }, ["inventory"] = {  } }, ["param2"] = 0, ["y"] = 0, ["param1"] = 0, ["z"] = 9, ["name"] = "lavatemple:brick" }, { ["x"] = 4, ["meta"] = { ["fields"] = {  }, ["inventory"] = {  } }, ["param2"] = 0, ["y"] = 0, ["param1"] = 0, ["z"] = 10, ["name"] = "lavatemple:brick" }, { ["x"] = 4, ["meta"] = { ["fields"] = {  }, ["inventory"] = {  } }, ["param2"] = 0, ["y"] = 1, ["param1"] = 0, ["z"] = 0, ["name"] = "lavatemple:brick" }, { ["x"] = 4, ["meta"] = { ["fields"] = {  }, ["inventory"] = {  } }, ["param2"] = 0, ["y"] = 1, ["param1"] = 0, ["z"] = 1, ["name"] = "lavatemple:brick" }, { ["x"] = 4, ["meta"] = { ["fields"] = {  }, ["inventory"] = {  } }, ["param2"] = 0, ["y"] = 1, ["param1"] = 0, ["z"] = 2, ["name"] = "lavatemple:brick" }, { ["x"] = 4, ["meta"] = { ["fields"] = {  }, ["inventory"] = {  } }, ["param2"] = 0, ["y"] = 1, ["param1"] = 0, ["z"] = 3, ["name"] = "lavatemple:brick" }, { ["x"] = 4, ["meta"] = { ["fields"] = {  }, ["inventory"] = {  } }, ["param2"] = 0, ["y"] = 1, ["param1"] = 0, ["z"] = 4, ["name"] = "lavatemple:brick" }, { ["x"] = 4, ["meta"] = { ["fields"] = {  }, ["inventory"] = {  } }, ["param2"] = 0, ["y"] = 1, ["param1"] = 0, ["z"] = 5, ["name"] = "lavatemple:brick" }, { ["x"] = 4, ["meta"] = { ["fields"] = {  }, ["inventory"] = {  } }, ["param2"] = 0, ["y"] = 1, ["param1"] = 0, ["z"] = 6, ["name"] = "lavatemple:brick" }, { ["x"] = 4, ["meta"] = { ["fields"] = {  }, ["inventory"] = {  } }, ["param2"] = 0, ["y"] = 1, ["param1"] = 0, ["z"] = 7, ["name"] = "lavatemple:brick" }, { ["x"] = 4, ["meta"] = { ["fields"] = {  }, ["inventory"] = {  } }, ["param2"] = 0, ["y"] = 1, ["param1"] = 0, ["z"] = 8, ["name"] = "lavatemple:brick" }, { ["x"] = 4, ["meta"] = { ["fields"] = {  }, ["inventory"] = {  } }, ["param2"] = 0, ["y"] = 1, ["param1"] = 0, ["z"] = 9, ["name"] = "lavatemple:brick" }, { ["x"] = 4, ["meta"] = { ["fields"] = {  }, ["inventory"] = {  } }, ["param2"] = 0, ["y"] = 1, ["param1"] = 0, ["z"] = 10, ["name"] = "lavatemple:brick" }, { ["x"] = 4, ["meta"] = { ["fields"] = {  }, ["inventory"] = {  } }, ["param2"] = 0, ["y"] = 2, ["param1"] = 0, ["z"] = 0, ["name"] = "lavatemple:brick" }, { ["x"] = 4, ["meta"] = { ["fields"] = {  }, ["inventory"] = {  } }, ["param2"] = 0, ["y"] = 2, ["param1"] = 0, ["z"] = 1, ["name"] = "lavatemple:brick" }, { ["x"] = 4, ["meta"] = { ["fields"] = {  }, ["inventory"] = {  } }, ["param2"] = 0, ["y"] = 2, ["param1"] = 0, ["z"] = 2, ["name"] = "lavatemple:brick" }, { ["x"] = 4, ["meta"] = { ["fields"] = {  }, ["inventory"] = {  } }, ["param2"] = 0, ["y"] = 2, ["param1"] = 170, ["z"] = 3, ["name"] = "lavatemple:fence_brick" }, { ["x"] = 4, ["meta"] = { ["fields"] = {  }, ["inventory"] = {  } }, ["param2"] = 0, ["y"] = 2, ["param1"] = 187, ["z"] = 4, ["name"] = "lavatemple:fence_brick" }, { ["x"] = 4, ["meta"] = { ["fields"] = {  }, ["inventory"] = {  } }, ["param2"] = 0, ["y"] = 2, ["param1"] = 170, ["z"] = 5, ["name"] = "lavatemple:fence_brick" }, { ["x"] = 4, ["meta"] = { ["fields"] = {  }, ["inventory"] = {  } }, ["param2"] = 0, ["y"] = 2, ["param1"] = 170, ["z"] = 6, ["name"] = "lavatemple:fence_brick" }, { ["x"] = 4, ["meta"] = { ["fields"] = {  }, ["inventory"] = {  } }, ["param2"] = 0, ["y"] = 2, ["param1"] = 153, ["z"] = 7, ["name"] = "lavatemple:fence_brick" }, { ["x"] = 4, ["meta"] = { ["fields"] = {  }, ["inventory"] = {  } }, ["param2"] = 0, ["y"] = 2, ["param1"] = 0, ["z"] = 8, ["name"] = "lavatemple:brick" }, { ["x"] = 4, ["meta"] = { ["fields"] = {  }, ["inventory"] = {  } }, ["param2"] = 0, ["y"] = 2, ["param1"] = 0, ["z"] = 9, ["name"] = "lavatemple:brick" }, { ["x"] = 4, ["meta"] = { ["fields"] = {  }, ["inventory"] = {  } }, ["param2"] = 0, ["y"] = 2, ["param1"] = 0, ["z"] = 10, ["name"] = "lavatemple:brick" }, { ["x"] = 4, ["meta"] = { ["fields"] = {  }, ["inventory"] = {  } }, ["param2"] = 0, ["y"] = 3, ["param1"] = 0, ["z"] = 0, ["name"] = "lavatemple:brick" }, { ["x"] = 4, ["meta"] = { ["fields"] = {  }, ["inventory"] = {  } }, ["param2"] = 0, ["y"] = 3, ["param1"] = 0, ["z"] = 1, ["name"] = "lavatemple:brick" }, { ["x"] = 4, ["meta"] = { ["fields"] = {  }, ["inventory"] = {  } }, ["param2"] = 0, ["y"] = 3, ["param1"] = 0, ["z"] = 2, ["name"] = "lavatemple:brick" }, { ["x"] = 4, ["meta"] = { ["fields"] = {  }, ["inventory"] = {  } }, ["param2"] = 0, ["y"] = 3, ["param1"] = 0, ["z"] = 3, ["name"] = "lavatemple:brick" }, { ["x"] = 4, ["meta"] = { ["fields"] = {  }, ["inventory"] = {  } }, ["param2"] = 0, ["y"] = 3, ["param1"] = 0, ["z"] = 4, ["name"] = "lavatemple:brick" }, { ["x"] = 4, ["meta"] = { ["fields"] = {  }, ["inventory"] = {  } }, ["param2"] = 0, ["y"] = 3, ["param1"] = 0, ["z"] = 5, ["name"] = "lavatemple:brick" }, { ["x"] = 4, ["meta"] = { ["fields"] = {  }, ["inventory"] = {  } }, ["param2"] = 0, ["y"] = 3, ["param1"] = 0, ["z"] = 6, ["name"] = "lavatemple:brick" }, { ["x"] = 4, ["meta"] = { ["fields"] = {  }, ["inventory"] = {  } }, ["param2"] = 0, ["y"] = 3, ["param1"] = 0, ["z"] = 7, ["name"] = "lavatemple:brick" }, { ["x"] = 4, ["meta"] = { ["fields"] = {  }, ["inventory"] = {  } }, ["param2"] = 0, ["y"] = 3, ["param1"] = 0, ["z"] = 8, ["name"] = "lavatemple:brick" }, { ["x"] = 4, ["meta"] = { ["fields"] = {  }, ["inventory"] = {  } }, ["param2"] = 0, ["y"] = 3, ["param1"] = 0, ["z"] = 9, ["name"] = "lavatemple:brick" }, { ["x"] = 4, ["meta"] = { ["fields"] = {  }, ["inventory"] = {  } }, ["param2"] = 0, ["y"] = 3, ["param1"] = 0, ["z"] = 10, ["name"] = "lavatemple:brick" }, { ["x"] = 4, ["meta"] = { ["fields"] = {  }, ["inventory"] = {  } }, ["param2"] = 0, ["y"] = 4, ["param1"] = 0, ["z"] = 0, ["name"] = "lavatemple:brick" }, { ["x"] = 4, ["meta"] = { ["fields"] = {  }, ["inventory"] = {  } }, ["param2"] = 0, ["y"] = 4, ["param1"] = 0, ["z"] = 1, ["name"] = "lavatemple:brick" }, { ["x"] = 4, ["meta"] = { ["fields"] = {  }, ["inventory"] = {  } }, ["param2"] = 0, ["y"] = 4, ["param1"] = 0, ["z"] = 3, ["name"] = "lavatemple:brick" }, { ["x"] = 4, ["meta"] = { ["fields"] = {  }, ["inventory"] = {  } }, ["param2"] = 0, ["y"] = 4, ["param1"] = 0, ["z"] = 4, ["name"] = "lavatemple:brick" }, { ["x"] = 4, ["meta"] = { ["fields"] = {  }, ["inventory"] = {  } }, ["param2"] = 0, ["y"] = 4, ["param1"] = 0, ["z"] = 5, ["name"] = "lavatemple:brick" }, { ["x"] = 4, ["meta"] = { ["fields"] = {  }, ["inventory"] = {  } }, ["param2"] = 0, ["y"] = 4, ["param1"] = 0, ["z"] = 6, ["name"] = "lavatemple:brick" }, { ["x"] = 4, ["meta"] = { ["fields"] = {  }, ["inventory"] = {  } }, ["param2"] = 0, ["y"] = 4, ["param1"] = 0, ["z"] = 7, ["name"] = "lavatemple:brick" }, { ["x"] = 4, ["meta"] = { ["fields"] = {  }, ["inventory"] = {  } }, ["param2"] = 0, ["y"] = 4, ["param1"] = 0, ["z"] = 9, ["name"] = "lavatemple:brick" }, { ["x"] = 4, ["meta"] = { ["fields"] = {  }, ["inventory"] = {  } }, ["param2"] = 0, ["y"] = 4, ["param1"] = 0, ["z"] = 10, ["name"] = "lavatemple:brick" }, { ["x"] = 4, ["meta"] = { ["fields"] = {  }, ["inventory"] = {  } }, ["param2"] = 0, ["y"] = 5, ["param1"] = 0, ["z"] = 0, ["name"] = "lavatemple:brick" }, { ["x"] = 4, ["meta"] = { ["fields"] = {  }, ["inventory"] = {  } }, ["param2"] = 0, ["y"] = 5, ["param1"] = 0, ["z"] = 1, ["name"] = "lavatemple:brick" }, { ["x"] = 4, ["meta"] = { ["fields"] = {  }, ["inventory"] = {  } }, ["param2"] = 0, ["y"] = 5, ["param1"] = 0, ["z"] = 3, ["name"] = "lavatemple:brick" }, { ["x"] = 4, ["meta"] = { ["fields"] = {  }, ["inventory"] = {  } }, ["param2"] = 0, ["y"] = 5, ["param1"] = 0, ["z"] = 4, ["name"] = "lavatemple:brick" }, { ["x"] = 4, ["meta"] = { ["fields"] = {  }, ["inventory"] = {  } }, ["param2"] = 0, ["y"] = 5, ["param1"] = 0, ["z"] = 5, ["name"] = "lavatemple:brick" }, { ["x"] = 4, ["meta"] = { ["fields"] = {  }, ["inventory"] = {  } }, ["param2"] = 0, ["y"] = 5, ["param1"] = 0, ["z"] = 6, ["name"] = "lavatemple:brick" }, { ["x"] = 4, ["meta"] = { ["fields"] = {  }, ["inventory"] = {  } }, ["param2"] = 0, ["y"] = 5, ["param1"] = 0, ["z"] = 7, ["name"] = "lavatemple:brick" }, { ["x"] = 4, ["meta"] = { ["fields"] = {  }, ["inventory"] = {  } }, ["param2"] = 0, ["y"] = 5, ["param1"] = 0, ["z"] = 9, ["name"] = "lavatemple:brick" }, { ["x"] = 4, ["meta"] = { ["fields"] = {  }, ["inventory"] = {  } }, ["param2"] = 0, ["y"] = 5, ["param1"] = 0, ["z"] = 10, ["name"] = "lavatemple:brick" }, { ["x"] = 4, ["meta"] = { ["fields"] = {  }, ["inventory"] = {  } }, ["param2"] = 0, ["y"] = 6, ["param1"] = 0, ["z"] = 0, ["name"] = "lavatemple:brick" }, { ["x"] = 4, ["meta"] = { ["fields"] = {  }, ["inventory"] = {  } }, ["param2"] = 0, ["y"] = 6, ["param1"] = 0, ["z"] = 1, ["name"] = "lavatemple:brick" }, { ["x"] = 4, ["meta"] = { ["fields"] = {  }, ["inventory"] = {  } }, ["param2"] = 0, ["y"] = 6, ["param1"] = 0, ["z"] = 2, ["name"] = "lavatemple:brick" }, { ["x"] = 4, ["meta"] = { ["fields"] = {  }, ["inventory"] = {  } }, ["param2"] = 0, ["y"] = 6, ["param1"] = 0, ["z"] = 3, ["name"] = "lavatemple:brick" }, { ["x"] = 4, ["meta"] = { ["fields"] = {  }, ["inventory"] = {  } }, ["param2"] = 0, ["y"] = 6, ["param1"] = 0, ["z"] = 7, ["name"] = "lavatemple:brick" }, { ["x"] = 4, ["meta"] = { ["fields"] = {  }, ["inventory"] = {  } }, ["param2"] = 0, ["y"] = 6, ["param1"] = 0, ["z"] = 8, ["name"] = "lavatemple:brick" }, { ["x"] = 4, ["meta"] = { ["fields"] = {  }, ["inventory"] = {  } }, ["param2"] = 0, ["y"] = 6, ["param1"] = 0, ["z"] = 9, ["name"] = "lavatemple:brick" }, { ["x"] = 4, ["meta"] = { ["fields"] = {  }, ["inventory"] = {  } }, ["param2"] = 0, ["y"] = 6, ["param1"] = 0, ["z"] = 10, ["name"] = "lavatemple:brick" }, { ["x"] = 4, ["meta"] = { ["fields"] = {  }, ["inventory"] = {  } }, ["param2"] = 0, ["y"] = 7, ["param1"] = 0, ["z"] = 0, ["name"] = "lavatemple:brick" }, { ["x"] = 4, ["meta"] = { ["fields"] = {  }, ["inventory"] = {  } }, ["param2"] = 0, ["y"] = 7, ["param1"] = 0, ["z"] = 1, ["name"] = "lavatemple:brick" }, { ["x"] = 4, ["meta"] = { ["fields"] = {  }, ["inventory"] = {  } }, ["param2"] = 0, ["y"] = 7, ["param1"] = 0, ["z"] = 2, ["name"] = "lavatemple:brick" }, { ["x"] = 4, ["meta"] = { ["fields"] = {  }, ["inventory"] = {  } }, ["param2"] = 0, ["y"] = 7, ["param1"] = 0, ["z"] = 3, ["name"] = "lavatemple:brick" }, { ["x"] = 4, ["meta"] = { ["fields"] = {  }, ["inventory"] = {  } }, ["param2"] = 0, ["y"] = 7, ["param1"] = 0, ["z"] = 7, ["name"] = "lavatemple:brick" }, { ["x"] = 4, ["meta"] = { ["fields"] = {  }, ["inventory"] = {  } }, ["param2"] = 0, ["y"] = 7, ["param1"] = 0, ["z"] = 8, ["name"] = "lavatemple:brick" }, { ["x"] = 4, ["meta"] = { ["fields"] = {  }, ["inventory"] = {  } }, ["param2"] = 0, ["y"] = 7, ["param1"] = 0, ["z"] = 9, ["name"] = "lavatemple:brick" }, { ["x"] = 4, ["meta"] = { ["fields"] = {  }, ["inventory"] = {  } }, ["param2"] = 0, ["y"] = 7, ["param1"] = 0, ["z"] = 10, ["name"] = "lavatemple:brick" }, { ["x"] = 4, ["meta"] = { ["fields"] = {  }, ["inventory"] = {  } }, ["param2"] = 0, ["y"] = 8, ["param1"] = 0, ["z"] = 0, ["name"] = "lavatemple:brick" }, { ["x"] = 4, ["meta"] = { ["fields"] = {  }, ["inventory"] = {  } }, ["param2"] = 0, ["y"] = 8, ["param1"] = 0, ["z"] = 1, ["name"] = "lavatemple:brick" }, { ["x"] = 4, ["meta"] = { ["fields"] = {  }, ["inventory"] = {  } }, ["param2"] = 0, ["y"] = 8, ["param1"] = 0, ["z"] = 2, ["name"] = "lavatemple:brick" }, { ["x"] = 4, ["meta"] = { ["fields"] = {  }, ["inventory"] = {  } }, ["param2"] = 0, ["y"] = 8, ["param1"] = 0, ["z"] = 3, ["name"] = "lavatemple:brick" }, { ["x"] = 4, ["meta"] = { ["fields"] = {  }, ["inventory"] = {  } }, ["param2"] = 0, ["y"] = 8, ["param1"] = 0, ["z"] = 4, ["name"] = "lavatemple:brick" }, { ["x"] = 4, ["meta"] = { ["fields"] = {  }, ["inventory"] = {  } }, ["param2"] = 0, ["y"] = 8, ["param1"] = 0, ["z"] = 5, ["name"] = "lavatemple:brick" }, { ["x"] = 4, ["meta"] = { ["fields"] = {  }, ["inventory"] = {  } }, ["param2"] = 0, ["y"] = 8, ["param1"] = 0, ["z"] = 6, ["name"] = "lavatemple:brick" }, { ["x"] = 4, ["meta"] = { ["fields"] = {  }, ["inventory"] = {  } }, ["param2"] = 0, ["y"] = 8, ["param1"] = 0, ["z"] = 7, ["name"] = "lavatemple:brick" }, { ["x"] = 4, ["meta"] = { ["fields"] = {  }, ["inventory"] = {  } }, ["param2"] = 0, ["y"] = 8, ["param1"] = 0, ["z"] = 8, ["name"] = "lavatemple:brick" }, { ["x"] = 4, ["meta"] = { ["fields"] = {  }, ["inventory"] = {  } }, ["param2"] = 0, ["y"] = 8, ["param1"] = 0, ["z"] = 9, ["name"] = "lavatemple:brick" }, { ["x"] = 4, ["meta"] = { ["fields"] = {  }, ["inventory"] = {  } }, ["param2"] = 0, ["y"] = 8, ["param1"] = 0, ["z"] = 10, ["name"] = "lavatemple:brick" }, { ["x"] = 5, ["meta"] = { ["fields"] = {  }, ["inventory"] = {  } }, ["param2"] = 0, ["y"] = 0, ["param1"] = 0, ["z"] = 0, ["name"] = "lavatemple:brick" }, { ["x"] = 5, ["meta"] = { ["fields"] = {  }, ["inventory"] = {  } }, ["param2"] = 0, ["y"] = 0, ["param1"] = 0, ["z"] = 1, ["name"] = "lavatemple:brick" }, { ["x"] = 5, ["meta"] = { ["fields"] = {  }, ["inventory"] = {  } }, ["param2"] = 0, ["y"] = 0, ["param1"] = 0, ["z"] = 2, ["name"] = "lavatemple:brick" }, { ["x"] = 5, ["meta"] = { ["fields"] = {  }, ["inventory"] = {  } }, ["param2"] = 0, ["y"] = 0, ["param1"] = 0, ["z"] = 3, ["name"] = "lavatemple:brick" }, { ["x"] = 5, ["meta"] = { ["fields"] = {  }, ["inventory"] = {  } }, ["param2"] = 0, ["y"] = 0, ["param1"] = 0, ["z"] = 4, ["name"] = "lavatemple:brick" }, { ["x"] = 5, ["meta"] = { ["fields"] = {  }, ["inventory"] = {  } }, ["param2"] = 0, ["y"] = 0, ["param1"] = 0, ["z"] = 5, ["name"] = "lavatemple:brick" }, { ["x"] = 5, ["meta"] = { ["fields"] = {  }, ["inventory"] = {  } }, ["param2"] = 0, ["y"] = 0, ["param1"] = 0, ["z"] = 6, ["name"] = "lavatemple:brick" }, { ["x"] = 5, ["meta"] = { ["fields"] = {  }, ["inventory"] = {  } }, ["param2"] = 0, ["y"] = 0, ["param1"] = 0, ["z"] = 7, ["name"] = "lavatemple:brick" }, { ["x"] = 5, ["meta"] = { ["fields"] = {  }, ["inventory"] = {  } }, ["param2"] = 0, ["y"] = 0, ["param1"] = 0, ["z"] = 8, ["name"] = "lavatemple:brick" }, { ["x"] = 5, ["meta"] = { ["fields"] = {  }, ["inventory"] = {  } }, ["param2"] = 0, ["y"] = 0, ["param1"] = 0, ["z"] = 9, ["name"] = "lavatemple:brick" }, { ["x"] = 5, ["meta"] = { ["fields"] = {  }, ["inventory"] = {  } }, ["param2"] = 0, ["y"] = 0, ["param1"] = 0, ["z"] = 10, ["name"] = "lavatemple:brick" }, { ["x"] = 5, ["meta"] = { ["fields"] = {  }, ["inventory"] = {  } }, ["param2"] = 0, ["y"] = 1, ["param1"] = 0, ["z"] = 0, ["name"] = "lavatemple:brick" }, { ["x"] = 5, ["meta"] = { ["fields"] = {  }, ["inventory"] = {  } }, ["param2"] = 0, ["y"] = 1, ["param1"] = 0, ["z"] = 1, ["name"] = "lavatemple:brick" }, { ["x"] = 5, ["meta"] = { ["fields"] = {  }, ["inventory"] = {  } }, ["param2"] = 0, ["y"] = 1, ["param1"] = 0, ["z"] = 2, ["name"] = "lavatemple:brick" }, { ["x"] = 5, ["meta"] = { ["fields"] = {  }, ["inventory"] = {  } }, ["param2"] = 0, ["y"] = 1, ["param1"] = 0, ["z"] = 3, ["name"] = "lavatemple:brick" }, { ["x"] = 5, ["meta"] = { ["fields"] = {  }, ["inventory"] = {  } }, ["param2"] = 0, ["y"] = 1, ["param1"] = 0, ["z"] = 4, ["name"] = "lavatemple:brick" }, { ["x"] = 5, ["meta"] = { ["fields"] = {  }, ["inventory"] = {  } }, ["param2"] = 0, ["y"] = 1, ["param1"] = 0, ["z"] = 5, ["name"] = "lavatemple:brick" }, { ["x"] = 5, ["meta"] = { ["fields"] = {  }, ["inventory"] = {  } }, ["param2"] = 0, ["y"] = 1, ["param1"] = 0, ["z"] = 6, ["name"] = "lavatemple:brick" }, { ["x"] = 5, ["meta"] = { ["fields"] = {  }, ["inventory"] = {  } }, ["param2"] = 0, ["y"] = 1, ["param1"] = 0, ["z"] = 7, ["name"] = "lavatemple:brick" }, { ["x"] = 5, ["meta"] = { ["fields"] = {  }, ["inventory"] = {  } }, ["param2"] = 0, ["y"] = 1, ["param1"] = 0, ["z"] = 8, ["name"] = "lavatemple:brick" }, { ["x"] = 5, ["meta"] = { ["fields"] = {  }, ["inventory"] = {  } }, ["param2"] = 0, ["y"] = 1, ["param1"] = 0, ["z"] = 9, ["name"] = "lavatemple:brick" }, { ["x"] = 5, ["meta"] = { ["fields"] = {  }, ["inventory"] = {  } }, ["param2"] = 0, ["y"] = 1, ["param1"] = 0, ["z"] = 10, ["name"] = "lavatemple:brick" }, { ["x"] = 5, ["meta"] = { ["fields"] = {  }, ["inventory"] = {  } }, ["param2"] = 0, ["y"] = 2, ["param1"] = 0, ["z"] = 0, ["name"] = "lavatemple:brick" }, { ["x"] = 5, ["meta"] = { ["fields"] = {  }, ["inventory"] = {  } }, ["param2"] = 0, ["y"] = 2, ["param1"] = 0, ["z"] = 1, ["name"] = "lavatemple:brick" }, { ["x"] = 5, ["meta"] = { ["fields"] = {  }, ["inventory"] = {  } }, ["param2"] = 0, ["y"] = 2, ["param1"] = 0, ["z"] = 2, ["name"] = "lavatemple:brick" }, { ["x"] = 5, ["meta"] = { ["fields"] = {  }, ["inventory"] = {  } }, ["param2"] = 0, ["y"] = 2, ["param1"] = 0, ["z"] = 3, ["name"] = "lavatemple:brick" }, { ["x"] = 5, ["meta"] = { ["fields"] = {  }, ["inventory"] = {  } }, ["param2"] = 2, ["y"] = 2, ["param1"] = 204, ["z"] = 4, ["name"] = "stairs:stair_lavatemple_brick" }, { ["x"] = 5, ["meta"] = { ["fields"] = {  }, ["inventory"] = {  } }, ["param2"] = 1, ["y"] = 2, ["param1"] = 187, ["z"] = 5, ["name"] = "lavatemple:ladder" }, { ["x"] = 5, ["meta"] = { ["fields"] = {  }, ["inventory"] = {  } }, ["param2"] = 0, ["y"] = 2, ["param1"] = 187, ["z"] = 6, ["name"] = "stairs:stair_lavatemple_brick" }, { ["x"] = 5, ["meta"] = { ["fields"] = {  }, ["inventory"] = {  } }, ["param2"] = 0, ["y"] = 2, ["param1"] = 0, ["z"] = 7, ["name"] = "lavatemple:brick" }, { ["x"] = 5, ["meta"] = { ["fields"] = {  }, ["inventory"] = {  } }, ["param2"] = 0, ["y"] = 2, ["param1"] = 0, ["z"] = 8, ["name"] = "lavatemple:brick" }, { ["x"] = 5, ["meta"] = { ["fields"] = {  }, ["inventory"] = {  } }, ["param2"] = 0, ["y"] = 2, ["param1"] = 0, ["z"] = 9, ["name"] = "lavatemple:brick" }, { ["x"] = 5, ["meta"] = { ["fields"] = {  }, ["inventory"] = {  } }, ["param2"] = 0, ["y"] = 2, ["param1"] = 0, ["z"] = 10, ["name"] = "lavatemple:brick" }, { ["x"] = 5, ["meta"] = { ["fields"] = {  }, ["inventory"] = {  } }, ["param2"] = 0, ["y"] = 3, ["param1"] = 0, ["z"] = 0, ["name"] = "lavatemple:brick" }, { ["x"] = 5, ["meta"] = { ["fields"] = {  }, ["inventory"] = {  } }, ["param2"] = 0, ["y"] = 3, ["param1"] = 0, ["z"] = 1, ["name"] = "lavatemple:brick" }, { ["x"] = 5, ["meta"] = { ["fields"] = {  }, ["inventory"] = {  } }, ["param2"] = 0, ["y"] = 3, ["param1"] = 0, ["z"] = 2, ["name"] = "lavatemple:brick" }, { ["x"] = 5, ["meta"] = { ["fields"] = {  }, ["inventory"] = {  } }, ["param2"] = 2, ["y"] = 3, ["param1"] = 187, ["z"] = 3, ["name"] = "stairs:stair_lavatemple_brick" }, { ["x"] = 5, ["meta"] = { ["fields"] = {  }, ["inventory"] = {  } }, ["param2"] = 0, ["y"] = 3, ["param1"] = 153, ["z"] = 7, ["name"] = "stairs:stair_lavatemple_brick" }, { ["x"] = 5, ["meta"] = { ["fields"] = {  }, ["inventory"] = {  } }, ["param2"] = 0, ["y"] = 3, ["param1"] = 0, ["z"] = 8, ["name"] = "lavatemple:brick" }, { ["x"] = 5, ["meta"] = { ["fields"] = {  }, ["inventory"] = {  } }, ["param2"] = 0, ["y"] = 3, ["param1"] = 0, ["z"] = 9, ["name"] = "lavatemple:brick" }, { ["x"] = 5, ["meta"] = { ["fields"] = {  }, ["inventory"] = {  } }, ["param2"] = 0, ["y"] = 3, ["param1"] = 0, ["z"] = 10, ["name"] = "lavatemple:brick" }, { ["x"] = 5, ["meta"] = { ["fields"] = {  }, ["inventory"] = {  } }, ["param2"] = 0, ["y"] = 4, ["param1"] = 0, ["z"] = 0, ["name"] = "lavatemple:brick" }, { ["x"] = 5, ["meta"] = { ["fields"] = {  }, ["inventory"] = {  } }, ["param2"] = 0, ["y"] = 4, ["param1"] = 0, ["z"] = 1, ["name"] = "lavatemple:brick" }, { ["x"] = 5, ["meta"] = { ["fields"] = {  }, ["inventory"] = {  } }, ["param2"] = 0, ["y"] = 4, ["param1"] = 0, ["z"] = 9, ["name"] = "lavatemple:brick" }, { ["x"] = 5, ["meta"] = { ["fields"] = {  }, ["inventory"] = {  } }, ["param2"] = 0, ["y"] = 4, ["param1"] = 0, ["z"] = 10, ["name"] = "lavatemple:brick" }, { ["x"] = 5, ["meta"] = { ["fields"] = {  }, ["inventory"] = {  } }, ["param2"] = 0, ["y"] = 5, ["param1"] = 0, ["z"] = 0, ["name"] = "lavatemple:brick" }, { ["x"] = 5, ["meta"] = { ["fields"] = {  }, ["inventory"] = {  } }, ["param2"] = 0, ["y"] = 5, ["param1"] = 0, ["z"] = 1, ["name"] = "lavatemple:brick" }, { ["x"] = 5, ["meta"] = { ["fields"] = {  }, ["inventory"] = {  } }, ["param2"] = 0, ["y"] = 5, ["param1"] = 0, ["z"] = 5, ["name"] = "lavatemple:brick" }, { ["x"] = 5, ["meta"] = { ["fields"] = {  }, ["inventory"] = {  } }, ["param2"] = 0, ["y"] = 5, ["param1"] = 0, ["z"] = 9, ["name"] = "lavatemple:brick" }, { ["x"] = 5, ["meta"] = { ["fields"] = {  }, ["inventory"] = {  } }, ["param2"] = 0, ["y"] = 5, ["param1"] = 0, ["z"] = 10, ["name"] = "lavatemple:brick" }, { ["x"] = 5, ["meta"] = { ["fields"] = {  }, ["inventory"] = {  } }, ["param2"] = 0, ["y"] = 6, ["param1"] = 0, ["z"] = 0, ["name"] = "lavatemple:brick" }, { ["x"] = 5, ["meta"] = { ["fields"] = {  }, ["inventory"] = {  } }, ["param2"] = 0, ["y"] = 6, ["param1"] = 0, ["z"] = 1, ["name"] = "lavatemple:brick" }, { ["x"] = 5, ["meta"] = { ["fields"] = {  }, ["inventory"] = {  } }, ["param2"] = 0, ["y"] = 6, ["param1"] = 0, ["z"] = 2, ["name"] = "lavatemple:brick" }, { ["x"] = 5, ["meta"] = { ["fields"] = {  }, ["inventory"] = {  } }, ["param2"] = 0, ["y"] = 6, ["param1"] = 0, ["z"] = 3, ["name"] = "lavatemple:brick" }, { ["x"] = 5, ["meta"] = { ["fields"] = {  }, ["inventory"] = {  } }, ["param2"] = 0, ["y"] = 6, ["param1"] = 0, ["z"] = 4, ["name"] = "lavatemple:brick" }, { ["x"] = 5, ["meta"] = { ["fields"] = {  }, ["inventory"] = {  } }, ["param2"] = 0, ["y"] = 6, ["param1"] = 0, ["z"] = 6, ["name"] = "lavatemple:brick" }, { ["x"] = 5, ["meta"] = { ["fields"] = {  }, ["inventory"] = {  } }, ["param2"] = 0, ["y"] = 6, ["param1"] = 0, ["z"] = 7, ["name"] = "lavatemple:brick" }, { ["x"] = 5, ["meta"] = { ["fields"] = {  }, ["inventory"] = {  } }, ["param2"] = 0, ["y"] = 6, ["param1"] = 0, ["z"] = 8, ["name"] = "lavatemple:brick" }, { ["x"] = 5, ["meta"] = { ["fields"] = {  }, ["inventory"] = {  } }, ["param2"] = 0, ["y"] = 6, ["param1"] = 0, ["z"] = 9, ["name"] = "lavatemple:brick" }, { ["x"] = 5, ["meta"] = { ["fields"] = {  }, ["inventory"] = {  } }, ["param2"] = 0, ["y"] = 6, ["param1"] = 0, ["z"] = 10, ["name"] = "lavatemple:brick" }, { ["x"] = 5, ["meta"] = { ["fields"] = {  }, ["inventory"] = {  } }, ["param2"] = 0, ["y"] = 7, ["param1"] = 0, ["z"] = 0, ["name"] = "lavatemple:brick" }, { ["x"] = 5, ["meta"] = { ["fields"] = {  }, ["inventory"] = {  } }, ["param2"] = 0, ["y"] = 7, ["param1"] = 0, ["z"] = 1, ["name"] = "lavatemple:brick" }, { ["x"] = 5, ["meta"] = { ["fields"] = {  }, ["inventory"] = {  } }, ["param2"] = 0, ["y"] = 7, ["param1"] = 0, ["z"] = 2, ["name"] = "lavatemple:brick" }, { ["x"] = 5, ["meta"] = { ["fields"] = {  }, ["inventory"] = {  } }, ["param2"] = 0, ["y"] = 7, ["param1"] = 0, ["z"] = 3, ["name"] = "lavatemple:brick" }, { ["x"] = 5, ["meta"] = { ["fields"] = {  }, ["inventory"] = {  } }, ["param2"] = 0, ["y"] = 7, ["param1"] = 0, ["z"] = 4, ["name"] = "lavatemple:brick" }, { ["x"] = 5, ["meta"] = { ["fields"] = {  }, ["inventory"] = {  } }, ["param2"] = 0, ["y"] = 7, ["param1"] = 0, ["z"] = 6, ["name"] = "lavatemple:brick" }, { ["x"] = 5, ["meta"] = { ["fields"] = {  }, ["inventory"] = {  } }, ["param2"] = 0, ["y"] = 7, ["param1"] = 0, ["z"] = 7, ["name"] = "lavatemple:brick" }, { ["x"] = 5, ["meta"] = { ["fields"] = {  }, ["inventory"] = {  } }, ["param2"] = 0, ["y"] = 7, ["param1"] = 0, ["z"] = 8, ["name"] = "lavatemple:brick" }, { ["x"] = 5, ["meta"] = { ["fields"] = {  }, ["inventory"] = {  } }, ["param2"] = 0, ["y"] = 7, ["param1"] = 0, ["z"] = 9, ["name"] = "lavatemple:brick" }, { ["x"] = 5, ["meta"] = { ["fields"] = {  }, ["inventory"] = {  } }, ["param2"] = 0, ["y"] = 7, ["param1"] = 0, ["z"] = 10, ["name"] = "lavatemple:brick" }, { ["x"] = 5, ["meta"] = { ["fields"] = {  }, ["inventory"] = {  } }, ["param2"] = 0, ["y"] = 8, ["param1"] = 0, ["z"] = 0, ["name"] = "lavatemple:brick" }, { ["x"] = 5, ["meta"] = { ["fields"] = {  }, ["inventory"] = {  } }, ["param2"] = 0, ["y"] = 8, ["param1"] = 0, ["z"] = 1, ["name"] = "lavatemple:brick" }, { ["x"] = 5, ["meta"] = { ["fields"] = {  }, ["inventory"] = {  } }, ["param2"] = 0, ["y"] = 8, ["param1"] = 0, ["z"] = 2, ["name"] = "lavatemple:brick" }, { ["x"] = 5, ["meta"] = { ["fields"] = {  }, ["inventory"] = {  } }, ["param2"] = 0, ["y"] = 8, ["param1"] = 0, ["z"] = 3, ["name"] = "lavatemple:brick" }, { ["x"] = 5, ["meta"] = { ["fields"] = {  }, ["inventory"] = {  } }, ["param2"] = 0, ["y"] = 8, ["param1"] = 0, ["z"] = 4, ["name"] = "lavatemple:brick" }, { ["x"] = 5, ["meta"] = { ["fields"] = {  }, ["inventory"] = {  } }, ["param2"] = 0, ["y"] = 8, ["param1"] = 0, ["z"] = 5, ["name"] = "lavatemple:brick" }, { ["x"] = 5, ["meta"] = { ["fields"] = {  }, ["inventory"] = {  } }, ["param2"] = 0, ["y"] = 8, ["param1"] = 0, ["z"] = 6, ["name"] = "lavatemple:brick" }, { ["x"] = 5, ["meta"] = { ["fields"] = {  }, ["inventory"] = {  } }, ["param2"] = 0, ["y"] = 8, ["param1"] = 0, ["z"] = 7, ["name"] = "lavatemple:brick" }, { ["x"] = 5, ["meta"] = { ["fields"] = {  }, ["inventory"] = {  } }, ["param2"] = 0, ["y"] = 8, ["param1"] = 0, ["z"] = 8, ["name"] = "lavatemple:brick" }, { ["x"] = 5, ["meta"] = { ["fields"] = {  }, ["inventory"] = {  } }, ["param2"] = 0, ["y"] = 8, ["param1"] = 0, ["z"] = 9, ["name"] = "lavatemple:brick" }, { ["x"] = 5, ["meta"] = { ["fields"] = {  }, ["inventory"] = {  } }, ["param2"] = 0, ["y"] = 8, ["param1"] = 0, ["z"] = 10, ["name"] = "lavatemple:brick" }, { ["x"] = 6, ["meta"] = { ["fields"] = {  }, ["inventory"] = {  } }, ["param2"] = 0, ["y"] = 0, ["param1"] = 0, ["z"] = 0, ["name"] = "lavatemple:brick" }, { ["x"] = 6, ["meta"] = { ["fields"] = {  }, ["inventory"] = {  } }, ["param2"] = 0, ["y"] = 0, ["param1"] = 0, ["z"] = 1, ["name"] = "lavatemple:brick" }, { ["x"] = 6, ["meta"] = { ["fields"] = {  }, ["inventory"] = {  } }, ["param2"] = 0, ["y"] = 0, ["param1"] = 0, ["z"] = 2, ["name"] = "lavatemple:brick" }, { ["x"] = 6, ["meta"] = { ["fields"] = {  }, ["inventory"] = {  } }, ["param2"] = 0, ["y"] = 0, ["param1"] = 0, ["z"] = 3, ["name"] = "lavatemple:brick" }, { ["x"] = 6, ["meta"] = { ["fields"] = {  }, ["inventory"] = {  } }, ["param2"] = 0, ["y"] = 0, ["param1"] = 0, ["z"] = 4, ["name"] = "lavatemple:brick" }, { ["x"] = 6, ["meta"] = { ["fields"] = {  }, ["inventory"] = {  } }, ["param2"] = 0, ["y"] = 0, ["param1"] = 0, ["z"] = 5, ["name"] = "lavatemple:brick" }, { ["x"] = 6, ["meta"] = { ["fields"] = {  }, ["inventory"] = {  } }, ["param2"] = 0, ["y"] = 0, ["param1"] = 0, ["z"] = 6, ["name"] = "lavatemple:brick" }, { ["x"] = 6, ["meta"] = { ["fields"] = {  }, ["inventory"] = {  } }, ["param2"] = 0, ["y"] = 0, ["param1"] = 0, ["z"] = 7, ["name"] = "lavatemple:brick" }, { ["x"] = 6, ["meta"] = { ["fields"] = {  }, ["inventory"] = {  } }, ["param2"] = 0, ["y"] = 0, ["param1"] = 0, ["z"] = 8, ["name"] = "lavatemple:brick" }, { ["x"] = 6, ["meta"] = { ["fields"] = {  }, ["inventory"] = {  } }, ["param2"] = 0, ["y"] = 0, ["param1"] = 0, ["z"] = 9, ["name"] = "lavatemple:brick" }, { ["x"] = 6, ["meta"] = { ["fields"] = {  }, ["inventory"] = {  } }, ["param2"] = 0, ["y"] = 0, ["param1"] = 0, ["z"] = 10, ["name"] = "lavatemple:brick" }, { ["x"] = 6, ["meta"] = { ["fields"] = {  }, ["inventory"] = {  } }, ["param2"] = 0, ["y"] = 1, ["param1"] = 0, ["z"] = 0, ["name"] = "lavatemple:brick" }, { ["x"] = 6, ["meta"] = { ["fields"] = {  }, ["inventory"] = {  } }, ["param2"] = 0, ["y"] = 1, ["param1"] = 0, ["z"] = 1, ["name"] = "lavatemple:brick" }, { ["x"] = 6, ["meta"] = { ["fields"] = {  }, ["inventory"] = {  } }, ["param2"] = 0, ["y"] = 1, ["param1"] = 0, ["z"] = 2, ["name"] = "lavatemple:brick" }, { ["x"] = 6, ["meta"] = { ["fields"] = {  }, ["inventory"] = {  } }, ["param2"] = 0, ["y"] = 1, ["param1"] = 0, ["z"] = 3, ["name"] = "lavatemple:brick" }, { ["x"] = 6, ["meta"] = { ["fields"] = {  }, ["inventory"] = {  } }, ["param2"] = 0, ["y"] = 1, ["param1"] = 0, ["z"] = 4, ["name"] = "lavatemple:brick" }, { ["x"] = 6, ["meta"] = { ["fields"] = {  }, ["inventory"] = {  } }, ["param2"] = 3, ["y"] = 1, ["param1"] = 187, ["z"] = 5, ["name"] = "stairs:stair_lavatemple_brick" }, { ["x"] = 6, ["meta"] = { ["fields"] = {  }, ["inventory"] = {  } }, ["param2"] = 0, ["y"] = 1, ["param1"] = 0, ["z"] = 6, ["name"] = "lavatemple:brick" }, { ["x"] = 6, ["meta"] = { ["fields"] = {  }, ["inventory"] = {  } }, ["param2"] = 0, ["y"] = 1, ["param1"] = 0, ["z"] = 7, ["name"] = "lavatemple:brick" }, { ["x"] = 6, ["meta"] = { ["fields"] = {  }, ["inventory"] = {  } }, ["param2"] = 0, ["y"] = 1, ["param1"] = 0, ["z"] = 8, ["name"] = "lavatemple:brick" }, { ["x"] = 6, ["meta"] = { ["fields"] = {  }, ["inventory"] = {  } }, ["param2"] = 0, ["y"] = 1, ["param1"] = 0, ["z"] = 9, ["name"] = "lavatemple:brick" }, { ["x"] = 6, ["meta"] = { ["fields"] = {  }, ["inventory"] = {  } }, ["param2"] = 0, ["y"] = 1, ["param1"] = 0, ["z"] = 10, ["name"] = "lavatemple:brick" }, { ["x"] = 6, ["meta"] = { ["fields"] = {  }, ["inventory"] = {  } }, ["param2"] = 0, ["y"] = 2, ["param1"] = 0, ["z"] = 0, ["name"] = "lavatemple:brick" }, { ["x"] = 6, ["meta"] = { ["fields"] = {  }, ["inventory"] = {  } }, ["param2"] = 0, ["y"] = 2, ["param1"] = 0, ["z"] = 1, ["name"] = "lavatemple:brick" }, { ["x"] = 6, ["meta"] = { ["fields"] = {  }, ["inventory"] = {  } }, ["param2"] = 0, ["y"] = 2, ["param1"] = 0, ["z"] = 2, ["name"] = "lavatemple:brick" }, { ["x"] = 6, ["meta"] = { ["fields"] = {  }, ["inventory"] = {  } }, ["param2"] = 0, ["y"] = 2, ["param1"] = 0, ["z"] = 3, ["name"] = "default:lava_source" }, { ["x"] = 6, ["meta"] = { ["fields"] = {  }, ["inventory"] = {  } }, ["param2"] = 0, ["y"] = 2, ["param1"] = 204, ["z"] = 4, ["name"] = "default:obsidian_glass" }, { ["x"] = 6, ["meta"] = { ["fields"] = {  }, ["inventory"] = {  } }, ["param2"] = 0, ["y"] = 2, ["param1"] = 204, ["z"] = 6, ["name"] = "default:obsidian_glass" }, { ["x"] = 6, ["meta"] = { ["fields"] = {  }, ["inventory"] = {  } }, ["param2"] = 0, ["y"] = 2, ["param1"] = 0, ["z"] = 7, ["name"] = "default:lava_source" }, { ["x"] = 6, ["meta"] = { ["fields"] = {  }, ["inventory"] = {  } }, ["param2"] = 0, ["y"] = 2, ["param1"] = 0, ["z"] = 8, ["name"] = "lavatemple:brick" }, { ["x"] = 6, ["meta"] = { ["fields"] = {  }, ["inventory"] = {  } }, ["param2"] = 0, ["y"] = 2, ["param1"] = 0, ["z"] = 9, ["name"] = "lavatemple:brick" }, { ["x"] = 6, ["meta"] = { ["fields"] = {  }, ["inventory"] = {  } }, ["param2"] = 0, ["y"] = 2, ["param1"] = 0, ["z"] = 10, ["name"] = "lavatemple:brick" }, { ["x"] = 6, ["meta"] = { ["fields"] = {  }, ["inventory"] = {  } }, ["param2"] = 0, ["y"] = 3, ["param1"] = 0, ["z"] = 0, ["name"] = "lavatemple:brick" }, { ["x"] = 6, ["meta"] = { ["fields"] = {  }, ["inventory"] = {  } }, ["param2"] = 0, ["y"] = 3, ["param1"] = 0, ["z"] = 1, ["name"] = "lavatemple:brick" }, { ["x"] = 6, ["meta"] = { ["fields"] = {  }, ["inventory"] = {  } }, ["param2"] = 0, ["y"] = 3, ["param1"] = 0, ["z"] = 2, ["name"] = "lavatemple:brick" }, { ["x"] = 6, ["meta"] = { ["fields"] = {  }, ["inventory"] = {  } }, ["param2"] = 0, ["y"] = 3, ["param1"] = 0, ["z"] = 3, ["name"] = "lavatemple:brick" }, { ["x"] = 6, ["meta"] = { ["fields"] = {  }, ["inventory"] = {  } }, ["param2"] = 0, ["y"] = 3, ["param1"] = 0, ["z"] = 4, ["name"] = "lavatemple:brick" }, { ["x"] = 6, ["meta"] = { ["fields"] = {  }, ["inventory"] = {  } }, ["param2"] = 0, ["y"] = 3, ["param1"] = 0, ["z"] = 6, ["name"] = "lavatemple:brick" }, { ["x"] = 6, ["meta"] = { ["fields"] = {  }, ["inventory"] = {  } }, ["param2"] = 0, ["y"] = 3, ["param1"] = 0, ["z"] = 7, ["name"] = "lavatemple:brick" }, { ["x"] = 6, ["meta"] = { ["fields"] = {  }, ["inventory"] = {  } }, ["param2"] = 0, ["y"] = 3, ["param1"] = 0, ["z"] = 8, ["name"] = "lavatemple:brick" }, { ["x"] = 6, ["meta"] = { ["fields"] = {  }, ["inventory"] = {  } }, ["param2"] = 0, ["y"] = 3, ["param1"] = 0, ["z"] = 9, ["name"] = "lavatemple:brick" }, { ["x"] = 6, ["meta"] = { ["fields"] = {  }, ["inventory"] = {  } }, ["param2"] = 0, ["y"] = 3, ["param1"] = 0, ["z"] = 10, ["name"] = "lavatemple:brick" }, { ["x"] = 6, ["meta"] = { ["fields"] = {  }, ["inventory"] = {  } }, ["param2"] = 0, ["y"] = 4, ["param1"] = 0, ["z"] = 0, ["name"] = "lavatemple:brick" }, { ["x"] = 6, ["meta"] = { ["fields"] = {  }, ["inventory"] = {  } }, ["param2"] = 0, ["y"] = 4, ["param1"] = 0, ["z"] = 1, ["name"] = "lavatemple:brick" }, { ["x"] = 6, ["meta"] = { ["fields"] = {  }, ["inventory"] = {  } }, ["param2"] = 0, ["y"] = 4, ["param1"] = 0, ["z"] = 2, ["name"] = "lavatemple:brick" }, { ["x"] = 6, ["meta"] = { ["fields"] = {  }, ["inventory"] = {  } }, ["param2"] = 0, ["y"] = 4, ["param1"] = 0, ["z"] = 3, ["name"] = "lavatemple:brick" }, { ["x"] = 6, ["meta"] = { ["fields"] = {  }, ["inventory"] = {  } }, ["param2"] = 0, ["y"] = 4, ["param1"] = 0, ["z"] = 4, ["name"] = "lavatemple:brick" }, { ["x"] = 6, ["meta"] = { ["fields"] = {  }, ["inventory"] = {  } }, ["param2"] = 0, ["y"] = 4, ["param1"] = 0, ["z"] = 5, ["name"] = "lavatemple:brick" }, { ["x"] = 6, ["meta"] = { ["fields"] = {  }, ["inventory"] = {  } }, ["param2"] = 0, ["y"] = 4, ["param1"] = 0, ["z"] = 6, ["name"] = "lavatemple:brick" }, { ["x"] = 6, ["meta"] = { ["fields"] = {  }, ["inventory"] = {  } }, ["param2"] = 0, ["y"] = 4, ["param1"] = 0, ["z"] = 7, ["name"] = "lavatemple:brick" }, { ["x"] = 6, ["meta"] = { ["fields"] = {  }, ["inventory"] = {  } }, ["param2"] = 0, ["y"] = 4, ["param1"] = 0, ["z"] = 8, ["name"] = "lavatemple:brick" }, { ["x"] = 6, ["meta"] = { ["fields"] = {  }, ["inventory"] = {  } }, ["param2"] = 0, ["y"] = 4, ["param1"] = 0, ["z"] = 9, ["name"] = "lavatemple:brick" }, { ["x"] = 6, ["meta"] = { ["fields"] = {  }, ["inventory"] = {  } }, ["param2"] = 0, ["y"] = 4, ["param1"] = 0, ["z"] = 10, ["name"] = "lavatemple:brick" }, { ["x"] = 6, ["meta"] = { ["fields"] = {  }, ["inventory"] = {  } }, ["param2"] = 0, ["y"] = 5, ["param1"] = 0, ["z"] = 0, ["name"] = "lavatemple:brick" }, { ["x"] = 6, ["meta"] = { ["fields"] = {  }, ["inventory"] = {  } }, ["param2"] = 0, ["y"] = 5, ["param1"] = 0, ["z"] = 1, ["name"] = "lavatemple:brick" }, { ["x"] = 6, ["meta"] = { ["fields"] = {  }, ["inventory"] = {  } }, ["param2"] = 0, ["y"] = 5, ["param1"] = 0, ["z"] = 2, ["name"] = "lavatemple:brick" }, { ["x"] = 6, ["meta"] = { ["fields"] = {  }, ["inventory"] = {  } }, ["param2"] = 0, ["y"] = 5, ["param1"] = 0, ["z"] = 3, ["name"] = "lavatemple:brick" }, { ["x"] = 6, ["meta"] = { ["fields"] = {  }, ["inventory"] = {  } }, ["param2"] = 0, ["y"] = 5, ["param1"] = 0, ["z"] = 4, ["name"] = "lavatemple:brick" }, { ["x"] = 6, ["meta"] = { ["fields"] = {  }, ["inventory"] = {  } }, ["param2"] = 0, ["y"] = 5, ["param1"] = 0, ["z"] = 5, ["name"] = "lavatemple:brick" }, { ["x"] = 6, ["meta"] = { ["fields"] = {  }, ["inventory"] = {  } }, ["param2"] = 0, ["y"] = 5, ["param1"] = 0, ["z"] = 6, ["name"] = "lavatemple:brick" }, { ["x"] = 6, ["meta"] = { ["fields"] = {  }, ["inventory"] = {  } }, ["param2"] = 0, ["y"] = 5, ["param1"] = 0, ["z"] = 7, ["name"] = "lavatemple:brick" }, { ["x"] = 6, ["meta"] = { ["fields"] = {  }, ["inventory"] = {  } }, ["param2"] = 0, ["y"] = 5, ["param1"] = 0, ["z"] = 8, ["name"] = "lavatemple:brick" }, { ["x"] = 6, ["meta"] = { ["fields"] = {  }, ["inventory"] = {  } }, ["param2"] = 0, ["y"] = 5, ["param1"] = 0, ["z"] = 9, ["name"] = "lavatemple:brick" }, { ["x"] = 6, ["meta"] = { ["fields"] = {  }, ["inventory"] = {  } }, ["param2"] = 0, ["y"] = 5, ["param1"] = 0, ["z"] = 10, ["name"] = "lavatemple:brick" }, { ["x"] = 6, ["meta"] = { ["fields"] = {  }, ["inventory"] = {  } }, ["param2"] = 0, ["y"] = 6, ["param1"] = 0, ["z"] = 0, ["name"] = "lavatemple:brick" }, { ["x"] = 6, ["meta"] = { ["fields"] = {  }, ["inventory"] = {  } }, ["param2"] = 0, ["y"] = 6, ["param1"] = 0, ["z"] = 1, ["name"] = "lavatemple:brick" }, { ["x"] = 6, ["meta"] = { ["fields"] = {  }, ["inventory"] = {  } }, ["param2"] = 0, ["y"] = 6, ["param1"] = 0, ["z"] = 2, ["name"] = "lavatemple:brick" }, { ["x"] = 6, ["meta"] = { ["fields"] = {  }, ["inventory"] = {  } }, ["param2"] = 0, ["y"] = 6, ["param1"] = 0, ["z"] = 3, ["name"] = "lavatemple:brick" }, { ["x"] = 6, ["meta"] = { ["fields"] = {  }, ["inventory"] = {  } }, ["param2"] = 0, ["y"] = 6, ["param1"] = 0, ["z"] = 7, ["name"] = "lavatemple:brick" }, { ["x"] = 6, ["meta"] = { ["fields"] = {  }, ["inventory"] = {  } }, ["param2"] = 0, ["y"] = 6, ["param1"] = 0, ["z"] = 8, ["name"] = "lavatemple:brick" }, { ["x"] = 6, ["meta"] = { ["fields"] = {  }, ["inventory"] = {  } }, ["param2"] = 0, ["y"] = 6, ["param1"] = 0, ["z"] = 9, ["name"] = "lavatemple:brick" }, { ["x"] = 6, ["meta"] = { ["fields"] = {  }, ["inventory"] = {  } }, ["param2"] = 0, ["y"] = 6, ["param1"] = 0, ["z"] = 10, ["name"] = "lavatemple:brick" }, { ["x"] = 6, ["meta"] = { ["fields"] = {  }, ["inventory"] = {  } }, ["param2"] = 0, ["y"] = 7, ["param1"] = 0, ["z"] = 0, ["name"] = "lavatemple:brick" }, { ["x"] = 6, ["meta"] = { ["fields"] = {  }, ["inventory"] = {  } }, ["param2"] = 0, ["y"] = 7, ["param1"] = 0, ["z"] = 1, ["name"] = "lavatemple:brick" }, { ["x"] = 6, ["meta"] = { ["fields"] = {  }, ["inventory"] = {  } }, ["param2"] = 0, ["y"] = 7, ["param1"] = 0, ["z"] = 2, ["name"] = "lavatemple:brick" }, { ["x"] = 6, ["meta"] = { ["fields"] = {  }, ["inventory"] = {  } }, ["param2"] = 0, ["y"] = 7, ["param1"] = 0, ["z"] = 3, ["name"] = "lavatemple:brick" }, { ["x"] = 6, ["meta"] = { ["fields"] = {  }, ["inventory"] = {  } }, ["param2"] = 0, ["y"] = 7, ["param1"] = 0, ["z"] = 7, ["name"] = "lavatemple:brick" }, { ["x"] = 6, ["meta"] = { ["fields"] = {  }, ["inventory"] = {  } }, ["param2"] = 0, ["y"] = 7, ["param1"] = 0, ["z"] = 8, ["name"] = "lavatemple:brick" }, { ["x"] = 6, ["meta"] = { ["fields"] = {  }, ["inventory"] = {  } }, ["param2"] = 0, ["y"] = 7, ["param1"] = 0, ["z"] = 9, ["name"] = "lavatemple:brick" }, { ["x"] = 6, ["meta"] = { ["fields"] = {  }, ["inventory"] = {  } }, ["param2"] = 0, ["y"] = 7, ["param1"] = 0, ["z"] = 10, ["name"] = "lavatemple:brick" }, { ["x"] = 6, ["meta"] = { ["fields"] = {  }, ["inventory"] = {  } }, ["param2"] = 0, ["y"] = 8, ["param1"] = 0, ["z"] = 0, ["name"] = "lavatemple:brick" }, { ["x"] = 6, ["meta"] = { ["fields"] = {  }, ["inventory"] = {  } }, ["param2"] = 0, ["y"] = 8, ["param1"] = 0, ["z"] = 1, ["name"] = "lavatemple:brick" }, { ["x"] = 6, ["meta"] = { ["fields"] = {  }, ["inventory"] = {  } }, ["param2"] = 0, ["y"] = 8, ["param1"] = 0, ["z"] = 2, ["name"] = "lavatemple:brick" }, { ["x"] = 6, ["meta"] = { ["fields"] = {  }, ["inventory"] = {  } }, ["param2"] = 0, ["y"] = 8, ["param1"] = 0, ["z"] = 3, ["name"] = "lavatemple:brick" }, { ["x"] = 6, ["meta"] = { ["fields"] = {  }, ["inventory"] = {  } }, ["param2"] = 0, ["y"] = 8, ["param1"] = 0, ["z"] = 4, ["name"] = "lavatemple:brick" }, { ["x"] = 6, ["meta"] = { ["fields"] = {  }, ["inventory"] = {  } }, ["param2"] = 0, ["y"] = 8, ["param1"] = 0, ["z"] = 5, ["name"] = "lavatemple:brick" }, { ["x"] = 6, ["meta"] = { ["fields"] = {  }, ["inventory"] = {  } }, ["param2"] = 0, ["y"] = 8, ["param1"] = 0, ["z"] = 6, ["name"] = "lavatemple:brick" }, { ["x"] = 6, ["meta"] = { ["fields"] = {  }, ["inventory"] = {  } }, ["param2"] = 0, ["y"] = 8, ["param1"] = 0, ["z"] = 7, ["name"] = "lavatemple:brick" }, { ["x"] = 6, ["meta"] = { ["fields"] = {  }, ["inventory"] = {  } }, ["param2"] = 0, ["y"] = 8, ["param1"] = 0, ["z"] = 8, ["name"] = "lavatemple:brick" }, { ["x"] = 6, ["meta"] = { ["fields"] = {  }, ["inventory"] = {  } }, ["param2"] = 0, ["y"] = 8, ["param1"] = 0, ["z"] = 9, ["name"] = "lavatemple:brick" }, { ["x"] = 6, ["meta"] = { ["fields"] = {  }, ["inventory"] = {  } }, ["param2"] = 0, ["y"] = 8, ["param1"] = 0, ["z"] = 10, ["name"] = "lavatemple:brick" }, { ["x"] = 7, ["meta"] = { ["fields"] = {  }, ["inventory"] = {  } }, ["param2"] = 0, ["y"] = 0, ["param1"] = 0, ["z"] = 0, ["name"] = "lavatemple:brick" }, { ["x"] = 7, ["meta"] = { ["fields"] = {  }, ["inventory"] = {  } }, ["param2"] = 0, ["y"] = 0, ["param1"] = 0, ["z"] = 1, ["name"] = "lavatemple:brick" }, { ["x"] = 7, ["meta"] = { ["fields"] = {  }, ["inventory"] = {  } }, ["param2"] = 0, ["y"] = 0, ["param1"] = 0, ["z"] = 2, ["name"] = "lavatemple:brick" }, { ["x"] = 7, ["meta"] = { ["fields"] = {  }, ["inventory"] = {  } }, ["param2"] = 0, ["y"] = 0, ["param1"] = 0, ["z"] = 3, ["name"] = "lavatemple:brick" }, { ["x"] = 7, ["meta"] = { ["fields"] = {  }, ["inventory"] = {  } }, ["param2"] = 0, ["y"] = 0, ["param1"] = 0, ["z"] = 4, ["name"] = "lavatemple:brick" }, { ["x"] = 7, ["meta"] = { ["fields"] = {  }, ["inventory"] = {  } }, ["param2"] = 0, ["y"] = 0, ["param1"] = 0, ["z"] = 5, ["name"] = "lavatemple:brick" }, { ["x"] = 7, ["meta"] = { ["fields"] = {  }, ["inventory"] = {  } }, ["param2"] = 0, ["y"] = 0, ["param1"] = 0, ["z"] = 6, ["name"] = "lavatemple:brick" }, { ["x"] = 7, ["meta"] = { ["fields"] = {  }, ["inventory"] = {  } }, ["param2"] = 0, ["y"] = 0, ["param1"] = 0, ["z"] = 7, ["name"] = "lavatemple:brick" }, { ["x"] = 7, ["meta"] = { ["fields"] = {  }, ["inventory"] = {  } }, ["param2"] = 0, ["y"] = 0, ["param1"] = 0, ["z"] = 8, ["name"] = "lavatemple:brick" }, { ["x"] = 7, ["meta"] = { ["fields"] = {  }, ["inventory"] = {  } }, ["param2"] = 0, ["y"] = 0, ["param1"] = 0, ["z"] = 9, ["name"] = "lavatemple:brick" }, { ["x"] = 7, ["meta"] = { ["fields"] = {  }, ["inventory"] = {  } }, ["param2"] = 0, ["y"] = 0, ["param1"] = 0, ["z"] = 10, ["name"] = "lavatemple:brick" }, { ["x"] = 7, ["meta"] = { ["fields"] = {  }, ["inventory"] = {  } }, ["param2"] = 0, ["y"] = 1, ["param1"] = 0, ["z"] = 0, ["name"] = "lavatemple:brick" }, { ["x"] = 7, ["meta"] = { ["fields"] = {  }, ["inventory"] = {  } }, ["param2"] = 0, ["y"] = 1, ["param1"] = 0, ["z"] = 1, ["name"] = "lavatemple:brick" }, { ["x"] = 7, ["meta"] = { ["fields"] = {  }, ["inventory"] = {  } }, ["param2"] = 0, ["y"] = 1, ["param1"] = 0, ["z"] = 2, ["name"] = "lavatemple:brick" }, { ["x"] = 7, ["meta"] = { ["fields"] = {  }, ["inventory"] = {  } }, ["param2"] = 0, ["y"] = 1, ["param1"] = 0, ["z"] = 3, ["name"] = "lavatemple:brick" }, { ["x"] = 7, ["meta"] = { ["fields"] = {  }, ["inventory"] = {  } }, ["param2"] = 0, ["y"] = 1, ["param1"] = 0, ["z"] = 4, ["name"] = "lavatemple:brick" }, { ["x"] = 7, ["meta"] = { ["fields"] = {  }, ["inventory"] = {  } }, ["param2"] = 0, ["y"] = 1, ["param1"] = 0, ["z"] = 6, ["name"] = "lavatemple:brick" }, { ["x"] = 7, ["meta"] = { ["fields"] = {  }, ["inventory"] = {  } }, ["param2"] = 0, ["y"] = 1, ["param1"] = 0, ["z"] = 7, ["name"] = "lavatemple:brick" }, { ["x"] = 7, ["meta"] = { ["fields"] = {  }, ["inventory"] = {  } }, ["param2"] = 0, ["y"] = 1, ["param1"] = 0, ["z"] = 8, ["name"] = "lavatemple:brick" }, { ["x"] = 7, ["meta"] = { ["fields"] = {  }, ["inventory"] = {  } }, ["param2"] = 0, ["y"] = 1, ["param1"] = 0, ["z"] = 9, ["name"] = "lavatemple:brick" }, { ["x"] = 7, ["meta"] = { ["fields"] = {  }, ["inventory"] = {  } }, ["param2"] = 0, ["y"] = 1, ["param1"] = 0, ["z"] = 10, ["name"] = "lavatemple:brick" }, { ["x"] = 7, ["meta"] = { ["fields"] = {  }, ["inventory"] = {  } }, ["param2"] = 0, ["y"] = 2, ["param1"] = 0, ["z"] = 0, ["name"] = "lavatemple:brick" }, { ["x"] = 7, ["meta"] = { ["fields"] = {  }, ["inventory"] = {  } }, ["param2"] = 0, ["y"] = 2, ["param1"] = 0, ["z"] = 1, ["name"] = "lavatemple:brick" }, { ["x"] = 7, ["meta"] = { ["fields"] = {  }, ["inventory"] = {  } }, ["param2"] = 0, ["y"] = 2, ["param1"] = 0, ["z"] = 2, ["name"] = "lavatemple:brick" }, { ["x"] = 7, ["meta"] = { ["fields"] = {  }, ["inventory"] = {  } }, ["param2"] = 0, ["y"] = 2, ["param1"] = 0, ["z"] = 3, ["name"] = "default:lava_source" }, { ["x"] = 7, ["meta"] = { ["fields"] = {  }, ["inventory"] = {  } }, ["param2"] = 0, ["y"] = 2, ["param1"] = 204, ["z"] = 4, ["name"] = "default:obsidian_glass" }, { ["x"] = 7, ["meta"] = { ["fields"] = {  }, ["inventory"] = {  } }, ["param2"] = 0, ["y"] = 2, ["param1"] = 204, ["z"] = 6, ["name"] = "default:obsidian_glass" }, { ["x"] = 7, ["meta"] = { ["fields"] = {  }, ["inventory"] = {  } }, ["param2"] = 0, ["y"] = 2, ["param1"] = 0, ["z"] = 7, ["name"] = "default:lava_source" }, { ["x"] = 7, ["meta"] = { ["fields"] = {  }, ["inventory"] = {  } }, ["param2"] = 0, ["y"] = 2, ["param1"] = 0, ["z"] = 8, ["name"] = "lavatemple:brick" }, { ["x"] = 7, ["meta"] = { ["fields"] = {  }, ["inventory"] = {  } }, ["param2"] = 0, ["y"] = 2, ["param1"] = 0, ["z"] = 9, ["name"] = "lavatemple:brick" }, { ["x"] = 7, ["meta"] = { ["fields"] = {  }, ["inventory"] = {  } }, ["param2"] = 0, ["y"] = 2, ["param1"] = 0, ["z"] = 10, ["name"] = "lavatemple:brick" }, { ["x"] = 7, ["meta"] = { ["fields"] = {  }, ["inventory"] = {  } }, ["param2"] = 0, ["y"] = 3, ["param1"] = 0, ["z"] = 0, ["name"] = "lavatemple:brick" }, { ["x"] = 7, ["meta"] = { ["fields"] = {  }, ["inventory"] = {  } }, ["param2"] = 0, ["y"] = 3, ["param1"] = 0, ["z"] = 1, ["name"] = "lavatemple:brick" }, { ["x"] = 7, ["meta"] = { ["fields"] = {  }, ["inventory"] = {  } }, ["param2"] = 0, ["y"] = 3, ["param1"] = 0, ["z"] = 2, ["name"] = "lavatemple:brick" }, { ["x"] = 7, ["meta"] = { ["fields"] = {  }, ["inventory"] = {  } }, ["param2"] = 0, ["y"] = 3, ["param1"] = 0, ["z"] = 3, ["name"] = "lavatemple:brick" }, { ["x"] = 7, ["meta"] = { ["fields"] = {  }, ["inventory"] = {  } }, ["param2"] = 0, ["y"] = 3, ["param1"] = 0, ["z"] = 4, ["name"] = "lavatemple:brick" }, { ["x"] = 7, ["meta"] = { ["fields"] = {  }, ["inventory"] = {  } }, ["param2"] = 0, ["y"] = 3, ["param1"] = 0, ["z"] = 6, ["name"] = "lavatemple:brick" }, { ["x"] = 7, ["meta"] = { ["fields"] = {  }, ["inventory"] = {  } }, ["param2"] = 0, ["y"] = 3, ["param1"] = 0, ["z"] = 7, ["name"] = "lavatemple:brick" }, { ["x"] = 7, ["meta"] = { ["fields"] = {  }, ["inventory"] = {  } }, ["param2"] = 0, ["y"] = 3, ["param1"] = 0, ["z"] = 8, ["name"] = "lavatemple:brick" }, { ["x"] = 7, ["meta"] = { ["fields"] = {  }, ["inventory"] = {  } }, ["param2"] = 0, ["y"] = 3, ["param1"] = 0, ["z"] = 9, ["name"] = "lavatemple:brick" }, { ["x"] = 7, ["meta"] = { ["fields"] = {  }, ["inventory"] = {  } }, ["param2"] = 0, ["y"] = 3, ["param1"] = 0, ["z"] = 10, ["name"] = "lavatemple:brick" }, { ["x"] = 7, ["meta"] = { ["fields"] = {  }, ["inventory"] = {  } }, ["param2"] = 0, ["y"] = 4, ["param1"] = 0, ["z"] = 0, ["name"] = "lavatemple:brick" }, { ["x"] = 7, ["meta"] = { ["fields"] = {  }, ["inventory"] = {  } }, ["param2"] = 0, ["y"] = 4, ["param1"] = 0, ["z"] = 1, ["name"] = "lavatemple:brick" }, { ["x"] = 7, ["meta"] = { ["fields"] = {  }, ["inventory"] = {  } }, ["param2"] = 0, ["y"] = 4, ["param1"] = 0, ["z"] = 2, ["name"] = "lavatemple:brick" }, { ["x"] = 7, ["meta"] = { ["fields"] = {  }, ["inventory"] = {  } }, ["param2"] = 0, ["y"] = 4, ["param1"] = 0, ["z"] = 3, ["name"] = "lavatemple:brick" }, { ["x"] = 7, ["meta"] = { ["fields"] = {  }, ["inventory"] = {  } }, ["param2"] = 0, ["y"] = 4, ["param1"] = 0, ["z"] = 4, ["name"] = "lavatemple:brick" }, { ["x"] = 7, ["meta"] = { ["fields"] = {  }, ["inventory"] = {  } }, ["param2"] = 0, ["y"] = 4, ["param1"] = 0, ["z"] = 5, ["name"] = "lavatemple:brick" }, { ["x"] = 7, ["meta"] = { ["fields"] = {  }, ["inventory"] = {  } }, ["param2"] = 0, ["y"] = 4, ["param1"] = 0, ["z"] = 6, ["name"] = "lavatemple:brick" }, { ["x"] = 7, ["meta"] = { ["fields"] = {  }, ["inventory"] = {  } }, ["param2"] = 0, ["y"] = 4, ["param1"] = 0, ["z"] = 7, ["name"] = "lavatemple:brick" }, { ["x"] = 7, ["meta"] = { ["fields"] = {  }, ["inventory"] = {  } },